Workbook

Sheet Company Cover
C2: ADANI ENERGY SOLUTIONS LTD.
C3: NSE/BSE Listed | Sector: Power | Industry: Power Transmission & Distribution | Part of Adani Group
B14: ABOUT THE COMPANY
B15: Adani Energy Solutions Ltd (AESL) is India's largest private power transmission company and part of the Adani Group. AESL operates across four segments: Power Transmission (~40%), Power Distribution (~50%), Smart Metering (~3%), and Trading/Others (~7%). The company serves 13 Mn+ consumers in Mumbai & Mundra SEZ and operates 36 transmission assets across 16 states with 27,949 ckm network. AESL's under-construction transmission pipeline stands at ~₹71,779 Cr with a smart metering pipeline of ₹29,519 Cr across 24.6 Mn meters. The company targets 30,000 ckm of transmission lines by 2030, backed by planned capex of ₹22,000 Cr (FY27) and ₹23,000 Cr (FY28).
B19: REGISTERED OFFICE
B21: Address: Shantigram, Near Vaishno Devi Circle, S.G. Highway, Khodiyar, Ahmedabad, Gujarat – 382421
B23: S.No. | C23: Name of Entity | D23: Type
B24: 1 | C24: Adani Energy Solutions Limited | D24: Holding Company
B25: 2 | C25: Adani Transmission Step-One Limited | D25: Wholly Owned Subsidiary
B26: 3 | C26: Adani Transmission Limited | D26: Wholly Owned Subsidiary
B27: 4 | C27: Adani Electricity Mumbai Limited | D27: Subsidiary
B28: 5 | C28: Adani Electricity Navi Mumbai Limited | D28: Subsidiary
B29: 6 | C29: Adani Electricity Services Limited | D29: Subsidiary
B30: 7 | C30: Adani Electricity Mulund Limited | D30: Subsidiary
B31: 8 | C31: Maharashtra Eastern Grid Power Transmission Company Limited | D31: Subsidiary
B32: 9 | C32: Kharghar Vikhroli Transmission Private Limited | D32: Subsidiary
B33: 10 | C33: Western Transmission (Maharashtra) Private Limited | D33: Subsidiary
B34: 11 | C34: Maru Transmission Service Company Limited | D34: Subsidiary
B35: 12 | C35: Fatehgarh Bhadla Transmission Limited | D35: Subsidiary
... B48: 25 | C48: Various Project SPVs acquired through TBCB bidding routes | D48: Subsidiaries

Sheet Promoters
B1: Shareholding Pattern
B2: Adani Energy Solutions Ltd
B3: Scrip Code : 539254 | C3: Quarter Ending : Mar-26
B4: Statement showing shareholding pattern of the Promoter and Promoter Group
B5: Category of shareholder | C5: Entity Type | D5: Nos. of shareholders | E5: No. of fully paid up equity shares held | F5: Total nos. shares held | G5: Shareholding as a % of total no. of shares (calculated as per SCRR, 1957)As a % of (A+B+C2) | H5: Number of Voting Rights held in each class of securities | J5: Total No. Of shares on fully diluted basis (including warrants, ESOP, Convertible Securities etc.) | K5: Shareholding , as a % assuming full conversion of convertible securities ( as a percentage of diluted share capital)As a % of (A+B+C2) | L5: Number of Shares pledged or otherwise encumbered | N5: Total Number of Shares encumbered | P5: Number of equity shares held in dematerialized form
H6: Class eg: X | I6: Total | L6: No.(a) | M6: As a % of total Shares held(b) | N6: No.(a) | O6: As a % of total Shares held(b)
B8: A9) Indian | D8: - | E8: - | F8: - | G8: 0 | H8: - | I8: 0 | J8: - | K8: 0 | L8: - | M8: 0 | N8: - | O8: 0 | P8: -
B9: Individuals/Hindu undivided Family | D9: 2 | E9: 2 | F9: 2 | G9: 0 | H9: 2 | I9: 0 | J9: 2 | K9: 0 | L9: - | M9: 0 | N9: - | O9: 0 | P9: 2
B10: Gautambhai Shantilal Adani | C10: Promoter | D10: 1 | E10: 1 | F10: 1 | G10: 0 | H10: 1 | I10: 0 | J10: 1 | K10: 0 | L10: - | M10: 0 | N10: - | O10: 0 | P10: 1
B11: Rajeshbhai Shantilal Adani | C11: Promoter | D11: 1 | E11: 1 | F11: 1 | G11: 0 | H11: 1 | I11: 0 | J11: 1 | K11: 0 | L11: - | M11: 0 | N11: - | O11: 0 | P11: 1
B12: Any Other (specify) | D12: 3 | E12: 717701985 | F12: 717701985 | G12: 59.74 | H12: 717701985 | I12: 59.74 | J12: 717701985 | K12: 59.74 | L12: 4700000 | M12: 0.65 | N12: 4700000 | O12: 0.65 | P12: 717701985
B13: Gautambhai Shantilal Adani and Rajeshbhai Shantilal Adani (on behalf of S.B. Adani Family Trust) | C13: Promoter Group | D13: 1 | E13: 601634660 | F13: 601634660 | G13: 50.08 | H13: 601634660 | I13: 50.08 | J13: 601634660 | K13: 50.08 | L13: - | M13: 0 | N13: - | O13: 0 | P13: 601634660
B14: Shri Gautam S. Adani/Smt.Priti G. Adani (on behalf of Gautam S. Adani Family Trust) | C14: Promoter Group | D14: - | E14: - | F14: - | G14: 0 | H14: - | I14: 0 | J14: - | K14: 0 | L14: - | M14: 0 | N14: - | O14: 0 | P14: -
B15: Adani Tradeline Private Limited | C15: Promoter Group | D15: 1 | E15: 97617325 | F15: 97617325 | G15: 8.13 | H15: 97617325 | I15: 8.13 | J15: 97617325 | K15: 8.13 | L15: 4700000 | M15: 4.81 | N15: 4700000 | O15: 4.81 | P15: 97617325
B16: Adani Infra (India) Limited | C16: Promoter Group | D16: 1 | E16: 18450000 | F16: 18450000 | G16: 1.54 | H16: 18450000 | I16: 1.54 | J16: 18450000 | K16: 1.54 | L16: - | M16: 0 | N16: - | O16: 0 | P16: 18450000
B17: Adani Properties Private Limited | C17: Promoter Group | D17: - | E17: - | F17: - | G17: 0 | H17: - | I17: 0 | J17: - | K17: 0 | L17: - | M17: 0 | N17: - | O17: 0 | P17: -
B18: Sub Total A1 | D18: 5 | E18: 717701987 | F18: 717701987 | G18: 59.74 | H18: 717701987 | I18: 59.74 | J18: 717701987 | K18: 59.74 | L18: 4700000 | M18: 0.65 | N18: 4700000 | O18: 0.65 | P18: 717701987
B19: A10) Foreign | D19: - | E19: - | F19: - | G19: 0 | H19: - | I19: 0 | J19: - | K19: 0 | L19: - | M19: 0 | N19: - | O19: 0 | P19: -
B20: Any Other (specify) | D20: 5 | E20: 155981400 | F20: 155981400 | G20: 12.98 | H20: 155981400 | I20: 12.98 | J20: 155981400 | K20: 12.98 | L20: - | M20: 0 | N20: - | O20: 0 | P20: 155981400
B21: Afro Asia Trade And Investments Limited | C21: Promoter Group | D21: 1 | E21: 30249700 | F21: 30249700 | G21: 2.52 | H21: 30249700 | I21: 2.52 | J21: 30249700 | K21: 2.52 | L21: - | M21: 0 | N21: - | O21: 0 | P21: 30249700
B22: Worldwide Emerging Market Holding Limited | C22: Promoter Group | D22: 1 | E22: 30249700 | F22: 30249700 | G22: 2.52 | H22: 30249700 | I22: 2.52 | J22: 30249700 | K22: 2.52 | L22: - | M22: 0 | N22: - | O22: 0 | P22: 30249700
B23: Flourishing Trade And Investment Limited | C23: Promoter Group | D23: 1 | E23: 3688000 | F23: 3688000 | G23: 0.31 | H23: 3688000 | I23: 0.31 | J23: 3688000 | K23: 0.31 | L23: - | M23: 0 | N23: - | O23: 0 | P23: 3688000
B24: Gelt Bery Trade and Investment Limited | C24: Promoter Group | D24: 1 | E24: 64760500 | F24: 64760500 | G24: 5.39 | H24: 64760500 | I24: 5.39 | J24: 64760500 | K24: 5.39 | L24: - | M24: 0 | N24: - | O24: 0 | P24: 64760500
B25: Fortitude Trade and Investment Limited | C25: Promoter Group | D25: - | E25: - | F25: - | G25: 0 | H25: - | I25: 0 | J25: - | K25: 0 | L25: - | M25: 0 | N25: - | O25: 0 | P25: -
B26: Emerging Market Investment DMCC | C26: Promoter Group | D26: 1 | E26: 27033500 | F26: 27033500 | G26: 2.25 | H26: 27033500 | I26: 2.25 | J26: 27033500 | K26: 2.25 | L26: - | M26: 0 | N26: - | O26: 0 | P26: 27033500
B27: Sub Total A2 | D27: 5 | E27: 155981400 | F27: 155981400 | G27: 12.98 | H27: 155981400 | I27: 12.98 | J27: 155981400 | K27: 12.98 | L27: - | M27: 0 | N27: - | O27: 0 | P27: 155981400
B28: A=A1+A2 | D28: 10 | E28: 873683387 | F28: 873683387 | G28: 72.73 | H28: 873683387 | I28: 72.73 | J28: 873683387 | K28: 72.73 | L28: 4700000 | M28: 0.54 | N28: 4700000 | O28: 0.54 | P28: 873683387

Sheet Public
B1: Shareholding Pattern Public Shareholder
B2: Adani Energy Solutions Ltd
B3: Scrip Code : 539254 | E3: Quarter Ending : Mar-26
B5: Statement showing shareholding pattern of the Public shareholder
B7: Category & Name of the Shareholders | C7: No. of shareholder | D7: No. of fully paid up equity shares held | E7: Total no. shares held | F7: Shareholding % calculated as per SCRR, 1957 As a % of (A+B+C2) | G7: No. of Voting Rights | H7: Total as a % of Total Voting right | I7: Total No. Of shares on fully diluted basis (including warrants, ESOP, Convertible Securities etc.) | J7: Shareholding , as a % assuming full conversion of convertible securities ( as a percentage of diluted share capital)As a % of (A+B+C2) | K7: No. of equity shares held in dematerialized form(Not Applicable) | L7: Sub-categorization of shares (XV)
L8: Shareholding (No. of shares) under
L9: SubCategory_I | M9: SubCategory_II | N9: SubCategory_III
B10: Institutions | C10: 0 | D10: 0 | E10: - | F10: 0 | G10: - | H10: 0 | I10: - | J10: 0 | K10: - | L10: - | M10: - | N10: -
B11: B2) Institutions (Domestic) | C11: 0 | D11: 0 | E11: - | F11: 0 | G11: - | H11: 0 | I11: - | J11: 0 | K11: - | L11: - | M11: - | N11: -
B12: Mutual Funds/ | C12: 33 | D12: 79195541 | E12: 79195541 | F12: 6.59 | G12: 79195541 | H12: 6.59 | I12: 79195541 | J12: 6.59 | K12: 79195541 | L12: - | M12: - | N12: -
B13: SBI Equity Hybrid Fund | C13: 1 | D13: 44073466 | E13: 44073466 | F13: 3.67 | G13: 44073466 | H13: 3.67 | I13: 44073466 | J13: 3.67 | K13: 44073466 | L13: - | M13: - | N13: -
B14: Venture Capital Funds | C14: 0 | D14: 0 | E14: - | F14: 0 | G14: - | H14: 0 | I14: - | J14: 0 | K14: - | L14: - | M14: - | N14: -
B15: Alternate Investment Funds | C15: 7 | D15: 897195 | E15: 897195 | F15: 0.07 | G15: 897195 | H15: 0.07 | I15: 897195 | J15: 0.07 | K15: 897195 | L15: - | M15: - | N15: -
B16: Banks | C16: 3 | D16: 387 | E16: 387 | F16: 0 | G16: 387 | H16: 0 | I16: 387 | J16: 0 | K16: 387 | L16: - | M16: - | N16: -
B17: Insurance Companies | C17: 6 | D17: 43049610 | E17: 43049610 | F17: 3.58 | G17: 43049610 | H17: 3.58 | I17: 43049610 | J17: 3.58 | K17: 43049610 | L17: - | M17: - | N17: -
B18: Life Insurance Corporation Of India | C18: 1 | D18: 41081207 | E18: 41081207 | F18: 3.42 | G18: 41081207 | H18: 3.42 | I18: 41081207 | J18: 3.42 | K18: 41081207 | L18: - | M18: - | N18: -
B19: Provident Funds/ Pension Funds | C19: 0 | D19: 0 | E19: - | F19: 0 | G19: - | H19: 0 | I19: - | J19: 0 | K19: - | L19: - | M19: - | N19: -
B20: Asset reconstruction companies | C20: 0 | D20: 0 | E20: - | F20: 0 | G20: - | H20: 0 | I20: - | J20: 0 | K20: - | L20: - | M20: - | N20: -
B21: Sovereign Wealth Funds | C21: 0 | D21: 0 | E21: - | F21: 0 | G21: - | H21: 0 | I21: - | J21: 0 | K21: - | L21: - | M21: - | N21: -
B22: NBFCs registered with RBI | C22: 4 | D22: 1709 | E22: 1709 | F22: 0 | G22: 1709 | H22: 0 | I22: 1709 | J22: 0 | K22: 1709 | L22: - | M22: - | N22: -
B23: Other Financial Institutions | C23: 0 | D23: 0 | E23: - | F23: 0 | G23: - | H23: 0 | I23: - | J23: 0 | K23: - | L23: - | M23: - | N23: -
B24: Any Other(Institutions (Domestic)) | C24: 0 | D24: 0 | E24: - | F24: 0 | G24: - | H24: 0 | I24: - | J24: 0 | K24: - | L24: - | M24: - | N24: -
B25: Sub Total B1 | C25: 53 | D25: 123144442 | E25: 123144442 | F25: 10.25 | G25: 123144442 | H25: 10.25 | I25: 123144442 | J25: 10.25 | K25: 123144442 | L25: - | M25: - | N25: -
B26: B17) Institutions (Foreign) | C26: 0 | D26: 0 | E26: - | F26: 0 | G26: - | H26: 0 | I26: - | J26: 0 | K26: - | L26: - | M26: - | N26: -
B27: Foreign Direct Investment | C27: 0 | D27: 0 | E27: - | F27: 0 | G27: - | H27: 0 | I27: - | J27: 0 | K27: - | L27: - | M27: - | N27: -
B28: Foreign Venture Capital Investors | C28: 0 | D28: 0 | E28: - | F28: 0 | G28: - | H28: 0 | I28: - | J28: 0 | K28: - | L28: - | M28: - | N28: -
B29: Sovereign Wealth Funds | C29: 0 | D29: 0 | E29: - | F29: 0 | G29: - | H29: 0 | I29: - | J29: 0 | K29: - | L29: - | M29: - | N29: -
B30: Foreign Portfolio Investors Category I | C30: 173 | D30: 130640837 | E30: 130640837 | F30: 10.88 | G30: 130640837 | H30: 10.88 | I30: 130640837 | J30: 10.88 | K30: 130640837 | L30: - | M30: - | N30: -
B31: Inq Holding Llc | C31: 1 | D31: 12868770 | E31: 12868770 | F31: 1.07 | G31: 12868770 | H31: 1.07 | I31: 12868770 | J31: 1.07 | K31: 12868770 | L31: - | M31: - | N31: -
B32: Gqg Partners Emerging Markets Equity Fund | C32: 1 | D32: 22886433 | E32: 22886433 | F32: 1.91 | G32: 22886433 | H32: 1.91 | I32: 22886433 | J32: 1.91 | K32: 22886433 | L32: - | M32: - | N32: -
B33: Goldman Sachs Trust Ii - Goldman Sachs Gqg Partners International Opportunities Fund | C33: 1 | D33: 35665659 | E33: 35665659 | F33: 2.97 | G33: 35665659 | H33: 2.97 | I33: 35665659 | J33: 2.97 | K33: 35665659 | L33: - | M33: - | N33: -
B34: Foreign Portfolio Investors Category II | C34: 18 | D34: 16249671 | E34: 16249671 | F34: 1.35 | G34: 16249671 | H34: 1.35 | I34: 16249671 | J34: 1.35 | K34: 16249671 | L34: - | M34: - | N34: -
B35: Overseas Depositories (holding DRs) (balancing figure) | C35: 0 | D35: 0 | E35: - | F35: 0 | G35: - | H35: 0 | I35: - | J35: 0 | K35: - | L35: - | M35: - | N35: -
B36: Any Other(Institutions (Foreign)) | C36: 0 | D36: 0 | E36: - | F36: 0 | G36: - | H36: 0 | I36: - | J36: 0 | K36: - | L36: - | M36: - | N36: -
B37: Sub Total B2 | C37: 191 | D37: 146890508 | E37: 146890508 | F37: 12.23 | G37: 146890508 | H37: 12.23 | I37: 146890508 | J37: 12.23 | K37: 146890508 | L37: - | M37: - | N37: -
B38: B29) Central Government/ State Government(s)/ President of India | C38: 0 | D38: 0 | E38: - | F38: 0 | G38: - | H38: 0 | I38: - | J38: 0 | K38: - | L38: - | M38: - | N38: -
B39: Central Government / President of India | C39: 0 | D39: 0 | E39: - | F39: 0 | G39: - | H39: 0 | I39: - | J39: 0 | K39: - | L39: - | M39: - | N39: -
B40: State Government / Governor | C40: 0 | D40: 0 | E40: - | F40: 0 | G40: - | H40: 0 | I40: - | J40: 0 | K40: - | L40: - | M40: - | N40: -
B41: Shareholding by Companies or Bodies Corporate where Central / State Government is a promoter | C41: 0 | D41: 0 | E41: - | F41: 0 | G41: - | H41: 0 | I41: - | J41: 0 | K41: - | L41: - | M41: - | N41: -
B42: Sub Total B3 | C42: 0 | D42: 0 | E42: - | F42: 0 | G42: - | H42: 0 | I42: - | J42: 0 | K42: - | L42: - | M42: - | N42: -
...

Sheet Consolidated Balance Sheet
B1: Adani Energy Solutions
B2: Consolidated Balance Sheet
C3: 44621 | D3: 44986 | E3: 45352 | F3: 45717 | G3: Mar 26
C5: 12 mths | D5: 12 mths | E5: 12 mths | F5: 12 mths | G5: 12 mths
B7: EQUITIES AND LIABILITIES | I7: Changes %
B8: SHAREHOLDER'S FUNDS | I8: 44621 | J8: 44986 | K8: 45352 | L8: 45717 | M8: Mar 26
B9: Equity Share Capital | C9: 1099.81 | D9: 1115.49 | E9: 1115.49 | F9: 1201.28 | G9: 1201.28 | J9: =(D9-C9)/C9 -> 0.014257008 | K9: =(E9-D9)/D9 -> 0 | L9: =(F9-E9)/E9 -> 0.076907906 | M9: =(G9-F9)/F9 -> 0
B10: Total Share Capital | C10: 1099.81 | D10: 1115.49 | E10: 1115.49 | F10: 1201.28 | G10: 1201.28 | J10: =(D10-C10)/C10 -> 0.014257008 | K10: =(E10-D10)/D10 -> 0 | L10: =(F10-E10)/E10 -> 0.076907906 | M10: =(G10-F10)/F10 -> 0
B11: Reserves and Surplus | C11: 5757.36 | D11: 10546.95 | E11: 11526.06 | F11: 20866.92 | G11: 24226.26 | J11: =(D11-C11)/C11 -> 0.83190733 | K11: =(E11-D11)/D11 -> 0.092833473 | L11: =(F11-E11)/E11 -> 0.81041223 | M11: =(G11-F11)/F11 -> 0.16098878
B12: Total Reserves and Surplus | C12: 5757.36 | D12: 10546.95 | E12: 11526.06 | F12: 20866.92 | G12: 24226.26 | J12: =(D12-C12)/C12 -> 0.83190733 | K12: =(E12-D12)/D12 -> 0.092833473 | L12: =(F12-E12)/E12 -> 0.81041223 | M12: =(G12-F12)/F12 -> 0.16098878
B13: Total Shareholders Funds | C13: 6857.17 | D13: 11662.44 | E13: 12641.55 | F13: 22068.2 | G13: 25427.54 | J13: =(D13-C13)/C13 -> 0.70076577 | K13: =(E13-D13)/D13 -> 0.08395413 | L13: =(F13-E13)/E13 -> 0.74568783 | M13: =(G13-F13)/F13 -> 0.15222537
B14: Hybrid/Debt/Other Securities | C14: 3055.65 | D14: 0 | E14: 0 | F14: 0 | G14: 0 | J14: =(D14-C14)/C14 -> -1 | K14: 0 | L14: 0 | M14: 0
B15: Minority Interest | C15: 1093.68 | D15: 1097.55 | E15: 1061.58 | F15: 943.06 | G15: 1098.1 | J15: =(D15-C15)/C15 -> 0.0035385122 | K15: =(E15-D15)/D15 -> -0.032772994 | L15: =(F15-E15)/E15 -> -0.11164491 | M15: =(G15-F15)/F15 -> 0.16440099
B16: NON-CURRENT LIABILITIES
B17: Long Term Borrowings | C17: 27774.04 | D17: 31330.39 | E17: 33559.62 | F17: 36992.29 | G17: 45367.32 | J17: =(D17-C17)/C17 -> 0.12804583 | K17: =(E17-D17)/D17 -> 0.071152322 | L17: =(F17-E17)/E17 -> 0.10228572 | M17: =(G17-F17)/F17 -> 0.22639934
B18: Deferred Tax Liabilities [Net] | C18: 1414.46 | D18: 1540.1 | E18: 1652.78 | F18: 1753.76 | G18: 2490.14 | J18: =(D18-C18)/C18 -> 0.088825417 | K18: =(E18-D18)/D18 -> 0.07316408 | L18: =(F18-E18)/E18 -> 0.061097061 | M18: =(G18-F18)/F18 -> 0.41988642
B19: Other Long Term Liabilities | C19: 723.4 | D19: 756.25 | E19: 1016.37 | F19: 1632.82 | G19: 2202.98 | J19: =(D19-C19)/C19 -> 0.045410561 | K19: =(E19-D19)/D19 -> 0.34396033 | L19: =(F19-E19)/E19 -> 0.60652125 | M19: =(G19-F19)/F19 -> 0.3491873
B20: Long Term Provisions | C20: 617.47 | D20: 527.73 | E20: 630.23 | F20: 553.57 | G20: 680.99 | J20: =(D20-C20)/C20 -> -0.145335 | K20: =(E20-D20)/D20 -> 0.19422811 | L20: =(F20-E20)/E20 -> -0.12163813 | M20: =(G20-F20)/F20 -> 0.23017866
B21: Total Non-Current Liabilities | C21: 30529.37 | D21: 34154.47 | E21: 36859 | F21: 40932.44 | G21: 50741.43 | J21: =(D21-C21)/C21 -> 0.1187414 | K21: =(E21-D21)/D21 -> 0.079185243 | L21: =(F21-E21)/E21 -> 0.11051412 | M21: =(G21-F21)/F21 -> 0.23963854
B22: CURRENT LIABILITIES
B23: Short Term Borrowings | C23: 2040.54 | D23: 2868.45 | E23: 3449.25 | F23: 3213.79 | G23: 3531.13 | J23: =(D23-C23)/C23 -> 0.40573084 | K23: =(E23-D23)/D23 -> 0.20247869 | L23: =(F23-E23)/E23 -> -0.068264115 | M23: =(G23-F23)/F23 -> 0.098743228
B24: Trade Payables | C24: 1607.91 | D24: 1800.43 | E24: 1722.11 | F24: 2955.62 | G24: 4993.65 | J24: =(D24-C24)/C24 -> 0.11973307 | K24: =(E24-D24)/D24 -> -0.043500719 | L24: =(F24-E24)/E24 -> 0.71627829 | M24: =(G24-F24)/F24 -> 0.68954399
B25: Other Current Liabilities | C25: 2208.88 | D25: 2229.12 | E25: 2746.81 | F25: 3741.47 | G25: 6836.2 | J25: =(D25-C25)/C25 -> 0.0091630147 | K25: =(E25-D25)/D25 -> 0.23223963 | L25: =(F25-E25)/E25 -> 0.3621146 | M25: =(G25-F25)/F25 -> 0.82714281
B26: Short Term Provisions | C26: 70.91 | D26: 119.29 | E26: 98.51 | F26: 105.52 | G26: 206.87 | J26: =(D26-C26)/C26 -> 0.6822733 | K26: =(E26-D26)/D26 -> -0.17419733 | L26: =(F26-E26)/E26 -> 0.071160288 | M26: =(G26-F26)/F26 -> 0.96048143
B27: Total Current Liabilities | C27: 5928.24 | D27: 7017.29 | E27: 8016.68 | F27: 10016.4 | G27: 15567.85 | J27: =(D27-C27)/C27 -> 0.18370545 | K27: =(E27-D27)/D27 -> 0.14241823 | L27: =(F27-E27)/E27 -> 0.24944491 | M27: =(G27-F27)/F27 -> 0.55423605
B28: Total Capital And Liabilities | C28: 47464.11 | D28: 53931.75 | E28: 58578.81 | F28: 73960.1 | G28: 92834.92 | J28: =(D28-C28)/C28 -> 0.1362638 | K28: =(E28-D28)/D28 -> 0.08616557 | L28: =(F28-E28)/E28 -> 0.2625743 | M28: =(G28-F28)/F28 -> 0.25520274
B29: ASSETS
B30: NON-CURRENT ASSETS
B31: Tangible Assets | C31: 28578.02 | D31: 30947.5 | E31: 37219.85 | F31: 37845.22 | G31: 45060.12 | J31: =(D31-C31)/C31 -> 0.082912672 | K31: =(E31-D31)/D31 -> 0.20267711 | L31: =(F31-E31)/E31 -> 0.016802056 | M31: =(G31-F31)/F31 -> 0.19064231
B32: Intangible Assets | C32: 1095.46 | D32: 1099.35 | E32: 1101.6 | F32: 1111.24 | G32: 1145.53 | J32: =(D32-C32)/C32 -> 0.0035510197 | K32: =(E32-D32)/D32 -> 0.0020466639 | L32: =(F32-E32)/E32 -> 0.0087509078 | M32: =(G32-F32)/F32 -> 0.030857421
B33: Capital Work-In-Progress | C33: 5060.16 | D33: 6200.44 | E33: 3002.69 | F33: 5695.36 | G33: 2053.6 | J33: =(D33-C33)/C33 -> 0.22534465 | K33: =(E33-D33)/D33 -> -0.51572953 | L33: =(F33-E33)/E33 -> 0.89675258 | M33: =(G33-F33)/F33 -> -0.63942578
B34: Intangible Assets Under Development | C34: 0 | D34: 0 | E34: 0 | F34: 6.88 | G34: 0 | J34: 0 | K34: 0 | L34: 0 | M34: =(G34-F34)/F34 -> -1
B35: Fixed Assets | C35: 34733.64 | D35: 38247.29 | E35: 41324.14 | F35: 44658.7 | G35: 48259.25 | J35: =(D35-C35)/C35 -> 0.10115986 | K35: =(E35-D35)/D35 -> 0.080446222 | L35: =(F35-E35)/E35 -> 0.080692786 | M35: =(G35-F35)/F35 -> 0.080623708
B36: Non-Current Investments | C36: 264.17 | D36: 312.89 | E36: 323.79 | F36: 348.72 | G36: 407.29 | J36: =(D36-C36)/C36 -> 0.18442669 | K36: =(E36-D36)/D36 -> 0.034836524 | L36: =(F36-E36)/E36 -> 0.076994348 | M36: =(G36-F36)/F36 -> 0.1679571
B37: Deferred Tax Assets [Net] | C37: 0 | D37: 0 | E37: 40.43 | F37: 57.85 | G37: 78.17 | J37: 0 | K37: 0 | L37: =(F37-E37)/E37 -> 0.43086817 | M37: =(G37-F37)/F37 -> 0.35125324
B38: Long Term Loans And Advances | C38: 1128.54 | D38: 26.1 | E38: 22.51 | F38: 15.88 | G38: 10.58 | J38: =(D38-C38)/C38 -> -0.97687277 | K38: =(E38-D38)/D38 -> -0.13754789 | L38: =(F38-E38)/E38 -> -0.29453576 | M38: =(G38-F38)/F38 -> -0.33375315
B39: Other Non-Current Assets | C39: 5096.85 | D39: 5840.32 | E39: 6651.53 | F39: 11606.54 | G39: 23639.66 | J39: =(D39-C39)/C39 -> 0.14586853 | K39: =(E39-D39)/D39 -> 0.13889821 | L39: =(F39-E39)/E39 -> 0.74494289 | M39: =(G39-F39)/F39 -> 1.0367534
B40: Total Non-Current Assets | C40: 41821.49 | D40: 45024.89 | E40: 48960.69 | F40: 57285.98 | G40: 72993.24 | J40: =(D40-C40)/C40 -> 0.076596984 | K40: =(E40-D40)/D40 -> 0.087413873 | L40: =(F40-E40)/E40 -> 0.17004029 | M40: =(G40-F40)/F40 -> 0.2741903
B41: CURRENT ASSETS
B42: Current Investments | C42: 296.35 | D42: 1056.79 | E42: 442.69 | F42: 2289.69 | G42: 2236.32 | J42: =(D42-C42)/C42 -> 2.5660199 | K42: =(E42-D42)/D42 -> -0.58109937 | L42: =(F42-E42)/E42 -> 4.1722198 | M42: =(G42-F42)/F42 -> -0.023308832
...

Sheet Consolidated Profit & Loss
B1: Adani Energy Solutions
B2: Consolidated Profit & Loss account
C3: 44621 | D3: 44986 | E3: 45352 | F3: 45717 | G3: Mar 26
C5: 12 mths | D5: 12 mths | E5: 12 mths | F5: 12 mths | G5: 12 mths
I6: Changes in %
B7: INCOME | I7: 44621 | J7: 44986 | K7: 45352 | L7: 45717 | M7: Mar 26
B8: Revenue From Operations [Gross] | C8: 10960.21 | D8: 12995.12 | E8: 16355.01 | F8: 23546.15 | G8: 27202.63 | J8: =(D8-C8)/C8 -> 0.18566341 | K8: =(E8-D8)/D8 -> 0.25855013 | L8: =(F8-E8)/E8 -> 0.43969035 | M8: =(G8-F8)/F8 -> 0.15528993
B9: Revenue From Operations [Net] | C9: 10960.21 | D9: 12995.12 | E9: 16355.01 | F9: 23546.15 | G9: 27202.63 | J9: =(D9-C9)/C9 -> 0.18566341 | K9: =(E9-D9)/D9 -> 0.25855013 | L9: =(F9-E9)/E9 -> 0.43969035 | M9: =(G9-F9)/F9 -> 0.15528993
B10: Other Operating Revenues | C10: 297.31 | D10: 297.6 | E10: 252.35 | F10: 220.94 | G10: 385.4 | J10: =(D10-C10)/C10 -> 0.00097541287 | K10: =(E10-D10)/D10 -> -0.15204973 | L10: =(F10-E10)/E10 -> -0.12446998 | M10: =(G10-F10)/F10 -> 0.74436499
B11: Total Operating Revenues | C11: 11257.52 | D11: 13292.72 | E11: 16607.36 | F11: 23767.09 | G11: 27588.03 | J11: =(D11-C11)/C11 -> 0.18078582 | K11: =(E11-D11)/D11 -> 0.24935754 | L11: =(F11-E11)/E11 -> 0.43111789 | M11: =(G11-F11)/F11 -> 0.160766
B12: Other Income | C12: 603.95 | D12: 547.74 | E12: 610.95 | F12: 679.46 | G12: 737.13 | J12: =(D12-C12)/C12 -> -0.093070618 | K12: =(E12-D12)/D12 -> 0.11540147 | L12: =(F12-E12)/E12 -> 0.11213684 | M12: =(G12-F12)/F12 -> 0.084876225
B13: Total Revenue | C13: 11861.47 | D13: 13840.46 | E13: 17218.31 | F13: 24446.55 | G13: 28325.16 | J13: =(D13-C13)/C13 -> 0.16684188 | K13: =(E13-D13)/D13 -> 0.24405619 | L13: =(F13-E13)/E13 -> 0.41979962 | M13: =(G13-F13)/F13 -> 0.15865674
B14: EXPENSES
B15: Purchase Of Stock-In Trade | C15: 821.23 | D15: 755.13 | E15: 1028.95 | F15: 1365.74 | G15: 1004.14 | J15: =(D15-C15)/C15 -> -0.080489023 | K15: =(E15-D15)/D15 -> 0.36261306 | L15: =(F15-E15)/E15 -> 0.32731425 | M15: =(G15-F15)/F15 -> -0.26476489
B16: Cost of Power Purchased | C16: 2778.88 | D16: 3839.98 | E16: 4340.3 | F16: 5584.14 | G16: 6347.88 | J16: =(D16-C16)/C16 -> 0.38184448 | K16: =(E16-D16)/D16 -> 0.13029235 | L16: =(F16-E16)/E16 -> 0.28657927 | M16: =(G16-F16)/F16 -> 0.13676949
B17: Cost Of Fuel | C17: 1065.99 | D17: 1384.18 | E17: 1119.09 | F17: 623.54 | G17: 0 | J17: =(D17-C17)/C17 -> 0.29849248 | K17: =(E17-D17)/D17 -> -0.19151411 | L17: =(F17-E17)/E17 -> -0.44281514 | M17: =(G17-F17)/F17 -> -1
B18: Operating And Direct Expenses | C18: 0 | D18: 0 | E18: 0 | F18: 0 | G18: 7135.35
B19: Employee Benefit Expenses | C19: 885.07 | D19: 986.65 | E19: 951.7 | F19: 1032.94 | G19: 1092.64 | J19: =(D19-C19)/C19 -> 0.11477058 | K19: =(E19-D19)/D19 -> -0.035422896 | L19: =(F19-E19)/E19 -> 0.085363035 | M19: =(G19-F19)/F19 -> 0.057796193
B20: Finance Costs | C20: 2364.95 | D20: 2781.47 | E20: 2766.51 | F20: 3259.16 | G20: 3632.9 | J20: =(D20-C20)/C20 -> 0.17612212 | K20: =(E20-D20)/D20 -> -0.005378451 | L20: =(F20-E20)/E20 -> 0.17807635 | M20: =(G20-F20)/F20 -> 0.11467372
B21: Depreciation And Amortisation Expenses | C21: 1427.15 | D21: 1607.74 | E21: 1776.08 | F21: 1905.95 | G21: 1978.23 | J21: =(D21-C21)/C21 -> 0.12653891 | K21: =(E21-D21)/D21 -> 0.10470598 | L21: =(F21-E21)/E21 -> 0.073121706 | M21: =(G21-F21)/F21 -> 0.037923345
B22: Other Expenses | C22: 1500.18 | D22: 1809.17 | E22: 2996.11 | F22: 6753.46 | G22: 2923.62 | J22: =(D22-C22)/C22 -> 0.20596862 | K22: =(E22-D22)/D22 -> 0.65606881 | L22: =(F22-E22)/E22 -> 1.2540761 | M22: =(G22-F22)/F22 -> -0.56709302
B23: Total Expenses | C23: 10843.45 | D23: 13164.32 | E23: 14978.74 | F23: 20524.93 | G23: 24114.76 | J23: =(D23-C23)/C23 -> 0.21403428 | K23: =(E23-D23)/D23 -> 0.13782862 | L23: =(F23-E23)/E23 -> 0.3702708 | M23: =(G23-F23)/F23 -> 0.17490096
B24: Profit/Loss Before Exceptional, ExtraOrdinary Items And Tax | C24: 1018.02 | D24: 676.14 | E24: 2239.57 | F24: 3921.62 | G24: 4210.4 | J24: =(D24-C24)/C24 -> -0.33582837 | K24: =(E24-D24)/D24 -> 2.3122874 | L24: =(F24-E24)/E24 -> 0.75105936 | M24: =(G24-F24)/F24 -> 0.073637935
B25: Exceptional Items | C25: 682.47 | D25: 1035.58 | E25: -460.01 | F25: -2846.77 | G25: -1095.56 | J25: =(D25-C25)/C25 -> 0.51740003 | K25: =(E25-D25)/D25 -> -1.4442052 | L25: =(F25-E25)/E25 -> 5.1884959 | M25: =(G25-F25)/F25 -> -0.61515683
B26: Profit/Loss Before Tax | C26: 1700.49 | D26: 1711.72 | E26: 1779.56 | F26: 1074.85 | G26: 3114.84 | J26: =(D26-C26)/C26 -> 0.0066039789 | K26: =(E26-D26)/D26 -> 0.03963265 | L26: =(F26-E26)/E26 -> -0.39600238 | M26: =(G26-F26)/F26 -> 1.8979299
B27: Tax Expenses-Continued Operations
B28: Current Tax | C28: 244.23 | D28: 260.94 | E28: 298.6 | F28: 195.04 | G28: 392.8 | J28: =(D28-C28)/C28 -> 0.068419113 | K28: =(E28-D28)/D28 -> 0.14432437 | L28: =(F28-E28)/E28 -> -0.34681849 | M28: =(G28-F28)/F28 -> 1.0139459
B29: Deferred Tax | C29: 191.83 | D29: 174.39 | E29: 281.53 | F29: -16.05 | G29: 378.91 | J29: =(D29-C29)/C29 -> -0.09091383 | K29: =(E29-D29)/D29 -> 0.61437009 | L29: =(F29-E29)/E29 -> -1.0570099 | M29: =(G29-F29)/F29 -> -24.6081
B30: Total Tax Expenses | C30: 436.06 | D30: 435.33 | E30: 580.13 | F30: 178.99 | G30: 771.71 | J30: =(D30-C30)/C30 -> -0.0016740815 | K30: =(E30-D30)/D30 -> 0.33262123 | L30: =(F30-E30)/E30 -> -0.69146571 | M30: =(G30-F30)/F30 -> 3.3114699
B31: Profit/Loss After Tax And Before ExtraOrdinary Items | C31: 1264.43 | D31: 1276.39 | E31: 1199.43 | F31: 895.86 | G31: 2343.13 | J31: =(D31-C31)/C31 -> 0.0094588075 | K31: =(E31-D31)/D31 -> -0.060295051 | L31: =(F31-E31)/E31 -> -0.25309522 | M31: =(G31-F31)/F31 -> 1.6155091
B32: Extraordinary Items | C32: -28.68 | D32: 4.21 | E32: -3.82 | F32: 25.83 | G32: 49.62 | J32: =(D32-C32)/C32 -> -1.1467922 | K32: =(E32-D32)/D32 -> -1.9073634 | L32: =(F32-E32)/E32 -> -7.7617801 | M32: =(G32-F32)/F32 -> 0.92102207
B33: Profit/Loss From Continuing Operations | C33: 1235.75 | D33: 1280.6 | E33: 1195.61 | F33: 921.69 | G33: 2392.75 | J33: =(D33-C33)/C33 -> 0.036293749 | K33: =(E33-D33)/D33 -> -0.066367328 | L33: =(F33-E33)/E33 -> -0.22910481 | M33: =(G33-F33)/F33 -> 1.5960464
B34: Profit/Loss For The Period | C34: 1235.75 | D34: 1280.6 | E34: 1195.61 | F34: 921.69 | G34: 2392.75 | J34: =(D34-C34)/C34 -> 0.036293749 | K34: =(E34-D34)/D34 -> -0.066367328 | L34: =(F34-E34)/E34 -> -0.22910481 | M34: =(G34-F34)/F34 -> 1.5960464
B35: Minority Interest | C35: -31.14 | D35: -24.27 | E35: -58.33 | F35: 138.28 | G35: -110.21 | J35: =(D35-C35)/C35 -> -0.22061657 | K35: =(E35-D35)/D35 -> 1.4033787 | L35: =(F35-E35)/E35 -> -3.3706498 | M35: =(G35-F35)/F35 -> -1.7970061
B36: Consolidated Profit/Loss After MI And Associates | C36: 1204.61 | D36: 1256.33 | E36: 1137.28 | F36: 1059.97 | G36: 2282.54 | J36: =(D36-C36)/C36 -> 0.042935058 | K36: =(E36-D36)/D36 -> -0.094760135 | L36: =(F36-E36)/E36 -> -0.067977983 | M36: =(G36-F36)/F36 -> 1.1534006
B37: OTHER ADDITIONAL INFORMATION
B38: EARNINGS PER SHARE
B39: Basic EPS (Rs.) | C39: 9 | D39: 11 | E39: 10 | F39: 9 | G39: 19 | J39: =(D39-C39)/C39 -> 0.22222222 | K39: =(E39-D39)/D39 -> -0.090909091 | L39: =(F39-E39)/E39 -> -0.1 | M39: =(G39-F39)/F39 -> 1.1111111
B40: Diluted EPS (Rs.) | C40: 5 | D40: 11 | E40: 10 | F40: 9 | G40: 19 | J40: =(D40-C40)/C40 -> 1.2 | K40: =(E40-D40)/D40 -> -0.090909091 | L40: =(F40-E40)/E40 -> -0.1 | M40: =(G40-F40)/F40 -> 1.1111111
B41: DIVIDEND AND DIVIDEND PERCENTAGE
...

Sheet Consolidated Cash Flow
B1: Adani Energy Solutions
B2: Cash Flow
C3: Mar 26 | D3: 46082 | E3: 45717 | F3: 45717 | G3: 45352
C5: 12 mths | D5: 12 mths | E5: 12 mths | F5: 12 mths | G5: 12 mths
B7: Net Profit/Loss Before Extraordinary Items And Tax | C7: 631.36 | D7: 631.36 | E7: 626.6 | F7: 626.6 | G7: 659.34
B8: Net CashFlow From Operating Activities | C8: 441.92 | D8: 441.92 | E8: -955.19 | F8: -955.19 | G8: -209.49
B9: Net Cash Used In Investing Activities | C9: -3695.05 | D9: -3695.05 | E9: -9164.34 | F9: -9164.34 | G9: -2000.95
B10: Net Cash Used From Financing Activities | C10: 2827.78 | D10: 2827.78 | E10: 10587.48 | F10: 10587.48 | G10: 2210.16
B11: Net Inc/Dec In Cash And Cash Equivalents | C11: -425.35 | D11: -425.35 | E11: 467.95 | F11: 467.95 | G11: -0.28
B12: Cash And Cash Equivalents Begin of Year | C12: 470.31 | D12: 470.31 | E12: 2.36 | F12: 2.36 | G12: 2.64
B13: Cash And Cash Equivalents End Of Year | C13: 44.96 | D13: 44.96 | E13: 470.31 | F13: 470.31 | G13: 2.36

Sheet Peer Comps
B1: Company | C1: Business Overview
B2: Adani Energy Solutions Ltd | C2: Adani Energy Solutions Ltd is one of India's largest private-sector power transmission companies. The company develops, owns, and operates transmission networks across multiple states and is expanding rapidly in smart metering, distribution infrastructure, and energy transition projects. It plays a key role in strengthening India's power delivery ecosystem through transmission, distribution, and utility modernization solutions.
B3: Tata Power Company Ltd | C3: Tata Power Company Ltd is one of India's largest integrated power companies with operations spanning power generation, transmission, distribution, renewable energy, solar manufacturing, EV charging infrastructure, and energy services. The company serves residential, commercial, and industrial customers while actively expanding its clean energy and sustainability-focused businesses.
B4: Torrent Power Ltd | C4: Torrent Power Ltd is an integrated power utility engaged in electricity generation, transmission, distribution, and renewable energy development. The company operates distribution networks across several Indian cities and has a growing portfolio of gas-based, renewable, and conventional power assets serving industrial, commercial, and retail consumers.
B5: Power Grid Corporation of India | C5: Power Grid Corporation of India Ltd is India's largest electric power transmission company and a central transmission utility. The company owns and operates an extensive high-voltage transmission network across the country and plays a critical role in integrating renewable energy, ensuring grid stability, and facilitating interstate power transmission.
B6: CESC Limited | C6: CESC Ltd is an integrated power utility primarily engaged in electricity generation and distribution. The company supplies power to Kolkata and surrounding areas while also having investments in power generation, distribution utilities, retail electricity businesses, and emerging energy-related ventures

Sheet Stock Analysis
B2: STOCK ANALYSIS — ADANI ENERGY SOLUTIONS LTD.
B18: MARKET SNAPSHOT | E18: Recommendation:
B19: Shares Outstanding (Cr) | C19: 120.13 | E19: AVOID/HOLD – Adani Energy Solutions Ltd, despite operating in a structurally favourable space of power transmission, distribution, and smart metering infrastructure, currently trades at a significant premium to its intrinsic value, with our DCF-based fair value estimate of ₹543 standing nearly 64% below the current market price of ₹1,495. The company's WACC of 12.77% and projected 10-year revenue CAGR of apx13.5% with EBIT margins near 30% reflect a fundamentally sound and growing business, but these growth assumptions appear to already be priced in, and then some. On the price front, AESL has been the weakest performer among its peer set over the past five years, returning just +32.49% compared to Tata Power (+284.24%), Torrent Power (+222.02%), and Power Grid (+124.00%), having crashed over 60% in early 2023 amid group-level concerns and remaining range-bound since, with no relative-strength reversal yet visible. While the company's exposure to India's grid modernization capex cycle and potential optionality from newer verticals such as data centre power and smart metering could support a future re-rating, this remains a forward-looking, sentiment-driven case rather than one supported by current cash flow projections. Elevated valuation versus DCF fair value, persistent underperformance versus sector peers, and sensitivity of the investment case to cost-of-capital normalization for the Adani group remain key monitorables.
B20: Book Value per Share (₹) | C20: 211.7
B21: Gross Debt (₹ Cr) | C21: 48,898
B22: Net Debt (₹ Cr) | C22: 44,951
B23: Net Debt / EBITDA (x) | C23: 4.58x
B24: Debt / Equity (x) | C24: 1.92x
B25: Interest Coverage (x) | C25: 1.16x
B26: Return on Equity | C26: 9.5%
B27: Return on Assets | C27: 2.5%
B28: Basic EPS (₹) FY26 | C28: 19.0
B29: EPS CAGR (FY22-FY26) | C29: 20.5%
B30: Revenue CAGR (FY22-FY26) | C30: 25.5%
B31: PAT CAGR (FY22-FY26) | C31: 17.3%
B32: Dividend | C32: Nil

Sheet Ratio Analysis
B1: RATIO ANALYSIS
B3: Ratio | C3: 2022 | D3: 2023 | E3: 2024 | F3: 2025 | G3: 2026 | H3: 5Y Avg
B4: Income Statement Ratios
B5: Sales Growth | D5: ='Consolidated Profit & Loss'!D9/'Consolidated Profit & Loss'!C9-1 -> 0.18566341 | E5: ='Consolidated Profit & Loss'!E9/'Consolidated Profit & Loss'!D9-1 -> 0.25855013 | F5: ='Consolidated Profit & Loss'!F9/'Consolidated Profit & Loss'!E9-1 -> 0.43969035 | G5: ='Consolidated Profit & Loss'!G9/'Consolidated Profit & Loss'!F9-1 -> 0.15528993 | H5: =AVERAGE(D5,E5,F5,G5) -> 0.25979846
B6: EBITDA | C6: ='Consolidated Profit & Loss'!C24+'Consolidated Profit & Loss'!C20+'Consolidated Profit & Loss'!C21 -> 4810.12 | D6: ='Consolidated Profit & Loss'!D24+'Consolidated Profit & Loss'!D20+'Consolidated Profit & Loss'!D21 -> 5065.35 | E6: ='Consolidated Profit & Loss'!E24+'Consolidated Profit & Loss'!E20+'Consolidated Profit & Loss'!E21 -> 6782.16 | F6: ='Consolidated Profit & Loss'!F24+'Consolidated Profit & Loss'!F20+'Consolidated Profit & Loss'!F21 -> 9086.73 | G6: ='Consolidated Profit & Loss'!G24+'Consolidated Profit & Loss'!G20+'Consolidated Profit & Loss'!G21 -> 9821.53 | H6: =AVERAGE(C6,D6,E6,F6,G6) -> 7113.178
B7: EBITDA Margins | C7: =('Consolidated Profit & Loss'!C24+'Consolidated Profit & Loss'!C20+'Consolidated Profit & Loss'!C21)/'Consolidated Profit & Loss'!C9 -> 0.43887115 | D7: =('Consolidated Profit & Loss'!D24+'Consolidated Profit & Loss'!D20+'Consolidated Profit & Loss'!D21)/'Consolidated Profit & Loss'!D9 -> 0.38978863 | E7: =('Consolidated Profit & Loss'!E24+'Consolidated Profit & Loss'!E20+'Consolidated Profit & Loss'!E21)/'Consolidated Profit & Loss'!E9 -> 0.41468394 | F7: =('Consolidated Profit & Loss'!F24+'Consolidated Profit & Loss'!F20+'Consolidated Profit & Loss'!F21)/'Consolidated Profit & Loss'!F9 -> 0.3859115 | G7: =('Consolidated Profit & Loss'!G24+'Consolidated Profit & Loss'!G20+'Consolidated Profit & Loss'!G21)/'Consolidated Profit & Loss'!G9 -> 0.36105075 | H7: =AVERAGE(C7,D7,E7,F7,G7) -> 0.39806119
B8: EBIT | C8: ='Consolidated Profit & Loss'!C24+'Consolidated Profit & Loss'!C20 -> 3382.97 | D8: ='Consolidated Profit & Loss'!D24+'Consolidated Profit & Loss'!D20 -> 3457.61 | E8: ='Consolidated Profit & Loss'!E24+'Consolidated Profit & Loss'!E20 -> 5006.08 | F8: ='Consolidated Profit & Loss'!F24+'Consolidated Profit & Loss'!F20 -> 7180.78 | G8: ='Consolidated Profit & Loss'!G24+'Consolidated Profit & Loss'!G20 -> 7843.3 | H8: =AVERAGE(C8,D8,E8,F8,G8) -> 5374.148
B9: EBIT Margin | C9: =('Consolidated Profit & Loss'!C24+'Consolidated Profit & Loss'!C20)/'Consolidated Profit & Loss'!C9 -> 0.30865923 | D9: =('Consolidated Profit & Loss'!D24+'Consolidated Profit & Loss'!D20)/'Consolidated Profit & Loss'!D9 -> 0.26606988 | E9: =('Consolidated Profit & Loss'!E24+'Consolidated Profit & Loss'!E20)/'Consolidated Profit & Loss'!E9 -> 0.30608847 | F9: =('Consolidated Profit & Loss'!F24+'Consolidated Profit & Loss'!F20)/'Consolidated Profit & Loss'!F9 -> 0.3049662 | G9: =('Consolidated Profit & Loss'!G24+'Consolidated Profit & Loss'!G20)/'Consolidated Profit & Loss'!G9 -> 0.28832874 | H9: =AVERAGE(C9,D9,E9,F9,G9) -> 0.2948225
B10: Finance Costs | C10: ='Consolidated Profit & Loss'!C20 -> 2364.95 | D10: ='Consolidated Profit & Loss'!D20 -> 2781.47 | E10: ='Consolidated Profit & Loss'!E20 -> 2766.51 | F10: ='Consolidated Profit & Loss'!F20 -> 3259.16 | G10: ='Consolidated Profit & Loss'!G20 -> 3632.9 | H10: =AVERAGE(C10,D10,E10,F10,G10) -> 2960.998
B11: Finance Costs % Revenue | C11: ='Consolidated Profit & Loss'!C20/'Consolidated Profit & Loss'!C9 -> 0.21577598 | D11: ='Consolidated Profit & Loss'!D20/'Consolidated Profit & Loss'!D9 -> 0.21403958 | E11: ='Consolidated Profit & Loss'!E20/'Consolidated Profit & Loss'!E9 -> 0.16915367 | F11: ='Consolidated Profit & Loss'!F20/'Consolidated Profit & Loss'!F9 -> 0.13841583 | G11: ='Consolidated Profit & Loss'!G20/'Consolidated Profit & Loss'!G9 -> 0.13354959 | H11: =AVERAGE(C11,D11,E11,F11,G11) -> 0.17418693
B12: Depreciation | C12: ='Consolidated Profit & Loss'!C21 -> 1427.15 | D12: ='Consolidated Profit & Loss'!D21 -> 1607.74 | E12: ='Consolidated Profit & Loss'!E21 -> 1776.08 | F12: ='Consolidated Profit & Loss'!F21 -> 1905.95 | G12: ='Consolidated Profit & Loss'!G21 -> 1978.23 | H12: =AVERAGE(C12,D12,E12,F12,G12) -> 1739.03
B13: Depreciation % of Sales | C13: ='Consolidated Profit & Loss'!C21/'Consolidated Profit & Loss'!C9 -> 0.13021192 | D13: ='Consolidated Profit & Loss'!D21/'Consolidated Profit & Loss'!D9 -> 0.12371875 | E13: ='Consolidated Profit & Loss'!E21/'Consolidated Profit & Loss'!E9 -> 0.10859547 | F13: ='Consolidated Profit & Loss'!F21/'Consolidated Profit & Loss'!F9 -> 0.080945293 | G13: ='Consolidated Profit & Loss'!G21/'Consolidated Profit & Loss'!G9 -> 0.072722013 | H13: =AVERAGE(C13,D13,E13,F13,G13) -> 0.10323869
B14: PBT | C14: ='Consolidated Profit & Loss'!C24 -> 1018.02 | D14: ='Consolidated Profit & Loss'!D24 -> 676.14 | E14: ='Consolidated Profit & Loss'!E24 -> 2239.57 | F14: ='Consolidated Profit & Loss'!F24 -> 3921.62 | G14: ='Consolidated Profit & Loss'!G24 -> 4210.4 | H14: =AVERAGE(C14,D14,E14,F14,G14) -> 2413.15
B15: PBT Margin | C15: ='Consolidated Profit & Loss'!C24/'Consolidated Profit & Loss'!C9 -> 0.092883257 | D15: ='Consolidated Profit & Loss'!D24/'Consolidated Profit & Loss'!D9 -> 0.052030301 | E15: ='Consolidated Profit & Loss'!E24/'Consolidated Profit & Loss'!E9 -> 0.1369348 | F15: ='Consolidated Profit & Loss'!F24/'Consolidated Profit & Loss'!F9 -> 0.16655037 | G15: ='Consolidated Profit & Loss'!G24/'Consolidated Profit & Loss'!G9 -> 0.15477915 | H15: =AVERAGE(C15,D15,E15,F15,G15) -> 0.12063558
B16: Net Profit | C16: ='Consolidated Profit & Loss'!C36 -> 1204.61 | D16: ='Consolidated Profit & Loss'!D36 -> 1256.33 | E16: ='Consolidated Profit & Loss'!E36 -> 1137.28 | F16: ='Consolidated Profit & Loss'!F36 -> 1059.97 | G16: ='Consolidated Profit & Loss'!G36 -> 2282.54 | H16: =AVERAGE(C16,D16,E16,F16,G16) -> 1388.146
B17: Net Margins | C17: ='Consolidated Profit & Loss'!C36/'Consolidated Profit & Loss'!C9 -> 0.10990757 | D17: ='Consolidated Profit & Loss'!D36/'Consolidated Profit & Loss'!D9 -> 0.09667706 | E17: ='Consolidated Profit & Loss'!E36/'Consolidated Profit & Loss'!E9 -> 0.069537102 | F17: ='Consolidated Profit & Loss'!F36/'Consolidated Profit & Loss'!F9 -> 0.045016701 | G17: ='Consolidated Profit & Loss'!G36/'Consolidated Profit & Loss'!G9 -> 0.083908799 | H17: =AVERAGE(C17,D17,E17,F17,G17) -> 0.081009446
B18: Earnings Per Share | C18: ='Consolidated Profit & Loss'!C39 -> 9 | D18: ='Consolidated Profit & Loss'!D39 -> 11 | E18: ='Consolidated Profit & Loss'!E39 -> 10 | F18: ='Consolidated Profit & Loss'!F39 -> 9 | G18: ='Consolidated Profit & Loss'!G39 -> 19 | H18: =AVERAGE(C18,D18,E18,F18,G18) -> 11.6
B19: EPS Growth % | D19: ='Consolidated Profit & Loss'!D39/'Consolidated Profit & Loss'!C39-1 -> 0.22222222 | E19: ='Consolidated Profit & Loss'!E39/'Consolidated Profit & Loss'!D39-1 -> -0.090909091 | F19: ='Consolidated Profit & Loss'!F39/'Consolidated Profit & Loss'!E39-1 -> -0.1 | G19: ='Consolidated Profit & Loss'!G39/'Consolidated Profit & Loss'!F39-1 -> 1.1111111 | H19: =AVERAGE(D19,E19,F19,G19) -> 0.28560606
B21: Balance Statement Ratios
B22: Total Shareholders Funds | C22: ='Consolidated Balance Sheet'!C13 -> 6857.17 | D22: ='Consolidated Balance Sheet'!D13 -> 11662.44 | E22: ='Consolidated Balance Sheet'!E13 -> 12641.55 | F22: ='Consolidated Balance Sheet'!F13 -> 22068.2 | G22: ='Consolidated Balance Sheet'!G13 -> 25427.54 | H22: =AVERAGE(C22,D22,E22,F22,G22) -> 15731.38
B23: Total Equity incl. Minority Interest | C23: ='Consolidated Balance Sheet'!C13+'Consolidated Balance Sheet'!C15 -> 7950.85 | D23: ='Consolidated Balance Sheet'!D13+'Consolidated Balance Sheet'!D15 -> 12759.99 | E23: ='Consolidated Balance Sheet'!E13+'Consolidated Balance Sheet'!E15 -> 13703.13 | F23: ='Consolidated Balance Sheet'!F13+'Consolidated Balance Sheet'!F15 -> 23011.26 | G23: ='Consolidated Balance Sheet'!G13+'Consolidated Balance Sheet'!G15 -> 26525.64 | H23: =AVERAGE(C23,D23,E23,F23,G23) -> 16790.174
B24: Long Term Borrowings | C24: ='Consolidated Balance Sheet'!C17 -> 27774.04 | D24: ='Consolidated Balance Sheet'!D17 -> 31330.39 | E24: ='Consolidated Balance Sheet'!E17 -> 33559.62 | F24: ='Consolidated Balance Sheet'!F17 -> 36992.29 | G24: ='Consolidated Balance Sheet'!G17 -> 45367.32 | H24: =AVERAGE(C24,D24,E24,F24,G24) -> 35004.732
B25: Short Term Borrowings | C25: ='Consolidated Balance Sheet'!C23 -> 2040.54 | D25: ='Consolidated Balance Sheet'!D23 -> 2868.45 | E25: ='Consolidated Balance Sheet'!E23 -> 3449.25 | F25: ='Consolidated Balance Sheet'!F23 -> 3213.79 | G25: ='Consolidated Balance Sheet'!G23 -> 3531.13 | H25: =AVERAGE(C25,D25,E25,F25,G25) -> 3020.632
B26: Gross Debt | C26: ='Consolidated Balance Sheet'!C17+'Consolidated Balance Sheet'!C23 -> 29814.58 | D26: ='Consolidated Balance Sheet'!D17+'Consolidated Balance Sheet'!D23 -> 34198.84 | E26: ='Consolidated Balance Sheet'!E17+'Consolidated Balance Sheet'!E23 -> 37008.87 | F26: ='Consolidated Balance Sheet'!F17+'Consolidated Balance Sheet'!F23 -> 40206.08 | G26: ='Consolidated Balance Sheet'!G17+'Consolidated Balance Sheet'!G23 -> 48898.45 | H26: =AVERAGE(C26,D26,E26,F26,G26) -> 38025.364
B27: Cash & Equivalents | C27: ='Consolidated Balance Sheet'!C45 -> 1492.57 | D27: ='Consolidated Balance Sheet'!D45 -> 1704.14 | E27: ='Consolidated Balance Sheet'!E45 -> 2228.14 | F27: ='Consolidated Balance Sheet'!F45 -> 3618.68 | G27: ='Consolidated Balance Sheet'!G45 -> 3947.34 | H27: =AVERAGE(C27,D27,E27,F27,G27) -> 2598.174
B28: Net Debt | C28: ='Consolidated Balance Sheet'!C17+'Consolidated Balance Sheet'!C23-'Consolidated Balance Sheet'!C45 -> 28322.01 | D28: ='Consolidated Balance Sheet'!D17+'Consolidated Balance Sheet'!D23-'Consolidated Balance Sheet'!D45 -> 32494.7 | E28: ='Consolidated Balance Sheet'!E17+'Consolidated Balance Sheet'!E23-'Consolidated Balance Sheet'!E45 -> 34780.73 | F28: ='Consolidated Balance Sheet'!F17+'Consolidated Balance Sheet'!F23-'Consolidated Balance Sheet'!F45 -> 36587.4 | G28: ='Consolidated Balance Sheet'!G17+'Consolidated Balance Sheet'!G23-'Consolidated Balance Sheet'!G45 -> 44951.11 | H28: =AVERAGE(C28,D28,E28,F28,G28) -> 35427.19
B29: Total Assets | C29: ='Consolidated Balance Sheet'!C49 -> 47464.11 | D29: ='Consolidated Balance Sheet'!D49 -> 53931.75 | E29: ='Consolidated Balance Sheet'!E49 -> 58578.81 | F29: ='Consolidated Balance Sheet'!F49 -> 73960.1 | G29: ='Consolidated Balance Sheet'!G49 -> 92834.92 | H29: =AVERAGE(C29,D29,E29,F29,G29) -> 65353.938
B30: Fixed Assets | C30: ='Consolidated Balance Sheet'!C35 -> 34733.64 | D30: ='Consolidated Balance Sheet'!D35 -> 38247.29 | E30: ='Consolidated Balance Sheet'!E35 -> 41324.14 | F30: ='Consolidated Balance Sheet'!F35 -> 44658.7 | G30: ='Consolidated Balance Sheet'!G35 -> 48259.25 | H30: =AVERAGE(C30,D30,E30,F30,G30) -> 41444.604
B32: Return Ratios
B33: RoE: PAT / Equity (%) | C33: ='Consolidated Profit & Loss'!C36/('Consolidated Balance Sheet'!C13+'Consolidated Balance Sheet'!C15) -> 0.15150707 | D33: ='Consolidated Profit & Loss'!D36/('Consolidated Balance Sheet'!D13+'Consolidated Balance Sheet'!D15) -> 0.098458541 | E33: ='Consolidated Profit & Loss'!E36/('Consolidated Balance Sheet'!E13+'Consolidated Balance Sheet'!E15) -> 0.082994177 | F33: ='Consolidated Profit & Loss'!F36/('Consolidated Balance Sheet'!F13+'Consolidated Balance Sheet'!F15) -> 0.046063101 | G33: ='Consolidated Profit & Loss'!G36/('Consolidated Balance Sheet'!G13+'Consolidated Balance Sheet'!G15) -> 0.086050327 | H33: =AVERAGE(C33,D33,E33,F33,G33) -> 0.093014644
B34: RoA: PAT / Total Assets (%) | C34: ='Consolidated Profit & Loss'!C36/'Consolidated Balance Sheet'!C49 -> 0.025379387 | D34: ='Consolidated Profit & Loss'!D36/'Consolidated Balance Sheet'!D49 -> 0.023294812 | E34: ='Consolidated Profit & Loss'!E36/'Consolidated Balance Sheet'!E49 -> 0.019414529 | F34: ='Consolidated Profit & Loss'!F36/'Consolidated Balance Sheet'!F49 -> 0.014331646 | G34: ='Consolidated Profit & Loss'!G36/'Consolidated Balance Sheet'!G49 -> 0.024587084 | H34: =AVERAGE(C34,D34,E34,F34,G34) -> 0.021401492
B35: RoCE: EBIT / Capital Employed (%) | C35: =('Consolidated Profit & Loss'!C24+'Consolidated Profit & Loss'!C20)/('Consolidated Balance Sheet'!C49-'Consolidated Balance Sheet'!C27) -> 0.081446952 | D35: =('Consolidated Profit & Loss'!D24+'Consolidated Profit & Loss'!D20)/('Consolidated Balance Sheet'!D49-'Consolidated Balance Sheet'!D27) -> 0.073700305 | E35: =('Consolidated Profit & Loss'!E24+'Consolidated Profit & Loss'!E20)/('Consolidated Balance Sheet'!E49-'Consolidated Balance Sheet'!E27) -> 0.099008487 | F35: =('Consolidated Profit & Loss'!F24+'Consolidated Profit & Loss'!F20)/('Consolidated Balance Sheet'!F49-'Consolidated Balance Sheet'!F27) -> 0.11229848 | G35: =('Consolidated Profit & Loss'!G24+'Consolidated Profit & Loss'!G20)/('Consolidated Balance Sheet'!G49-'Consolidated Balance Sheet'!G27) -> 0.10150896 | H35: =AVERAGE(C35,D35,E35,F35,G35) -> 0.093592636
B37: Leverage & Coverage Ratios
B38: Gross Debt / Equity (x) | C38: =('Consolidated Balance Sheet'!C17+'Consolidated Balance Sheet'!C23)/('Consolidated Balance Sheet'!C13+'Consolidated Balance Sheet'!C15) -> 3.7498607 | D38: =('Consolidated Balance Sheet'!D17+'Consolidated Balance Sheet'!D23)/('Consolidated Balance Sheet'!D13+'Consolidated Balance Sheet'!D15) -> 2.680162 | E38: =('Consolidated Balance Sheet'!E17+'Consolidated Balance Sheet'!E23)/('Consolidated Balance Sheet'!E13+'Consolidated Balance Sheet'!E15) -> 2.7007603 | F38: =('Consolidated Balance Sheet'!F17+'Consolidated Balance Sheet'!F23)/('Consolidated Balance Sheet'!F13+'Consolidated Balance Sheet'!F15) -> 1.747235 | G38: =('Consolidated Balance Sheet'!G17+'Consolidated Balance Sheet'!G23)/('Consolidated Balance Sheet'!G13+'Consolidated Balance Sheet'!G15) -> 1.8434409 | H38: =AVERAGE(C38,D38,E38,F38,G38) -> 2.5442918
B39: Net Debt / Equity (x) | C39: =('Consolidated Balance Sheet'!C17+'Consolidated Balance Sheet'!C23-'Consolidated Balance Sheet'!C45)/('Consolidated Balance Sheet'!C13+'Consolidated Balance Sheet'!C15) -> 3.5621361 | D39: =('Consolidated Balance Sheet'!D17+'Consolidated Balance Sheet'!D23-'Consolidated Balance Sheet'!D45)/('Consolidated Balance Sheet'!D13+'Consolidated Balance Sheet'!D15) -> 2.5466086 | E39: =('Consolidated Balance Sheet'!E17+'Consolidated Balance Sheet'!E23-'Consolidated Balance Sheet'!E45)/('Consolidated Balance Sheet'!E13+'Consolidated Balance Sheet'!E15) -> 2.5381595 | F39: =('Consolidated Balance Sheet'!F17+'Consolidated Balance Sheet'!F23-'Consolidated Balance Sheet'!F45)/('Consolidated Balance Sheet'!F13+'Consolidated Balance Sheet'!F15) -> 1.5899781 | G39: =('Consolidated Balance Sheet'!G17+'Consolidated Balance Sheet'!G23-'Consolidated Balance Sheet'!G45)/('Consolidated Balance Sheet'!G13+'Consolidated Balance Sheet'!G15) -> 1.6946287 | H39: =AVERAGE(C39,D39,E39,F39,G39) -> 2.3863022
B40: Net Debt / EBITDA (x) | C40: =('Consolidated Balance Sheet'!C17+'Consolidated Balance Sheet'!C23-'Consolidated Balance Sheet'!C45)/('Consolidated Profit & Loss'!C24+'Consolidated Profit & Loss'!C20+'Consolidated Profit & Loss'!C21) -> 5.8880049 | D40: =('Consolidated Balance Sheet'!D17+'Consolidated Balance Sheet'!D23-'Consolidated Balance Sheet'!D45)/('Consolidated Profit & Loss'!D24+'Consolidated Profit & Loss'!D20+'Consolidated Profit & Loss'!D21) -> 6.4150947 | E40: =('Consolidated Balance Sheet'!E17+'Consolidated Balance Sheet'!E23-'Consolidated Balance Sheet'!E45)/('Consolidated Profit & Loss'!E24+'Consolidated Profit & Loss'!E20+'Consolidated Profit & Loss'!E21) -> 5.1282674 | F40: =('Consolidated Balance Sheet'!F17+'Consolidated Balance Sheet'!F23-'Consolidated Balance Sheet'!F45)/('Consolidated Profit & Loss'!F24+'Consolidated Profit & Loss'!F20+'Consolidated Profit & Loss'!F21) -> 4.026465 | G40: =('Consolidated Balance Sheet'!G17+'Consolidated Balance Sheet'!G23-'Consolidated Balance Sheet'!G45)/('Consolidated Profit & Loss'!G24+'Consolidated Profit & Loss'!G20+'Consolidated Profit & Loss'!G21) -> 4.576793 | H40: =AVERAGE(C40,D40,E40,F40,G40) -> 5.206925
B41: Interest Coverage: EBIT / Finance (x) | C41: =('Consolidated Profit & Loss'!C24+'Consolidated Profit & Loss'!C20)/'Consolidated Profit & Loss'!C20 -> 1.4304615 | D41: =('Consolidated Profit & Loss'!D24+'Consolidated Profit & Loss'!D20)/'Consolidated Profit & Loss'!D20 -> 1.2430873 | E41: =('Consolidated Profit & Loss'!E24+'Consolidated Profit & Loss'!E20)/'Consolidated Profit & Loss'!E20 -> 1.809529 | F41: =('Consolidated Profit & Loss'!F24+'Consolidated Profit & Loss'!F20)/'Consolidated Profit & Loss'!F20 -> 2.203261 | G41: =('Consolidated Profit & Loss'!G24+'Consolidated Profit & Loss'!G20)/'Consolidated Profit & Loss'!G20 -> 2.1589639 | H41: =AVERAGE(C41,D41,E41,F41,G41) -> 1.7690605
B42: Gross Debt / Total Assets (%) | C42: =('Consolidated Balance Sheet'!C17+'Consolidated Balance Sheet'!C23)/'Consolidated Balance Sheet'!C49 -> 0.62814999 | D42: =('Consolidated Balance Sheet'!D17+'Consolidated Balance Sheet'!D23)/'Consolidated Balance Sheet'!D49 -> 0.6341133 | E42: =('Consolidated Balance Sheet'!E17+'Consolidated Balance Sheet'!E23)/'Consolidated Balance Sheet'!E49 -> 0.63177914 | F42: =('Consolidated Balance Sheet'!F17+'Consolidated Balance Sheet'!F23)/'Consolidated Balance Sheet'!F49 -> 0.54361852 | G42: =('Consolidated Balance Sheet'!G17+'Consolidated Balance Sheet'!G23)/'Consolidated Balance Sheet'!G49 -> 0.52672475 | H42: =AVERAGE(C42,D42,E42,F42,G42) -> 0.59287714
B44: Asset & Efficiency Ratios
B45: Asset Turnover: Revenue / Total Assets (x) | C45: ='Consolidated Profit & Loss'!C9/'Consolidated Balance Sheet'!C49 -> 0.23091574 | D45: ='Consolidated Profit & Loss'!D9/'Consolidated Balance Sheet'!D49 -> 0.24095491 | E45: ='Consolidated Profit & Loss'!E9/'Consolidated Balance Sheet'!E49 -> 0.27919669 | F45: ='Consolidated Profit & Loss'!F9/'Consolidated Balance Sheet'!F49 -> 0.31836287 | G45: ='Consolidated Profit & Loss'!G9/'Consolidated Balance Sheet'!G49 -> 0.29302153 | H45: =AVERAGE(C45,D45,E45,F45,G45) -> 0.27249035
...

Sheet Assumption
B1: Adani Energy Solutions Ltd.
B3: Particulars | C3: 44621 | D3: 44986 | E3: 45352 | F3: 45717 | G3: Mar-26
B4: Revenue from operations | C4: ='Consolidated Profit & Loss'!C11 -> 11257.52 | D4: ='Consolidated Profit & Loss'!D11 -> 13292.72 | E4: ='Consolidated Profit & Loss'!E11 -> 16607.36 | F4: ='Consolidated Profit & Loss'!F11 -> 23767.09 | G4: ='Consolidated Profit & Loss'!G11 -> 27588.03 | I4: Median of Revenue Growth
B5: Revenue growth in % | D5: =(D4/C4)-1 -> 0.18078582 | E5: =(E4/D4)-1 -> 0.24935754 | F5: =(F4/E4)-1 -> 0.43111789 | G5: =(G4/F4)-1 -> 0.160766 | I5: =MEDIAN(D5:G5) -> 0.21507168
B6: Less: Cost of Power Purchased | C6: ='Consolidated Profit & Loss'!C16 -> 2778.88 | D6: ='Consolidated Profit & Loss'!D16 -> 3839.98 | E6: ='Consolidated Profit & Loss'!E16 -> 4340.3 | F6: ='Consolidated Profit & Loss'!F16 -> 5584.14 | G6: ='Consolidated Profit & Loss'!G16 -> 6347.88
B7: Less: Employee Benefit Expenses | C7: ='Consolidated Profit & Loss'!C19 -> 885.07 | D7: ='Consolidated Profit & Loss'!D19 -> 986.65 | E7: ='Consolidated Profit & Loss'!E19 -> 951.7 | F7: ='Consolidated Profit & Loss'!F19 -> 1032.94 | G7: ='Consolidated Profit & Loss'!G19 -> 1092.64
B8: Less: Cost Of Fuel | C8: ='Consolidated Profit & Loss'!C17 -> 1065.99 | D8: ='Consolidated Profit & Loss'!D17 -> 1384.18 | E8: ='Consolidated Profit & Loss'!E17 -> 1119.09 | F8: ='Consolidated Profit & Loss'!F17 -> 623.54 | G8: ='Consolidated Profit & Loss'!G17 -> 0
B9: Less: Other Expenses | C9: ='Consolidated Profit & Loss'!C22 -> 1500.18 | D9: ='Consolidated Profit & Loss'!D22 -> 1809.17 | E9: ='Consolidated Profit & Loss'!E22 -> 2996.11 | F9: ='Consolidated Profit & Loss'!F22 -> 6753.46 | G9: ='Consolidated Profit & Loss'!G22 -> 2923.62
B10: Less: Purchase Of Stock-In Trade | C10: ='Consolidated Profit & Loss'!C15 -> 821.23 | D10: ='Consolidated Profit & Loss'!D15 -> 755.13 | E10: ='Consolidated Profit & Loss'!E15 -> 1028.95 | F10: ='Consolidated Profit & Loss'!F15 -> 1365.74 | G10: ='Consolidated Profit & Loss'!G15 -> 1004.14
B11: Total Expenses | C11: =C6+C7+C8+C9+C10 -> 7051.35 | D11: =D6+D7+D8+D9+D10 -> 8775.11 | E11: =E6+E7+E8+E9+E10 -> 10436.15 | F11: =F6+F7+F8+F9+F10 -> 15359.82 | G11: =G6+G7+G8+G9+G10 -> 11368.28
B12: EBITDA | C12: =C4-C11 -> 4206.17 | D12: =D4-D11 -> 4517.61 | E12: =E4-E11 -> 6171.21 | F12: =F4-F11 -> 8407.27 | G12: =G4-G11 -> 16219.75
B13: Less: Depreciation And Amortization | C13: ='Consolidated Profit & Loss'!C21 -> 1427.15 | D13: ='Consolidated Profit & Loss'!D21 -> 1607.74 | E13: ='Consolidated Profit & Loss'!E21 -> 1776.08 | F13: ='Consolidated Profit & Loss'!F21 -> 1905.95 | G13: ='Consolidated Profit & Loss'!G21 -> 1978.23
B14: EBIT | C14: =C12-C13 -> 2779.02 | D14: =D12-D13 -> 2909.87 | E14: =E12-E13 -> 4395.13 | F14: =F12-F13 -> 6501.32 | G14: =G12-G13 -> 14241.52
B15: ADD: Other Income / Non-Operating Income | C15: ='Consolidated Profit & Loss'!C12 -> 603.95 | D15: ='Consolidated Profit & Loss'!D12 -> 547.74 | E15: ='Consolidated Profit & Loss'!E12 -> 610.95 | F15: ='Consolidated Profit & Loss'!F12 -> 679.46 | G15: ='Consolidated Profit & Loss'!G12 -> 737.13
B16: Less: Finance Costs / Interest Expenses | C16: ='Consolidated Profit & Loss'!C20 -> 2364.95 | D16: ='Consolidated Profit & Loss'!D20 -> 2781.47 | E16: ='Consolidated Profit & Loss'!E20 -> 2766.51 | F16: ='Consolidated Profit & Loss'!F20 -> 3259.16 | G16: ='Consolidated Profit & Loss'!G20 -> 3632.9
B17: PBT | C17: =C14+C15-C16 -> 1018.02 | D17: =D14+D15-D16 -> 676.14 | E17: =E14+E15-E16 -> 2239.57 | F17: =F14+F15-F16 -> 3921.62 | G17: =G14+G15-G16 -> 11345.75
B18: Less: Total Tax Expenses | C18: ='Consolidated Profit & Loss'!C30 -> 436.06 | D18: ='Consolidated Profit & Loss'!D30 -> 435.33 | E18: ='Consolidated Profit & Loss'!E30 -> 580.13 | F18: ='Consolidated Profit & Loss'!F30 -> 178.99 | G18: ='Consolidated Profit & Loss'!G30 -> 771.71
B19: Tax Rate | C19: =C18/C17 -> 0.42834129 | D19: =D18/D17 -> 0.64384595 | E19: =E18/E17 -> 0.25903633 | F19: =F18/F17 -> 0.045641852 | G19: =G18/G17 -> 0.06801754
B20: Less: Minority Interest | C20: =-'Consolidated Profit & Loss'!C35 -> 31.14 | D20: =-'Consolidated Profit & Loss'!D35 -> 24.27 | E20: =-'Consolidated Profit & Loss'!E35 -> 58.33 | F20: =-'Consolidated Profit & Loss'!F35 -> -138.28 | G20: =-'Consolidated Profit & Loss'!G35 -> 110.21
B21: Net Profit - PAT | C21: =C17-C18-C20 -> 550.82 | D21: =D17-D18-D20 -> 216.54 | E21: =E17-E18-E20 -> 1601.11 | F21: =F17-F18-F20 -> 3880.91 | G21: =G17-G18-G20 -> 10463.83
B23: Historical Growth
B24: Average Growth | C24: =AVERAGE(D5:G5) -> 0.25550681
B25: CAGR | C25: =(G4/C4)^(1/4)-1 -> 0.25117913 | D25: =_xlfn.RRI(4,C4,G4) -> 0.25117913 | E25: RRI
B27: Margins
B28: EBITDA | C28: =C12/C4 -> 0.37363203 | D28: =D12/D4 -> 0.33985595 | E28: =E12/E4 -> 0.37159488 | F28: =F12/F4 -> 0.35373577 | G28: =G12/G4 -> 0.58792708
B29: EBIT | C29: =C14/C4 -> 0.24685899 | D29: =D14/D4 -> 0.21890704 | E29: =E14/E4 -> 0.26464953 | F29: =F14/F4 -> 0.27354295 | G29: =G14/G4 -> 0.51622098
B30: EBT | C30: =C17/C4 -> 0.090430219 | D30: =D17/D4 -> 0.050865436 | E30: =E17/E4 -> 0.13485406 | F30: =F17/F4 -> 0.16500211 | G30: =G17/G4 -> 0.41125626
B31: Net Profit | C31: =C21/C4 -> 0.048929071 | D31: =D21/D4 -> 0.01629012 | E31: =E21/E4 -> 0.096409664 | F31: =F21/F4 -> 0.16328924 | G31: =G21/G4 -> 0.37928877
B33: Tax Rate
B34: Effective tax rate | C34: =C18/C17 -> 0.42834129 | D34: =D18/D17 -> 0.64384595 | E34: =E18/E17 -> 0.25903633 | F34: =F18/F17 -> 0.045641852 | G34: =G18/G17 -> 0.06801754
B35: Marginal Tax rate | C35: 0.25 | D35: 0.25 | E35: 0.25 | F35: 0.25 | G35: 0.25
B37: Return On Capital
B38: EBIT*(1-T) | C38: =C14*(1-C35) -> 2084.265 | D38: =D14*(1-D35) -> 2182.4025 | E38: =E14*(1-E35) -> 3296.3475 | F38: =F14*(1-F35) -> 4875.99 | G38: =G14*(1-G35) -> 10681.14
B39: Book Equity | C39: ='Consolidated Balance Sheet'!C13 -> 6857.17 | D39: ='Consolidated Balance Sheet'!D13 -> 11662.44 | E39: ='Consolidated Balance Sheet'!E13 -> 12641.55 | F39: ='Consolidated Balance Sheet'!F13 -> 22068.2 | G39: ='Consolidated Balance Sheet'!G13 -> 25427.54
B40: Book Debt | C40: ='Consolidated Balance Sheet'!C17+'Consolidated Balance Sheet'!C23 -> 29814.58 | D40: ='Consolidated Balance Sheet'!D17+'Consolidated Balance Sheet'!D23 -> 34198.84 | E40: ='Consolidated Balance Sheet'!E17+'Consolidated Balance Sheet'!E23 -> 37008.87 | F40: ='Consolidated Balance Sheet'!F17+'Consolidated Balance Sheet'!F23 -> 40206.08 | G40: ='Consolidated Balance Sheet'!G17+'Consolidated Balance Sheet'!G23 -> 48898.45
B41: Cash and Cash Equivalents | C41: ='Consolidated Balance Sheet'!C45 -> 1492.57 | D41: ='Consolidated Balance Sheet'!D45 -> 1704.14 | E41: ='Consolidated Balance Sheet'!E45 -> 2228.14 | F41: ='Consolidated Balance Sheet'!F45 -> 3618.68 | G41: ='Consolidated Balance Sheet'!G45 -> 3947.34
B42: Capital Employed | C42: =C39+C40+C41 -> 38164.32 | D42: =D39+D40+D41 -> 47565.42 | E42: =E39+E40+E41 -> 51878.56 | F42: =F39+F40+F41 -> 65892.96 | G42: =G39+G40+G41 -> 78273.33
B44: Pre-Tax Return on Capital | C44: =C14/C42 -> 0.072817228 | D44: =D14/D42 -> 0.061176165 | E44: =E14/E42 -> 0.084719584 | F44: =F14/F42 -> 0.098664865 | G44: =G14/G42 -> 0.18194601
B45: Post Tax Return on Capital | C45: =C38/C42 -> 0.054612921 | D45: =D38/D42 -> 0.045882124 | E45: =E38/E42 -> 0.063539688 | F45: =F38/F42 -> 0.073998649 | G45: =G38/G42 -> 0.13645951
B47: Growth In EBIT | C47: ='Fixed Assets Schedule'!C29*Assumption!G45 -> 0.030537193

Sheet Historical FS
B1: Historical Financial Statement
B3: Years | C3: 2022 | D3: 2023 | E3: 2024 | F3: 2025 | G3: 2026
B4: Income statement
B5: Revenue from Operations | C5: ='Consolidated Profit & Loss'!C9 -> 10960.21 | D5: ='Consolidated Profit & Loss'!D9 -> 12995.12 | E5: ='Consolidated Profit & Loss'!E9 -> 16355.01 | F5: ='Consolidated Profit & Loss'!F9 -> 23546.15 | G5: ='Consolidated Profit & Loss'!G9 -> 27202.63
B6: Revenue Growth | D6: ='Consolidated Profit & Loss'!D9/'Consolidated Profit & Loss'!C9-1 -> 0.18566341 | E6: ='Consolidated Profit & Loss'!E9/'Consolidated Profit & Loss'!D9-1 -> 0.25855013 | F6: ='Consolidated Profit & Loss'!F9/'Consolidated Profit & Loss'!E9-1 -> 0.43969035 | G6: ='Consolidated Profit & Loss'!G9/'Consolidated Profit & Loss'!F9-1 -> 0.15528993
