Workbook

Sheet Company Overview
A1: ASIAN PAINTS LIMITED
B6: COMPANY OVERVIEW
B7: ABOUT THE COMPANY | L7: Source
B8: Asian Paints Limited (NSE: ASIANPAINT | BSE: 500820) is India's largest paint company and one of the leading players in the decorative and industrial coatings space across Asia, the Middle East and Africa. Originally set up in 1942 in a garage in Mumbai by four friends - Champaklal Choksey, Chimanlal Choksi, Suryakant Dani and Arvind Vakil - the company has grown into a multi-brand group with operations spanning 15+ countries and 27 manufacturing facilities, serving customers in more than 60 countries. Beyond its core decorative and industrial paints business, Asian Paints has steadily expanded into the home decor and improvement space, covering waterproofing, adhesives, wall coverings, modular kitchens, bath fittings and interior design services. The company commands a market share of over 50% in the organised Indian decorative paints segment and continues to invest in backward integration through a large multi-year capex programme aimed at securing raw material supply and improving cost efficiency.
B9: REGISTERED OFFICE
B10: Address | C10: 6A & 6B, Shantinagar, Santacruz (East), Mumbai - 400055, Maharashtra, India
B12: S.No | C12: Name of Entity | D12: Type | F12: Country / Region of Operation | G12: Primary Business | H12: Remarks
B13: 1 | C13: Berger International Limited (Asian Paints Berger) | D13: Subsidiary | F13: UAE, Bahrain, Oman, Qatar | G13: Decorative & industrial paints | H13: Middle East operations
B14: 2 | C14: SCIB Paints S.A.E. | D14: Subsidiary | F14: Egypt | G14: Decorative & industrial paints | H14: Africa operations
B15: 3 | C15: Taubmans Paints (Fiji) Limited | D15: Subsidiary | F15: Fiji, Samoa | G15: Decorative paints | H15: South Pacific operations
B16: 4 | C16: Apco Coatings (Fiji) Limited | D16: Subsidiary | F16: Fiji, Solomon Islands, Vanuatu | G16: Protective & marine coatings | H16: South Pacific operations
B17: 5 | C17: Asian Paints (Causeway) Limited | D17: Subsidiary | F17: Sri Lanka | G17: Decorative paints | H17: Asia operations
B18: 6 | C18: Kadisco Asian Paints Industries S.C. | D18: Associate | F18: Ethiopia | G18: Decorative, industrial & automotive paints, adhesives | H18: Africa operations
B19: 7 | C19: Asian Paints (Nepal) Private Limited | D19: Subsidiary | F19: Nepal | G19: Decorative paints | H19: Asia operations
B20: 8 | C20: Asian Paints International Pte. Limited | D20: Subsidiary | F20: Singapore | G20: Holding company | H20: Holding entity for international subsidiaries
B21: 9 | C21: PPG Asian Paints Private Limited | D21: Joint Venture (50:50 with PPG Inc.) | F21: India | G21: Automotive coatings | H21: JV with PPG Industries Inc.
B22: 10 | C22: Asian PPG Industrial Coatings Private Limited | D22: Joint Venture (50:50 with PPG Inc.) | F22: India | G22: Protective, powder & industrial coatings | H22: JV with PPG Industries Inc.
B23: 11 | C23: Sleek International Private Limited | D23: Subsidiary | F23: India | G23: Modular kitchens | H23: Home decor segment
B24: 12 | C24: Weatherseal Fenestration Private Limited | D24: Subsidiary | F24: India | G24: uPVC windows & doors | H24: Home improvement segment
... B26: 14 | C26: Maxbhumi Developers Limited | D26: Subsidiary | F26: India | G26: Real estate | H26: Support entity

Sheet Promoters
B1: Shareholding Pattern
B3: Asian Paints Ltd
B4: Scrip Code : 500820 | C4: Quarter Ending : Mar-26
B5: Statement showing shareholding pattern of the Promoter and Promoter Group
B6: Category of shareholder | C6: Entity Type | D6: Nos. of shareholders | E6: No. of fully paid up equity shares held | F6: Total nos. shares held | G6: Shareholding as a % of total no. of shares (calculated as per SCRR, 1957)As a % of (A+B+C2) | H6: Number of Voting Rights held in each class of securities | J6: Total No. Of shares on fully diluted basis (including warrants, ESOP, Convertible Securities etc.) | K6: Shareholding , as a % assuming full conversion of convertible securities ( as a percentage of diluted share capital)As a % of (A+B+C2) | L6: Number of Shares pledged or otherwise encumbered | N6: Total Number of Shares encumbered | P6: Number of equity shares held in dematerialized form
H7: Class eg: X | I7: Total | L7: No.(a) | M7: As a % of total Shares held(b) | N7: No.(a) | O7: As a % of total Shares held(b)
B9: A1) Indian | D9: - | E9: - | F9: - | G9: 0 | H9: - | I9: 0 | J9: - | K9: 0 | L9: - | M9: 0 | N9: - | O9: 0 | P9: -
B10: Individuals/Hindu undivided Family | D10: 52 | E10: 95399647 | F10: 95399647 | G10: 9.95 | H10: 95399647 | I10: 9.95 | J10: 95399647 | K10: 9.95 | L10: 2685727 | M10: 2.82 | N10: 2685727 | O10: 2.82 | P10: 95399647
B11: Dipika Amar Vakil | C11: Promoter Group | D11: 1 | E11: 12761340 | F11: 12761340 | G11: 1.33 | H11: 12761340 | I11: 1.33 | J11: 12761340 | K11: 1.33 | L11: - | M11: 0 | N11: - | O11: 0 | P11: 12761340
B12: Late Abhay Arvind Vakil | C12: Promoter | D12: 1 | E12: 12418060 | F12: 12418060 | G12: 1.29 | H12: 12418060 | I12: 1.29 | J12: 12418060 | K12: 1.29 | L12: - | M12: 0 | N12: - | O12: 0 | P12: 12418060
B13: Vivek Abhay Vakil | C13: Promoter | D13: 1 | E13: 6812369 | F13: 6812369 | G13: 0.71 | H13: 6812369 | I13: 0.71 | J13: 6812369 | K13: 0.71 | L13: - | M13: 0 | N13: - | O13: 0 | P13: 6812369
B14: Bhairavi Abhay Vakil | C14: Promoter | D14: 1 | E14: 6064322 | F14: 6064322 | G14: 0.63 | H14: 6064322 | I14: 0.63 | J14: 6064322 | K14: 0.63 | L14: - | M14: 0 | N14: - | O14: 0 | P14: 6064322
B15: Nehal Abhay Vakil | C15: Promoter | D15: 1 | E15: 5738489 | F15: 5738489 | G15: 0.6 | H15: 5738489 | I15: 0.6 | J15: 5738489 | K15: 0.6 | L15: - | M15: 0 | N15: - | O15: 0 | P15: 5738489
B16: Prafullika Shailesh Choksi | C16: Promoter Group | D16: 1 | E16: 3874480 | F16: 3874480 | G16: 0.4 | H16: 3874480 | I16: 0.4 | J16: 3874480 | K16: 0.4 | L16: - | M16: 0 | N16: - | O16: 0 | P16: 3874480
B17: Satyen Ashwin Gandhi | C17: Promoter Group | D17: 1 | E17: 3725954 | F17: 3725954 | G17: 0.39 | H17: 3725954 | I17: 0.39 | J17: 3725954 | K17: 0.39 | L17: 1391500 | M17: 37.35 | N17: 1391500 | O17: 37.35 | P17: 3725954
B18: Hiren Ashwin Gandhi | C18: Promoter Group | D18: 1 | E18: 3706265 | F18: 3706265 | G18: 0.39 | H18: 3706265 | I18: 0.39 | J18: 3706265 | K18: 0.39 | L18: 1294227 | M18: 34.92 | N18: 1294227 | O18: 34.92 | P18: 3706265
B19: Vishal Shailesh Choksi | C19: Promoter Group | D19: 1 | E19: 3380865 | F19: 3380865 | G19: 0.35 | H19: 3380865 | I19: 0.35 | J19: 3380865 | K19: 0.35 | L19: - | M19: 0 | N19: - | O19: 0 | P19: 3380865
B20: Hasit A Dani | C20: Promoter Group | D20: 1 | E20: 3150800 | F20: 3150800 | G20: 0.33 | H20: 3150800 | I20: 0.33 | J20: 3150800 | K20: 0.33 | L20: - | M20: 0 | N20: - | O20: 0 | P20: 3150800
B21: VAKIL HUF (VARUN AMAR VAKIL) | C21: Promoter Group | D21: 1 | E21: 3103290 | F21: 3103290 | G21: 0.32 | H21: 3103290 | I21: 0.32 | J21: 3103290 | K21: 0.32 | L21: - | M21: 0 | N21: - | O21: 0 | P21: 3103290
B22: Amrita Amar Vakil | C22: Promoter Group | D22: 1 | E22: 2566680 | F22: 2566680 | G22: 0.27 | H22: 2566680 | I22: 0.27 | J22: 2566680 | K22: 0.27 | L22: - | M22: 0 | N22: - | O22: 0 | P22: 2566680
B23: Jigish Shailesh Choksi | C23: Promoter Group | D23: 1 | E23: 2424825 | F23: 2424825 | G23: 0.25 | H23: 2424825 | I23: 0.25 | J23: 2424825 | K23: 0.25 | L23: - | M23: 0 | N23: - | O23: 0 | P23: 2424825
B24: Manish Mahendra Choksi | C24: Promoter | D24: 1 | E24: 2381040 | F24: 2381040 | G24: 0.25 | H24: 2381040 | I24: 0.25 | J24: 2381040 | K24: 0.25 | L24: - | M24: 0 | N24: - | O24: 0 | P24: 2381040
B25: Varun Amar Vakil | C25: Promoter Group | D25: 1 | E25: 2230590 | F25: 2230590 | G25: 0.23 | H25: 2230590 | I25: 0.23 | J25: 2230590 | K25: 0.23 | L25: - | M25: 0 | N25: - | O25: 0 | P25: 2230590
B26: AMAR ARVIND VAKIL HUF (VARUN AMAR VAKIL) | C26: Promoter Group | D26: 1 | E26: 2112190 | F26: 2112190 | G26: 0.22 | H26: 2112190 | I26: 0.22 | J26: 2112190 | K26: 0.22 | L26: - | M26: 0 | N26: - | O26: 0 | P26: 2112190
B27: ABHAY ARVIND VAKIL HUF (VIVEK ABHAY VAKIL) | C27: Promoter Group | D27: 1 | E27: 2076820 | F27: 2076820 | G27: 0.22 | H27: 2076820 | I27: 0.22 | J27: 2076820 | K27: 0.22 | L27: - | M27: 0 | N27: - | O27: 0 | P27: 2076820
B28: Rupal Anant Bhat | C28: Promoter Group | D28: 1 | E28: 1923770 | F28: 1923770 | G28: 0.2 | H28: 1923770 | I28: 0.2 | J28: 1923770 | K28: 0.2 | L28: - | M28: 0 | N28: - | O28: 0 | P28: 1923770
B29: SHAILESH CHIMANLAL CHOKSI HUF (JIGISH SHAILESH CHOKSI) | C29: Promoter Group | D29: 1 | E29: 1749690 | F29: 1749690 | G29: 0.18 | H29: 1749690 | I29: 0.18 | J29: 1749690 | K29: 0.18 | L29: - | M29: 0 | N29: - | O29: 0 | P29: 1749690
B30: Mahendra Chimanlal Choksi | C30: Promoter Group | D30: 1 | E30: 1656380 | F30: 1656380 | G30: 0.17 | H30: 1656380 | I30: 0.17 | J30: 1656380 | K30: 0.17 | L30: - | M30: 0 | N30: - | O30: 0 | P30: 1656380
... B62: ASHISH ASHWIN CHOKSI HUF (ASHISH ASHWIN CHOKSI) | C62: Promoter Group | D62: 1 | E62: 5620 | F62: 5620 | G62: 0 | H62: 5620 | I62: 0 | J62: 5620 | K62: 0 | L62: - | M62: 0 | N62: - | O62: 0 | P62: 5620
B63: ASHWIN SURYAKANT DANI HUF (ASHWIN SURYAKANT DANI) | C63: Promoter Group | D63: - | E63: - | F63: - | G63: 0 | H63: - | I63: 0 | J63: - | K63: 0 | L63: - | M63: 0 | N63: - | O63: 0 | P63: -
B64: Anant Raghuvir Bhat | C64: Promoter Group | D64: - | E64: - | F64: - | G64: 0 | H64: - | I64: 0 | J64: - | K64: 0 | L64: - | M64: 0 | N64: - | O64: 0 | P64: -
B65: Arhaan Anant Bhat | C65: Promoter Group | D65: - | E65: - | F65: - | G65: 0 | H65: - | I65: 0 | J65: - | K65: 0 | L65: - | M65: 0 | N65: - | O65: 0 | P65: -
B66: Rehaan Anant Bhat (Minor) | C66: Promoter Group | D66: - | E66: - | F66: - | G66: 0 | H66: - | I66: 0 | J66: - | K66: 0 | L66: - | M66: 0 | N66: - | O66: 0 | P66: -
B67: Priyanka Jigish Choksi | C67: Promoter Group | D67: - | E67: - | F67: - | G67: 0 | H67: - | I67: 0 | J67: - | K67: 0 | L67: - | M67: 0 | N67: - | O67: 0 | P67: -
B68: Aryan Jigish Choksi N/G Jigish Shailesh Choksi (Minor) | C68: Promoter Group | D68: - | E68: - | F68: - | G68: 0 | H68: - | I68: 0 | J68: - | K68: 0 | L68: - | M68: 0 | N68: - | O68: 0 | P68: -
B69: Gayatri Subhash Gujarathi | C69: Promoter Group | D69: - | E69: - | F69: - | G69: 0 | H69: - | I69: 0 | J69: - | K69: 0 | L69: - | M69: 0 | N69: - | O69: 0 | P69: -
B70: Amreen Sethi (Minor) | C70: Promoter Group | D70: - | E70: - | F70: - | G70: 0 | H70: - | I70: 0 | J70: - | K70: 0 | L70: - | M70: 0 | N70: - | O70: 0 | P70: -
B71: Any Other (specify) | D71: 28 | E71: 404283583 | F71: 404283583 | G71: 42.15 | H71: 404283583 | I71: 42.15 | J71: 404283583 | K71: 42.15 | L71: 47057000 | M71: 11.64 | N71: 47057000 | O71: 11.64 | P71: 404283583
B72: Sattva Holding and Trading Private Limited | C72: Promoter Group | D72: 1 | E72: 54789183 | F72: 54789183 | G72: 5.71 | H72: 54789183 | I72: 5.71 | J72: 54789183 | K72: 5.71 | L72: 6251000 | M72: 11.41 | N72: 6251000 | O72: 11.41 | P72: 54789183
B73: Smiti Holding and Trading Company Private Limited | C73: Promoter Group | D73: 1 | E73: 51442638 | F73: 51442638 | G73: 5.36 | H73: 51442638 | I73: 5.36 | J73: 51442638 | K73: 5.36 | L73: 38306000 | M73: 74.46 | N73: 38306000 | O73: 74.46 | P73: 51442638
...

Sheet Public
B1: Shareholding Pattern Public Shareholder
B3: Asian Paints Ltd
B4: Scrip Code : 500820 | E4: Quarter Ending : Mar-26
B6: Statement showing shareholding pattern of the Public shareholder
B8: Category & Name of the Shareholders | C8: No. of shareholder | D8: No. of fully paid up equity shares held | E8: Total no. shares held | F8: Shareholding % calculated as per SCRR, 1957 As a % of (A+B+C2) | G8: No. of Voting Rights | H8: Total as a % of Total Voting right | I8: Total No. Of shares on fully diluted basis (including warrants, ESOP, Convertible Securities etc.) | J8: Shareholding , as a % assuming full conversion of convertible securities ( as a percentage of diluted share capital)As a % of (A+B+C2) | K8: No. of equity shares held in dematerialized form(Not Applicable) | L8: Sub-categorization of shares (XV)
L9: Shareholding (No. of shares) under
L10: SubCategory_I | M10: SubCategory_II | N10: SubCategory_III
B11: Institutions | C11: 0 | D11: 0 | E11: - | F11: 0 | G11: - | H11: 0 | I11: - | J11: 0 | K11: - | L11: - | M11: - | N11: -
B12: B2) Institutions (Domestic) | C12: 0 | D12: 0 | E12: - | F12: 0 | G12: - | H12: 0 | I12: - | J12: 0 | K12: - | L12: - | M12: - | N12: -
B13: Mutual Funds/ | C13: 40 | D13: 109551686 | E13: 109551686 | F13: 11.42 | G13: 109551686 | H13: 11.42 | I13: 109551686 | J13: 11.42 | K13: 109551686 | L13: - | M13: - | N13: -
B14: UTI Mutual Fund | C14: 1 | D14: 11131106 | E14: 11131106 | F14: 1.16 | G14: 11131106 | H14: 1.16 | I14: 11131106 | J14: 1.16 | K14: 11131106 | L14: - | M14: - | N14: -
B15: ICICI Prudential Mutual Fund | C15: 1 | D15: 21582801 | E15: 21582801 | F15: 2.25 | G15: 21582801 | H15: 2.25 | I15: 21582801 | J15: 2.25 | K15: 21582801 | L15: - | M15: - | N15: -
B16: SBI Mutual Fund | C16: 1 | D16: 49885007 | E16: 49885007 | F16: 5.2 | G16: 49885007 | H16: 5.2 | I16: 49885007 | J16: 5.2 | K16: 49885007 | L16: - | M16: - | N16: -
B17: Venture Capital Funds | C17: 0 | D17: 0 | E17: - | F17: 0 | G17: - | H17: 0 | I17: - | J17: 0 | K17: - | L17: - | M17: - | N17: -
B18: Alternate Investment Funds | C18: 22 | D18: 4159909 | E18: 4159909 | F18: 0.43 | G18: 4159909 | H18: 0.43 | I18: 4159909 | J18: 0.43 | K18: 4159909 | L18: - | M18: - | N18: -
B19: Banks | C19: 9 | D19: 276596 | E19: 276596 | F19: 0.03 | G19: 276596 | H19: 0.03 | I19: 276596 | J19: 0.03 | K19: 272996 | L19: - | M19: - | N19: -
B20: Insurance Companies | C20: 32 | D20: 90823469 | E20: 90823469 | F20: 9.47 | G20: 90823469 | H20: 9.47 | I20: 90823469 | J20: 9.47 | K20: 90822469 | L20: - | M20: - | N20: -
B21: Life Insurance Corporation of India | C21: 1 | D21: 77822006 | E21: 77822006 | F21: 8.11 | G21: 77822006 | H21: 8.11 | I21: 77822006 | J21: 8.11 | K21: 77821006 | L21: - | M21: - | N21: -
B22: Provident Funds/ Pension Funds | C22: 1 | D22: 3732220 | E22: 3732220 | F22: 0.39 | G22: 3732220 | H22: 0.39 | I22: 3732220 | J22: 0.39 | K22: 3732220 | L22: - | M22: - | N22: -
B23: Asset reconstruction companies | C23: 0 | D23: 0 | E23: - | F23: 0 | G23: - | H23: 0 | I23: - | J23: 0 | K23: - | L23: - | M23: - | N23: -
B24: Sovereign Wealth Funds | C24: 2 | D24: 650782 | E24: 650782 | F24: 0.07 | G24: 650782 | H24: 0.07 | I24: 650782 | J24: 0.07 | K24: 650782 | L24: - | M24: - | N24: -
B25: NBFCs registered with RBI | C25: 8 | D25: 5298 | E25: 5298 | F25: 0 | G25: 5298 | H25: 0 | I25: 5298 | J25: 0 | K25: 5298 | L25: - | M25: - | N25: -
B26: Other Financial Institutions | C26: 2 | D26: 3630 | E26: 3630 | F26: 0 | G26: 3630 | H26: 0 | I26: 3630 | J26: 0 | K26: 240 | L26: - | M26: - | N26: -
B27: Any Other(Institutions (Domestic)) | C27: 0 | D27: 0 | E27: - | F27: 0 | G27: - | H27: 0 | I27: - | J27: 0 | K27: - | L27: - | M27: - | N27: -
B28: Sub Total B1 | C28: 116 | D28: 209203590 | E28: 209203590 | F28: 21.81 | G28: 209203590 | H28: 21.81 | I28: 209203590 | J28: 21.81 | K28: 209195600 | L28: - | M28: - | N28: -
B29: B19) Institutions (Foreign) | C29: 0 | D29: 0 | E29: - | F29: 0 | G29: - | H29: 0 | I29: - | J29: 0 | K29: - | L29: - | M29: - | N29: -
B30: Foreign Direct Investment | C30: 0 | D30: 0 | E30: - | F30: 0 | G30: - | H30: 0 | I30: - | J30: 0 | K30: - | L30: - | M30: - | N30: -
B31: Foreign Venture Capital Investors | C31: 0 | D31: 0 | E31: - | F31: 0 | G31: - | H31: 0 | I31: - | J31: 0 | K31: - | L31: - | M31: - | N31: -
B32: Sovereign Wealth Funds | C32: 0 | D32: 0 | E32: - | F32: 0 | G32: - | H32: 0 | I32: - | J32: 0 | K32: - | L32: - | M32: - | N32: -
B33: Foreign Portfolio Investors Category I | C33: 811 | D33: 113436518 | E33: 113436518 | F33: 11.83 | G33: 113436518 | H33: 11.83 | I33: 113436518 | J33: 11.83 | K33: 113436518 | L33: - | M33: - | N33: -
B34: Foreign Portfolio Investors Category II | C34: 39 | D34: 2712554 | E34: 2712554 | F34: 0.28 | G34: 2712554 | H34: 0.28 | I34: 2712554 | J34: 0.28 | K34: 2712554 | L34: - | M34: - | N34: -
B35: Overseas Depositories (holding DRs) (balancing figure) | C35: 0 | D35: 0 | E35: - | F35: 0 | G35: - | H35: 0 | I35: - | J35: 0 | K35: - | L35: - | M35: - | N35: -
B36: Any Other(Institutions (Foreign)) | C36: 0 | D36: 0 | E36: - | F36: 0 | G36: - | H36: 0 | I36: - | J36: 0 | K36: - | L36: - | M36: - | N36: -
B37: Sub Total B2 | C37: 850 | D37: 116149072 | E37: 116149072 | F37: 12.11 | G37: 116149072 | H37: 12.11 | I37: 116149072 | J37: 12.11 | K37: 116149072 | L37: - | M37: - | N37: -
B38: B28) Central Government/ State Government(s)/ President of India | C38: 0 | D38: 0 | E38: - | F38: 0 | G38: - | H38: 0 | I38: - | J38: 0 | K38: - | L38: - | M38: - | N38: -
B39: Central Government / President of India | C39: 3 | D39: 15420 | E39: 15420 | F39: 0 | G39: 15420 | H39: 0 | I39: 15420 | J39: 0 | K39: 15420 | L39: - | M39: - | N39: -
B40: State Government / Governor | C40: 1 | D40: 3 | E40: 3 | F40: 0 | G40: 3 | H40: 0 | I40: 3 | J40: 0 | K40: 3 | L40: - | M40: - | N40: -
B41: Shareholding by Companies or Bodies Corporate where Central / State Government is a promoter | C41: 0 | D41: 0 | E41: - | F41: 0 | G41: - | H41: 0 | I41: - | J41: 0 | K41: - | L41: - | M41: - | N41: -
B42: Sub Total B3 | C42: 4 | D42: 15423 | E42: 15423 | F42: 0 | G42: 15423 | H42: 0 | I42: 15423 | J42: 0 | K42: 15423 | L42: - | M42: - | N42: -
B43: B33) Non-Institutions | C43: 0 | D43: 0 | E43: - | F43: 0 | G43: - | H43: 0 | I43: - | J43: 0 | K43: - | L43: - | M43: - | N43: -
...

Sheet Balance Sheet
B1: Asian Paints
B2: Consolidated Balance Sheet
C3: Mar 26 | D3: 45717 | E3: 45352 | F3: 44986 | G3: 44621
C5: 12 mths | D5: 12 mths | E5: 12 mths | F5: 12 mths | G5: 12 mths
B7: EQUITIES AND LIABILITIES
B8: SHAREHOLDER'S FUNDS | I8: Changes in %
B9: Equity Share Capital | C9: 95.92 | D9: 95.92 | E9: 95.92 | F9: 95.92 | G9: 95.92 | I9: =D9/C9-1 -> 0 | J9: =E9/D9-1 -> 0 | K9: =F9/E9-1 -> 0 | L9: =G9/F9-1 -> 0
B10: Total Share Capital | C10: 95.92 | D10: 95.92 | E10: 95.92 | F10: 95.92 | G10: 95.92 | I10: =D10/C10-1 -> 0 | J10: =E10/D10-1 -> 0 | K10: =F10/E10-1 -> 0 | L10: =G10/F10-1 -> 0
B11: Reserves and Surplus | C11: 21275.67 | D11: 19303.89 | E11: 18632.38 | F11: 15896.31 | G11: 13715.64 | I11: =D11/C11-1 -> -0.092677692 | J11: =E11/D11-1 -> -0.034786253 | K11: =F11/E11-1 -> -0.1468449 | L11: =G11/F11-1 -> -0.13718089
B12: Total Reserves and Surplus | C12: 21275.67 | D12: 19303.89 | E12: 18632.38 | F12: 15896.31 | G12: 13715.64 | I12: =D12/C12-1 -> -0.092677692 | J12: =E12/D12-1 -> -0.034786253 | K12: =F12/E12-1 -> -0.1468449 | L12: =G12/F12-1 -> -0.13718089
B13: Total Shareholders Funds | C13: 21371.59 | D13: 19399.81 | E13: 18728.3 | F13: 15992.23 | G13: 13811.56 | I13: =D13/C13-1 -> -0.092261736 | J13: =E13/D13-1 -> -0.034614257 | K13: =F13/E13-1 -> -0.14609281 | L13: =G13/F13-1 -> -0.13635809
B14: Minority Interest | C14: 643.39 | D14: 659.24 | E14: 695.38 | F14: 453.66 | G14: 387.53 | I14: =D14/C14-1 -> 0.024635136 | J14: =E14/D14-1 -> 0.054820703 | K14: =F14/E14-1 -> -0.3476085 | L14: =G14/F14-1 -> -0.14576996
B15: NON-CURRENT LIABILITIES
B16: Long Term Borrowings | C16: 1247.17 | D16: 259.62 | E16: 54.38 | F16: 76.15 | G16: 44.54 | I16: =D16/C16-1 -> -0.79183271 | J16: =E16/D16-1 -> -0.79054002 | K16: =F16/E16-1 -> 0.400331 | L16: =G16/F16-1 -> -0.41510177
B17: Deferred Tax Liabilities [Net] | C17: 403.26 | D17: 404.91 | E17: 352.17 | F17: 334.84 | G17: 348.85 | I17: =D17/C17-1 -> 0.004091653 | J17: =E17/D17-1 -> -0.13025117 | K17: =F17/E17-1 -> -0.049209189 | L17: =G17/F17-1 -> 0.041840879
B18: Other Long Term Liabilities | C18: 1458.25 | D18: 1248.78 | E18: 1370.34 | F18: 814.49 | G18: 602.66 | I18: =D18/C18-1 -> -0.14364478 | J18: =E18/D18-1 -> 0.097343007 | K18: =F18/E18-1 -> -0.40562926 | L18: =G18/F18-1 -> -0.26007686
B19: Long Term Provisions | C19: 273.8 | D19: 257.78 | E19: 222.56 | F19: 230.7 | G19: 218.32 | I19: =D19/C19-1 -> -0.058509861 | J19: =E19/D19-1 -> -0.13662813 | K19: =F19/E19-1 -> 0.036574407 | L19: =G19/F19-1 -> -0.053662765
B20: Total Non-Current Liabilities | C20: 3382.48 | D20: 2171.09 | E20: 1999.45 | F20: 1456.18 | G20: 1214.37 | I20: =D20/C20-1 -> -0.35813663 | J20: =E20/D20-1 -> -0.079057064 | K20: =F20/E20-1 -> -0.27170972 | L20: =G20/F20-1 -> -0.16605777
B21: CURRENT LIABILITIES
B22: Short Term Borrowings | C22: 1046.09 | D22: 604.13 | E22: 1052.76 | F22: 896.06 | G22: 731.12 | I22: =D22/C22-1 -> -0.42248755 | J22: =E22/D22-1 -> 0.74260507 | K22: =F22/E22-1 -> -0.14884684 | L22: =G22/F22-1 -> -0.1840725
B23: Trade Payables | C23: 3863.04 | D23: 3848 | E23: 3831.34 | F23: 3635.44 | G23: 4164.3 | I23: =D23/C23-1 -> -0.0038933068 | J23: =E23/D23-1 -> -0.0043295218 | K23: =F23/E23-1 -> -0.051130936 | L23: =G23/F23-1 -> 0.14547345
B24: Other Current Liabilities | C24: 4011.32 | D24: 3621.95 | E24: 3554.38 | F24: 3290.22 | G24: 2605.87 | I24: =D24/C24-1 -> -0.097067798 | J24: =E24/D24-1 -> -0.018655697 | K24: =F24/E24-1 -> -0.074319572 | L24: =G24/F24-1 -> -0.20799521
B25: Short Term Provisions | C25: 216.58 | D25: 67.15 | E25: 62.48 | F25: 74.21 | G25: 69.7 | I25: =D25/C25-1 -> -0.6899529 | J25: =E25/D25-1 -> -0.069545793 | K25: =F25/E25-1 -> 0.18774008 | L25: =G25/F25-1 -> -0.060773481
B26: Total Current Liabilities | C26: 9137.03 | D26: 8141.23 | E26: 8500.96 | F26: 7895.93 | G26: 7570.99 | I26: =D26/C26-1 -> -0.10898509 | J26: =E26/D26-1 -> 0.044186198 | K26: =F26/E26-1 -> -0.071171962 | L26: =G26/F26-1 -> -0.041152847
B27: Total Capital And Liabilities | C27: 34534.49 | D27: 30371.37 | E27: 29924.09 | F27: 25798 | G27: 22984.45 | I27: =D27/C27-1 -> -0.12054963 | J27: =E27/D27-1 -> -0.014727027 | K27: =F27/E27-1 -> -0.13788523 | L27: =G27/F27-1 -> -0.10906078
B28: ASSETS
B29: NON-CURRENT ASSETS
B30: Tangible Assets | C30: 9165 | D30: 8631.34 | E30: 6302.47 | F30: 5354.57 | G30: 5090.21 | I30: =D30/C30-1 -> -0.058228041 | J30: =E30/D30-1 -> -0.26981558 | K30: =F30/E30-1 -> -0.15040135 | L30: =G30/F30-1 -> -0.049370911
B31: Intangible Assets | C31: 256.2 | D31: 369.18 | E31: 424.96 | F31: 187.41 | G31: 185.99 | I31: =D31/C31-1 -> 0.44098361 | J31: =E31/D31-1 -> 0.15109161 | K31: =F31/E31-1 -> -0.55899379 | L31: =G31/F31-1 -> -0.0075769703
B32: Capital Work-In-Progress | C32: 1848.67 | D32: 1254.49 | E32: 2698.37 | F32: 1019.59 | G32: 426.43 | I32: =D32/C32-1 -> -0.32140945 | J32: =E32/D32-1 -> 1.1509697 | K32: =F32/E32-1 -> -0.62214596 | L32: =G32/F32-1 -> -0.58176326
B33: Fixed Assets | C33: 11269.87 | D33: 10255.01 | E33: 9425.8 | F33: 6561.57 | G33: 5702.63 | I33: =D33/C33-1 -> -0.090050728 | J33: =E33/D33-1 -> -0.080859014 | K33: =F33/E33-1 -> -0.30387129 | L33: =G33/F33-1 -> -0.13090465
B34: Non-Current Investments | C34: 775.91 | D34: 1479.79 | E34: 1384.51 | F34: 1564.71 | G34: 1066.83 | I34: =D34/C34-1 -> 0.90716707 | J34: =E34/D34-1 -> -0.064387514 | K34: =F34/E34-1 -> 0.13015435 | L34: =G34/F34-1 -> -0.31819315
B35: Deferred Tax Assets [Net] | C35: 15.74 | D35: 16.12 | E35: 23.32 | F35: 18.67 | G35: 26.02 | I35: =D35/C35-1 -> 0.024142313 | J35: =E35/D35-1 -> 0.44665012 | K35: =F35/E35-1 -> -0.19939966 | L35: =G35/F35-1 -> 0.3936797
B36: Long Term Loans And Advances | C36: 1.57 | D36: 0 | E36: 0 | F36: 0 | G36: 0 | I36: =D36/C36-1 -> -1 | J36: 0 | K36: 0 | L36: 0
B37: Other Non-Current Assets | C37: 2067.68 | D37: 1409.19 | E37: 1134.21 | F37: 889.41 | G37: 793.78 | I37: =D37/C37-1 -> -0.31846804 | J37: =E37/D37-1 -> -0.19513337 | K37: =F37/E37-1 -> -0.21583305 | L37: =G37/F37-1 -> -0.10752072
B38: Total Non-Current Assets | C38: 14349.85 | D38: 13379.69 | E38: 12387.03 | F38: 9262.84 | G38: 7832.12 | I38: =D38/C38-1 -> -0.067607675 | J38: =E38/D38-1 -> -0.074191555 | K38: =F38/E38-1 -> -0.25221461 | L38: =G38/F38-1 -> -0.15445803
B39: CURRENT ASSETS
B40: Current Investments | C40: 6285.83 | D40: 3244.96 | E40: 3203.41 | F40: 2697 | G40: 2180.7 | I40: =D40/C40-1 -> -0.48376587 | J40: =E40/D40-1 -> -0.012804472 | K40: =F40/E40-1 -> -0.15808467 | L40: =G40/F40-1 -> -0.19143493
B41: Inventories | C41: 5743.69 | D41: 6719.27 | E41: 5923.41 | F41: 6210.64 | G41: 6152.98 | I41: =D41/C41-1 -> 0.16985248 | J41: =E41/D41-1 -> -0.11844441 | K41: =F41/E41-1 -> 0.04849065 | L41: =G41/F41-1 -> -0.0092840673
B42: Trade Receivables | C42: 4461.8 | D42: 4313.65 | E42: 4889.05 | F42: 4636.94 | G42: 3871.44 | I42: =D42/C42-1 -> -0.033204088 | J42: =E42/D42-1 -> 0.13339052 | K42: =F42/E42-1 -> -0.051566255 | L42: =G42/F42-1 -> -0.16508732
...

Sheet Profit & Loss
B1: Asian Paints
B2: Consolidated Profit & Loss account
C3: Mar 26 | D3: 45717 | E3: 45352 | F3: 44986 | G3: 44621
C5: 12 mths | D5: 12 mths | E5: 12 mths | F5: 12 mths | G5: 12 mths
B7: INCOME | I7: Chnages in %
B8: Revenue From Operations [Gross] | C8: 35516.37 | D8: 33797.36 | E8: 35382.12 | F8: 34367.83 | G8: 28923.48 | I8: =D8/C8-1 -> -0.048400498 | J8: =E8/D8-1 -> 0.046890053 | K8: =F8/E8-1 -> -0.028666739 | L8: =G8/F8-1 -> -0.15841413
B9: Revenue From Operations [Net] | C9: 35516.37 | D9: 33797.36 | E9: 35382.12 | F9: 34367.83 | G9: 28923.48 | I9: =D9/C9-1 -> -0.048400498 | J9: =E9/D9-1 -> 0.046890053 | K9: =F9/E9-1 -> -0.028666739 | L9: =G9/F9-1 -> -0.15841413
B10: Other Operating Revenues | C10: 67.17 | D10: 108.26 | E10: 112.61 | F10: 120.76 | G10: 177.8 | I10: =D10/C10-1 -> 0.61173143 | J10: =E10/D10-1 -> 0.040181046 | K10: =F10/E10-1 -> 0.072373679 | L10: =G10/F10-1 -> 0.47234184
B11: Total Operating Revenues | C11: 35583.54 | D11: 33905.62 | E11: 35494.73 | F11: 34488.59 | G11: 29101.28 | I11: =D11/C11-1 -> -0.047154387 | J11: =E11/D11-1 -> 0.046868631 | K11: =F11/E11-1 -> -0.02834618 | L11: =G11/F11-1 -> -0.15620557
B12: Other Income | C12: 723.8 | D12: 572.61 | E12: 687.96 | F12: 386.48 | G12: 380.01 | I12: =D12/C12-1 -> -0.20888367 | J12: =E12/D12-1 -> 0.20144601 | K12: =F12/E12-1 -> -0.43822315 | L12: =G12/F12-1 -> -0.01674084
B13: Total Revenue | C13: 36307.34 | D13: 34478.23 | E13: 36182.69 | F13: 34875.07 | G13: 29481.29 | I13: =D13/C13-1 -> -0.050378519 | J13: =E13/D13-1 -> 0.049435832 | K13: =F13/E13-1 -> -0.03613938 | L13: =G13/F13-1 -> -0.15466005
B14: EXPENSES
B15: Cost Of Materials Consumed | C15: 15384.05 | D15: 15793.92 | E15: 15868.21 | F15: 17330.58 | G15: 16254.59 | I15: =D15/C15-1 -> 0.026642529 | J15: =E15/D15-1 -> 0.0047037088 | K15: =F15/E15-1 -> 0.092157212 | L15: =G15/F15-1 -> -0.062086208
B16: Purchase Of Stock-In Trade | C16: 4014.05 | D16: 3926.86 | E16: 3858.2 | F16: 4135.65 | G16: 3371.13 | I16: =D16/C16-1 -> -0.021721204 | J16: =E16/D16-1 -> -0.017484708 | K16: =F16/E16-1 -> 0.071911772 | L16: =G16/F16-1 -> -0.1848609
B17: Changes In Inventories Of FG,WIP And Stock-In Trade | C17: 603.68 | D17: -205 | E17: 363.8 | F17: -309.73 | G17: -1324.97 | I17: =D17/C17-1 -> -1.3395839 | J17: =E17/D17-1 -> -2.7746341 | K17: =F17/E17-1 -> -1.8513744 | L17: =G17/F17-1 -> 3.2778226
B18: Employee Benefit Expenses | C18: 2799.59 | D18: 2597.23 | E18: 2326.18 | F18: 2028.07 | G18: 1786.67 | I18: =D18/C18-1 -> -0.072282013 | J18: =E18/D18-1 -> -0.10436118 | K18: =F18/E18-1 -> -0.12815431 | L18: =G18/F18-1 -> -0.11902942
B19: Finance Costs | C19: 195.41 | D19: 227.02 | E19: 205.17 | F19: 144.45 | G19: 95.41 | I19: =D19/C19-1 -> 0.16176245 | J19: =E19/D19-1 -> -0.096247027 | K19: =F19/E19-1 -> -0.2959497 | L19: =G19/F19-1 -> -0.33949463
B20: Depreciation And Amortisation Expenses | C20: 1228.85 | D20: 1026.34 | E20: 853 | F20: 858.02 | G20: 816.36 | I20: =D20/C20-1 -> -0.16479635 | J20: =E20/D20-1 -> -0.1688914 | K20: =F20/E20-1 -> 0.0058851114 | L20: =G20/F20-1 -> -0.048553647
B21: Other Expenses | C21: 6086.25 | D21: 5786.4 | E21: 5493.36 | F21: 5044.18 | G21: 4210.25 | I21: =D21/C21-1 -> -0.04926679 | J21: =E21/D21-1 -> -0.050642887 | K21: =F21/E21-1 -> -0.081767807 | L21: =G21/F21-1 -> -0.16532519
B22: Total Expenses | C22: 30311.88 | D22: 29152.77 | E22: 28967.92 | F22: 29231.22 | G22: 25209.44 | I22: =D22/C22-1 -> -0.038239463 | J22: =E22/D22-1 -> -0.0063407354 | K22: =F22/E22-1 -> 0.0090893651 | L22: =G22/F22-1 -> -0.13758509
B23: Profit/Loss Before Exceptional, ExtraOrdinary Items And Tax | C23: 5995.46 | D23: 5325.46 | E23: 7214.77 | F23: 5643.85 | G23: 4271.85 | I23: =D23/C23-1 -> -0.11175123 | J23: =E23/D23-1 -> 0.35476935 | K23: =F23/E23-1 -> -0.21773667 | L23: =G23/F23-1 -> -0.24309647
B24: Exceptional Items | C24: -157.61 | D24: -363.1 | E24: 0 | F24: -48.87 | G24: -115.7 | I24: =D24/C24-1 -> 1.3037878 | J24: =E24/D24-1 -> -1 | K24: 0 | L24: =G24/F24-1 -> 1.3675056
B25: Profit/Loss Before Tax | C25: 5837.85 | D25: 4962.36 | E25: 7214.77 | F25: 5594.98 | G25: 4156.15 | I25: =D25/C25-1 -> -0.14996788 | J25: =E25/D25-1 -> 0.45389895 | K25: =F25/E25-1 -> -0.22451028 | L25: =G25/F25-1 -> -0.25716446
B26: Tax Expenses-Continued Operations
B27: Current Tax | C27: 1608.75 | D27: 1388.98 | E27: 1836 | F27: 1504.14 | G27: 1161.53 | I27: =D27/C27-1 -> -0.13660917 | J27: =E27/D27-1 -> 0.32183329 | K27: =F27/E27-1 -> -0.18075163 | L27: =G27/F27-1 -> -0.227778
B28: Deferred Tax | C28: 0 | D28: 17.77 | E28: 5.43 | F28: -17.28 | G28: -61.44 | I28: 0 | J28: =E28/D28-1 -> -0.69442881 | K28: =F28/E28-1 -> -4.1823204 | L28: =G28/F28-1 -> 2.5555556
B29: Tax For Earlier Years | C29: 0 | D29: -13.39 | E29: -51.35 | F29: 6.64 | G29: 2.82 | I29: 0 | J29: =E29/D29-1 -> 2.8349515 | K29: =F29/E29-1 -> -1.1293087 | L29: =G29/F29-1 -> -0.5753012
B30: Total Tax Expenses | C30: 1608.75 | D30: 1393.36 | E30: 1790.08 | F30: 1493.5 | G30: 1102.91 | I30: =D30/C30-1 -> -0.13388656 | J30: =E30/D30-1 -> 0.28472182 | K30: =F30/E30-1 -> -0.16567975 | L30: =G30/F30-1 -> -0.26152662
B31: Profit/Loss After Tax And Before ExtraOrdinary Items | C31: 4229.1 | D31: 3569 | E31: 5424.69 | F31: 4101.48 | G31: 3053.24 | I31: =D31/C31-1 -> -0.15608522 | J31: =E31/D31-1 -> 0.51994676 | K31: =F31/E31-1 -> -0.24392362 | L31: =G31/F31-1 -> -0.25557604
B32: Profit/Loss From Continuing Operations | C32: 4229.1 | D32: 3569 | E32: 5424.69 | F32: 4101.48 | G32: 3053.24 | I32: =D32/C32-1 -> -0.15608522 | J32: =E32/D32-1 -> 0.51994676 | K32: =F32/E32-1 -> -0.24392362 | L32: =G32/F32-1 -> -0.25557604
B33: Profit/Loss For The Period | C33: 4229.1 | D33: 3569 | E33: 5424.69 | F33: 4101.48 | G33: 3053.24 | I33: =D33/C33-1 -> -0.15608522 | J33: =E33/D33-1 -> 0.51994676 | K33: =F33/E33-1 -> -0.24392362 | L33: =G33/F33-1 -> -0.25557604
B34: Minority Interest | C34: -69.34 | D34: -42.48 | E34: -97.46 | F34: -88.88 | G34: -54.24 | I34: =D34/C34-1 -> -0.3873666 | J34: =E34/D34-1 -> 1.2942561 | K34: =F34/E34-1 -> -0.088036117 | L34: =G34/F34-1 -> -0.38973897
B35: Share Of Profit/Loss Of Associates | C35: 165.59 | D35: 140.71 | E35: 133 | F35: 93.85 | G35: 31.57 | I35: =D35/C35-1 -> -0.15025062 | J35: =E35/D35-1 -> -0.054793547 | K35: =F35/E35-1 -> -0.2943609 | L35: =G35/F35-1 -> -0.66361215
B36: Consolidated Profit/Loss After MI And Associates | C36: 4325.35 | D36: 3667.23 | E36: 5460.23 | F36: 4106.45 | G36: 3030.57 | I36: =D36/C36-1 -> -0.15215416 | J36: =E36/D36-1 -> 0.48892488 | K36: =F36/E36-1 -> -0.24793461 | L36: =G36/F36-1 -> -0.26199759
B37: OTHER ADDITIONAL INFORMATION
B38: EARNINGS PER SHARE
B39: Basic EPS (Rs.) | C39: 45 | D39: 38 | E39: 57 | F39: 43 | G39: 32 | I39: =D39/C39-1 -> -0.15555556 | J39: =E39/D39-1 -> 0.5 | K39: =F39/E39-1 -> -0.24561404 | L39: =G39/F39-1 -> -0.25581395
B40: Diluted EPS (Rs.) | C40: 45 | D40: 38 | E40: 57 | F40: 43 | G40: 32 | I40: =D40/C40-1 -> -0.15555556 | J40: =E40/D40-1 -> 0.5 | K40: =F40/E40-1 -> -0.24561404 | L40: =G40/F40-1 -> -0.25581395
B41: DIVIDEND AND DIVIDEND PERCENTAGE
B42: Equity Share Dividend | C42: 0 | D42: 3107.91 | E42: 2532.38 | F42: 1908.86 | G42: 1740.95 | I42: 0 | J42: =E42/D42-1 -> -0.18518233 | K42: =F42/E42-1 -> -0.24621897 | L42: =G42/F42-1 -> -0.087963497

Sheet Cash Flow
B1: Asian Paints
B2: Consolidated Cash Flow
C3: Mar '26 | D3: Mar '25 | E3: Mar '24 | F3: Mar '23 | G3: Mar '22
C5: 12 mths | D5: 12 mths | E5: 12 mths | F5: 12 mths | G5: 12 mths
I6: Change in %
B7: Net Profit Before Tax | C7: 5837.85 | D7: 5103.07 | E7: 7347.77 | F7: 5688.83 | G7: 4187.72 | I7: =D7/C7-1 -> -0.12586483 | J7: =E7/D7-1 -> 0.43987247 | K7: =F7/E7-1 -> -0.22577462 | L7: =G7/F7-1 -> -0.26386972
B8: Net Cash From Operating Activities | C8: 7088.18 | D8: 4423.96 | E8: 6103.6 | F8: 4193.43 | G8: 986.49 | I8: =D8/C8-1 -> -0.37586799 | J8: =E8/D8-1 -> 0.37966889 | K8: =F8/E8-1 -> -0.31295793 | L8: =G8/F8-1 -> -0.76475344
B9: Net Cash (used in)/from | C9: -1334.07 | D9: -874.12 | E9: -2517.63 | F9: -1274.64 | G9: -321.69 | I9: =D9/C9-1 -> -0.34477201 | J9: =E9/D9-1 -> 1.8801881 | K9: =F9/E9-1 -> -0.49371433 | L9: =G9/F9-1 -> -0.74762286
B10: Investing Activities
B11: Net Cash (used in)/from Financing Activities | C11: -2376.51 | D11: -3752.58 | E11: -2982.5 | F11: -2140.05 | G11: -1807.61 | I11: =D11/C11-1 -> 0.57902975 | J11: =E11/D11-1 -> -0.20521348 | K11: =F11/E11-1 -> -0.28246438 | L11: =G11/F11-1 -> -0.15534216
B12: Net (decrease)/increase In Cash and Cash Equivalents | C12: 3383.44 | D12: -269.53 | E12: 572.62 | F12: 771.04 | G12: -1137.87 | I12: =D12/C12-1 -> -1.0796615 | J12: =E12/D12-1 -> -3.124513 | K12: =F12/E12-1 -> 0.34651252 | L12: =G12/F12-1 -> -2.47576
B13: Opening Cash & Cash Equivalents | C13: 3357.42 | D13: 3626.95 | E13: 3054.33 | F13: 2283.29 | G13: 3421.16 | I13: =D13/C13-1 -> 0.080278905 | J13: =E13/D13-1 -> -0.15787921 | K13: =F13/E13-1 -> -0.25244162 | L13: =G13/F13-1 -> 0.49834668
B14: Closing Cash & Cash Equivalents | C14: 6740.86 | D14: 3357.42 | E14: 3626.95 | F14: 3054.33 | G14: 2283.29 | I14: =D14/C14-1 -> -0.50193002 | J14: =E14/D14-1 -> 0.080278905 | K14: =F14/E14-1 -> -0.15787921 | L14: =G14/F14-1 -> -0.25244162

Sheet Stock Analysis
B18: Recommendation - Asian Paints Ltd: | I18: Financial Year | J18: Revenue | K18: PAT | L18: Revenue Change | M18: PAT Change
B19: "HOLD" Asian Paints Ltd remains India's dominant decorative paint franchise with 52% market share, but FY25 marks a structural inflection point driven by intensifying competition from Grasim's Birla Opus, muted urban demand, and raw-material-led margin compression. FY25 standalone revenue declined 4.5% YoY to ₹33,906 Cr, while net profit fell 34% YoY to ₹3,569 Cr OPM contracted from 21.7% to 17.1%, the sharpest single-year margin compression in over a decade. The chart reflects this reset: the stock has corrected 22% from its 52-week high, partially de-rating from 70x P/E toward 55x still elevated relative to peers (Berger at 58x, Kansai at 31x) and not yet at levels that price in the market share risk fully. Birla Opus captured ~6-10% market share in FY25 alone, with Asian Paints losing ~7 percentage points (59% → 52%); Morgan Stanley flags a further 209bps loss through FY28. Long-term moat remains intact: 70,000+ dealer touchpoints, brand equity built over 75+ years, low leverage (D/E < 0.1x), consistent 65%+ dividend payout ratio, and ROCE of 27.2% well above cost of capital. A recovery in urban housing demand, raw material cost tailwinds (crude-linked inputs), and new capacity from Vizag and Mysuru plants could support earnings revival in FY27. BUY trigger: price dip to ₹2,100-2,200 or visible PAT recovery of 20%+ in H1 FY26 results. | I19: 2024-25 | J19: 33906 | K19: 3569 | L19: =(J19-J20)/J20 -> -0.044766869 | M19: =(K19-K20)/K20 -> -0.346337
I20: 2023-24 | J20: 35495 | K20: 5460 | L20: =(J20-J21)/J21 -> 0.02916872 | M20: =(K20-K21)/K21 -> 0.32976132
I21: 2022-23 | J21: 34489 | K21: 4106 | L21: =(J21-J22)/J22 -> 0.192442 | M21: =(K21-K22)/K22 -> 0.0012192148
I22: 2021-22 | J22: 28923 | K22: 4101 | L22: =(J22-J23)/J23 -> 0.33212049 | M22: =(K22-K23)/K23 -> 0.29043424
I23: 2020-21 | J23: 21712 | K23: 3178 | L23: =IFERROR(J23/J24,0) -> 0 | M23: =IFERROR(K23/K24,0) -> 0

Sheet Historical Analysis
B1: Historical Financial Statement
B3: Years | C3: 2022 | D3: 2023 | E3: 2024 | F3: 2025 | G3: 2026
B4: Income statement
B5: Revenue from Operations | C5: ='Profit & Loss'!G9 -> 28923.48 | D5: ='Profit & Loss'!F9 -> 34367.83 | E5: ='Profit & Loss'!E9 -> 35382.12 | F5: ='Profit & Loss'!D9 -> 33797.36 | G5: ='Profit & Loss'!C9 -> 35516.37
B6: Revenue Growth | D6: ='Profit & Loss'!F9/'Profit & Loss'!G9-1 -> 0.18823288 | E6: ='Profit & Loss'!E9/'Profit & Loss'!F9-1 -> 0.029512774 | F6: ='Profit & Loss'!D9/'Profit & Loss'!E9-1 -> -0.044789854 | G6: ='Profit & Loss'!C9/'Profit & Loss'!D9-1 -> 0.050862257
B8: Total Operating Expenses (ex Finance & Depr) | C8: ='Profit & Loss'!G22-'Profit & Loss'!G19-'Profit & Loss'!G20 -> 24297.67 | D8: ='Profit & Loss'!F22-'Profit & Loss'!F19-'Profit & Loss'!F20 -> 28228.75 | E8: ='Profit & Loss'!E22-'Profit & Loss'!E19-'Profit & Loss'!E20 -> 27909.75 | F8: ='Profit & Loss'!D22-'Profit & Loss'!D19-'Profit & Loss'!D20 -> 27899.41 | G8: ='Profit & Loss'!C22-'Profit & Loss'!C19-'Profit & Loss'!C20 -> 28887.62
B9: Opex % Revenue | C9: =('Profit & Loss'!G22-'Profit & Loss'!G19-'Profit & Loss'!G20)/'Profit & Loss'!G9 -> 0.84006731 | D9: =('Profit & Loss'!F22-'Profit & Loss'!F19-'Profit & Loss'!F20)/'Profit & Loss'!F9 -> 0.82137132 | E9: =('Profit & Loss'!E22-'Profit & Loss'!E19-'Profit & Loss'!E20)/'Profit & Loss'!E9 -> 0.78880943 | F9: =('Profit & Loss'!D22-'Profit & Loss'!D19-'Profit & Loss'!D20)/'Profit & Loss'!D9 -> 0.82549081 | G9: =('Profit & Loss'!C22-'Profit & Loss'!C19-'Profit & Loss'!C20)/'Profit & Loss'!C9 -> 0.81336071
B11: EBITDA | C11: =C5-C8 -> 4625.81 | D11: =D5-D8 -> 6139.08 | E11: =E5-E8 -> 7472.37 | F11: =F5-F8 -> 5897.95 | G11: =G5-G8 -> 6628.75
B12: EBITDA Margins | C12: =('Profit & Loss'!G23+'Profit & Loss'!G19+'Profit & Loss'!G20)/'Profit & Loss'!G9 -> 0.17921841 | D12: =('Profit & Loss'!F23+'Profit & Loss'!F19+'Profit & Loss'!F20)/'Profit & Loss'!F9 -> 0.19338783 | E12: =('Profit & Loss'!E23+'Profit & Loss'!E19+'Profit & Loss'!E20)/'Profit & Loss'!E9 -> 0.23381697 | F12: =('Profit & Loss'!D23+'Profit & Loss'!D19+'Profit & Loss'!D20)/'Profit & Loss'!D9 -> 0.19465485 | G12: =('Profit & Loss'!C23+'Profit & Loss'!C19+'Profit & Loss'!C20)/'Profit & Loss'!C9 -> 0.20890986
B14: Depreciation & Amortisation | C14: ='Profit & Loss'!G20 -> 816.36 | D14: ='Profit & Loss'!F20 -> 858.02 | E14: ='Profit & Loss'!E20 -> 853 | F14: ='Profit & Loss'!D20 -> 1026.34 | G14: ='Profit & Loss'!C20 -> 1228.85
B15: Depreciation % of Sales | C15: ='Profit & Loss'!G20/'Profit & Loss'!G9 -> 0.028224819 | D15: ='Profit & Loss'!F20/'Profit & Loss'!F9 -> 0.024965789 | E15: ='Profit & Loss'!E20/'Profit & Loss'!E9 -> 0.024108222 | F15: ='Profit & Loss'!D20/'Profit & Loss'!D9 -> 0.030367461 | G15: ='Profit & Loss'!C20/'Profit & Loss'!C9 -> 0.034599538
B17: EBIT | C17: =C11-C14 -> 3809.45 | D17: =D11-D14 -> 5281.06 | E17: =E11-E14 -> 6619.37 | F17: =F11-F14 -> 4871.61 | G17: =G11-G14 -> 5399.9
B18: EBIT Margin | C18: =('Profit & Loss'!G23+'Profit & Loss'!G19)/'Profit & Loss'!G9 -> 0.15099359 | D18: =('Profit & Loss'!F23+'Profit & Loss'!F19)/'Profit & Loss'!F9 -> 0.16842204 | E18: =('Profit & Loss'!E23+'Profit & Loss'!E19)/'Profit & Loss'!E9 -> 0.20970875 | F18: =('Profit & Loss'!D23+'Profit & Loss'!D19)/'Profit & Loss'!D9 -> 0.16428739 | G18: =('Profit & Loss'!C23+'Profit & Loss'!C19)/'Profit & Loss'!C9 -> 0.17431033
B20: Finance Costs | C20: ='Profit & Loss'!G19 -> 95.41 | D20: ='Profit & Loss'!F19 -> 144.45 | E20: ='Profit & Loss'!E19 -> 205.17 | F20: ='Profit & Loss'!D19 -> 227.02 | G20: ='Profit & Loss'!C19 -> 195.41
B21: Finance Costs % of Sales | C21: ='Profit & Loss'!G19/'Profit & Loss'!G9 -> 0.003298704 | D21: ='Profit & Loss'!F19/'Profit & Loss'!F9 -> 0.0042030585 | E21: ='Profit & Loss'!E19/'Profit & Loss'!E9 -> 0.0057986915 | F21: ='Profit & Loss'!D19/'Profit & Loss'!D9 -> 0.0067170927 | G21: ='Profit & Loss'!C19/'Profit & Loss'!C9 -> 0.0055019699
B23: Other Income | C23: ='Profit & Loss'!G12 -> 380.01 | D23: ='Profit & Loss'!F12 -> 386.48 | E23: ='Profit & Loss'!E12 -> 687.96 | F23: ='Profit & Loss'!D12 -> 572.61 | G23: ='Profit & Loss'!C12 -> 723.8
B25: Profit Before Tax | C25: ='Profit & Loss'!G23 -> 4271.85 | D25: ='Profit & Loss'!F23 -> 5643.85 | E25: ='Profit & Loss'!E23 -> 7214.77 | F25: ='Profit & Loss'!D23 -> 5325.46 | G25: ='Profit & Loss'!C23 -> 5995.46
B26: PBT % Sales | C26: ='Profit & Loss'!G23/'Profit & Loss'!G9 -> 0.14769488 | D26: ='Profit & Loss'!F23/'Profit & Loss'!F9 -> 0.16421898 | E26: ='Profit & Loss'!E23/'Profit & Loss'!E9 -> 0.20391005 | F26: ='Profit & Loss'!D23/'Profit & Loss'!D9 -> 0.1575703 | G26: ='Profit & Loss'!C23/'Profit & Loss'!C9 -> 0.16880836
B28: Total Tax Expenses | C28: ='Profit & Loss'!G30 -> 1102.91 | D28: ='Profit & Loss'!F30 -> 1493.5 | E28: ='Profit & Loss'!E30 -> 1790.08 | F28: ='Profit & Loss'!D30 -> 1393.36 | G28: ='Profit & Loss'!C30 -> 1608.75
B29: Effective Tax Rate | C29: ='Profit & Loss'!G30/'Profit & Loss'!G25 -> 0.26536819 | D29: ='Profit & Loss'!F30/'Profit & Loss'!F25 -> 0.26693572 | E29: ='Profit & Loss'!E30/'Profit & Loss'!E25 -> 0.24811325 | F29: ='Profit & Loss'!D30/'Profit & Loss'!D25 -> 0.28078576 | G29: ='Profit & Loss'!C30/'Profit & Loss'!C25 -> 0.27557234
B31: Net Profit | C31: ='Profit & Loss'!G36 -> 3030.57 | D31: ='Profit & Loss'!F36 -> 4106.45 | E31: ='Profit & Loss'!E36 -> 5460.23 | F31: ='Profit & Loss'!D36 -> 3667.23 | G31: ='Profit & Loss'!C36 -> 4325.35
B32: Net Margins | C32: ='Profit & Loss'!G36/'Profit & Loss'!G9 -> 0.10477889 | D32: ='Profit & Loss'!F36/'Profit & Loss'!F9 -> 0.11948529 | E32: ='Profit & Loss'!E36/'Profit & Loss'!E9 -> 0.15432173 | F32: ='Profit & Loss'!D36/'Profit & Loss'!D9 -> 0.1085064 | G32: ='Profit & Loss'!C36/'Profit & Loss'!C9 -> 0.12178469
B34: Basic EPS (₹) | C34: ='Profit & Loss'!G39 -> 32 | D34: ='Profit & Loss'!F39 -> 43 | E34: ='Profit & Loss'!E39 -> 57 | F34: ='Profit & Loss'!D39 -> 38 | G34: ='Profit & Loss'!C39 -> 45
B35: EPS Growth % | D35: ='Profit & Loss'!F39/'Profit & Loss'!G39-1 -> 0.34375 | E35: ='Profit & Loss'!E39/'Profit & Loss'!F39-1 -> 0.3255814 | F35: ='Profit & Loss'!D39/'Profit & Loss'!E39-1 -> -0.33333333 | G35: ='Profit & Loss'!C39/'Profit & Loss'!D39-1 -> 0.18421053
B38: Balance Sheet | C38: 2022 | D38: 2023 | E38: 2024 | F38: 2025 | G38: 2026
B39: Equity Share Capital | C39: ='Balance Sheet'!G9 -> 95.92 | D39: ='Balance Sheet'!F9 -> 95.92 | E39: ='Balance Sheet'!E9 -> 95.92 | F39: ='Balance Sheet'!D9 -> 95.92 | G39: ='Balance Sheet'!C9 -> 95.92
B40: Reserves & Surplus | C40: ='Balance Sheet'!G11 -> 13715.64 | D40: ='Balance Sheet'!F11 -> 15896.31 | E40: ='Balance Sheet'!E11 -> 18632.38 | F40: ='Balance Sheet'!D11 -> 19303.89 | G40: ='Balance Sheet'!C11 -> 21275.67
B41: Total Shareholders Funds | C41: ='Balance Sheet'!G13 -> 13811.56 | D41: ='Balance Sheet'!F13 -> 15992.23 | E41: ='Balance Sheet'!E13 -> 18728.3 | F41: ='Balance Sheet'!D13 -> 19399.81 | G41: ='Balance Sheet'!C13 -> 21371.59
B42: Minority Interest | C42: ='Balance Sheet'!G14 -> 387.53 | D42: ='Balance Sheet'!F14 -> 453.66 | E42: ='Balance Sheet'!E14 -> 695.38 | F42: ='Balance Sheet'!D14 -> 659.24 | G42: ='Balance Sheet'!C14 -> 643.39
B43: Long Term Borrowings | C43: ='Balance Sheet'!G16 -> 44.54 | D43: ='Balance Sheet'!F16 -> 76.15 | E43: ='Balance Sheet'!E16 -> 54.38 | F43: ='Balance Sheet'!D16 -> 259.62 | G43: ='Balance Sheet'!C16 -> 1247.17
B44: Short Term Borrowings | C44: ='Balance Sheet'!G22 -> 731.12 | D44: ='Balance Sheet'!F22 -> 896.06 | E44: ='Balance Sheet'!E22 -> 1052.76 | F44: ='Balance Sheet'!D22 -> 604.13 | G44: ='Balance Sheet'!C22 -> 1046.09
B45: Total Borrowings | C45: ='Balance Sheet'!G16+'Balance Sheet'!G22 -> 775.66 | D45: ='Balance Sheet'!F16+'Balance Sheet'!F22 -> 972.21 | E45: ='Balance Sheet'!E16+'Balance Sheet'!E22 -> 1107.14 | F45: ='Balance Sheet'!D16+'Balance Sheet'!D22 -> 863.75 | G45: ='Balance Sheet'!C16+'Balance Sheet'!C22 -> 2293.26
B46: Other Liabilities | C46: ='Balance Sheet'!G17+'Balance Sheet'!G18+'Balance Sheet'!G19 -> 1169.83 | D46: ='Balance Sheet'!F17+'Balance Sheet'!F18+'Balance Sheet'!F19 -> 1380.03 | E46: ='Balance Sheet'!E17+'Balance Sheet'!E18+'Balance Sheet'!E19 -> 1945.07 | F46: ='Balance Sheet'!D17+'Balance Sheet'!D18+'Balance Sheet'!D19 -> 1911.47 | G46: ='Balance Sheet'!C17+'Balance Sheet'!C18+'Balance Sheet'!C19 -> 2135.31
B47: Total Current Liabilities | C47: ='Balance Sheet'!G26 -> 7570.99 | D47: ='Balance Sheet'!F26 -> 7895.93 | E47: ='Balance Sheet'!E26 -> 8500.96 | F47: ='Balance Sheet'!D26 -> 8141.23 | G47: ='Balance Sheet'!C26 -> 9137.03
B48: Total Liabilities | C48: ='Balance Sheet'!G20+'Balance Sheet'!G26 -> 8785.36 | D48: ='Balance Sheet'!F20+'Balance Sheet'!F26 -> 9352.11 | E48: ='Balance Sheet'!E20+'Balance Sheet'!E26 -> 10500.41 | F48: ='Balance Sheet'!D20+'Balance Sheet'!D26 -> 10312.32 | G48: ='Balance Sheet'!C20+'Balance Sheet'!C26 -> 12519.51
B50: Fixed Assets (Net Block) | C50: ='Balance Sheet'!G33 -> 5702.63 | D50: ='Balance Sheet'!F33 -> 6561.57 | E50: ='Balance Sheet'!E33 -> 9425.8 | F50: ='Balance Sheet'!D33 -> 10255.01 | G50: ='Balance Sheet'!C33 -> 11269.87
B51: Capital Work in Progress | C51: ='Balance Sheet'!G32 -> 426.43 | D51: ='Balance Sheet'!F32 -> 1019.59 | E51: ='Balance Sheet'!E32 -> 2698.37 | F51: ='Balance Sheet'!D32 -> 1254.49 | G51: ='Balance Sheet'!C32 -> 1848.67
B52: Non-Current Investments | C52: ='Balance Sheet'!G34 -> 1066.83 | D52: ='Balance Sheet'!F34 -> 1564.71 | E52: ='Balance Sheet'!E34 -> 1384.51 | F52: ='Balance Sheet'!D34 -> 1479.79 | G52: ='Balance Sheet'!C34 -> 775.91
B53: Other Non-Current Assets | C53: ='Balance Sheet'!G37 -> 793.78 | D53: ='Balance Sheet'!F37 -> 889.41 | E53: ='Balance Sheet'!E37 -> 1134.21 | F53: ='Balance Sheet'!D37 -> 1409.19 | G53: ='Balance Sheet'!C37 -> 2067.68
B54: Total Non Current Assets | C54: ='Balance Sheet'!G38 -> 7832.12 | D54: ='Balance Sheet'!F38 -> 9262.84 | E54: ='Balance Sheet'!E38 -> 12387.03 | F54: ='Balance Sheet'!D38 -> 13379.69 | G54: ='Balance Sheet'!C38 -> 14349.85
...

Sheet Ratio Analysis
B1: RATIO ANALYSIS
B3: Ratio | C3: 2022 | D3: 2023 | E3: 2024 | F3: 2025 | G3: 2026 | H3: 5Y Avg
B4: Income Statement Ratios
B5: Sales Growth | D5: ='Profit & Loss'!F9/'Profit & Loss'!G9-1 -> 0.18823288 | E5: ='Profit & Loss'!E9/'Profit & Loss'!F9-1 -> 0.029512774 | F5: ='Profit & Loss'!D9/'Profit & Loss'!E9-1 -> -0.044789854 | G5: ='Profit & Loss'!C9/'Profit & Loss'!D9-1 -> 0.050862257 | H5: =AVERAGE(D5,E5,F5,G5) -> 0.055954515
B6: EBITDA | C6: ='Profit & Loss'!G23+'Profit & Loss'!G19+'Profit & Loss'!G20 -> 5183.62 | D6: ='Profit & Loss'!F23+'Profit & Loss'!F19+'Profit & Loss'!F20 -> 6646.32 | E6: ='Profit & Loss'!E23+'Profit & Loss'!E19+'Profit & Loss'!E20 -> 8272.94 | F6: ='Profit & Loss'!D23+'Profit & Loss'!D19+'Profit & Loss'!D20 -> 6578.82 | G6: ='Profit & Loss'!C23+'Profit & Loss'!C19+'Profit & Loss'!C20 -> 7419.72 | H6: =AVERAGE(C6,D6,E6,F6,G6) -> 6820.284
B7: EBITDA Margins | C7: =('Profit & Loss'!G23+'Profit & Loss'!G19+'Profit & Loss'!G20)/'Profit & Loss'!G9 -> 0.17921841 | D7: =('Profit & Loss'!F23+'Profit & Loss'!F19+'Profit & Loss'!F20)/'Profit & Loss'!F9 -> 0.19338783 | E7: =('Profit & Loss'!E23+'Profit & Loss'!E19+'Profit & Loss'!E20)/'Profit & Loss'!E9 -> 0.23381697 | F7: =('Profit & Loss'!D23+'Profit & Loss'!D19+'Profit & Loss'!D20)/'Profit & Loss'!D9 -> 0.19465485 | G7: =('Profit & Loss'!C23+'Profit & Loss'!C19+'Profit & Loss'!C20)/'Profit & Loss'!C9 -> 0.20890986 | H7: =AVERAGE(C7,D7,E7,F7,G7) -> 0.20199758
B8: EBIT | C8: ='Profit & Loss'!G23+'Profit & Loss'!G19 -> 4367.26 | D8: ='Profit & Loss'!F23+'Profit & Loss'!F19 -> 5788.3 | E8: ='Profit & Loss'!E23+'Profit & Loss'!E19 -> 7419.94 | F8: ='Profit & Loss'!D23+'Profit & Loss'!D19 -> 5552.48 | G8: ='Profit & Loss'!C23+'Profit & Loss'!C19 -> 6190.87 | H8: =AVERAGE(C8,D8,E8,F8,G8) -> 5863.77
B9: EBIT Margin | C9: =('Profit & Loss'!G23+'Profit & Loss'!G19)/'Profit & Loss'!G9 -> 0.15099359 | D9: =('Profit & Loss'!F23+'Profit & Loss'!F19)/'Profit & Loss'!F9 -> 0.16842204 | E9: =('Profit & Loss'!E23+'Profit & Loss'!E19)/'Profit & Loss'!E9 -> 0.20970875 | F9: =('Profit & Loss'!D23+'Profit & Loss'!D19)/'Profit & Loss'!D9 -> 0.16428739 | G9: =('Profit & Loss'!C23+'Profit & Loss'!C19)/'Profit & Loss'!C9 -> 0.17431033 | H9: =AVERAGE(C9,D9,E9,F9,G9) -> 0.17354442
B10: Finance Costs | C10: ='Profit & Loss'!G19 -> 95.41 | D10: ='Profit & Loss'!F19 -> 144.45 | E10: ='Profit & Loss'!E19 -> 205.17 | F10: ='Profit & Loss'!D19 -> 227.02 | G10: ='Profit & Loss'!C19 -> 195.41 | H10: =AVERAGE(C10,D10,E10,F10,G10) -> 173.492
B11: Finance Costs % Revenue | C11: ='Profit & Loss'!G19/'Profit & Loss'!G9 -> 0.003298704 | D11: ='Profit & Loss'!F19/'Profit & Loss'!F9 -> 0.0042030585 | E11: ='Profit & Loss'!E19/'Profit & Loss'!E9 -> 0.0057986915 | F11: ='Profit & Loss'!D19/'Profit & Loss'!D9 -> 0.0067170927 | G11: ='Profit & Loss'!C19/'Profit & Loss'!C9 -> 0.0055019699 | H11: =AVERAGE(C11,D11,E11,F11,G11) -> 0.0051039033
B12: Depreciation | C12: ='Profit & Loss'!G20 -> 816.36 | D12: ='Profit & Loss'!F20 -> 858.02 | E12: ='Profit & Loss'!E20 -> 853 | F12: ='Profit & Loss'!D20 -> 1026.34 | G12: ='Profit & Loss'!C20 -> 1228.85 | H12: =AVERAGE(C12,D12,E12,F12,G12) -> 956.514
B13: Depreciation % of Sales | C13: ='Profit & Loss'!G20/'Profit & Loss'!G9 -> 0.028224819 | D13: ='Profit & Loss'!F20/'Profit & Loss'!F9 -> 0.024965789 | E13: ='Profit & Loss'!E20/'Profit & Loss'!E9 -> 0.024108222 | F13: ='Profit & Loss'!D20/'Profit & Loss'!D9 -> 0.030367461 | G13: ='Profit & Loss'!C20/'Profit & Loss'!C9 -> 0.034599538 | H13: =AVERAGE(C13,D13,E13,F13,G13) -> 0.028453166
B14: PBT | C14: ='Profit & Loss'!G23 -> 4271.85 | D14: ='Profit & Loss'!F23 -> 5643.85 | E14: ='Profit & Loss'!E23 -> 7214.77 | F14: ='Profit & Loss'!D23 -> 5325.46 | G14: ='Profit & Loss'!C23 -> 5995.46 | H14: =AVERAGE(C14,D14,E14,F14,G14) -> 5690.278
B15: PBT Margin | C15: ='Profit & Loss'!G23/'Profit & Loss'!G9 -> 0.14769488 | D15: ='Profit & Loss'!F23/'Profit & Loss'!F9 -> 0.16421898 | E15: ='Profit & Loss'!E23/'Profit & Loss'!E9 -> 0.20391005 | F15: ='Profit & Loss'!D23/'Profit & Loss'!D9 -> 0.1575703 | G15: ='Profit & Loss'!C23/'Profit & Loss'!C9 -> 0.16880836 | H15: =AVERAGE(C15,D15,E15,F15,G15) -> 0.16844051
B16: Net Profit | C16: ='Profit & Loss'!G36 -> 3030.57 | D16: ='Profit & Loss'!F36 -> 4106.45 | E16: ='Profit & Loss'!E36 -> 5460.23 | F16: ='Profit & Loss'!D36 -> 3667.23 | G16: ='Profit & Loss'!C36 -> 4325.35 | H16: =AVERAGE(C16,D16,E16,F16,G16) -> 4117.966
B17: Net Margins | C17: ='Profit & Loss'!G36/'Profit & Loss'!G9 -> 0.10477889 | D17: ='Profit & Loss'!F36/'Profit & Loss'!F9 -> 0.11948529 | E17: ='Profit & Loss'!E36/'Profit & Loss'!E9 -> 0.15432173 | F17: ='Profit & Loss'!D36/'Profit & Loss'!D9 -> 0.1085064 | G17: ='Profit & Loss'!C36/'Profit & Loss'!C9 -> 0.12178469 | H17: =AVERAGE(C17,D17,E17,F17,G17) -> 0.1217754
B18: Earnings Per Share | C18: ='Profit & Loss'!G39 -> 32 | D18: ='Profit & Loss'!F39 -> 43 | E18: ='Profit & Loss'!E39 -> 57 | F18: ='Profit & Loss'!D39 -> 38 | G18: ='Profit & Loss'!C39 -> 45 | H18: =AVERAGE(C18,D18,E18,F18,G18) -> 43
B19: EPS Growth % | D19: ='Profit & Loss'!F39/'Profit & Loss'!G39-1 -> 0.34375 | E19: ='Profit & Loss'!E39/'Profit & Loss'!F39-1 -> 0.3255814 | F19: ='Profit & Loss'!D39/'Profit & Loss'!E39-1 -> -0.33333333 | G19: ='Profit & Loss'!C39/'Profit & Loss'!D39-1 -> 0.18421053 | H19: =AVERAGE(D19,E19,F19,G19) -> 0.13005215
B21: Balance Statement Ratios
B22: Total Shareholders Funds | C22: ='Balance Sheet'!G13 -> 13811.56 | D22: ='Balance Sheet'!F13 -> 15992.23 | E22: ='Balance Sheet'!E13 -> 18728.3 | F22: ='Balance Sheet'!D13 -> 19399.81 | G22: ='Balance Sheet'!C13 -> 21371.59 | H22: =AVERAGE(C22,D22,E22,F22,G22) -> 17860.698
B23: Total Equity incl. Minority Interest | C23: ='Balance Sheet'!G13+'Balance Sheet'!G14 -> 14199.09 | D23: ='Balance Sheet'!F13+'Balance Sheet'!F14 -> 16445.89 | E23: ='Balance Sheet'!E13+'Balance Sheet'!E14 -> 19423.68 | F23: ='Balance Sheet'!D13+'Balance Sheet'!D14 -> 20059.05 | G23: ='Balance Sheet'!C13+'Balance Sheet'!C14 -> 22014.98 | H23: =AVERAGE(C23,D23,E23,F23,G23) -> 18428.538
B24: Long Term Borrowings | C24: ='Balance Sheet'!G16 -> 44.54 | D24: ='Balance Sheet'!F16 -> 76.15 | E24: ='Balance Sheet'!E16 -> 54.38 | F24: ='Balance Sheet'!D16 -> 259.62 | G24: ='Balance Sheet'!C16 -> 1247.17 | H24: =AVERAGE(C24,D24,E24,F24,G24) -> 336.372
B25: Short Term Borrowings | C25: ='Balance Sheet'!G22 -> 731.12 | D25: ='Balance Sheet'!F22 -> 896.06 | E25: ='Balance Sheet'!E22 -> 1052.76 | F25: ='Balance Sheet'!D22 -> 604.13 | G25: ='Balance Sheet'!C22 -> 1046.09 | H25: =AVERAGE(C25,D25,E25,F25,G25) -> 866.032
B26: Gross Debt | C26: ='Balance Sheet'!G16+'Balance Sheet'!G22 -> 775.66 | D26: ='Balance Sheet'!F16+'Balance Sheet'!F22 -> 972.21 | E26: ='Balance Sheet'!E16+'Balance Sheet'!E22 -> 1107.14 | F26: ='Balance Sheet'!D16+'Balance Sheet'!D22 -> 863.75 | G26: ='Balance Sheet'!C16+'Balance Sheet'!C22 -> 2293.26 | H26: =AVERAGE(C26,D26,E26,F26,G26) -> 1202.404
B27: Cash & Equivalents | C27: ='Balance Sheet'!G43 -> 864.33 | D27: ='Balance Sheet'!F43 -> 843.82 | E27: ='Balance Sheet'!E43 -> 1084.01 | F27: ='Balance Sheet'!D43 -> 781.98 | G27: ='Balance Sheet'!C43 -> 1073.68 | H27: =AVERAGE(C27,D27,E27,F27,G27) -> 929.564
B28: Net Debt | C28: ='Balance Sheet'!G16+'Balance Sheet'!G22-'Balance Sheet'!G43 -> -88.67 | D28: ='Balance Sheet'!F16+'Balance Sheet'!F22-'Balance Sheet'!F43 -> 128.39 | E28: ='Balance Sheet'!E16+'Balance Sheet'!E22-'Balance Sheet'!E43 -> 23.13 | F28: ='Balance Sheet'!D16+'Balance Sheet'!D22-'Balance Sheet'!D43 -> 81.77 | G28: ='Balance Sheet'!C16+'Balance Sheet'!C22-'Balance Sheet'!C43 -> 1219.58 | H28: =AVERAGE(C28,D28,E28,F28,G28) -> 272.84
B29: Total Assets | C29: ='Balance Sheet'!G47 -> 22984.45 | D29: ='Balance Sheet'!F47 -> 25798 | E29: ='Balance Sheet'!E47 -> 29924.09 | F29: ='Balance Sheet'!D47 -> 30371.37 | G29: ='Balance Sheet'!C47 -> 34534.49 | H29: =AVERAGE(C29,D29,E29,F29,G29) -> 28722.48
B30: Fixed Assets | C30: ='Balance Sheet'!G33 -> 5702.63 | D30: ='Balance Sheet'!F33 -> 6561.57 | E30: ='Balance Sheet'!E33 -> 9425.8 | F30: ='Balance Sheet'!D33 -> 10255.01 | G30: ='Balance Sheet'!C33 -> 11269.87 | H30: =AVERAGE(C30,D30,E30,F30,G30) -> 8642.976
B32: Return Ratios
B33: RoE: PAT / Equity (%) | C33: ='Profit & Loss'!G36/('Balance Sheet'!G13+'Balance Sheet'!G14) -> 0.2134341 | D33: ='Profit & Loss'!F36/('Balance Sheet'!F13+'Balance Sheet'!F14) -> 0.2496946 | E33: ='Profit & Loss'!E36/('Balance Sheet'!E13+'Balance Sheet'!E14) -> 0.28111202 | F33: ='Profit & Loss'!D36/('Balance Sheet'!D13+'Balance Sheet'!D14) -> 0.18282172 | G33: ='Profit & Loss'!C36/('Balance Sheet'!C13+'Balance Sheet'!C14) -> 0.19647304 | H33: =AVERAGE(C33,D33,E33,F33,G33) -> 0.2247071
B34: RoA: PAT / Total Assets (%) | C34: ='Profit & Loss'!G36/'Balance Sheet'!G47 -> 0.13185306 | D34: ='Profit & Loss'!F36/'Balance Sheet'!F47 -> 0.15917707 | E34: ='Profit & Loss'!E36/'Balance Sheet'!E47 -> 0.18246938 | F34: ='Profit & Loss'!D36/'Balance Sheet'!D47 -> 0.12074628 | G34: ='Profit & Loss'!C36/'Balance Sheet'!C47 -> 0.12524725 | H34: =AVERAGE(C34,D34,E34,F34,G34) -> 0.14389861
B35: RoCE: EBIT / Capital Employed (%) | C35: =('Profit & Loss'!G23+'Profit & Loss'!G19)/('Balance Sheet'!G47-'Balance Sheet'!G26) -> 0.28334066 | D35: =('Profit & Loss'!F23+'Profit & Loss'!F19)/('Balance Sheet'!F47-'Balance Sheet'!F26) -> 0.32333132 | E35: =('Profit & Loss'!E23+'Profit & Loss'!E19)/('Balance Sheet'!E47-'Balance Sheet'!E26) -> 0.34635182 | F35: =('Profit & Loss'!D23+'Profit & Loss'!D19)/('Balance Sheet'!D47-'Balance Sheet'!D26) -> 0.24977261 | G35: =('Profit & Loss'!C23+'Profit & Loss'!C19)/('Balance Sheet'!C47-'Balance Sheet'!C26) -> 0.24375942 | H35: =AVERAGE(C35,D35,E35,F35,G35) -> 0.28931117
B37: Leverage & Coverage Ratios
B38: Gross Debt / Equity (x) | C38: =('Balance Sheet'!G16+'Balance Sheet'!G22)/('Balance Sheet'!G13+'Balance Sheet'!G14) -> 0.054627444 | D38: =('Balance Sheet'!F16+'Balance Sheet'!F22)/('Balance Sheet'!F13+'Balance Sheet'!F14) -> 0.059115682 | E38: =('Balance Sheet'!E16+'Balance Sheet'!E22)/('Balance Sheet'!E13+'Balance Sheet'!E14) -> 0.056999498 | F38: =('Balance Sheet'!D16+'Balance Sheet'!D22)/('Balance Sheet'!D13+'Balance Sheet'!D14) -> 0.043060364 | G38: =('Balance Sheet'!C16+'Balance Sheet'!C22)/('Balance Sheet'!C13+'Balance Sheet'!C14) -> 0.10416816 | H38: =AVERAGE(C38,D38,E38,F38,G38) -> 0.06359423
B39: Net Debt / Equity (x) | C39: =('Balance Sheet'!G16+'Balance Sheet'!G22-'Balance Sheet'!G43)/('Balance Sheet'!G13+'Balance Sheet'!G14) -> -0.0062447664 | D39: =('Balance Sheet'!F16+'Balance Sheet'!F22-'Balance Sheet'!F43)/('Balance Sheet'!F13+'Balance Sheet'!F14) -> 0.0078068137 | E39: =('Balance Sheet'!E16+'Balance Sheet'!E22-'Balance Sheet'!E43)/('Balance Sheet'!E13+'Balance Sheet'!E14) -> 0.0011908145 | F39: =('Balance Sheet'!D16+'Balance Sheet'!D22-'Balance Sheet'!D43)/('Balance Sheet'!D13+'Balance Sheet'!D14) -> 0.0040764642 | G39: =('Balance Sheet'!C16+'Balance Sheet'!C22-'Balance Sheet'!C43)/('Balance Sheet'!C13+'Balance Sheet'!C14) -> 0.055397734 | H39: =AVERAGE(C39,D39,E39,F39,G39) -> 0.012445412
B40: Net Debt / EBITDA (x) | C40: =('Balance Sheet'!G16+'Balance Sheet'!G22-'Balance Sheet'!G43)/('Profit & Loss'!G23+'Profit & Loss'!G19+'Profit & Loss'!G20) -> -0.017105806 | D40: =('Balance Sheet'!F16+'Balance Sheet'!F22-'Balance Sheet'!F43)/('Profit & Loss'!F23+'Profit & Loss'!F19+'Profit & Loss'!F20) -> 0.019317457 | E40: =('Balance Sheet'!E16+'Balance Sheet'!E22-'Balance Sheet'!E43)/('Profit & Loss'!E23+'Profit & Loss'!E19+'Profit & Loss'!E20) -> 0.0027958622 | F40: =('Balance Sheet'!D16+'Balance Sheet'!D22-'Balance Sheet'!D43)/('Profit & Loss'!D23+'Profit & Loss'!D19+'Profit & Loss'!D20) -> 0.012429281 | G40: =('Balance Sheet'!C16+'Balance Sheet'!C22-'Balance Sheet'!C43)/('Profit & Loss'!C23+'Profit & Loss'!C19+'Profit & Loss'!C20) -> 0.16437008 | H40: =AVERAGE(C40,D40,E40,F40,G40) -> 0.036361375
B41: Interest Coverage: EBIT / Finance (x) | C41: =('Profit & Loss'!G23+'Profit & Loss'!G19)/'Profit & Loss'!G19 -> 45.773609 | D41: =('Profit & Loss'!F23+'Profit & Loss'!F19)/'Profit & Loss'!F19 -> 40.071305 | E41: =('Profit & Loss'!E23+'Profit & Loss'!E19)/'Profit & Loss'!E19 -> 36.164839 | F41: =('Profit & Loss'!D23+'Profit & Loss'!D19)/'Profit & Loss'!D19 -> 24.458109 | G41: =('Profit & Loss'!C23+'Profit & Loss'!C19)/'Profit & Loss'!C19 -> 31.681439 | H41: =AVERAGE(C41,D41,E41,F41,G41) -> 35.62986
B42: Gross Debt / Total Assets (%) | C42: =('Balance Sheet'!G16+'Balance Sheet'!G22)/'Balance Sheet'!G47 -> 0.033747164 | D42: =('Balance Sheet'!F16+'Balance Sheet'!F22)/'Balance Sheet'!F47 -> 0.037685479 | E42: =('Balance Sheet'!E16+'Balance Sheet'!E22)/'Balance Sheet'!E47 -> 0.036998285 | F42: =('Balance Sheet'!D16+'Balance Sheet'!D22)/'Balance Sheet'!D47 -> 0.028439613 | G42: =('Balance Sheet'!C16+'Balance Sheet'!C22)/'Balance Sheet'!C47 -> 0.066404919 | H42: =AVERAGE(C42,D42,E42,F42,G42) -> 0.040655092
B44: Asset & Efficiency Ratios
B45: Asset Turnover: Revenue / Total Assets (x) | C45: ='Profit & Loss'!G9/'Balance Sheet'!G47 -> 1.2583934 | D45: ='Profit & Loss'!F9/'Balance Sheet'!F47 -> 1.3321897 | E45: ='Profit & Loss'!E9/'Balance Sheet'!E47 -> 1.1823959 | F45: ='Profit & Loss'!D9/'Balance Sheet'!D47 -> 1.1128033 | G45: ='Profit & Loss'!C9/'Balance Sheet'!C47 -> 1.0284319 | H45: =AVERAGE(C45,D45,E45,F45,G45) -> 1.1828428
...

Sheet Fixed Assets Schedule
B1: Fixed Assets Schedule
B3: Particular | C3: 2022 | D3: 2023 | E3: 2024 | F3: 2025 | G3: 2026
B4: Beginning balance | D4: =C8 -> 5702.63 | E4: =D8 -> 6561.57 | F4: =E8 -> 9425.8 | G4: =F8 -> 10255.01
B5: Add: Net Purchases | D5: ='Balance Sheet'!F33-'Balance Sheet'!G33+'Profit & Loss'!F20 -> 1716.96 | E5: ='Balance Sheet'!E33-'Balance Sheet'!F33+'Profit & Loss'!E20 -> 3717.23 | F5: ='Balance Sheet'!D33-'Balance Sheet'!E33+'Profit & Loss'!D20 -> 1855.55 | G5: ='Balance Sheet'!C33-'Balance Sheet'!D33+'Profit & Loss'!C20 -> 2243.71
B6: Total Fixed Assets | C6: =C7+C8 -> 6518.99 | D6: =D4+D5 -> 7419.59 | E6: =E4+E5 -> 10278.8 | F6: =F4+F5 -> 11281.35 | G6: =G4+G5 -> 12498.72
