Workbook

Sheet About
B2: BAJAJ FINSERV LTD
B3: NSE: BAJAJFINSV | BSE: 532978 | Sector: Financial Services | Holding Company
B15: Company Snapshot
B16: Legal Name | C16: Bajaj Finserv Limited | E16: CIN | F16: L65923PN2007PLC130075
B17: Incorporated | C17: 30-Apr-2007 (demerger from Bajaj Auto Limited) | E17: Registered Office | F17: Bajaj Auto Limited Complex, Mumbai-Pune Road, Pune, Maharashtra 411035
B18: Chairman & Managing Dir. | C18: Sanjiv Bajaj | E18: Website | F18: www.bajajfinserv.in
B19: Face Value | C19: ₹1 per share | E19: NSE / BSE | F19: Financial Services > Finance > Holding Company
B22: Business Description
B23: Bajaj Finserv Ltd. is the listed holding company for the financial services businesses of the Bajaj Group. It is an unregistered Core Investment Company (CIC) under RBI's CIC Directions and does not itself carry out an operating business value accrues from its stakes in operating subsidiaries spanning retail/SME/commercial lending (Bajaj Finance Ltd.), general & health insurance (Bajaj General Insurance Co. Ltd., formerly BAGIC), life insurance (Bajaj Life Insurance Co. Ltd., formerly BALIC), and a small direct-to-consumer platform (Bajaj Markets). Post Allianz buy-out in FY26, BFS holds 100% of both insurance arms.
B26: Group Structure - Holdings
B27: Entity | C27: Business | E27: BFS Effective Stake | F27: Listing Status
B28: Bajaj Finance Limited | C28: NBFC - retail, SME & commercial lending | E28: 51.32% | F28: Listed (BAJFINANCE)
B29: Bajaj Housing Finance Limited | C29: Housing finance (88.70%-owned subsidiary of Bajaj Finance) | E29: ~45.5% look-through | F29: Listed (BAJAJHFL)
B30: Bajaj General Insurance Co. Ltd. | C30: General & health insurance (fka BAGIC) | E30: 100% (post Allianz buy-out, FY26) | F30: Unlisted
B31: Bajaj Life Insurance Co. Ltd. | C31: Life insurance (fka BALIC) | E31: 100% (post Allianz buy-out, FY26) | F31: Unlisted
B32: Bajaj Markets (Finserv Direct) | C32: Digital consumer platform - loans, cards, insurance, MF | E32: 100% | F32: Unlisted

Sheet Promoter
B1: Shareholding Pattern
B3: Bajaj Finserv Ltd
B4: Scrip Code : 532978 | C4: Quarter Ending : Mar-26
B5: Statement showing shareholding pattern of the Promoter and Promoter Group
B6: Category of shareholder | C6: Entity Type | D6: Nos. of shareholders | E6: No. of fully paid up equity shares held | F6: Total nos. shares held | G6: Shareholding as a % of total no. of shares (calculated as per SCRR, 1957)As a % of (A+B+C2) | H6: Number of Voting Rights held in each class of securities | J6: No. Of Outstanding ESOP Granted | K6: Total No. Of shares on fully diluted basis (including warrants, ESOP, Convertible Securities etc.) | L6: Shareholding , as a % assuming full conversion of convertible securities ( as a percentage of diluted share capital)As a % of (A+B+C2) | M6: Other Encumbrances, if any | O6: Number of equity shares held in dematerialized form
H7: Class eg: X | I7: Total | M7: No.(a) | N7: As a % of total Shares held(b)
B9: A1) Indian | D9: - | E9: - | F9: - | G9: 0 | H9: - | I9: 0 | J9: - | K9: - | L9: 0 | M9: - | N9: 0 | O9: -
B10: Individuals/Hindu undivided Family | D10: 23 | E10: 36420130 | F10: 36420130 | G10: 2.28 | H10: 36420130 | I10: 2.28 | J10: - | K10: 36420130 | L10: 2.26 | M10: 100360 | N10: 0.28 | O10: 36420130
B11: DEEPA BAJAJ | C11: Promoter Group | D11: 1 | E11: 1000 | F11: 1000 | G11: 0 | H11: 1000 | I11: 0 | J11: - | K11: 1000 | L11: 0 | M11: - | N11: 0 | O11: 1000
B12: GEETIKA BAJAJ | C12: Promoter Group | D12: 1 | E12: 2479000 | F12: 2479000 | G12: 0.15 | H12: 2479000 | I12: 0.15 | J12: - | K12: 2479000 | L12: 0.15 | M12: - | N12: 0 | O12: 2479000
B13: KIRAN BAJAJ | C13: Promoter Group | D13: 1 | E13: 3925600 | F13: 3925600 | G13: 0.25 | H13: 3925600 | I13: 0.25 | J13: - | K13: 3925600 | L13: 0.24 | M13: - | N13: 0 | O13: 3925600
B14: KRITI BAJAJ | C14: Promoter Group | D14: 1 | E14: 742000 | F14: 742000 | G14: 0.05 | H14: 742000 | I14: 0.05 | J14: - | K14: 742000 | L14: 0.05 | M14: - | N14: 0 | O14: 742000
B15: KUMUD BAJAJ | C15: Promoter Group | D15: 1 | E15: 1000000 | F15: 1000000 | G15: 0.06 | H15: 1000000 | I15: 0.06 | J15: - | K15: 1000000 | L15: 0.06 | M15: - | N15: 0 | O15: 1000000
B16: MINAL BAJAJ | C16: Promoter Group | D16: 1 | E16: 642000 | F16: 642000 | G16: 0.04 | H16: 642000 | I16: 0.04 | J16: - | K16: 642000 | L16: 0.04 | M16: - | N16: 0 | O16: 642000
B17: NEELIMA BAJAJ SWAMY | C17: Promoter Group | D17: 1 | E17: 500000 | F17: 500000 | G17: 0.03 | H17: 500000 | I17: 0.03 | J17: - | K17: 500000 | L17: 0.03 | M17: - | N17: 0 | O17: 500000
B18: NIMISHA JAIPURIA | C18: Promoter Group | D18: 1 | E18: 514000 | F18: 514000 | G18: 0.03 | H18: 514000 | I18: 0.03 | J18: - | K18: 514000 | L18: 0.03 | M18: - | N18: 0 | O18: 514000
B19: NIRAJ BAJAJ | C19: Promoter | D19: 1 | E19: 2953150 | F19: 2953150 | G19: 0.18 | H19: 2953150 | I19: 0.18 | J19: - | K19: 2953150 | L19: 0.18 | M19: - | N19: 0 | O19: 2953150
B20: NIRAVNAYAN BAJAJ | C20: Promoter Group | D20: 1 | E20: 2058660 | F20: 2058660 | G20: 0.13 | H20: 2058660 | I20: 0.13 | J20: - | K20: 2058660 | L20: 0.13 | M20: - | N20: 0 | O20: 2058660
B21: RAJIVNAYAN BAJAJ | C21: Promoter | D21: 1 | E21: 1000 | F21: 1000 | G21: 0 | H21: 1000 | I21: 0 | J21: - | K21: 1000 | L21: 0 | M21: - | N21: 0 | O21: 1000
B22: RISHABNAYAN BAJAJ | C22: Promoter Group | D22: 1 | E22: 112320 | F22: 112320 | G22: 0.01 | H22: 112320 | I22: 0.01 | J22: - | K22: 112320 | L22: 0.01 | M22: - | N22: 0 | O22: 112320
... B29: POOJA BAJAJ | C29: Promoter Group | D29: 1 | E29: 744360 | F29: 744360 | G29: 0.05 | H29: 744360 | I29: 0.05 | J29: - | K29: 744360 | L29: 0.05 | M29: - | N29: 0 | O29: 744360
B30: AARAV SWAMY | C30: Promoter Group | D30: - | E30: - | F30: - | G30: 0 | H30: - | I30: 0 | J30: - | K30: - | L30: 0 | M30: - | N30: 0 | O30: -
B31: VIHAAN JAIPURIA | C31: Promoter Group | D31: - | E31: - | F31: - | G31: 0 | H31: - | I31: 0 | J31: - | K31: - | L31: 0 | M31: - | N31: 0 | O31: -
B32: VANRAJ BAJAJ | C32: Promoter Group | D32: 1 | E32: 332360 | F32: 332360 | G32: 0.02 | H32: 332360 | I32: 0.02 | J32: - | K32: 332360 | L32: 0.02 | M32: 100360 | N32: 30.2 | O32: 332360
B33: SHEETAL BAJAJ | C33: Promoter Group | D33: 1 | E33: 199000 | F33: 199000 | G33: 0.01 | H33: 199000 | I33: 0.01 | J33: - | K33: 199000 | L33: 0.01 | M33: - | N33: 0 | O33: 199000
B34: ARYAN BAJAJ | C34: Promoter Group | D34: - | E34: - | F34: - | G34: 0 | H34: - | I34: 0 | J34: - | K34: - | L34: 0 | M34: - | N34: 0 | O34: -
B35: Estate of Rahulkumar Bajaj | C35: Promoter Group | D35: - | E35: - | F35: - | G35: 0 | H35: - | I35: 0 | J35: - | K35: - | L35: 0 | M35: - | N35: 0 | O35: -
B36: SIDDHANTNAYAN BAJAJ | C36: Promoter Group | D36: 1 | E36: 903690 | F36: 903690 | G36: 0.06 | H36: 903690 | I36: 0.06 | J36: - | K36: 903690 | L36: 0.06 | M36: - | N36: 0 | O36: 903690
B37: SANJALI BAJAJ | C37: Promoter Group | D37: 1 | E37: 903690 | F37: 903690 | G37: 0.06 | H37: 903690 | I37: 0.06 | J37: - | K37: 903690 | L37: 0.06 | M37: - | N37: 0 | O37: 903690
B38: Any Other (specify) | D38: 41 | E38: 903118240 | F38: 903118240 | G38: 56.43 | H38: 903118240 | I38: 56.43 | J38: - | K38: 903118240 | L38: 55.96 | M38: - | N38: 0 | O38: 903118240
B39: BACHHRAJ AND COMPANY PRIVATE LIMITED | C39: Promoter Group | D39: 1 | E39: 23314745 | F39: 23314745 | G39: 1.46 | H39: 23314745 | I39: 1.46 | J39: - | K39: 23314745 | L39: 1.44 | M39: - | N39: 0 | O39: 23314745
B40: BACHHRAJ FACTORIES PRIVATE LIMITED | C40: Promoter Group | D40: 1 | E40: 10787870 | F40: 10787870 | G40: 0.67 | H40: 10787870 | I40: 0.67 | J40: - | K40: 10787870 | L40: 0.67 | M40: - | N40: 0 | O40: 10787870
B41: BAJAJ AUTO HOLDINGS LIMITED | C41: Promoter Group | D41: 1 | E41: 2090050 | F41: 2090050 | G41: 0.13 | H41: 2090050 | I41: 0.13 | J41: - | K41: 2090050 | L41: 0.13 | M41: - | N41: 0 | O41: 2090050
B42: BAJAJ HOLDINGS AND INVESTMENT LIMITED | C42: Promoter | D42: 1 | E42: 612742140 | F42: 612742140 | G42: 38.28 | H42: 612742140 | I42: 38.28 | J42: - | K42: 612742140 | L42: 37.97 | M42: - | N42: 0 | O42: 612742140
B43: BAJAJ SEVASHRAM PRIVATE LIMITED | C43: Promoter Group | D43: 1 | E43: 26685025 | F43: 26685025 | G43: 1.67 | H43: 26685025 | I43: 1.67 | J43: - | K43: 26685025 | L43: 1.65 | M43: - | N43: 0 | O43: 26685025
B44: BARODA INDUSTRIES PRIVATE LIMITED | C44: Promoter Group | D44: 1 | E44: 9190010 | F44: 9190010 | G44: 0.57 | H44: 9190010 | I44: 0.57 | J44: - | K44: 9190010 | L44: 0.57 | M44: - | N44: 0 | O44: 9190010
B45: HERCULES INVESTMENTS LIMITED (erstwhile Hercules Hoists Limited) | C45: Promoter Group | D45: 1 | E45: 1105630 | F45: 1105630 | G45: 0.07 | H45: 1105630 | I45: 0.07 | J45: - | K45: 1105630 | L45: 0.07 | M45: - | N45: 0 | O45: 1105630
B46: JAMNALAL SONS PRIVATE LIMITED | C46: Promoter Group | D46: 1 | E46: 136700840 | F46: 136700840 | G46: 8.54 | H46: 136700840 | I46: 8.54 | J46: - | K46: 136700840 | L46: 8.47 | M46: - | N46: 0 | O46: 136700840
B47: KAMALNAYAN INVESTMENT & TRADING PRIVATE LIMITED | C47: Promoter Group | D47: 1 | E47: 900000 | F47: 900000 | G47: 0.06 | H47: 900000 | I47: 0.06 | J47: - | K47: 900000 | L47: 0.06 | M47: - | N47: 0 | O47: 900000
B48: MADHUR SECURITIES PVT LTD | C48: Promoter Group | D48: 1 | E48: 941000 | F48: 941000 | G48: 0.06 | H48: 941000 | I48: 0.06 | J48: - | K48: 941000 | L48: 0.06 | M48: - | N48: 0 | O48: 941000
...

Sheet Public
B1: Shareholding Pattern Public Shareholder
B3: Bajaj Finserv Ltd
B4: Scrip Code : 532978 | E4: Quarter Ending : Mar-26
B6: Statement showing shareholding pattern of the Public shareholder
B8: Category & Name of the Shareholders | C8: No. of shareholder | D8: No. of fully paid up equity shares held | E8: Total no. shares held | F8: Shareholding % calculated as per SCRR, 1957 As a % of (A+B+C2) | G8: No. of Voting Rights | H8: Total as a % of Total Voting right | I8: Total No. Of shares on fully diluted basis (including warrants, ESOP, Convertible Securities etc.) | J8: Shareholding , as a % assuming full conversion of convertible securities ( as a percentage of diluted share capital)As a % of (A+B+C2) | K8: No. of equity shares held in dematerialized form(Not Applicable) | L8: Sub-categorization of shares (XV)
L9: Shareholding (No. of shares) under
L10: SubCategory_I | M10: SubCategory_II | N10: SubCategory_III
B11: Institutions | C11: 0 | D11: 0 | E11: - | F11: 0 | G11: - | H11: 0 | I11: - | J11: 0 | K11: - | L11: - | M11: - | N11: -
B12: B2) Institutions (Domestic) | C12: 0 | D12: 0 | E12: - | F12: 0 | G12: - | H12: 0 | I12: - | J12: 0 | K12: - | L12: - | M12: - | N12: -
B13: Mutual Funds/ | C13: 45 | D13: 133618938 | E13: 133618938 | F13: 8.35 | G13: 133618938 | H13: 8.35 | I13: 133618938 | J13: 8.28 | K13: 133614688 | L13: - | M13: - | N13: -
B14: SBI ARBITRAGE OPPORTUNITIES FUND | C14: 1 | D14: 43986119 | E14: 43986119 | F14: 2.75 | G14: 43986119 | H14: 2.75 | I14: 43986119 | J14: 2.73 | K14: 43986119 | L14: - | M14: - | N14: -
B15: ICICI PRUDENTIAL SENSEX ETF | C15: 1 | D15: 37482550 | E15: 37482550 | F15: 2.34 | G15: 37482550 | H15: 2.34 | I15: 37482550 | J15: 2.32 | K15: 37482550 | L15: - | M15: - | N15: -
B16: Venture Capital Funds | C16: 0 | D16: 0 | E16: - | F16: 0 | G16: - | H16: 0 | I16: - | J16: 0 | K16: - | L16: - | M16: - | N16: -
B17: Alternate Investment Funds | C17: 38 | D17: 4161839 | E17: 4161839 | F17: 0.26 | G17: 4161839 | H17: 0.26 | I17: 4161839 | J17: 0.26 | K17: 4161839 | L17: - | M17: - | N17: -
B18: Banks | C18: 12 | D18: 717833 | E18: 717833 | F18: 0.04 | G18: 717833 | H18: 0.04 | I18: 717833 | J18: 0.04 | K18: 714433 | L18: - | M18: - | N18: -
B19: Insurance Companies | C19: 24 | D19: 43707947 | E19: 43707947 | F19: 2.73 | G19: 43707947 | H19: 2.73 | I19: 43707947 | J19: 2.71 | K19: 43707947 | L19: - | M19: - | N19: -
B20: LICI ASM NON PAR | C20: 1 | D20: 32557234 | E20: 32557234 | F20: 2.03 | G20: 32557234 | H20: 2.03 | I20: 32557234 | J20: 2.02 | K20: 32557234 | L20: - | M20: - | N20: -
B21: Provident Funds/ Pension Funds | C21: 1 | D21: 6079022 | E21: 6079022 | F21: 0.38 | G21: 6079022 | H21: 0.38 | I21: 6079022 | J21: 0.38 | K21: 6079022 | L21: - | M21: - | N21: -
B22: Asset reconstruction companies | C22: 0 | D22: 0 | E22: - | F22: 0 | G22: - | H22: 0 | I22: - | J22: 0 | K22: - | L22: - | M22: - | N22: -
B23: Sovereign Wealth Funds | C23: 0 | D23: 0 | E23: - | F23: 0 | G23: - | H23: 0 | I23: - | J23: 0 | K23: - | L23: - | M23: - | N23: -
B24: NBFCs registered with RBI | C24: 6 | D24: 4821 | E24: 4821 | F24: 0 | G24: 4821 | H24: 0 | I24: 4821 | J24: 0 | K24: 4821 | L24: - | M24: - | N24: -
B25: Other Financial Institutions | C25: 0 | D25: 0 | E25: - | F25: 0 | G25: - | H25: 0 | I25: - | J25: 0 | K25: - | L25: - | M25: - | N25: -
B26: Any Other(Institutions (Domestic)) | C26: 0 | D26: 0 | E26: - | F26: 0 | G26: - | H26: 0 | I26: - | J26: 0 | K26: - | L26: - | M26: - | N26: -
B27: Sub Total B1 | C27: 126 | D27: 188290400 | E27: 188290400 | F27: 11.76 | G27: 188290400 | H27: 11.76 | I27: 188290400 | J27: 11.67 | K27: 188282750 | L27: - | M27: - | N27: -
B28: B18) Institutions (Foreign) | C28: 0 | D28: 0 | E28: - | F28: 0 | G28: - | H28: 0 | I28: - | J28: 0 | K28: - | L28: - | M28: - | N28: -
B29: Foreign Direct Investment | C29: 0 | D29: 0 | E29: - | F29: 0 | G29: - | H29: 0 | I29: - | J29: 0 | K29: - | L29: - | M29: - | N29: -
B30: Foreign Venture Capital Investors | C30: 0 | D30: 0 | E30: - | F30: 0 | G30: - | H30: 0 | I30: - | J30: 0 | K30: - | L30: - | M30: - | N30: -
B31: Sovereign Wealth Funds | C31: 1 | D31: 1441972 | E31: 1441972 | F31: 0.09 | G31: 1441972 | H31: 0.09 | I31: 1441972 | J31: 0.09 | K31: 1441972 | L31: - | M31: - | N31: -
B32: Foreign Portfolio Investors Category I | C32: 671 | D32: 110024008 | E32: 110024008 | F32: 6.87 | G32: 110024008 | H32: 6.87 | I32: 110024008 | J32: 6.82 | K32: 110024008 | L32: - | M32: - | N32: -
B33: Foreign Portfolio Investors Category II | C33: 30 | D33: 4400044 | E33: 4400044 | F33: 0.27 | G33: 4400044 | H33: 0.27 | I33: 4400044 | J33: 0.27 | K33: 4400044 | L33: - | M33: - | N33: -
B34: Overseas Depositories (holding DRs) (balancing figure) | C34: 0 | D34: 0 | E34: - | F34: 0 | G34: - | H34: 0 | I34: - | J34: 0 | K34: - | L34: - | M34: - | N34: -
B35: Any Other(Institutions (Foreign)) | C35: 10 | D35: 27050 | E35: 27050 | F35: 0 | G35: 27050 | H35: 0 | I35: 27050 | J35: 0 | K35: 14000 | L35: - | M35: - | N35: -
B36: FOREIGN INSTITUTIONAL INVESTORS | C36: 5 | D36: 11500 | E36: 11500 | F36: 0 | G36: 11500 | H36: 0 | I36: 11500 | J36: 0 | K36: - | L36: - | M36: - | N36: -
B37: Foreign Banks | C37: 5 | D37: 15550 | E37: 15550 | F37: 0 | G37: 15550 | H37: 0 | I37: 15550 | J37: 0 | K37: 14000 | L37: - | M37: - | N37: -
B38: Sub Total B2 | C38: 712 | D38: 115893074 | E38: 115893074 | F38: 7.24 | G38: 115893074 | H38: 7.24 | I38: 115893074 | J38: 7.18 | K38: 115880024 | L38: - | M38: - | N38: -
B39: B29) Central Government/ State Government(s)/ President of India | C39: 0 | D39: 0 | E39: - | F39: 0 | G39: - | H39: 0 | I39: - | J39: 0 | K39: - | L39: - | M39: - | N39: -
B40: Central Government / President of India | C40: 0 | D40: 0 | E40: - | F40: 0 | G40: - | H40: 0 | I40: - | J40: 0 | K40: - | L40: - | M40: - | N40: -
B41: State Government / Governor | C41: 0 | D41: 0 | E41: - | F41: 0 | G41: - | H41: 0 | I41: - | J41: 0 | K41: - | L41: - | M41: - | N41: -
B42: Shareholding by Companies or Bodies Corporate where Central / State Government is a promoter | C42: 2 | D42: 4400 | E42: 4400 | F42: 0 | G42: 4400 | H42: 0 | I42: 4400 | J42: 0 | K42: 4400 | L42: - | M42: - | N42: -
B43: Sub Total B3 | C43: 2 | D43: 4400 | E43: 4400 | F43: 0 | G43: 4400 | H43: 0 | I43: 4400 | J43: 0 | K43: 4400 | L43: - | M43: - | N43: -
...

Sheet Stock Analysis
B1: Stock Analysis
B17: Recommendation:
B18: BUY – Bajaj Finserv Ltd. is the listed holding company for the Bajaj Group's financial services businesses, with stakes in Bajaj Finance (51.3%), and post-Allianz buyout in FY26, 100% ownership of both Bajaj Life Insurance (BALIC) and Bajaj General Insurance (BAGIC). FY26 consolidated revenues stood at ₹1,50,530 Cr with PAT of ₹20,059 Cr. The consolidated loan book crossed ₹5,00,016 Cr (up 22% YoY). ROE sustained above 26% and BVPS reached ₹975/share. At CMP ₹1,754, BFS trades at 1.80x FY26 P/B vs. intrinsic value estimate of ₹2,050+; with loan book CAGR of ~27% over FY22-26 and improving insurance profitability post-buyout, the holdco discount to NAV offers a compelling entry. Key risks: BFL credit cost spike, regulatory tightening on NBFC lending, and insurance JV restructuring costs.
B28: Financial Year | C28: Total Income (₹ Cr) | D28: PAT (₹ Cr) | E28: Total Income Change | F28: PAT Change (%)
B29: FY 2025-26 | C29: ='Historical FS'!G6 -> 150530.38 | D29: ='Historical FS'!G38 -> 20059.11 | E29: =(C29-C30)/C30 -> 0.12485425 | F29: =(D29-D30)/D30 -> 0.14357392
B30: FY 2024-25 | C30: ='Historical FS'!F6 -> 133822.12 | D30: ='Historical FS'!F38 -> 17540.72 | E30: =(C30-C31)/C31 -> 0.21234357 | F30: =(D30-D31)/D31 -> 0.12524473
B31: FY 2023-24 | C31: ='Historical FS'!E6 -> 110383 | D31: ='Historical FS'!E38 -> 15588.36 | E31: =(C31-C32)/C32 -> 0.34495305 | F31: =(D31-D32)/D32 -> 0.27677998
B32: FY 2022-23 | C32: ='Historical FS'!D6 -> 82072.01 | D32: ='Historical FS'!D38 -> 12209.12 | E32: =(C32-C33)/C33 -> 0.19919978 | F32: =(D32-D33)/D33 -> 0.46273238
B33: FY 2021-22 | C33: ='Historical FS'!C6 -> 68438.98 | D33: ='Historical FS'!C38 -> 8346.79 | E33: 0 | F33: 0
B35: Particulars | C35: 2022 | D35: 2023 | E35: 2024 | F35: 2025 | G35: 2026 | H35: Avg 5Y

Sheet Data Sheet
A1: Profit & Loss Account
A2: Particulars | B2: Mar '22 | C2: Mar '23 | D2: Mar '24 | E2: Mar '25 | F2: Mar '26
A3: INCOME
A4: Revenue From Operations [Net] | B4: 68406.08 | C4: 82071.24 | D4: 110381.91 | E4: 133821.05 | F4: 150503.77
A5: Other Operating Revenues | B5: 0 | C5: 0 | D5: 0 | E5: 0 | F5: 0
A6: Total Operating Revenues | B6: 68438.98 | C6: 82072.01 | D6: 110383 | E6: 133822.12 | F6: 150530.38
A7: Other Income | B7: 32.9 | C7: 0.77 | D7: 1.09 | E7: 1.07 | F7: 26.61
A8: Total Revenue | B8: 68438.98 | C8: 82072.01 | D8: 110383 | E8: 133822.12 | F8: 150530.38
A9: EXPENSES
A10: Operating & Direct Expenses | B10: 31550.7 | C10: 34485.44 | D10: 48619.49 | E10: 57663.42 | F10: 0
A11: Employee Benefit Expenses | B11: 6559.58 | C11: 8767.15 | D11: 10360.95 | E11: 12069.62 | F11: 14122.17
A12: Finance Costs | B12: 9498.26 | C12: 12201.42 | D12: 18399.51 | E12: 24309.7 | F12: 28231.78
A13: Provisions & Contingencies | B13: 4889.85 | C13: 3230.98 | D13: 4633.58 | E13: 7947.58 | F13: 9479.99
A14: Depreciation & Amortisation | B14: 562.73 | C14: 677.8 | D14: 900.13 | E14: 1170.32 | F14: 1291.36
A15: Other Expenses | B15: 4106.92 | C15: 5899.28 | D15: 6102.4 | E15: 6931.26 | F15: 70158.9
A16: Total Expenses | B16: 57168.04 | C16: 65262.07 | D16: 89016.06 | E16: 110091.9 | F16: 123284.2
A17: PROFIT
A18: Profit Before Exceptional Items & Tax | B18: 11270.94 | C18: 16809.94 | D18: 21366.94 | E18: 23730.22 | F18: 26866.69
A19: Exceptional Items | B19: 0 | C19: 0 | D19: 0 | E19: 0 | F19: 0
A20: Profit Before Tax | B20: 11270.94 | C20: 16809.94 | D20: 21366.94 | E20: 23730.22 | F20: 26866.69
A21: Current Tax | B21: 2957.05 | C21: 4601.59 | D21: 5779.67 | E21: 6190.57 | F21: 7213.68
A22: Deferred Tax | B22: 0 | C22: 0 | D22: 0 | E22: 0 | F22: 0
A23: Tax for Earlier Years | B23: 0 | C23: 0 | D23: 0 | E23: 0 | F23: 0
A24: Total Tax Expenses | B24: 2957.05 | C24: 4601.59 | D24: 5779.67 | E24: 6190.57 | F24: 7213.68
A25: Profit After Tax | B25: 8313.89 | C25: 12208.35 | D25: 15587.27 | E25: 17539.65 | F25: 19653.01
A26: Consolidated PAT (After MI & Associates) | B26: 4556.77 | C26: 6417.28 | D26: 8147.79 | E26: 8872.31 | F26: 9800.97
A27: EPS
A28: Basic EPS (Rs.) | B28: 209 | C28: 153 | D28: 196 | E28: 220 | F28: 246
A29: Diluted EPS (Rs.) | B29: 209 | C29: 153 | D29: 196 | E29: 220 | F29: 246
A30: DIVIDEND
A31: Equity Share Dividend | B31: 47.74 | C31: 63.65 | D31: 127.43 | E31: 159.67 | F31: 0
A34: Balance Sheet
A35: Particulars | B35: Mar '22 | C35: Mar '23 | D35: Mar '24 | E35: Mar '25 | F35: Mar '26
A36: EQUITIES & LIABILITIES
A37: SHAREHOLDER'S FUNDS
A38: Equity Share Capital | B38: 79.57 | C38: 159.26 | D38: 159.41 | E38: 159.6 | F38: 159.87
A39: Total Share Capital | B39: 79.57 | C39: 159.26 | D39: 159.41 | E39: 159.6 | F39: 159.87
A40: Reserves and Surplus | B40: 40167.23 | C40: 46248.08 | D40: 60169.21 | E40: 72235.71 | F40: 77754.66
A41: Total Reserves and Surplus | B41: 40167.23 | C41: 46248.08 | D41: 60169.21 | E41: 72235.71 | F41: 77754.66
A42: Total Shareholders Funds | B42: 40246.8 | C42: 46407.34 | D42: 60328.62 | E42: 72395.31 | F42: 77914.53
...

Sheet Historical FS
B2: Historical Financial Statement
B3: Years | C3: ='Data Sheet'!B2 -> Mar '22 | D3: ='Data Sheet'!C2 -> Mar '23 | E3: ='Data Sheet'!D2 -> Mar '24 | F3: ='Data Sheet'!E2 -> Mar '25 | G3: ='Data Sheet'!F2 -> Mar '26 | H3: LTM
A5: # | B5: Income statement
B6: Interest Income (Revenue) | C6: =IFERROR('Data Sheet'!B6,0) -> 68438.98 | D6: =IFERROR('Data Sheet'!C6,0) -> 82072.01 | E6: =IFERROR('Data Sheet'!D6,0) -> 110383 | F6: =IFERROR('Data Sheet'!E6,0) -> 133822.12 | G6: =IFERROR('Data Sheet'!F6,0) -> 150530.38 | H6: =IFERROR('Data Sheet'!F6,0) -> 150530.38 | K6: Average Sales Growth
B7: Sales Growth | C7: - | D7: =D6/C6-1 -> 0.19919978 | E7: =E6/D6-1 -> 0.34495305 | F7: =F6/E6-1 -> 0.21234357 | G7: =G6/F6-1 -> 0.12485425 | H7: =H6/G6-1 -> 0 | K7: =AVERAGE(D7:G7) -> 0.22033766
B9: Finance Costs (Cost of Funds) | C9: =IFERROR('Data Sheet'!B12,0) -> 9498.26 | D9: =IFERROR('Data Sheet'!C12,0) -> 12201.42 | E9: =IFERROR('Data Sheet'!D12,0) -> 18399.51 | F9: =IFERROR('Data Sheet'!E12,0) -> 24309.7 | G9: =IFERROR('Data Sheet'!F12,0) -> 28231.78 | H9: =IFERROR('Data Sheet'!F12,0) -> 28231.78
B10: Cost of Funds % Revenue | C10: =C9/C6 -> 0.13878436 | D10: =D9/D6 -> 0.14866725 | E10: =E9/E6 -> 0.1666879 | F10: =F9/F6 -> 0.18165681 | G10: =G9/G6 -> 0.18754872 | H10: =H9/H6 -> 0.18754872
B12: Net Interest Income (NII) | C12: =C6-C9 -> 58940.72 | D12: =D6-D9 -> 69870.59 | E12: =E6-E9 -> 91983.49 | F12: =F6-F9 -> 109512.42 | G12: =G6-G9 -> 122298.6 | H12: =H6-H9 -> 122298.6
B13: NII Margin | C13: =C12/C6 -> 0.86121564 | D13: =D12/D6 -> 0.85133275 | E13: =E12/E6 -> 0.8333121 | F13: =F12/F6 -> 0.81834319 | G13: =G12/G6 -> 0.81245128 | H13: =H12/H6 -> 0.81245128
B15: Operating Expenses (OpEx) | C15: =IFERROR(SUM('Data Sheet'!B10,'Data Sheet'!B11,'Data Sheet'!B15),0) -> 42217.2 | D15: =IFERROR(SUM('Data Sheet'!C10,'Data Sheet'!C11,'Data Sheet'!C15),0) -> 49151.87 | E15: =IFERROR(SUM('Data Sheet'!D10,'Data Sheet'!D11,'Data Sheet'!D15),0) -> 65082.84 | F15: =IFERROR(SUM('Data Sheet'!E10,'Data Sheet'!E11,'Data Sheet'!E15),0) -> 76664.3 | G15: =IFERROR(SUM('Data Sheet'!F10,'Data Sheet'!F11,'Data Sheet'!F15),0) -> 84281.07 | H15: =IFERROR(SUM('Data Sheet'!F10,'Data Sheet'!F11,'Data Sheet'!F15),0) -> 84281.07
B16: OpEx % Revenue | C16: =C15/C6 -> 0.61685899 | D16: =D15/D6 -> 0.59888712 | E16: =E15/E6 -> 0.58960927 | F16: =F15/F6 -> 0.57288212 | G16: =G15/G6 -> 0.55989409 | H16: =H15/H6 -> 0.55989409
B18: EBITDA | C18: =C12-C15 -> 16723.52 | D18: =D12-D15 -> 20718.72 | E18: =E12-E15 -> 26900.65 | F18: =F12-F15 -> 32848.12 | G18: =G12-G15 -> 38017.53 | H18: =H12-H15 -> 38017.53
B19: EBITDA Margins | C19: =C18/C6 -> 0.24435665 | D19: =D18/D6 -> 0.25244563 | E19: =E18/E6 -> 0.24370283 | F19: =F18/F6 -> 0.24546106 | G19: =G18/G6 -> 0.25255719 | H19: =H18/H6 -> 0.25255719
B21: Depriciation | C21: =IFERROR(SUM('Data Sheet'!B14),0) -> 562.73 | D21: =IFERROR(SUM('Data Sheet'!C14),0) -> 677.8 | E21: =IFERROR(SUM('Data Sheet'!D14),0) -> 900.13 | F21: =IFERROR(SUM('Data Sheet'!E14),0) -> 1170.32 | G21: =IFERROR(SUM('Data Sheet'!F14),0) -> 1291.36 | H21: =IFERROR(SUM('Data Sheet'!F14),0) -> 1291.36
B22: Depriciation % of Sales | C22: =C21/C6 -> 0.008222361 | D22: =D21/D6 -> 0.0082586012 | E22: =E21/E6 -> 0.0081546071 | F22: =F21/F6 -> 0.0087453405 | G22: =G21/G6 -> 0.0085787334 | H22: =H21/H6 -> 0.0085787334
B24: EBIT | C24: =IFERROR(C18-C21,0) -> 16160.79 | D24: =IFERROR(D18-D21,0) -> 20040.92 | E24: =IFERROR(E18-E21,0) -> 26000.52 | F24: =IFERROR(F18-F21,0) -> 31677.8 | G24: =IFERROR(G18-G21,0) -> 36726.17 | H24: =IFERROR(H18-H21,0) -> 36726.17
B25: EBIT Margin | C25: =C24/C6 -> 0.23613429 | D25: =D24/D6 -> 0.24418703 | E25: =E24/E6 -> 0.23554823 | F25: =F24/F6 -> 0.23671572 | G25: =G24/G6 -> 0.24397846 | H25: =H24/H6 -> 0.24397846
B27: Provisions & Contingencies | C27: =IFERROR('Data Sheet'!B13,0) -> 4889.85 | D27: =IFERROR('Data Sheet'!C13,0) -> 3230.98 | E27: =IFERROR('Data Sheet'!D13,0) -> 4633.58 | F27: =IFERROR('Data Sheet'!E13,0) -> 7947.58 | G27: =IFERROR('Data Sheet'!F13,0) -> 9479.99 | H27: =IFERROR('Data Sheet'!F13,0) -> 9479.99
B28: Provisions % Revenue | C28: =C27/C6 -> 0.071448318 | D28: =D27/D6 -> 0.039367624 | E28: =E27/E6 -> 0.041977297 | F28: =F27/F6 -> 0.059389135 | G28: =G27/G6 -> 0.062977254 | H28: =H27/H6 -> 0.062977254
B30: Other Income | C30: =IFERROR('Data Sheet'!B7,0) -> 32.9 | D30: =IFERROR('Data Sheet'!C7,0) -> 0.77 | E30: =IFERROR('Data Sheet'!D7,0) -> 1.09 | F30: =IFERROR('Data Sheet'!E7,0) -> 1.07 | G30: =IFERROR('Data Sheet'!F7,0) -> 26.61 | H30: =IFERROR('Data Sheet'!F7,0) -> 26.61
B32: Profit Before Tax (PBT) | C32: =IFERROR(C24-C27+C30+IFERROR('Data Sheet'!B19,0),0) -> 11303.84 | D32: =IFERROR(D24-D27+D30+IFERROR('Data Sheet'!C19,0),0) -> 16810.71 | E32: =IFERROR(E24-E27+E30+IFERROR('Data Sheet'!D19,0),0) -> 21368.03 | F32: =IFERROR(F24-F27+F30+IFERROR('Data Sheet'!E19,0),0) -> 23731.29 | G32: =IFERROR(G24-G27+G30+IFERROR('Data Sheet'!F19,0),0) -> 27272.79 | H32: =IFERROR(H24-H27+H30+IFERROR('Data Sheet'!F19,0),0) -> 27272.79
B33: EBT % Sales | C33: =C32/C6 -> 0.16516669 | D33: =D32/D6 -> 0.20482878 | E33: =E32/E6 -> 0.19358081 | F33: =F32/F6 -> 0.17733458 | G33: =G32/G6 -> 0.18117798 | H33: =H32/H6 -> 0.18117798
B35: Tax | C35: =IFERROR('Data Sheet'!B24,0) -> 2957.05 | D35: =IFERROR('Data Sheet'!C24,0) -> 4601.59 | E35: =IFERROR('Data Sheet'!D24,0) -> 5779.67 | F35: =IFERROR('Data Sheet'!E24,0) -> 6190.57 | G35: =IFERROR('Data Sheet'!F24,0) -> 7213.68 | H35: =IFERROR('Data Sheet'!F24,0) -> 7213.68
B36: Effective Tax Rate | C36: =C35/C32 -> 0.26159694 | D36: =D35/D32 -> 0.27372966 | E36: =E35/E32 -> 0.27048212 | F36: =F35/F32 -> 0.26086108 | G36: =G35/G32 -> 0.26450099 | H36: =H35/H32 -> 0.26450099
B38: Net Profit | C38: =IFERROR(C32-C35,0) -> 8346.79 | D38: =IFERROR(D32-D35,0) -> 12209.12 | E38: =IFERROR(E32-E35,0) -> 15588.36 | F38: =IFERROR(F32-F35,0) -> 17540.72 | G38: =IFERROR(G32-G35,0) -> 20059.11 | H38: =IFERROR(H32-H35,0) -> 20059.11
B39: Net Margins | C39: =C38/C6 -> 0.12195959 | D39: =D38/D6 -> 0.14876107 | E39: =E38/E6 -> 0.14122066 | F39: =F38/F6 -> 0.13107489 | G39: =G38/G6 -> 0.13325622 | H39: =H38/H6 -> 0.13325622
B41: No. of Equity Shares | C41: =IFERROR('Data Sheet'!B38/'Data Sheet'!B89,0) -> 39.785 | D41: =IFERROR('Data Sheet'!C38/'Data Sheet'!C89,0) -> 79.63 | E41: =IFERROR('Data Sheet'!D38/'Data Sheet'!D89,0) -> 79.705 | F41: =IFERROR('Data Sheet'!E38/'Data Sheet'!E89,0) -> 79.8 | G41: =IFERROR('Data Sheet'!F38/'Data Sheet'!F89,0) -> 79.935 | H41: =IFERROR('Data Sheet'!F38/'Data Sheet'!F89,0) -> 79.935
B43: Earnings Per Share (Basic EPS) | C43: =C38/C41 -> 209.79741 | D43: =D38/D41 -> 153.32312 | E43: =E38/E41 -> 195.57569 | F43: =F38/F41 -> 219.80852 | G43: =G38/G41 -> 250.94277 | H43: =H38/H41 -> 250.94277
B44: EPS Growth % | D44: =IFERROR(D43/C43-1,0) -> -0.26918488 | E44: =IFERROR(E43/D43-1,0) -> 0.27557857 | F44: =IFERROR(F43/E43-1,0) -> 0.12390516 | G44: =IFERROR(G43/F43-1,0) -> 0.14164257 | H44: =IFERROR(H43/G43-1,0) -> 0
B46: Dividend per Share | C46: =IFERROR('Data Sheet'!B31/'Historical FS'!C41,0) -> 1.1999497 | D46: =IFERROR('Data Sheet'!C31/'Historical FS'!D41,0) -> 0.79932186 | E46: =IFERROR('Data Sheet'!D31/'Historical FS'!E41,0) -> 1.5987705 | F46: =IFERROR('Data Sheet'!E31/'Historical FS'!F41,0) -> 2.0008772 | G46: 0 | H46: =IFERROR('Data Sheet'!F31/'Historical FS'!H41,0) -> 0
B47: Divident Payout Ratio | C47: =IFERROR(C46/C43,0) -> 0.005719564 | D47: =IFERROR(D46/D43,0) -> 0.0052133159 | E47: =IFERROR(E46/E43,0) -> 0.0081746893 | F47: =IFERROR(F46/F43,0) -> 0.009102819 | G47: 0 | H47: =IFERROR(H46/H43,0) -> 0
B49: Retained Earnings | C49: =IFERROR(IF(C43>C46,1-C47,0),0) -> 0.99428044 | D49: =IFERROR(IF(D43>D46,1-D47,0),0) -> 0.99478668 | E49: =IFERROR(IF(E43>E46,1-E47,0),0) -> 0.99182531 | F49: =IFERROR(IF(F43>F46,1-F47,0),0) -> 0.99089718 | G49: =IFERROR(IF(G43>G46,1-G47,0),0) -> 1 | H49: =IFERROR(IF(H43>H46,1-H47,0),0) -> 1
A51: # | B51: Balance statement | C51: =C3 -> Mar '22 | D51: =D3 -> Mar '23 | E51: =E3 -> Mar '24 | F51: =F3 -> Mar '25 | G51: =G3 -> Mar '26 | H51: =H3 -> LTM
B52: Equity Share Capital | C52: =IFERROR('Data Sheet'!B38,0) -> 79.57 | D52: =IFERROR('Data Sheet'!C38,0) -> 159.26 | E52: =IFERROR('Data Sheet'!D38,0) -> 159.41 | F52: =IFERROR('Data Sheet'!E38,0) -> 159.6 | G52: =IFERROR('Data Sheet'!F38,0) -> 159.87 | H52: =IFERROR('Data Sheet'!F38,0) -> 159.87
B53: Reserves | C53: =IFERROR('Data Sheet'!B40,0) -> 40167.23 | D53: =IFERROR('Data Sheet'!C40,0) -> 46248.08 | E53: =IFERROR('Data Sheet'!D40,0) -> 60169.21 | F53: =IFERROR('Data Sheet'!E40,0) -> 72235.71 | G53: =IFERROR('Data Sheet'!F40,0) -> 77754.66 | H53: =IFERROR('Data Sheet'!F40,0) -> 77754.66
B54: Borrowings | C54: =IFERROR(SUM('Data Sheet'!B45,'Data Sheet'!B50,'Data Sheet'!B43),0) -> 186587.52 | D54: =IFERROR(SUM('Data Sheet'!C45,'Data Sheet'!C50,'Data Sheet'!C43),0) -> 242632.02 | E54: =IFERROR(SUM('Data Sheet'!D45,'Data Sheet'!D50,'Data Sheet'!D43),0) -> 331046.04 | F54: =IFERROR(SUM('Data Sheet'!E45,'Data Sheet'!E50,'Data Sheet'!E43),0) -> 410388.76 | G54: =IFERROR(SUM('Data Sheet'!F45,'Data Sheet'!F50,'Data Sheet'!F43),0) -> 491298.28 | H54: =IFERROR(SUM('Data Sheet'!F45,'Data Sheet'!F50,'Data Sheet'!F43),0) -> 491298.28
B55: Other Liabilities | C55: =IFERROR(SUM('Data Sheet'!B46,'Data Sheet'!B47,'Data Sheet'!B51,'Data Sheet'!B52),0) -> 106884.64 | D55: =IFERROR(SUM('Data Sheet'!C46,'Data Sheet'!C47,'Data Sheet'!C51,'Data Sheet'!C52),0) -> 116469.83 | E55: =IFERROR(SUM('Data Sheet'!D46,'Data Sheet'!D47,'Data Sheet'!D51,'Data Sheet'!D52),0) -> 146554.97 | F55: =IFERROR(SUM('Data Sheet'!E46,'Data Sheet'!E47,'Data Sheet'!E51,'Data Sheet'!E52),0) -> 169447.54 | G55: =IFERROR(SUM('Data Sheet'!F46,'Data Sheet'!F47,'Data Sheet'!F51,'Data Sheet'!F52),0) -> 189284.73 | H55: =IFERROR(SUM('Data Sheet'!F46,'Data Sheet'!F47,'Data Sheet'!F51,'Data Sheet'!F52),0) -> 189284.73
B56: Total Liabilities | C56: =IFERROR('Data Sheet'!B54,0) -> 333718.96 | D56: =IFERROR('Data Sheet'!C54,0) -> 405509.19 | E56: =IFERROR('Data Sheet'!D54,0) -> 537929.63 | F56: =IFERROR('Data Sheet'!E54,0) -> 652231.61 | G56: =IFERROR('Data Sheet'!F54,0) -> 758497.54 | H56: =IFERROR('Data Sheet'!F54,0) -> 758497.54
B58: Fixed Assets Net Block | C58: =IFERROR(SUM('Data Sheet'!B57,'Data Sheet'!B58),0) -> 2955.41 | D58: =IFERROR(SUM('Data Sheet'!C57,'Data Sheet'!C58),0) -> 3776.1 | E58: =IFERROR(SUM('Data Sheet'!D57,'Data Sheet'!D58),0) -> 4903.96 | F58: =IFERROR(SUM('Data Sheet'!E57,'Data Sheet'!E58),0) -> 5685.37 | G58: =IFERROR(SUM('Data Sheet'!F57,'Data Sheet'!F58),0) -> 5997.23 | H58: =IFERROR(SUM('Data Sheet'!F57,'Data Sheet'!F58),0) -> 5997.23
B59: Capital Work in Progress | C59: =IFERROR('Data Sheet'!B59,0) -> 53.64 | D59: =IFERROR('Data Sheet'!C59,0) -> 61.84 | E59: =IFERROR('Data Sheet'!D59,0) -> 82.12 | F59: =IFERROR('Data Sheet'!E59,0) -> 122.95 | G59: =IFERROR('Data Sheet'!F59,0) -> 250.31 | H59: =IFERROR('Data Sheet'!F59,0) -> 250.31
...

Sheet Assumptions
B2: Assumptions: BAJAJ FINSERV
B3: Margins | C3: 44651 | D3: 45016 | E3: 45382 | F3: 45747 | G3: 46112
B4: EBITDA | C4: =IFERROR('Historical FS'!C19,0) -> 0.24435665 | D4: =IFERROR('Historical FS'!D19,0) -> 0.25244563 | E4: =IFERROR('Historical FS'!E19,0) -> 0.24370283 | F4: =IFERROR('Historical FS'!F19,0) -> 0.24546106 | G4: =IFERROR('Historical FS'!G19,0) -> 0.25255719
B5: EBIT | C5: =IFERROR('Historical FS'!C25,0) -> 0.23613429 | D5: =IFERROR('Historical FS'!D25,0) -> 0.24418703 | E5: =IFERROR('Historical FS'!E25,0) -> 0.23554823 | F5: =IFERROR('Historical FS'!F25,0) -> 0.23671572 | G5: =IFERROR('Historical FS'!G25,0) -> 0.24397846
B6: EBT | C6: =IFERROR('Historical FS'!C33,0) -> 0.16516669 | D6: =IFERROR('Historical FS'!D33,0) -> 0.20482878 | E6: =IFERROR('Historical FS'!E33,0) -> 0.19358081 | F6: =IFERROR('Historical FS'!F33,0) -> 0.17733458 | G6: =IFERROR('Historical FS'!G33,0) -> 0.18117798
B7: Net Profit | C7: =IFERROR('Historical FS'!C39,0) -> 0.12195959 | D7: =IFERROR('Historical FS'!D39,0) -> 0.14876107 | E7: =IFERROR('Historical FS'!E39,0) -> 0.14122066 | F7: =IFERROR('Historical FS'!F39,0) -> 0.13107489 | G7: =IFERROR('Historical FS'!G39,0) -> 0.13325622
B9: Historical Growth | C9: 44651 | D9: 45016 | E9: 45382 | F9: 45747 | G9: 46112
B10: Average Growth | C10: =IFERROR(AVERAGE('Historical FS'!D7:G7),0) -> 0.22033766
B11: CAGR % | C11: =IFERROR(('Historical FS'!G6/'Historical FS'!C6)^(1/4)-1,0) -> 0.21781174 | D11: =IFERROR(('Historical FS'!G6/'Historical FS'!C6)^(1/4)-1,0) -> 0.21781174 | E11: (RRI Formula)
B13: Tax Rate | C13: 44651 | D13: 45016 | E13: 45382 | F13: 45747 | G13: 46112
B14: Effective Tax Rate | C14: =IFERROR('Historical FS'!C36,0) -> 0.26159694 | D14: =IFERROR('Historical FS'!D36,0) -> 0.27372966 | E14: =IFERROR('Historical FS'!E36,0) -> 0.27048212 | F14: =IFERROR('Historical FS'!F36,0) -> 0.26086108 | G14: =IFERROR('Historical FS'!G36,0) -> 0.26450099
B15: Marginal Tax Rate | C15: 0.265
B17: Return On Capital Employed | C17: 44651 | D17: 45016 | E17: 45382 | F17: 45747 | G17: 46112
B18: EBIT*(1-T) | C18: =IFERROR('Historical FS'!C24*(1-Assumptions!$C$15),0) -> 11878.181 | D18: =IFERROR('Historical FS'!D24*(1-Assumptions!$C$15),0) -> 14730.076 | E18: =IFERROR('Historical FS'!E24*(1-Assumptions!$C$15),0) -> 19110.382 | F18: =IFERROR('Historical FS'!F24*(1-Assumptions!$C$15),0) -> 23283.183 | G18: =IFERROR('Historical FS'!G24*(1-Assumptions!$C$15),0) -> 26993.735
B19: Book Equity | C19: =IFERROR('Historical FS'!C52+'Historical FS'!C53,0) -> 40246.8 | D19: =IFERROR('Historical FS'!D52+'Historical FS'!D53,0) -> 46407.34 | E19: =IFERROR('Historical FS'!E52+'Historical FS'!E53,0) -> 60328.62 | F19: =IFERROR('Historical FS'!F52+'Historical FS'!F53,0) -> 72395.31 | G19: =IFERROR('Historical FS'!G52+'Historical FS'!G53,0) -> 77914.53
B20: Book Debt | C20: =IFERROR('Historical FS'!C54,0) -> 186587.52 | D20: =IFERROR('Historical FS'!D54,0) -> 242632.02 | E20: =IFERROR('Historical FS'!E54,0) -> 331046.04 | F20: =IFERROR('Historical FS'!F54,0) -> 410388.76 | G20: =IFERROR('Historical FS'!G54,0) -> 491298.28
B21: Cash and Equivalents | C21: =IFERROR('Historical FS'!C66,0) -> 4403.03 | D21: =IFERROR('Historical FS'!D66,0) -> 5377.22 | E21: =IFERROR('Historical FS'!E66,0) -> 12386.66 | F21: =IFERROR('Historical FS'!F66,0) -> 15736.8 | G21: =IFERROR('Historical FS'!G66,0) -> 17618.04
B22: Capital Employed | C22: =C19+C20-C21 -> 222431.29 | D22: =D19+D20-D21 -> 283662.14 | E22: =E19+E20-E21 -> 378988 | F22: =F19+F20-F21 -> 467047.27 | G22: =G19+G20-G21 -> 551594.77
B24: Pre/Post Tax Return on Capital Employed | C24: 44651 | D24: 45016 | E24: 45382 | F24: 45747 | G24: 46112
B25: Pre Tax Return on Capital | C25: =IFERROR('Historical FS'!C24/Assumptions!C22,0) -> 0.072655201 | D25: =IFERROR('Historical FS'!D24/Assumptions!D22,0) -> 0.070650669 | E25: =IFERROR('Historical FS'!E24/Assumptions!E22,0) -> 0.068605127 | F25: =IFERROR('Historical FS'!F24/Assumptions!F22,0) -> 0.067825683 | G25: =IFERROR('Historical FS'!G24/Assumptions!G22,0) -> 0.066581795
B26: Post Tax Return on Capital | C26: =IFERROR(C18/C22,0) -> 0.053401572 | D26: =IFERROR(D18/D22,0) -> 0.051928242 | E26: =IFERROR(E18/E22,0) -> 0.050424769 | F26: =IFERROR(F18/F22,0) -> 0.049851877 | G26: =IFERROR(G18/G22,0) -> 0.048937619
B28: Growth in EBIT | C28: =IFERROR(('Historical FS'!G24/'Historical FS'!C24)^(1/4)-1,0) -> 0.22780179
B40: ROCE / Capital Employed framework retained for analytical reference only. Not used to drive growth assumptions, intrinsic value, or terminal value for Bajaj Finserv — ROE-based methods (P/B, Residual Income) are the appropriate framework for a financial holding company.

Sheet Ratio Analysis
B2: Ratio Analysis - BAJAJ FINSERV
B3: Years | D3: 44621 | E3: 44986 | F3: 45352 | G3: 45717 | H3: 46082 | I3: Trends | J3: Mean | K3: Median
B5: Sales Growth | D5: =IFERROR('Historical FS'!D7,0) -> 0.19919978 | E5: =IFERROR('Historical FS'!E7,0) -> 0.34495305 | F5: =IFERROR('Historical FS'!F7,0) -> 0.21234357 | G5: =IFERROR('Historical FS'!G7,0) -> 0.12485425 | H5: =IFERROR('Historical FS'!H7,0) -> 0 | J5: =IFERROR(AVERAGE(D5:H5),0) -> 0.17627013 | K5: =IFERROR(MEDIAN(D5:H5),0) -> 0.19919978
B6: EBITDA Growth | D6: =IFERROR('Historical FS'!D18/'Historical FS'!C18-1,0) -> 0.23889707 | E6: =IFERROR('Historical FS'!E18/'Historical FS'!D18-1,0) -> 0.29837413 | F6: =IFERROR('Historical FS'!F18/'Historical FS'!E18-1,0) -> 0.2210902 | G6: =IFERROR('Historical FS'!G18/'Historical FS'!F18-1,0) -> 0.15737309 | H6: =IFERROR('Historical FS'!H18/'Historical FS'!G18-1,0) -> 0 | J6: =IFERROR(AVERAGE(D6:H6),0) -> 0.1831469 | K6: =IFERROR(MEDIAN(D6:H6),0) -> 0.2210902
B7: EBIT Growth | D7: =IFERROR('Historical FS'!D24/'Historical FS'!C24-1,0) -> 0.24009532 | E7: =IFERROR('Historical FS'!E24/'Historical FS'!D24-1,0) -> 0.29737158 | F7: =IFERROR('Historical FS'!F24/'Historical FS'!E24-1,0) -> 0.21835256 | G7: =IFERROR('Historical FS'!G24/'Historical FS'!F24-1,0) -> 0.15936618 | H7: =IFERROR('Historical FS'!H24/'Historical FS'!G24-1,0) -> 0 | J7: =IFERROR(AVERAGE(D7:H7),0) -> 0.18303713 | K7: =IFERROR(MEDIAN(D7:H7),0) -> 0.21835256
B8: Net Profit Growth | D8: =IFERROR('Historical FS'!D38/'Historical FS'!C38-1,0) -> 0.46273238 | E8: =IFERROR('Historical FS'!E38/'Historical FS'!D38-1,0) -> 0.27677998 | F8: =IFERROR('Historical FS'!F38/'Historical FS'!E38-1,0) -> 0.12524473 | G8: =IFERROR('Historical FS'!G38/'Historical FS'!F38-1,0) -> 0.14357392 | H8: =IFERROR('Historical FS'!H38/'Historical FS'!G38-1,0) -> 0 | J8: =IFERROR(AVERAGE(D8:H8),0) -> 0.2016662 | K8: =IFERROR(MEDIAN(D8:H8),0) -> 0.14357392
B9: Dividend Growth | D9: =IFERROR('Historical FS'!D46/'Historical FS'!C46-1,0) -> -0.33387054 | E9: =IFERROR('Historical FS'!E46/'Historical FS'!D46-1,0) -> 1.0001586 | F9: =IFERROR('Historical FS'!F46/'Historical FS'!E46-1,0) -> 0.25150998 | G9: =IFERROR('Historical FS'!G46/'Historical FS'!F46-1,0) -> -1 | H9: =IFERROR('Historical FS'!H46/'Historical FS'!G46-1,0) -> 0 | J9: =IFERROR(AVERAGE(D9:H9),0) -> -0.016440401 | K9: =IFERROR(MEDIAN(D9:H9),0) -> 0
B11: Gross Margin | C11: =IFERROR('Historical FS'!C13,0) -> 0.86121564 | D11: =IFERROR('Historical FS'!D13,0) -> 0.85133275 | E11: =IFERROR('Historical FS'!E13,0) -> 0.8333121 | F11: =IFERROR('Historical FS'!F13,0) -> 0.81834319 | G11: =IFERROR('Historical FS'!G13,0) -> 0.81245128 | H11: =IFERROR('Historical FS'!H13,0) -> 0.81245128 | J11: =IFERROR(AVERAGE(C11:H11),0) -> 0.83151771 | K11: =IFERROR(MEDIAN(C11:H11),0) -> 0.82582764
B12: EBITDA Margin | C12: =IFERROR('Historical FS'!C19,0) -> 0.24435665 | D12: =IFERROR('Historical FS'!D19,0) -> 0.25244563 | E12: =IFERROR('Historical FS'!E19,0) -> 0.24370283 | F12: =IFERROR('Historical FS'!F19,0) -> 0.24546106 | G12: =IFERROR('Historical FS'!G19,0) -> 0.25255719 | H12: =IFERROR('Historical FS'!H19,0) -> 0.25255719 | J12: =IFERROR(AVERAGE(C12:H12),0) -> 0.24851343 | K12: =IFERROR(MEDIAN(C12:H12),0) -> 0.24895335
B13: EBIT Margin | C13: =IFERROR('Historical FS'!C25,0) -> 0.23613429 | D13: =IFERROR('Historical FS'!D25,0) -> 0.24418703 | E13: =IFERROR('Historical FS'!E25,0) -> 0.23554823 | F13: =IFERROR('Historical FS'!F25,0) -> 0.23671572 | G13: =IFERROR('Historical FS'!G25,0) -> 0.24397846 | H13: =IFERROR('Historical FS'!H25,0) -> 0.24397846 | J13: =IFERROR(AVERAGE(C13:H13),0) -> 0.24009036 | K13: =IFERROR(MEDIAN(C13:H13),0) -> 0.24034709
B14: EBT Margin | C14: =IFERROR('Historical FS'!C33,0) -> 0.16516669 | D14: =IFERROR('Historical FS'!D33,0) -> 0.20482878 | E14: =IFERROR('Historical FS'!E33,0) -> 0.19358081 | F14: =IFERROR('Historical FS'!F33,0) -> 0.17733458 | G14: =IFERROR('Historical FS'!G33,0) -> 0.18117798 | H14: =IFERROR('Historical FS'!H33,0) -> 0.18117798 | J14: =IFERROR(AVERAGE(C14:H14),0) -> 0.1838778 | K14: =IFERROR(MEDIAN(C14:H14),0) -> 0.18117798
B15: Net Profit Margin | C15: =IFERROR('Historical FS'!C39,0) -> 0.12195959 | D15: =IFERROR('Historical FS'!D39,0) -> 0.14876107 | E15: =IFERROR('Historical FS'!E39,0) -> 0.14122066 | F15: =IFERROR('Historical FS'!F39,0) -> 0.13107489 | G15: =IFERROR('Historical FS'!G39,0) -> 0.13325622 | H15: =IFERROR('Historical FS'!H39,0) -> 0.13325622 | J15: =IFERROR(AVERAGE(C15:H15),0) -> 0.13492144 | K15: =IFERROR(MEDIAN(C15:H15),0) -> 0.13325622
B17: Sales Expenses%Sales | C17: =IFERROR('Historical FS'!C16,0) -> 0.61685899 | D17: =IFERROR('Historical FS'!D16,0) -> 0.59888712 | E17: =IFERROR('Historical FS'!E16,0) -> 0.58960927 | F17: =IFERROR('Historical FS'!F16,0) -> 0.57288212 | G17: =IFERROR('Historical FS'!G16,0) -> 0.55989409 | H17: =IFERROR('Historical FS'!H16,0) -> 0.55989409 | J17: =IFERROR(AVERAGE(C17:H17),0) -> 0.58300428 | K17: =IFERROR(MEDIAN(C17:H17),0) -> 0.5812457
B18: Depriciation%Sales | C18: =IFERROR('Historical FS'!C22,0) -> 0.008222361 | D18: =IFERROR('Historical FS'!D22,0) -> 0.0082586012 | E18: =IFERROR('Historical FS'!E22,0) -> 0.0081546071 | F18: =IFERROR('Historical FS'!F22,0) -> 0.0087453405 | G18: =IFERROR('Historical FS'!G22,0) -> 0.0085787334 | H18: =IFERROR('Historical FS'!H22,0) -> 0.0085787334 | J18: =IFERROR(AVERAGE(C18:H18),0) -> 0.0084230628 | K18: =IFERROR(MEDIAN(C18:H18),0) -> 0.0084186673
B19: Operating Income%Sales | C19: =C13 -> 0.23613429 | D19: =D13 -> 0.24418703 | E19: =E13 -> 0.23554823 | F19: =F13 -> 0.23671572 | G19: =G13 -> 0.24397846 | H19: =H13 -> 0.24397846 | J19: =IFERROR(AVERAGE(C19:H19),0) -> 0.24009036 | K19: =IFERROR(MEDIAN(C19:H19),0) -> 0.24034709
B21: Return on Capital Employed | C21: =IFERROR(Assumptions!C26,0) -> 0.053401572 | D21: =IFERROR(Assumptions!D26,0) -> 0.051928242 | E21: =IFERROR(Assumptions!E26,0) -> 0.050424769 | F21: =IFERROR(Assumptions!F26,0) -> 0.049851877 | G21: =IFERROR(Assumptions!G26,0) -> 0.048937619 | H21: =IFERROR(Assumptions!G26,0) -> 0.048937619 | J21: =IFERROR(AVERAGE(C21:H21),0) -> 0.050580283 | K21: =IFERROR(MEDIAN(C21:H21),0) -> 0.050138323
B22: Retained Earning % | C22: =IFERROR('Historical FS'!C49,0) -> 0.99428044 | D22: =IFERROR('Historical FS'!D49,0) -> 0.99478668 | E22: =IFERROR('Historical FS'!E49,0) -> 0.99182531 | F22: =IFERROR('Historical FS'!F49,0) -> 0.99089718 | G22: =IFERROR('Historical FS'!G49,0) -> 1 | H22: =IFERROR('Historical FS'!H49,0) -> 1 | J22: =IFERROR(AVERAGE(C22:H22),0) -> 0.99529827 | K22: =IFERROR(MEDIAN(C22:H22),0) -> 0.99453356
B23: Return on Equity % | C23: =IFERROR('Historical FS'!C38/('Historical FS'!C52+'Historical FS'!C53),0) -> 0.20739015 | D23: =IFERROR('Historical FS'!D38/(('Historical FS'!D52+'Historical FS'!D53+'Historical FS'!C52+'Historical FS'!C53)/2),0) -> 0.28178965 | E23: =IFERROR('Historical FS'!E38/(('Historical FS'!E52+'Historical FS'!E53+'Historical FS'!D52+'Historical FS'!D53)/2),0) -> 0.292092 | F23: =IFERROR('Historical FS'!F38/(('Historical FS'!F52+'Historical FS'!F53+'Historical FS'!E52+'Historical FS'!E53)/2),0) -> 0.26431888 | G23: =IFERROR('Historical FS'!G38/(('Historical FS'!G52+'Historical FS'!G53+'Historical FS'!F52+'Historical FS'!F53)/2),0) -> 0.26690348 | H23: =IFERROR('Historical FS'!H38/(('Historical FS'!H52+'Historical FS'!H53+'Historical FS'!G52+'Historical FS'!G53)/2),0) -> 0.25745018 | J23: =IFERROR(AVERAGE(C23:H23),0) -> 0.26165739 | K23: =IFERROR(MEDIAN(C23:H23),0) -> 0.26561118
B24: Self Sustained Growth Rate | C24: =IFERROR(C22*C23,0) -> 0.20620397 | D24: =IFERROR(D22*D23,0) -> 0.28032059 | E24: =IFERROR(E22*E23,0) -> 0.28970424 | F24: =IFERROR(F22*F23,0) -> 0.26191283 | G24: =IFERROR(G22*G23,0) -> 0.26690348 | H24: =IFERROR(H22*H23,0) -> 0.25745018 | J24: =IFERROR(AVERAGE(C24:H24),0) -> 0.26041588 | K24: =IFERROR(MEDIAN(C24:H24),0) -> 0.26440816
B25: NBFC-Specific Ratios
B26: Net Interest Margin (NIM) | C26: =IFERROR('Historical FS'!C12/'Historical FS'!C69,0) -> 0.17661783 | D26: =IFERROR('Historical FS'!D12/'Historical FS'!D69,0) -> 0.17230335 | E26: =IFERROR('Historical FS'!E12/'Historical FS'!E69,0) -> 0.1709954 | F26: =IFERROR('Historical FS'!F12/'Historical FS'!F69,0) -> 0.16790419 | G26: =IFERROR('Historical FS'!G12/'Historical FS'!G69,0) -> 0.16123797 | H26: =IFERROR('Historical FS'!H12/'Historical FS'!H69,0) -> 0.16123797 | J26: =IFERROR(AVERAGE(C26:H26),0) -> 0.16838278 | K26: =IFERROR(MEDIAN(C26:H26),0) -> 0.16944979
B27: Cost of Funds % | C27: =IFERROR('Historical FS'!C9/'Historical FS'!C54,0) -> 0.050905119 | D27: =IFERROR('Historical FS'!D9/'Historical FS'!D54,0) -> 0.050287757 | E27: =IFERROR('Historical FS'!E9/'Historical FS'!E54,0) -> 0.055579913 | F27: =IFERROR('Historical FS'!F9/'Historical FS'!F54,0) -> 0.059235784 | G27: =IFERROR('Historical FS'!G9/'Historical FS'!G54,0) -> 0.057463625 | H27: =IFERROR('Historical FS'!H9/'Historical FS'!H54,0) -> 0.057463625 | J27: =IFERROR(AVERAGE(C27:H27),0) -> 0.05515597 | K27: =IFERROR(MEDIAN(C27:H27),0) -> 0.056521769
B28: Yield on Loan Book | C28: =IFERROR('Historical FS'!C6/'Historical FS'!C65,0) -> 0.35672588 | D28: =IFERROR('Historical FS'!D6/'Historical FS'!D65,0) -> 0.33809333 | E28: =IFERROR('Historical FS'!E6/'Historical FS'!E65,0) -> 0.33782907 | F28: =IFERROR('Historical FS'!F6/'Historical FS'!F65,0) -> 0.32760133 | G28: =IFERROR('Historical FS'!G6/'Historical FS'!G65,0) -> 0.30105114 | H28: =IFERROR('Historical FS'!H6/'Historical FS'!H65,0) -> 0.30105114 | J28: =IFERROR(AVERAGE(C28:H28),0) -> 0.32705865 | K28: =IFERROR(MEDIAN(C28:H28),0) -> 0.3327152
B29: Loan Book Growth | D29: =IFERROR('Historical FS'!D65/'Historical FS'!C65-1,0) -> 0.26528849 | E29: =IFERROR('Historical FS'!E65/'Historical FS'!D65-1,0) -> 0.3460051 | F29: =IFERROR('Historical FS'!F65/'Historical FS'!E65-1,0) -> 0.25019303 | G29: =IFERROR('Historical FS'!G65/'Historical FS'!F65-1,0) -> 0.22405696 | H29: =IFERROR('Historical FS'!H65/'Historical FS'!G65-1,0) -> 0 | J29: =IFERROR(AVERAGE(D29:H29),0) -> 0.21710872 | K29: =IFERROR(MEDIAN(D29:H29),0) -> 0.25019303
B30: Credit Cost (Provisions / Loan Book) | C30: =IFERROR('Historical FS'!C27/'Historical FS'!C65,0) -> 0.025487464 | D30: =IFERROR('Historical FS'!D27/'Historical FS'!D65,0) -> 0.013309931 | E30: =IFERROR('Historical FS'!E27/'Historical FS'!E65,0) -> 0.014181151 | F30: =IFERROR('Historical FS'!F27/'Historical FS'!F65,0) -> 0.01945596 | G30: =IFERROR('Historical FS'!G27/'Historical FS'!G65,0) -> 0.018959374 | H30: =IFERROR('Historical FS'!H27/'Historical FS'!H65,0) -> 0.018959374 | J30: =IFERROR(AVERAGE(C30:H30),0) -> 0.018392209 | K30: =IFERROR(MEDIAN(C30:H30),0) -> 0.018959374
B31: OpEx Ratio (OpEx / NII) | C31: =IFERROR('Historical FS'!C15/'Historical FS'!C12,0) -> 0.71626543 | D31: =IFERROR('Historical FS'!D15/'Historical FS'!D12,0) -> 0.70347009 | E31: =IFERROR('Historical FS'!E15/'Historical FS'!E12,0) -> 0.70754915 | F31: =IFERROR('Historical FS'!F15/'Historical FS'!F12,0) -> 0.70005119 | G31: =IFERROR('Historical FS'!G15/'Historical FS'!G12,0) -> 0.68914174 | H31: =IFERROR('Historical FS'!H15/'Historical FS'!H12,0) -> 0.68914174 | J31: =IFERROR(AVERAGE(C31:H31),0) -> 0.70093656 | K31: =IFERROR(MEDIAN(C31:H31),0) -> 0.70176064
B32: Return on Assets (ROA) | C32: =IFERROR('Historical FS'!C38/'Historical FS'!C69,0) -> 0.025011435 | D32: =IFERROR('Historical FS'!D38/'Historical FS'!D69,0) -> 0.030108122 | E32: =IFERROR('Historical FS'!E38/'Historical FS'!E69,0) -> 0.028978437 | F32: =IFERROR('Historical FS'!F38/'Historical FS'!F69,0) -> 0.026893391 | G32: =IFERROR('Historical FS'!G38/'Historical FS'!G69,0) -> 0.026445847 | H32: =IFERROR('Historical FS'!H38/'Historical FS'!H69,0) -> 0.026445847 | J32: =IFERROR(AVERAGE(C32:H32),0) -> 0.027313847 | K32: =IFERROR(MEDIAN(C32:H32),0) -> 0.026669619
B33: Net Gearing (Borrowings / Equity) | C33: =IFERROR('Historical FS'!C54/('Historical FS'!C52+'Historical FS'!C53),0) -> 4.6360834 | D33: =IFERROR('Historical FS'!D54/('Historical FS'!D52+'Historical FS'!D53),0) -> 5.2283113 | E33: =IFERROR('Historical FS'!E54/('Historical FS'!E52+'Historical FS'!E53),0) -> 5.4873796 | F33: =IFERROR('Historical FS'!F54/('Historical FS'!F52+'Historical FS'!F53),0) -> 5.6687203 | G33: =IFERROR('Historical FS'!G54/('Historical FS'!G52+'Historical FS'!G53),0) -> 6.3056054 | H33: =IFERROR('Historical FS'!H54/('Historical FS'!H52+'Historical FS'!H53),0) -> 6.3056054 | J33: =IFERROR(AVERAGE(C33:H33),0) -> 5.6052842 | K33: =IFERROR(MEDIAN(C33:H33),0) -> 5.5780499
B34: P/B (at CMP) | C34: =IFERROR(Valuation!$C$17/'Historical FS'!C70,0) -> 1.7398054 | D34: =IFERROR(Valuation!$C$17/'Historical FS'!D70,0) -> 3.0199705 | E34: =IFERROR(Valuation!$C$17/'Historical FS'!E70,0) -> 2.3252778 | F34: =IFERROR(Valuation!$C$17/'Historical FS'!F70,0) -> 1.9400152 | G34: =IFERROR(Valuation!$C$17/'Historical FS'!G70,0) -> 1.8056401 | H34: =IFERROR(Valuation!$C$17/'Historical FS'!H70,0) -> 1.8056401 | J34: =IFERROR(AVERAGE(C34:H34),0) -> 2.1060582 | K34: =IFERROR(MEDIAN(C34:H34),0) -> 1.8728276
B35: P/E (at CMP) | C35: =IFERROR(Valuation!$C$17/'Historical FS'!C43,0) -> 8.3890454 | D35: =IFERROR(Valuation!$C$17/'Historical FS'!D43,0) -> 11.479026 | E35: =IFERROR(Valuation!$C$17/'Historical FS'!E43,0) -> 8.9990737 | F35: =IFERROR(Valuation!$C$17/'Historical FS'!F43,0) -> 8.0069689 | G35: =IFERROR(Valuation!$C$17/'Historical FS'!G43,0) -> 7.0135514 | H35: =IFERROR(Valuation!$C$17/'Historical FS'!H43,0) -> 7.0135514 | J35: =IFERROR(AVERAGE(C35:H35),0) -> 8.4835361 | K35: =IFERROR(MEDIAN(C35:H35),0) -> 8.1980071
B37: Cash Flow Ratios
B38: CFO / Total Assets | C38: =IFERROR('Historical FS'!C83/'Historical FS'!C69,0) -> -0.10089628 | D38: =IFERROR('Historical FS'!D83/'Historical FS'!D69,0) -> -0.097359076 | E38: =IFERROR('Historical FS'!E83/'Historical FS'!E69,0) -> -0.12176686 | F38: =IFERROR('Historical FS'!F83/'Historical FS'!F69,0) -> -0.095228442 | G38: =IFERROR('Historical FS'!G83/'Historical FS'!G69,0) -> -0.072908608 | H38: =IFERROR('Historical FS'!H83/'Historical FS'!H69,0) -> -0.072908608 | J38: =IFERROR(AVERAGE(C38:H38),0) -> -0.093511311 | K38: =IFERROR(MEDIAN(C38:H38),0) -> -0.096293759
B39: CFO / Net Profit | C39: =IFERROR('Historical FS'!C83/'Historical FS'!C38,0) -> -4.0340059 | D39: =IFERROR('Historical FS'!D83/'Historical FS'!D38,0) -> -3.2336483 | E39: =IFERROR('Historical FS'!E83/'Historical FS'!E38,0) -> -4.2019815 | F39: =IFERROR('Historical FS'!F83/'Historical FS'!F38,0) -> -3.5409607 | G39: =IFERROR('Historical FS'!G83/'Historical FS'!G38,0) -> -2.756902 | H39: =IFERROR('Historical FS'!H83/'Historical FS'!H38,0) -> -2.756902 | J39: =IFERROR(AVERAGE(C39:H39),0) -> -3.4207334 | K39: =IFERROR(MEDIAN(C39:H39),0) -> -3.3873045
B40: CFO / Borrowings | C40: =IFERROR('Historical FS'!C83/'Historical FS'!C54,0) -> -0.18045687 | D40: =IFERROR('Historical FS'!D83/'Historical FS'!D54,0) -> -0.16271554 | E40: =IFERROR('Historical FS'!E83/'Historical FS'!E54,0) -> -0.19786372 | F40: =IFERROR('Historical FS'!F83/'Historical FS'!F54,0) -> -0.15134674 | G40: =IFERROR('Historical FS'!G83/'Historical FS'!G54,0) -> -0.11256095 | H40: =IFERROR('Historical FS'!H83/'Historical FS'!H54,0) -> -0.11256095 | J40: =IFERROR(AVERAGE(C40:H40),0) -> -0.15291746 | K40: =IFERROR(MEDIAN(C40:H40),0) -> -0.15703114

Sheet Fixed Assets Schedule
B2: Fixed Asset Schedule
B3: Particulars | C3: 44621 | D3: 44986 | E3: 45352 | F3: 45717 | G3: 46082
B4: Beginning Balance | D4: =IFERROR(C8,0) -> 2955.41 | E4: =IFERROR(D8,0) -> 3776.1 | F4: =IFERROR(E8,0) -> 4903.96 | G4: =IFERROR(F8,0) -> 5685.37
B5: Add: Net Purchases | D5: =IFERROR(D6-D4,0) -> 1498.49 | E5: =IFERROR(E6-E4,0) -> 2027.99 | F5: =IFERROR(F6-F4,0) -> 1951.73 | G5: =IFERROR(G6-G4,0) -> 1603.22
B6: Total Fixed Assets | C6: =IFERROR(SUM(C7+C8),0) -> 3518.14 | D6: =IFERROR(SUM(D7+D8),0) -> 4453.9 | E6: =IFERROR(SUM(E7+E8),0) -> 5804.09 | F6: =IFERROR(SUM(F7+F8),0) -> 6855.69 | G6: =IFERROR(SUM(G7+G8),0) -> 7288.59
B7: Less: Depriciation | C7: =IFERROR('Historical FS'!C21,0) -> 562.73 | D7: =IFERROR('Historical FS'!D21,0) -> 677.8 | E7: =IFERROR('Historical FS'!E21,0) -> 900.13 | F7: =IFERROR('Historical FS'!F21,0) -> 1170.32 | G7: =IFERROR('Historical FS'!G21,0) -> 1291.36
B8: Closing Balance (Fixed Assets) | C8: =IFERROR('Historical FS'!C58,0) -> 2955.41 | D8: =IFERROR('Historical FS'!D58,0) -> 3776.1 | E8: =IFERROR('Historical FS'!E58,0) -> 4903.96 | F8: =IFERROR('Historical FS'!F58,0) -> 5685.37 | G8: =IFERROR('Historical FS'!G58,0) -> 5997.23
B10: Net Capital Expenditure | D10: =IFERROR(D5-D7,0) -> 820.69 | E10: =IFERROR(E5-E7,0) -> 1127.86 | F10: =IFERROR(F5-F7,0) -> 781.41 | G10: =IFERROR(G5-G7,0) -> 311.86
B11: Net Capital Expenditure / Sales % | D11: =IFERROR(D10/'Historical FS'!D6,0) -> 0.0099996332 | E11: =IFERROR(E10/'Historical FS'!E6,0) -> 0.010217697 | F11: =IFERROR(F10/'Historical FS'!F6,0) -> 0.0058391692 | G11: =IFERROR(G10/'Historical FS'!G6,0) -> 0.0020717413
B13: Median Capex / sales % | D13: =IFERROR(MEDIAN(D11:G11),0) -> 0.0079194012
B14: Average capital expenditure / sales % | D14: =IFERROR(AVERAGE(D11:G11),0) -> 0.0070320601

Sheet Changes In Working Capital
B2: Change in Working Capital
B3: Particulars | C3: 44621 | D3: 44986 | E3: 45352 | F3: 45717 | G3: 46082
B4: Inventories | C4: 0 | D4: 0 | E4: 0 | F4: 0 | G4: 0
B5: Receivables | C5: =IFERROR('Historical FS'!C64,0) -> 3004.81 | D5: =IFERROR('Historical FS'!D64,0) -> 3458.64 | E5: =IFERROR('Historical FS'!E64,0) -> 5973.86 | F5: =IFERROR('Historical FS'!F64,0) -> 8319.35 | G5: =IFERROR('Historical FS'!G64,0) -> 9332.08
B6: Payables | C6: =IFERROR('Data Sheet'!B51,0) -> 4821.89 | D6: =IFERROR('Data Sheet'!C51,0) -> 6330.8 | E6: =IFERROR('Data Sheet'!D51,0) -> 8142.11 | F6: =IFERROR('Data Sheet'!E51,0) -> 10560.4 | G6: =IFERROR('Data Sheet'!F51,0) -> 11493.31
B7: Non Cash WC | C7: =IFERROR(C4+C5-C6,0) -> -1817.08 | D7: =IFERROR(D4+D5-D6,0) -> -2872.16 | E7: =IFERROR(E4+E5-E6,0) -> -2168.25 | F7: =IFERROR(F4+F5-F6,0) -> -2241.05 | G7: =IFERROR(G4+G5-G6,0) -> -2161.23
B9: Change in working capital | D9: =IFERROR(D7-C7,0) -> -1055.08 | E9: =IFERROR(E7-D7,0) -> 703.91 | F9: =IFERROR(F7-E7,0) -> -72.8 | G9: =IFERROR(G7-F7,0) -> 79.82
B10: Change in Working Capital / % of sales | D10: =IFERROR(D9/'Historical FS'!D6,0) -> -0.01285554 | E10: =IFERROR(E9/'Historical FS'!E6,0) -> 0.0063769783 | F10: =IFERROR(F9/'Historical FS'!F6,0) -> -0.00054400573 | G10: =IFERROR(G9/'Historical FS'!G6,0) -> 0.00053025841
B12: Median Change in working capital / % of sales | D12: =IFERROR(MEDIAN(D10:G10),0) -> -6.8736596e-06
B13: Average Change in working capital / % of sales | D13: =IFERROR(AVERAGE(D10:G10),0) -> -0.0016230772

Sheet FCFF
B2: FCFF
B3: Particulars | C3: 44621 | D3: 44986 | E3: 45352 | F3: 45717 | G3: 46082
B4: EBIT | C4: =IFERROR('Historical FS'!C24,0) -> 16160.79 | D4: =IFERROR('Historical FS'!D24,0) -> 20040.92 | E4: =IFERROR('Historical FS'!E24,0) -> 26000.52 | F4: =IFERROR('Historical FS'!F24,0) -> 31677.8 | G4: =IFERROR('Historical FS'!G24,0) -> 36726.17
B5: Less: Tax on EBIT | C5: =IFERROR(Assumptions!$C$15*C4,0) -> 4282.6093 | D5: =IFERROR(Assumptions!$C$15*D4,0) -> 5310.8438 | E5: =IFERROR(Assumptions!$C$15*E4,0) -> 6890.1378 | F5: =IFERROR(Assumptions!$C$15*F4,0) -> 8394.617 | G5: =IFERROR(Assumptions!$C$15*G4,0) -> 9732.4351
B6: EBIT*(1-tax) | C6: =IFERROR(C4-C5,0) -> 11878.181 | D6: =IFERROR(D4-D5,0) -> 14730.076 | E6: =IFERROR(E4-E5,0) -> 19110.382 | F6: =IFERROR(F4-F5,0) -> 23283.183 | G6: =IFERROR(G4-G5,0) -> 26993.735
B7: Less: Net capital expenditure | D7: =IFERROR('Fixed Assets Schedule'!D10,0) -> 820.69 | E7: =IFERROR('Fixed Assets Schedule'!E10,0) -> 1127.86 | F7: =IFERROR('Fixed Assets Schedule'!F10,0) -> 781.41 | G7: =IFERROR('Fixed Assets Schedule'!G10,0) -> 311.86
B8: Less: Change in WC | D8: =IFERROR('Changes In Working Capital'!D9,0) -> -1055.08 | E8: =IFERROR('Changes In Working Capital'!E9,0) -> 703.91 | F8: =IFERROR('Changes In Working Capital'!F9,0) -> -72.8 | G8: =IFERROR('Changes In Working Capital'!G9,0) -> 79.82
B9: Reinvestment | D9: =IFERROR(SUM(D7+D8),0) -> -234.39 | E9: =IFERROR(SUM(E7+E8),0) -> 1831.77 | F9: =IFERROR(SUM(F7+F8),0) -> 708.61 | G9: =IFERROR(SUM(G7+G8),0) -> 391.68
B10: Free Cah Flow to Firm | D10: =IFERROR(D6-D9,0) -> 14964.466 | E10: =IFERROR(E6-E9,0) -> 17278.612 | F10: =IFERROR(F6-F9,0) -> 22574.573 | G10: =IFERROR(G6-G9,0) -> 26602.055
B12: Reinvestment Rate % | D12: =IFERROR(D9/D6,0) -> -0.015912341 | E12: =IFERROR(E9/E6,0) -> 0.095852086 | F12: =IFERROR(F9/F6,0) -> 0.030434413 | G12: =IFERROR(G9/G6,0) -> 0.014510034
B13: Medium Reinvestment Rate | D13: =IFERROR(MEDIAN(D12:G12),0) -> 0.022472223
B14: Average Reinvestment Rate | D14: =IFERROR(AVERAGE(D12:G12),0) -> 0.031221048
B30: FCFF presented for academic/reference purposes only. Not used in final valuation weighting due to limitations in applying industrial-company FCFF methodology (Net Capex / ΔWC) to a financial institution, where loan-book growth and borrowings are the core operating drivers, not working capital. FCFF Weight in blended valuation = 0%.

Sheet Beta Calculation
C2: Beta Calculation
K3: Data Source: NSE Historical Data (Monthly, Jan 2020 - Dec 2024, 60 months)
B4: BAJAJ Finserv | G4: Nifty 50 | K4: BETA-
B5: Date | C5: BAJAJFINSV.NS Monthly Close | D5: Return | G5: Date | H5: ^NSEI Monthly Close | I5: Return
B6: 44227 | C6: 870.31708 | G6: Jan-20 | H6: 13634.6 | L6: =IFERROR(SLOPE(D7:D65,I7:I65),0) -> 1.4537586
B7: 44255 | C7: 962.69415 | D7: =C7/C6-1 -> 0.10614186 | G7: Feb-20 | H7: 14529.15 | I7: =H7/H6-1 -> 0.065608878 | L7: =IFERROR(COVAR(D7:D65,I7:I65)/VAR(I7:I65),0) -> 1.4291187
B8: 44286 | C8: 964.68964 | D8: =C8/C7-1 -> 0.0020728114 | G8: Mar-20 | H8: 14690.7 | I8: =H8/H7-1 -> 0.011119012 | L8: =IFERROR(L6,0) -> 1.4537586
B9: 44316 | C9: 1101.6865 | D9: =C9/C8-1 -> 0.14201136 | G9: Apr-20 | H9: 14631.1 | I9: =H9/H8-1 -> -0.0040570283 | K9: Vasicek Adj Beta | L9: =(2/3*L6)+(1/3*1) -> 1.3025058
B10: 44347 | C10: 1177.9799 | D10: =C10/C9-1 -> 0.069251401 | G10: May-20 | H10: 15582.8 | I10: =H10/H9-1 -> 0.065046389 | K10: (2/3 × raw + 1/3 × 1.0)
B11: 44377 | C11: 1208.187 | D11: =C11/C10-1 -> 0.025643183 | G11: Jun-20 | H11: 15721.5 | I11: =H11/H10-1 -> 0.008900852
B12: 44408 | C12: 1419.3715 | D12: =C12/C11-1 -> 0.1747945 | G12: Jul-20 | H12: 15763.05 | I12: =H12/H11-1 -> 0.0026428652
B13: 44439 | C13: 1711.4406 | D13: =C13/C12-1 -> 0.20577354 | G13: Aug-20 | H13: 17132.199 | I13: =H13/H12-1 -> 0.086858154
B14: 44469 | C14: 1775.1128 | D14: =C14/C13-1 -> 0.037203887 | G14: Sep-20 | H14: 17618.15 | I14: =H14/H13-1 -> 0.028364786
B15: 44500 | C15: 1778.5459 | D15: =C15/C14-1 -> 0.001934021 | G15: Oct-20 | H15: 17671.65 | I15: =H15/H14-1 -> 0.0030366411
B16: 44530 | C16: 1720.2828 | D16: =C16/C15-1 -> -0.032758818 | G16: Nov-20 | H16: 16983.199 | I16: =H16/H15-1 -> -0.038957944
B17: 44561 | C17: 1637.3342 | D17: =C17/C16-1 -> -0.048218006 | G17: Dec-20 | H17: 17354.051 | I17: =H17/H16-1 -> 0.021836378
B18: 44592 | C18: 1565.8126 | D18: =C18/C17-1 -> -0.043681739 | G18: Jan-21 | H18: 17339.85 | I18: =H18/H17-1 -> -0.00081832029
B19: 44620 | C19: 1598.0481 | D19: =C19/C18-1 -> 0.020587057 | G19: Feb-21 | H19: 16793.9 | I19: =H19/H18-1 -> -0.031485234
B20: 44651 | C20: 1702.6282 | D20: =C20/C19-1 -> 0.065442385 | G20: Mar-21 | H20: 17464.75 | I20: =H20/H19-1 -> 0.039946028
B21: 44681 | C21: 1488.1287 | D21: =C21/C20-1 -> -0.12598142 | G21: Apr-21 | H21: 17102.551 | I21: =H21/H20-1 -> -0.020738872
B22: 44712 | C22: 1290.8097 | D22: =C22/C21-1 -> -0.13259537 | G22: May-21 | H22: 16584.551 | I22: =H22/H21-1 -> -0.03028788
... B65: 46022 | C65: 2026.4 | D65: =C65/C64-1 -> -0.032282701 | G65: Dec-24 | H65: 25938.85 | I65: =H65/H64-1 -> -0.010079003

Sheet WACC
