Workbook

Sheet About 
D19: About
D21: Canara Bank is one of India's largest public sector banks, headquartered in Bengaluru, Karnataka. Established in 1906, the bank was nationalised in 1969 and operates under the ownership of the Government of India. It serves over 100 million customers through a network of 10,000+ branches and 12,000+ ATMs across India and select international locations. Canara Bank offers a comprehensive suite of banking products and services spanning retail banking, corporate banking, MSME lending, agricultural finance, and treasury operations. The bank is listed on both NSE (CANBK) and BSE and forms part of the Nifty PSU Bank index. It is well regarded for its strong government banking franchise, improving asset quality metrics, and expanding digital banking initiatives. FY25 marked continued improvement in Gross NPA ratios and consistent profitability growth.
D34: Subsidiaries (as on 31 March 2026) | H34: Associate Companies / Units
D36: Subsidiary | E36: Ownership | H36: Associate | I36: Ownership
D37: Canbank Venture Capital Fund Ltd. | E37: 1 | H37: Can Fin Homes Ltd. | I37: 0.2999
D38: Canbank Financial Services Ltd. | E38: 1 | H38: Kerala Gramin Bank | I38: 0.35
D39: Canara Bank Securities Ltd. | E39: 1 | H39: Karnataka Grameena Bank | I39: 0.35
D40: Canbank Factors Ltd. | E40: 0.7 | H40: Canara Robeco Asset Management Company Ltd. | I40: 0.38
D41: Canbank Computer Services Ltd. | E41: 0.6914 | H41: Canara HSBC Life Insurance Company Ltd. | I41: 0.365
D42: Canara Tanzania Ltd. (In Liquidation) | E42: 1 | H42: Joint Venture | I42: Ownership
D43: CRMF Trustee Private Ltd. | E43: 0.51 | H43: Higher Education Financing Agency (HEFA) | I43: 0.0909

Sheet Shareholding 
B1: CANARA BANK
B2: Shareholding Pattern – Promoter & Public Shareholding
B3: As at March 31, 2026
B5: KEY NOTE — GOVERNMENT CONTROLLED PSU BANK
B6: Canara Bank is a Public Sector Bank under the Banking Companies (Acquisition and Transfer of Undertakings) Act, 1970. The Government of India is the Promoter and majority shareholder, holding 62.93% of the Bank's equity share capital as on March 31, 2026. The remaining 37.07% is held by public shareholders including domestic institutions, mutual funds, insurance companies, FPIs, corporates and retail investors.
B14: (A) PROMOTER SHAREHOLDING
B16: Sr. No. | C16: Promoter | D16: Category | E16: No. of Shares Held | F16: % Holding
B17: 1 | C17: Government of India | D17: Promoter | E17: 5707355738 | F17: 0.6293
B19: TOTAL PROMOTER SHAREHOLDING
B21: Category | C21: No. of Shares Held | D21: % Holding
B22: Government of India | C22: 5707355738 | D22: 0.6293
B24: (B) PUBLIC SHAREHOLDING
B26: Category | C26: No. of Shares Held | D26: % Holding
B27: Public Shareholders | C27: 3363295522 | D27: 0.3707
B29: PUBLIC SHAREHOLDERS INCLUDE
B31: Sr. No. | C31: Category
B32: 1 | C32: Mutual Funds
B33: 2 | C33: Insurance Companies
B34: 3 | C34: Foreign Portfolio Investors (FPIs)
B35: 4 | C35: Domestic Financial Institutions
B36: 5 | C36: Banks & Financial Institutions
B37: 6 | C37: Bodies Corporate
B38: 7 | C38: Retail Investors
B39: 8 | C39: HUFs
B40: 9 | C40: NRIs
B41: 10 | C41: Trusts & Others
B43: SUMMARY OF SHARE CAPITAL
B45: Particulars | C45: No. of Shares | D45: % Holding
B46: Government of India (Promoter) | C46: 5707355738 | D46: 0.6293
B47: Public Shareholders | C47: 3363295522 | D47: 0.3707
B48: Total Equity Share Capital | C48: 9070651260 | D48: 1
B50: DEMAT HOLDING STRUCTURE
B52: Category | C52: No. of Shares | D52: % of Issued Capital
B53: NSDL | C53: 2978667477 | D53: 0.3284
B54: CDSL | C54: 6071230638 | D54: 0.6693
B55: Physical | C55: 20753145 | D55: 0.0023
B56: Total | C56: 9070651260 | D56: 1

Sheet Consolidated FS
B2: Audited Consolidated Profit and Loss Account (For the year ended) | K2: Audited Consolidated Balance Sheet (As of March 31st) | S2: Audited Consolidated Cash Flow Statement
B3: Particulars (₹ in crore) | C3: 2021 | D3: 2022 | E3: 2023 | F3: 2024 | G3: 2025 | K3: Capital and Liabilities (₹ in crore) | L3: 2021 | M3: 2022 | N3: 2023 | O3: 2024 | P3: 2025 | S3: Particulars (₹ in crore) | T3: 2021 | U3: 2022 | V3: 2023 | W3: 2024 | X3: 2025
B4: I. INCOME | K4: Capital | L4: 1814 | M4: 1814 | N4: 1814 | O4: 1814 | P4: 1814 | S4: Net Profit Before Taxes | T4: 6124.83 | U4: 11254.75 | V4: 15278.57 | W4: 17539.62 | X4: 23603.11
B5: Interest Earned | C5: 70613.79 | D5: 85884.73 | E5: 110518.75 | F5: 121601.11 | G5: 126371.2 | K5: Employees' Stock Options Outstanding | L5: 0 | M5: 0 | N5: 0 | O5: 0 | P5: 0 | S5: Adjustments for:
B6: Other Income | C6: 23643.1 | D6: 25325.04 | E6: 28646.18 | F6: 31056.77 | G6: 26712.02 | K6: Reserves and Surplus | L6: 68147 | M6: 76240 | N6: 90319 | O6: 103603 | P6: 115891 | S6: Depreciation | T6: 0 | U6: 0 | V6: 0 | W6: 0 | X6: 0
B7: Total Income | C7: 94256.88 | D7: 111209.76 | E7: 139164.94 | F7: 152657.89 | G7: 153083.22 | K7: Deposits | L7: 1086341 | M7: 1179086 | N7: 1312242 | O7: 1456495 | P7: 156833 | S7: (Profit) / Loss on sale of Investments | T7: 0 | U7: 0 | V7: 0 | W7: 0 | X7: 0
B8: II. EXPENDITURE | K8: Borrowings | L8: 46285 | M8: 58073 | N8: 57538 | O8: 89665 | P8: 155288 | S8: Provision for NPAs & Others | T8: 0 | U8: 0 | V8: 0 | W8: 0 | X8: 0
B9: Interest Expended | C9: 43035.47 | D9: 52990.06 | E9: 72117.59 | F9: 82680.68 | G9: 89137.52 | K9: Policyholders' Funds | L9: 0 | M9: 0 | N9: 0 | O9: 0 | P9: 0 | S9: Operating Profit before WC Changes | T9: 0 | U9: 0 | V9: 0 | W9: 0 | X9: 0
B10: Operating Expenses | C10: 27923.7 | D10: 30245.42 | E10: 37336.87 | F10: 38188.56 | G10: 31141.87 | K10: Other Liabilities and Provisions | L10: 56202 | M10: 65816 | N10: 73104 | O10: 80950 | P10: 45999 | S10: Changes in Working Capital:
B11: Provisions & Contingencies | C11: 17502.62 | D11: 17166.48 | E11: 14928.13 | F11: 14452.67 | G11: 13852.61 | K11: Total Liabilities | L11: 1258789 | M11: 1381030 | N11: 1535018 | O11: 1732527 | P11: 1887325 | S11: (Increase) / Decrease in Investments | T11: 0 | U11: 0 | V11: 0 | W11: 0 | X11: 0
B12: Total Expenditure | C12: 88461.79 | D12: 100401.97 | E12: 124382.58 | F12: 135321.9 | G12: 134131.99 | S12: (Increase) / Decrease in Advances | T12: 0 | U12: 0 | V12: 0 | W12: 0 | X12: 0
B13: III. PROFIT / LOSS | K13: Assets | S13: Increase / (Decrease) in Deposits | T13: 0 | U13: 0 | V13: 0 | W13: 0 | X13: 0
B14: Profit before Tax | C14: 9145.01 | D14: 14426.66 | E14: 20000.33 | F14: 22336.02 | G14: 24681.46 | K14: Cash and Balances with RBI | L14: 47532 | M14: 51074 | N14: 67707 | O14: 86837 | P14: 50762 | S14: Net Cash from Operating Activities | T14: 918.99 | U14: -39977.87 | V14: 15046.5 | W14: 60668.58 | X14: 7941.94
B15: Less: Provision for Taxes | C15: 3349.91 | D15: 3618.86 | E15: 5217.2 | F15: 5689.03 | G15: 5730.23 | K15: Balances with Banks & Money at Call | L15: 0 | M15: 0 | N15: 0 | O15: 0 | P15: 0 | S15: Net Cash from Investing Activities | T15: -1255.88 | U15: -1237.8 | V15: -1748 | W15: -2461.24 | X15: -2812.2
B16: NET PROFIT AFTER TAX | C16: 5795.1 | D16: 10807.8 | E16: 14782.36 | F16: 17335.99 | G16: 18951.23 | K16: Investments | L16: 311347 | M16: 352893 | N16: 399207 | O16: 428024 | P16: 407389 | S16: Net Cash from Financing Activities | T16: 4035.45 | U16: 445.36 | V16: -3834.47 | W16: -3505.99 | X16: -4794.78
K17: Advances | L17: 872374 | M17: 974088 | N17: 1038185 | O17: 1191269 | P17: 1403374 | S17: Net Change in Cash & Equivalents | T17: 3525.06 | U17: -40688.61 | V17: 9461.87 | W17: 54725.42 | X17: 440.32
K18: Fixed Assets | L18: 11447 | M18: 10334 | N18: 12184 | O18: 10302 | P18: 10595 | S18: Opening Cash & Equivalents | T18: 178866.37 | U18: 182391.43 | V18: 141702.82 | W18: 151164.69 | X18: 205890.11
K19: Other Assets | L19: 16089 | M19: 19641 | N19: 17735 | O19: 16095 | P19: 15205 | S19: Closing Cash & Equivalents | T19: 182391.43 | U19: 141702.82 | V19: 151164.69 | W19: 205890.11 | X19: 206330.43
K20: Goodwill on Consolidation | L20: 0 | M20: 0 | N20: 0 | O20: 0 | P20: 0
K21: Total Assets | L21: 1258789 | M21: 1381030 | N21: 1535018 | O21: 1732527 | P21: 1887325
K23: Contingent Liabilities | L23: 0 | M23: 0 | N23: 0 | O23: 0 | P23: 0
K24: Bills for Collection | L24: 0 | M24: 0 | N24: 0 | O24: 0 | P24: 0

Sheet Stock Analysis
B1: Stock Analysis
B10: Recommendation: | I10: Financial Year | J10: Total Income (₹ Cr) | K10: PAT (₹ Cr) | L10: Total Income Change (%) | M10: PAT Change (%)
B11: BUY - Canara Bank is one of India's largest public sector banks, delivering consistent improvement in profitability, asset quality, and return ratios over FY2021–25. The bank reported FY25 Net Profit of ₹18,951 Cr (up 9.3% YoY) on Total Income of ₹1,53,083 Cr, with ROE of 15.9% and ROA of 1.0%. Gross NPA improved to 4.23% (from ~8.4% in FY21) reflecting strong credit discipline. CASA ratio stands at 33.5% and NIM at 2.17%. The bank's capital adequacy remains comfortable with Tier-1 CAR at 14.6%. At CMP ₹135, Canara trades at 1.04x FY25 P/B vs peer median of ~1.01x fairly valued with upside potential as ROE improves toward 17%+ in FY27E. Key risks: NPA re-emergence, deposit repricing pressure, and slower-than-expected credit growth in the agriculture/MSME book. | I11: FY 2024-25 | J11: ='Consolidated FS'!G7 -> 153083.22 | K11: ='Consolidated FS'!G16 -> 18951.23 | L11: =(J11-J12)/J12 -> 0.0027861645 | M11: =(K11-K12)/K12 -> 0.093172643
I12: FY 2023-24 | J12: ='Consolidated FS'!F7 -> 152657.89 | K12: ='Consolidated FS'!F16 -> 17335.99 | L12: =(J12-J13)/J13 -> 0.096956532 | M12: =(K12-K13)/K13 -> 0.17274847
I13: FY 2022-23 | J13: ='Consolidated FS'!E7 -> 139164.94 | K13: ='Consolidated FS'!E16 -> 14782.36 | L13: =(J13-J14)/J14 -> 0.25137344 | M13: =(K13-K14)/K14 -> 0.36774922
I14: FY 2021-22 | J14: ='Consolidated FS'!D7 -> 111209.76 | K14: ='Consolidated FS'!D16 -> 10807.8 | L14: =(J14-J15)/J15 -> 0.17985828 | M14: =(K14-K15)/K15 -> 0.86498939
I15: FY 2020-21 | J15: ='Consolidated FS'!C7 -> 94256.88 | K15: ='Consolidated FS'!C16 -> 5795.1 | L15: 0 | M15: 0

Sheet Assumptions 
C2: Actual | H2: Average | I2: Estimated
C3: 2021 | D3: =C3+1 -> 2022 | E3: =D3+1 -> 2023 | F3: =G3-1 -> 2024 | G3: 2025 | I3: =G3+1 -> 2026 | J3: =I3+1 -> 2027 | K3: =J3+1 -> 2028 | L3: =K3+1 -> 2029 | M3: =L3+1 -> 2030
B4: Assumptions
B5: Loan Growth % | D5: =('Consolidated FS'!M17-'Consolidated FS'!L17)/'Consolidated FS'!L17 -> 0.11659449 | E5: =('Consolidated FS'!N17-'Consolidated FS'!M17)/'Consolidated FS'!M17 -> 0.065802063 | F5: =('Consolidated FS'!O17-'Consolidated FS'!N17)/'Consolidated FS'!N17 -> 0.14745349 | G5: =('Consolidated FS'!P17-'Consolidated FS'!O17)/'Consolidated FS'!O17 -> 0.17804963 | H5: =MEDIAN(D5:G5) -> 0.13202399 | I5: =H5+V5 -> 0.12561919 | J5: =I5+$V$5 -> 0.11921439 | K5: =J5+$V$5 -> 0.1128096 | L5: =K5+$V$5 -> 0.1064048 | M5: =L5+$V$5 -> 0.1 | P5: Terminal Growth | R5: 0.1 | T5: Annual Step Down | V5: =-(H5-R5)/5 -> -0.0064047977
B6: Deposit Growth % | D6: =('Consolidated FS'!M7-'Consolidated FS'!L7)/'Consolidated FS'!L7 -> 0.085373745 | E6: =('Consolidated FS'!N7-'Consolidated FS'!M7)/'Consolidated FS'!M7 -> 0.11293154 | F6: =('Consolidated FS'!O7-'Consolidated FS'!N7)/'Consolidated FS'!N7 -> 0.10992866 | G6: =('Consolidated FS'!P7-'Consolidated FS'!O7)/'Consolidated FS'!O7 -> -0.89232164 | H6: =MEDIAN(D6:G6) -> 0.097651201 | I6: =I5-$R$6 -> 0.11561919 | J6: =J5-$R$6 -> 0.10921439 | K6: =K5-$R$6 -> 0.1028096 | L6: =L5-$R$6 -> 0.096404798 | M6: =M5-$R$6 -> 0.09 | P6: Spread to Loan Growth | R6: 0.01
B7: NIM % | D7: =('Consolidated FS'!D5-'Consolidated FS'!D9)/AVERAGE('Consolidated FS'!M17+'Consolidated FS'!M16+'Consolidated FS'!M15,'Consolidated FS'!L17+'Consolidated FS'!L16+'Consolidated FS'!L15) -> 0.026203564 | E7: =('Consolidated FS'!E5-'Consolidated FS'!E9)/AVERAGE('Consolidated FS'!N17+'Consolidated FS'!N16+'Consolidated FS'!N15,'Consolidated FS'!M17+'Consolidated FS'!M16+'Consolidated FS'!M15) -> 0.027782908 | F7: =('Consolidated FS'!F5-'Consolidated FS'!F9)/AVERAGE('Consolidated FS'!O17+'Consolidated FS'!O16+'Consolidated FS'!O15,'Consolidated FS'!N17+'Consolidated FS'!N16+'Consolidated FS'!N15) -> 0.025465777 | G7: =('Consolidated FS'!G5-'Consolidated FS'!G9)/AVERAGE('Consolidated FS'!P17+'Consolidated FS'!P16+'Consolidated FS'!P15,'Consolidated FS'!O17+'Consolidated FS'!O16+'Consolidated FS'!O15) -> 0.021710246 | H7: =MEDIAN(D7:G7) -> 0.025834671 | I7: =G7 -> 0.021710246 | J7: =I7+$V$7 -> 0.020960246 | K7: =J7+$V$7 -> 0.020210246 | L7: =K7+$V$7 -> 0.019460246 | M7: =L7+$V$7 -> 0.018710246 | P7: Terminal NIM | R7: =G7-0.003 -> 0.018710246 | T7: Annual Step Down | V7: =-(G7-R7)/4 -> -0.00075
B8: Cost to Income % | C8: ='Consolidated FS'!C10/'Consolidated FS'!C7 -> 0.29625105 | D8: ='Consolidated FS'!D10/'Consolidated FS'!D7 -> 0.27196732 | E8: ='Consolidated FS'!E10/'Consolidated FS'!E7 -> 0.26829221 | F8: ='Consolidated FS'!F10/'Consolidated FS'!F7 -> 0.25015779 | G8: ='Consolidated FS'!G10/'Consolidated FS'!G7 -> 0.20343098 | H8: =MEDIAN(D8:G8) -> 0.259225 | I8: =H8+V8 -> 0.24738 | J8: =I8+$V$8 -> 0.235535 | K8: =J8+$V$8 -> 0.22369 | L8: =K8+$V$8 -> 0.211845 | M8: =L8+$V$8 -> 0.2 | P8: Terminal CTI | R8: 0.2 | T8: Annual Step Down | V8: =-(H8-R8)/5 -> -0.011845
B9: Credit Cost % | D9: ='Consolidated FS'!D11/AVERAGE('Consolidated FS'!M17,'Consolidated FS'!L17) -> 0.018593916 | E9: ='Consolidated FS'!E11/AVERAGE('Consolidated FS'!N17,'Consolidated FS'!M17) -> 0.014837082 | F9: ='Consolidated FS'!F11/AVERAGE('Consolidated FS'!O17,'Consolidated FS'!N17) -> 0.01296521 | G9: ='Consolidated FS'!G11/AVERAGE('Consolidated FS'!P17,'Consolidated FS'!O17) -> 0.010677854 | H9: =AVERAGE(D9:G9) -> 0.014268516 | I9: =H9+V9 -> 0.013414813 | J9: =I9+$V$9 -> 0.012561109 | K9: =J9+$V$9 -> 0.011707406 | L9: =K9+$V$9 -> 0.010853703 | M9: =L9+$V$9 -> 0.01 | P9: Terminal Cost | R9: 0.01 | T9: Annual Step Down | V9: =-(H9-R9)/5 -> -0.00085370316
B10: Tax Rate % | C10: ='Consolidated FS'!C15/'Consolidated FS'!C14 -> 0.36631015 | D10: ='Consolidated FS'!D15/'Consolidated FS'!D14 -> 0.25084531 | E10: ='Consolidated FS'!E15/'Consolidated FS'!E14 -> 0.2608557 | F10: ='Consolidated FS'!F15/'Consolidated FS'!F14 -> 0.25470205 | G10: ='Consolidated FS'!G15/'Consolidated FS'!G14 -> 0.23216738 | H10: =AVERAGE(C10:G10) -> 0.27297612 | I10: =$H$10 -> 0.27297612 | J10: =$H$10 -> 0.27297612 | K10: =$H$10 -> 0.27297612 | L10: =$H$10 -> 0.27297612 | M10: =$H$10 -> 0.27297612
B11: Dividend Payout % | C11: =1988.22/'Consolidated FS'!C16 -> 0.3430864 | D11: =1988.22/'Consolidated FS'!D16 -> 0.18396158 | E11: =1988.22/'Consolidated FS'!E16 -> 0.1344995 | F11: =1988.22/'Consolidated FS'!F16 -> 0.11468742 | G11: =1988.22/'Consolidated FS'!G16 -> 0.10491245 | H11: =MEDIAN(C11:G11) -> 0.1344995 | I11: =(1988/I29)+$V$11 -> 0.11582359 | J11: =1988.22/J29 -> 0.073629245 | K11: =1988.22/K29 -> 0.06580151 | L11: =1988.22/L29 -> 0.059063391 | M11: =1988.22/M29 -> 0.053256586 | P11: Terminal Payout | R11: 0.3 | T11: Annual Step Down | V11: =(R11-H11)/5 -> 0.0331001
B12: Yield on Earning Assets % | D12: ='Consolidated FS'!D5 / AVERAGE('Consolidated FS'!M17+'Consolidated FS'!M16, 'Consolidated FS'!L17+'Consolidated FS'!L16) -> 0.068414913 | E12: ='Consolidated FS'!E5 / AVERAGE('Consolidated FS'!N17+'Consolidated FS'!N16, 'Consolidated FS'!M17+'Consolidated FS'!M16) -> 0.079959361 | F12: ='Consolidated FS'!F5 / AVERAGE('Consolidated FS'!O17+'Consolidated FS'!O16, 'Consolidated FS'!N17+'Consolidated FS'!N16) -> 0.079564044 | G12: ='Consolidated FS'!G5 / AVERAGE('Consolidated FS'!P17+'Consolidated FS'!P16, 'Consolidated FS'!O17+'Consolidated FS'!O16) -> 0.073684628
B14: Advances (Loans) | C14: ='Consolidated FS'!L17 -> 872374 | D14: ='Consolidated FS'!M17 -> 974088 | E14: ='Consolidated FS'!N17 -> 1038185 | F14: ='Consolidated FS'!O17 -> 1191269 | G14: ='Consolidated FS'!P17 -> 1403374 | I14: =G14*(1+I5) -> 1579664.7 | J14: =I14*(1+J5) -> 1767983.5 | K14: =J14*(1+K5) -> 1967429 | L14: =K14*(1+L5) -> 2176772.9 | M14: =L14*(M5+1) -> 2394450.1
B15: Deposits | C15: ='Consolidated FS'!L7 -> 1086341 | D15: ='Consolidated FS'!M7 -> 1179086 | E15: ='Consolidated FS'!N7 -> 1312242 | F15: ='Consolidated FS'!O7 -> 1456495 | G15: ='Consolidated FS'!P7 -> 156833 | I15: =G15*(I6+1) -> 174965.9 | J15: =I15*(1+J6) -> 194074.7 | K15: =J15*(1+K6) -> 214027.44 | L15: =K15*(1+L6) -> 234660.71 | M15: =L15*(1+M6) -> 255780.18
B16: Borrowings | C16: ='Consolidated FS'!L8 -> 46285 | D16: ='Consolidated FS'!M8 -> 58073 | E16: ='Consolidated FS'!N8 -> 57538 | F16: ='Consolidated FS'!O8 -> 89665 | G16: ='Consolidated FS'!P8 -> 155288 | I16: =I14*0.18 -> 284339.65 | J16: =J14*0.18 -> 318237.03 | K16: =K14*0.18 -> 354137.22 | L16: =L14*0.18 -> 391819.11 | M16: =M14*0.18 -> 431001.03
B18: Interest Income | C18: ='Consolidated FS'!C5 -> 70613.79 | D18: ='Consolidated FS'!D5 -> 85884.73 | E18: ='Consolidated FS'!E5 -> 110518.75 | F18: ='Consolidated FS'!F5 -> 121601.11 | G18: ='Consolidated FS'!G5 -> 126371.2 | I18: =((I14+G14)/2)*(('Consolidated FS'!P15+'Consolidated FS'!P16+'Consolidated FS'!P17)/'Consolidated FS'!P17)*I7+I19 -> 78784.868 | J18: =((J14+I14)/2)*(('Consolidated FS'!P15+'Consolidated FS'!P16+'Consolidated FS'!P17)/'Consolidated FS'!P17)*J7+J19 -> 91874.595 | K18: =((K14+J14)/2)*(('Consolidated FS'!P15+'Consolidated FS'!P16+'Consolidated FS'!P17)/'Consolidated FS'!P17)*K7+K19 -> 100532.42 | L18: =((L14+K14)/2)*(('Consolidated FS'!P15+'Consolidated FS'!P16+'Consolidated FS'!P17)/'Consolidated FS'!P17)*L7+L19 -> 109333.62 | M18: =((M14+L14)/2)*(('Consolidated FS'!P15+'Consolidated FS'!P16+'Consolidated FS'!P17)/'Consolidated FS'!P17)*M7+M19 -> 118172.68
B19: Interest Expense | C19: ='Consolidated FS'!C9 -> 43035.47 | D19: ='Consolidated FS'!D9 -> 52990.06 | E19: ='Consolidated FS'!E9 -> 72117.59 | F19: ='Consolidated FS'!F9 -> 82680.68 | G19: ='Consolidated FS'!G9 -> 89137.52 | I19: =((I15 + I16 + G15 + G16) / 2) * WACC!$F$15 -> 37003.58 | J19: =((J15 + J16 + I15 + I16) / 2) * WACC!$F$15 -> 46606.275 | K19: =((K15 + K16 + J15 + J16) / 2) * WACC!$F$15 -> 51827.999 | L19: =((L15 + L16 + K15 + K16) / 2) * WACC!$F$15 -> 57304.383 | M19: =((M15 + M16 + L15 + L16) / 2) * WACC!$F$15 -> 62994.15
B20: NII | C20: =C18-C19 -> 27578.32 | D20: =D18-D19 -> 32894.67 | E20: =E18-E19 -> 38401.16 | F20: =F18-F19 -> 38920.43 | G20: =G18-G19 -> 37233.68 | I20: =I18-I19 -> 41781.288 | J20: =J18-J19 -> 45268.32 | K20: =K18-K19 -> 48704.418 | L20: =L18-L19 -> 52029.232 | M20: =M18-M19 -> 55178.527
B21: Other Income | C21: ='Consolidated FS'!C6 -> 23643.1 | D21: ='Consolidated FS'!D6 -> 25325.04 | E21: ='Consolidated FS'!E6 -> 28646.18 | F21: ='Consolidated FS'!F6 -> 31056.77 | G21: ='Consolidated FS'!G6 -> 26712.02 | I21: =G21*(1+R21+V21) -> 28723.854 | J21: =I21*(1+R21+2*V21) -> 30820.315 | K21: =J21*(1+R21+3*V21) -> 32998.012 | L21: =K21*(1+R21+4*V21) -> 35252.731 | M21: =L21*(1+R21+5*V21) -> 37579.411 | P21: Other Income growth | R21: =MEDIAN((D21-C21)/C21,(E21-D21)/D21,(F21-E21)/E21,(G21-F21)/F21) -> 0.077644606 | T21: Annual Step Down | V21: =-(R21-WACC!$C$14)/5 -> -0.0023289213
B22: Total Income | C22: ='Consolidated FS'!C7 -> 94256.88 | D22: ='Consolidated FS'!D7 -> 111209.76 | E22: ='Consolidated FS'!E7 -> 139164.94 | F22: ='Consolidated FS'!F7 -> 152657.89 | G22: ='Consolidated FS'!G7 -> 153083.22 | I22: =I21+I20 -> 70505.142 | J22: =J21+J20 -> 76088.635 | K22: =K21+K20 -> 81702.43 | L22: =L21+L20 -> 87281.963 | M22: =M21+M20 -> 92757.938
B24: Operating Expense | C24: ='Consolidated FS'!C10 -> 27923.7 | D24: ='Consolidated FS'!D10 -> 30245.42 | E24: ='Consolidated FS'!E10 -> 37336.87 | F24: ='Consolidated FS'!F10 -> 38188.56 | G24: ='Consolidated FS'!G10 -> 31141.87 | I24: =I22*I8 -> 17441.562 | J24: =J22*J8 -> 17921.537 | K24: =K22*K8 -> 18276.017 | L24: =L22*L8 -> 18490.247 | M24: =M22*M8 -> 18551.588
B25: Provisions | C25: ='Consolidated FS'!C11 -> 17502.62 | D25: ='Consolidated FS'!D11 -> 17166.48 | E25: ='Consolidated FS'!E11 -> 14928.13 | F25: ='Consolidated FS'!F11 -> 14452.67 | G25: ='Consolidated FS'!G11 -> 13852.61 | I25: =((I14+G14)/2)*I9 -> 20008.453 | J25: =((J14+I14)/2)*J9 -> 21025.088 | K25: =((K14+J14)/2)*K9 -> 21865.996 | L25: =((L14+K14)/2)*L9 -> 22489.968 | M25: =((M14+L14)/2)*M9 -> 22856.115
B26: PBT | C26: ='Consolidated FS'!C14 -> 9145.01 | D26: ='Consolidated FS'!D14 -> 14426.66 | E26: ='Consolidated FS'!E14 -> 20000.33 | F26: ='Consolidated FS'!F14 -> 22336.02 | G26: ='Consolidated FS'!G14 -> 24681.46 | I26: =I22-I24-I25 -> 33055.127 | J26: =J22-J24-J25 -> 37142.011 | K26: =K22-K24-K25 -> 41560.418 | L26: =L22-L24-L25 -> 46301.747 | M26: =M22-M24-M25 -> 51350.235
B27: Tax | C27: ='Consolidated FS'!C15 -> 3349.91 | D27: ='Consolidated FS'!D15 -> 3618.86 | E27: ='Consolidated FS'!E15 -> 5217.2 | F27: ='Consolidated FS'!F15 -> 5689.03 | G27: ='Consolidated FS'!G15 -> 5730.23 | I27: =I26*I10 -> 9023.2603 | J27: =J26*J10 -> 10138.882 | K27: =K26*K10 -> 11345.001 | L27: =L26*L10 -> 12639.271 | M27: =M26*M10 -> 14017.388
B29: PAT | C29: ='Consolidated FS'!C16 -> 5795.1 | D29: ='Consolidated FS'!D16 -> 10807.8 | E29: ='Consolidated FS'!E16 -> 14782.36 | F29: ='Consolidated FS'!F16 -> 17335.99 | G29: ='Consolidated FS'!G16 -> 18951.23 | I29: =I26-I27 -> 24031.867 | J29: =J26-J27 -> 27003.129 | K29: =K26-K27 -> 30215.416 | L29: =L26-L27 -> 33662.476 | M29: =M26-M27 -> 37332.847

Sheet Equity Schedule 
C2: 2021 | D2: =C2+1 -> 2022 | E2: =D2+1 -> 2023 | F2: =E2+1 -> 2024 | G2: =F2+1 -> 2025 | H2: =G2+1 -> 2026 | I2: =H2+1 -> 2027 | J2: =I2+1 -> 2028 | K2: =J2+1 -> 2029 | L2: =K2+1 -> 2030
B3: Opening Equity | C3: ='Consolidated FS'!L4+'Consolidated FS'!L6 -> 69961 | D3: =C7 -> 73767.88 | E3: =D7 -> 82587.46 | F3: =E7 -> 95381.6 | G3: =F7 -> 110729.37 | H3: =G7 -> 127692.38 | I3: =H7 -> 148940.79 | J3: =I7 -> 173955.7 | K3: =J7 -> 202182.89 | L3: =K7 -> 233857.15
B4: PAT | C4: ='Assumptions '!C29 -> 5795.1 | D4: ='Assumptions '!D29 -> 10807.8 | E4: ='Assumptions '!E29 -> 14782.36 | F4: ='Assumptions '!F29 -> 17335.99 | G4: ='Assumptions '!G29 -> 18951.23 | H4: ='Assumptions '!I29 -> 24031.867 | I4: ='Assumptions '!J29 -> 27003.129 | J4: ='Assumptions '!K29 -> 30215.416 | K4: ='Assumptions '!L29 -> 33662.476 | L4: ='Assumptions '!M29 -> 37332.847
B5: Dividend Paid | C5: ='Assumptions '!C29*'Assumptions '!C11 -> 1988.22 | D5: ='Assumptions '!D29*'Assumptions '!D11 -> 1988.22 | E5: ='Assumptions '!E29*'Assumptions '!E11 -> 1988.22 | F5: ='Assumptions '!F29*'Assumptions '!F11 -> 1988.22 | G5: ='Assumptions '!G29*'Assumptions '!G11 -> 1988.22 | H5: ='Assumptions '!I29*'Assumptions '!I11 -> 2783.4572 | I5: ='Assumptions '!J29*'Assumptions '!J11 -> 1988.22 | J5: ='Assumptions '!K29*'Assumptions '!K11 -> 1988.22 | K5: ='Assumptions '!L29*'Assumptions '!L11 -> 1988.22 | L5: ='Assumptions '!M29*'Assumptions '!M11 -> 1988.22
B6: Retained Earnings | C6: =C4-C5 -> 3806.88 | D6: =D4-D5 -> 8819.58 | E6: =E4-E5 -> 12794.14 | F6: =F4-F5 -> 15347.77 | G6: =G4-G5 -> 16963.01 | H6: =H4-H5 -> 21248.41 | I6: =I4-I5 -> 25014.909 | J6: =J4-J5 -> 28227.196 | ... L6: =L4-L5 -> 35344.627
B7: Closing Equity | C7: =C3+C6 -> 73767.88 | D7: =D3+D6 -> 82587.46 | E7: =E3+E6 -> 95381.6 | F7: =F3+F6 -> 110729.37 | G7: =G3+G6 -> 127692.38 | H7: =H3+H6 -> 148940.79 | I7: =I3+I6 -> 173955.7 | J7: =J3+J6 -> 202182.89 | ... L7: =L3+L6 -> 269201.78
B8: Average Equity | C8: =(C3+C7)/2 -> 71864.44 | D8: =(D3+D7)/2 -> 78177.67 | E8: =(E3+E7)/2 -> 88984.53 | F8: =(F3+F7)/2 -> 103055.49 | G8: =(G3+G7)/2 -> 119210.88 | H8: =(H3+H7)/2 -> 138316.58 | I8: =(I3+I7)/2 -> 161448.24 | J8: =(J3+J7)/2 -> 188069.3 | ... L8: =(L3+L7)/2 -> 251529.46
B9: RoE | C9: =C4/C8 -> 0.080639326 | D9: =D4/D8 -> 0.13824664 | E9: =E4/E8 -> 0.16612281 | F9: =F4/F8 -> 0.16821996 | G9: =G4/G8 -> 0.15897233 | H9: =H4/H8 -> 0.17374538 | I9: =I4/I8 -> 0.16725564 | J9: =J4/J8 -> 0.16066108 | ... L9: =L4/L8 -> 0.14842336
B10: Ke | C10: =WACC!$C$17 -> 0.17086652 | D10: =WACC!$C$17 -> 0.17086652 | E10: =WACC!$C$17 -> 0.17086652 | F10: =WACC!$C$17 -> 0.17086652 | G10: =WACC!$C$17 -> 0.17086652 | H10: =WACC!$C$17 -> 0.17086652 | I10: =WACC!$C$17 -> 0.17086652 | J10: =WACC!$C$17 -> 0.17086652 | ... L10: =WACC!$C$17 -> 0.17086652
B11: Excess Returns | C11: =C9-C10 -> -0.090227197 | D11: =D9-D10 -> -0.032619885 | E11: =E9-E10 -> -0.0047437147 | F11: =F9-F10 -> -0.0026465585 | G11: =G9-G10 -> -0.011894197 | H11: =H9-H10 -> 0.0028788533 | I11: =I9-I10 -> -0.0036108857 | J11: =J9-J10 -> -0.010205444 | ... L11: =L9-L10 -> -0.022443167

Sheet Residual Income Schedule 
B2: B | C2: C | D2: D | E2: E | F2: F | G2: G | J2: CANBK.NS
B3: Item | C3: 2026 | D3: 2027 | E3: 2028 | F3: 2029 | G3: 2030
B4: Opening Equity | C4: ='Equity Schedule '!H3 -> 127692.38 | D4: ='Equity Schedule '!I3 -> 148940.79 | E4: ='Equity Schedule '!J3 -> 173955.7 | F4: ='Equity Schedule '!K3 -> 202182.89 | G4: ='Equity Schedule '!L3 -> 233857.15 | J4: fullExchangeName | K4: NSE
B5: PAT | C5: ='Equity Schedule '!H4 -> 24031.867 | D5: ='Equity Schedule '!I4 -> 27003.129 | E5: ='Equity Schedule '!J4 -> 30215.416 | F5: ='Equity Schedule '!K4 -> 33662.476 | G5: ='Equity Schedule '!L4 -> 37332.847 | J5: instrumentType | K5: EQUITY
B6: Capital Charge | C6: ='Equity Schedule '!H3*WACC!$C$17 -> 21818.353 | D6: ='Equity Schedule '!I3*WACC!$C$17 -> 25448.995 | E6: ='Equity Schedule '!J3*WACC!$C$17 -> 29723.205 | F6: ='Equity Schedule '!K3*WACC!$C$17 -> 34546.288 | G6: ='Equity Schedule '!L3*WACC!$C$17 -> 39958.358 | J6: firstTradeDate | K6: 820454400
B7: Residual Income | C7: =C5-C6 -> 2213.5141 | D7: =D5-D6 -> 1554.1341 | E7: =E5-E6 -> 492.21078 | F7: =F5-F6 -> -883.81214 | G7: =G5-G6 -> -2625.511 | J7: regularMarketTime | K7: 1780908425
B8: Discount Factor | C8: =1/(1+WACC!$C$17)^1 -> 0.85406832 | D8: =1/(1+WACC!$C$17)^2 -> 0.72943269 | E8: =1/(1+WACC!$C$17)^3 -> 0.62298535 | F8: =1/(1+WACC!$C$17)^4 -> 0.53207205 | G8: =1/(1+WACC!$C$17)^5 -> 0.45442588
B9: PV of RI | C9: =C7*C8 -> 1890.4923 | D9: =D7*D8 -> 1133.6362 | E9: =E7*E8 -> 306.64011 | F9: =F7*F8 -> -470.25174 | G9: =G7*G8 -> -1193.1001 | J9: gmtoffset | K9: 19800
J10: timezone | K10: IST
B11: Terminal Growth | C11: =WACC!$C$14 -> 0.066 | J11: exchangeTimezoneName | K11: Asia/Kolkata
B12: Terminal RI | C12: =G7*(1+$C$11)/(WACC!$C$17-$C$11) -> -26689.115 | J12: regularMarketPrice | K12: 132.5
B13: PV Terminal RI | C13: =C12*G8 -> -12128.225 | J13: fiftyTwoWeekHigh | K13: 162.9
J14: fiftyTwoWeekLow | K14: 103.55
B15: Current Book Value | C15: ='Consolidated FS'!P4+'Consolidated FS'!P6 -> 117705 | J15: shortName | K15: CANARA BANK
B16: Equity Value | C16: =C15+SUM(C9:G9)+C13 -> 107244.19
B17: Shares Outstanding | C17: 995
B18: Value Per Share | C18: =C16/C17 -> 107.78311
B20: Upside/Downside | D20: =(C18-F20)/F20 -> -0.20160661 | E20: Current Value | F20: 135

Sheet BETA 
B2: CANARA.NS | G2: NIFTY50
C3: Date | D3: Close | G3: Date | H3: Closing Price | L3: BETA
C4: 44287 | D4: 31.27 | G4: 44287 | H4: 14867.35
C5: 44291 | D5: 29.35 | E5: =(D5-D4)/D4 -> -0.061400705 | G5: 44291 | H5: 14637.8 | I5: =(H5-H4)/H4 -> -0.015439861 | L5: =SLOPE(E5:E1237,I5:I1237) -> 1.4980932
C6: 44292 | D6: 29.6 | E6: =(D6-D5)/D5 -> 0.0085178875 | G6: 44292 | H6: 14683.5 | I6: =(H6-H5)/H5 -> 0.0031220672
C7: 44293 | D7: 29.93 | E7: =(D7-D6)/D6 -> 0.011148646 | G7: 44293 | H7: 14819.05 | I7: =(H7-H6)/H6 -> 0.009231437 | L7: SUMMARY OUTPUT
C8: 44294 | D8: 29.440001 | E8: =(D8-D7)/D7 -> -0.016371526 | G8: 44294 | H8: 14873.8 | I8: =(H8-H7)/H7 -> 0.0036945689
C9: 44295 | D9: 29.75 | E9: =(D9-D8)/D8 -> 0.010529873 | G9: 44295 | H9: 14834.85 | I9: =(H9-H8)/H8 -> -0.0026187118 | L9: Regression Statistics
C10: 44298 | D10: 26.440001 | E10: =(D10-D9)/D9 -> -0.11126049 | G10: 44298 | H10: 14310.8 | I10: =(H10-H9)/H9 -> -0.035325589 | L10: Multiple R | M10: 0.58706256
C11: 44299 | D11: 27.469999 | E11: =(D11-D10)/D10 -> 0.03895608 | G11: 44299 | H11: 14504.8 | I11: =(H11-H10)/H10 -> 0.013556196 | L11: R Square | M11: 0.34464245
C12: 44301 | D12: 27.15 | E12: =(D12-D11)/D11 -> -0.011649061 | G12: 44301 | H12: 14581.45 | I12: =(H12-H11)/H11 -> 0.0052844846 | L12: Adjusted R Square | M12: 0.34411007
C13: 44302 | D13: 26.84 | E13: =(D13-D12)/D12 -> -0.011418028 | G13: 44302 | H13: 14617.85 | I13: =(H13-H12)/H12 -> 0.0024962822 | L13: Standard Error | M13: 0.01167144
C14: 44305 | D14: 25.860001 | E14: =(D14-D13)/D13 -> -0.03651265 | G14: 44305 | H14: 14359.45 | I14: =(H14-H13)/H13 -> -0.017676979 | L14: Observations | M14: 1233
C15: 44306 | D15: 25.610001 | E15: =(D15-D14)/D14 -> -0.0096674398 | G15: 44306 | H15: 14296.4 | I15: =(H15-H14)/H14 -> -0.004390823
C16: 44308 | D16: 26.049999 | E16: =(D16-D15)/D15 -> 0.017180735 | G16: 44308 | H16: 14406.15 | I16: =(H16-H15)/H15 -> 0.0076767576 | L16: ANOVA
C17: 44309 | D17: 26.1 | E17: =(D17-D16)/D16 -> 0.0019194298 | G17: 44309 | H17: 14341.35 | I17: =(H17-H16)/H16 -> -0.0044981331 | M17: df | N17: SS | O17: MS | P17: F | Q17: Significance F
C18: 44312 | D18: 27.049999 | E18: =(D18-D17)/D17 -> 0.036398423 | G18: 44312 | H18: 14485 | I18: =(H18-H17)/H17 -> 0.010016518 | L18: Regression | M18: 1 | N18: 0.08818554 | O18: 0.08818554 | P18: 647.36395 | Q18: 4.2635427e-115
C19: 44313 | D19: 27.93 | E19: =(D19-D18)/D18 -> 0.032532388 | G19: 44313 | H19: 14653.05 | I19: =(H19-H18)/H18 -> 0.011601643 | L19: Residual | M19: 1231 | N19: 0.16768991 | O19: 0.00013622251
C20: 44314 | D20: 28.620001 | E20: =(D20-D19)/D19 -> 0.024704638 | G20: 44314 | H20: 14864.55 | I20: =(H20-H19)/H19 -> 0.014433855 | L20: Total | M20: 1232 | N20: 0.25587545
C21: 44315 | D21: 27.9 | E21: =(D21-D20)/D20 -> -0.025157275 | G21: 44315 | H21: 14894.9 | I21: =(H21-H20)/H20 -> 0.00204181
C22: 44316 | D22: 27.75 | E22: =(D22-D21)/D21 -> -0.0053763305 | G22: 44316 | H22: 14631.1 | I22: =(H22-H21)/H21 -> -0.017710812 | M22: Coefficients | N22: Standard Error | O22: t Stat | P22: P-value | Q22: Lower 95% | R22: Upper 95% | S22: Lower 95.0% | T22: Upper 95.0%
C23: 44319 | D23: 27.75 | E23: =(D23-D22)/D22 -> 0 | G23: 44319 | H23: 14634.15 | I23: =(H23-H22)/H22 -> 0.00020851346 | L23: Intercept | M23: -0.00026836264 | N23: 0.00033268498 | O23: -0.80665691 | P23: 0.42001999 | Q23: -0.00092105497 | R23: 0.00038432969 | S23: -0.00092105497 | T23: 0.00038432969
C24: 44320 | D24: 28.27 | E24: =(D24-D23)/D23 -> 0.018738755 | G24: 44320 | H24: 14496.5 | I24: =(H24-H23)/H23 -> -0.0094061074 | L24: X Variable 1 | M24: 0.97558336 | N24: 0.038343357 | O24: 25.443348 | P24: 4.2635427e-115 | Q24: 0.9003578 | R24: 1.0508089 | S24: 0.9003578 | T24: 1.0508089
C25: 44321 | D25: 29.120001 | E25: =(D25-D24)/D24 -> 0.030067222 | G25: 44321 | H25: 14617.85 | I25: =(H25-H24)/H24 -> 0.0083709592
C26: 44322 | D26: 28.690001 | E26: =(D26-D25)/D25 -> -0.014766494 | G26: 44322 | H26: 14724.8 | I26: =(H26-H25)/H25 -> 0.007316411
C27: 44323 | D27: 28.860001 | E27: =(D27-D26)/D26 -> 0.0059254121 | G27: 44323 | H27: 14823.15 | I27: =(H27-H26)/H26 -> 0.0066792477
C28: 44326 | D28: 29.43 | E28: =(D28-D27)/D27 -> 0.019750509 | G28: 44326 | H28: 14942.35 | I28: =(H28-H27)/H27 -> 0.0080414227
C29: 44327 | D29: 30.02 | E29: =(D29-D28)/D28 -> 0.020047575 | G29: 44327 | H29: 14850.75 | I29: =(H29-H28)/H28 -> -0.0061302012
C30: 44328 | D30: 30.440001 | E30: =(D30-D29)/D29 -> 0.013990675 | G30: 44328 | H30: 14696.5 | I30: =(H30-H29)/H29 -> -0.010386681
C31: 44330 | D31: 29.51 | E31: =(D31-D30)/D30 -> -0.030551915 | G31: 44330 | H31: 14677.8 | I31: =(H31-H30)/H30 -> -0.0012724251
C32: 44333 | D32: 30.700001 | E32: =(D32-D31)/D31 -> 0.040325331 | G32: 44333 | H32: 14923.15 | I32: =(H32-H31)/H31 -> 0.01671576
C33: 44334 | D33: 29.33 | E33: =(D33-D32)/D32 -> -0.044625433 | G33: 44334 | H33: 15108.1 | I33: =(H33-H32)/H32 -> 0.012393443
C34: 44335 | D34: 29.280001 | E34: =(D34-D33)/D33 -> -0.0017047132 | G34: 44335 | H34: 15030.15 | I34: =(H34-H33)/H33 -> -0.0051594324
C35: 44336 | D35: 29.48 | E35: =(D35-D34)/D34 -> 0.0068305618 | G35: 44336 | H35: 14906.05 | I35: =(H35-H34)/H34 -> -0.0082567761
C36: 44337 | D36: 30.57 | E36: =(D36-D35)/D35 -> 0.036974226 | G36: 44337 | H36: 15175.3 | I36: =(H36-H35)/H35 -> 0.018063136
... C1237: 46111 | D1237: 123.45 | E1237: =(D1237-D1236)/D1236 -> -0.053660408 | G1237: 46111 | H1237: 22331.4 | I1237: =(H1237-H1236)/H1236 -> -0.021393856

Sheet WACC
B1: Weighted Average Cost of Capital
B3: Capital Structure
B4: Total Debt | C4: ='Consolidated FS'!P8 -> 155288
B5: Total Equity | C5: =SUM('Consolidated FS'!P4:P6) -> 117705
B6: Total Mix | C6: =SUM(C4:C5) -> 272993
B7: % of Debt | C7: =C4/C6 -> 0.5688351
B8: % of Equity | C8: =C5/C6 -> 0.4311649
B9: Debt to Equity | C9: =C4/C5 -> 1.3192982
B13: Cost of Equity | E13: Cost of Debt
B14: Risk free rate(Rf) | C14: 0.066
B15: Beta | C15: ='BETA '!L5 -> 1.4980932 | E15: Cost of debt* | F15: ='Consolidated FS'!G9/(AVERAGE(SUM('Consolidated FS'!O7:O8),SUM('Consolidated FS'!P7:P8))) -> 0.095935459
B16: Market risk premium | C16: 0.07 | E16: Tax rate | F16: 0.25
B17: Cost of equity | C17: =C14+C15*C16 -> 0.17086652 | E17: Cost of Debt after tax | F17: =F15*(1-F16) -> 0.071951594
B20: WACC
B21: Source | C21: Weight | D21: Cost | E21: Weighted Cost
B22: Debt | C22: =C7 -> 0.5688351 | D22: =F17 -> 0.071951594 | E22: =C22*D22 -> 0.040928592
B23: Equity | C23: =C8 -> 0.4311649 | D23: =C17 -> 0.17086652 | E23: =C23*D23 -> 0.073671647
B24: WACC | E24: =SUM(E22:E23) -> 0.11460024

Sheet Peer Comparison
B1: Peer Comparison
B2: Company | C2: Business Overview
B3: Canara Bank | C3: Canara Bank is one of India's largest PSU banks with 10,000+ branches. It offers retail, corporate, agriculture, and MSME banking. GoI holds ~62.9% stake. Known for strong rural & priority sector lending exposure.
B4: State Bank of India | C4: SBI is India's largest commercial bank by assets, deposits, and branch network (~22,000+ branches). Operates across retail, corporate, treasury, and international banking. Majority owned by GoI.
B5: Bank of Baroda | C5: Bank of Baroda is a leading PSU bank with a significant international presence across 17 countries, offering retail, SME, and corporate banking. Merged with Vijaya Bank and Dena Bank in 2019.
B6: Punjab National Bank | C6: Punjab National Bank (PNB) is one of India's oldest PSU banks. Focuses on retail, MSME, and corporate banking with digital transformation post-merger with OBC and United Bank of India.
B7: Union Bank of India | C7: Union Bank of India (formed after merger with Andhra Bank and Corporation Bank in 2020) serves retail, MSME, agriculture, and corporate customers with improving margin and asset quality profile.
B9: Attribute | C9: Canara Bank | D9: SBI | E9: Bank of Baroda | F9: PNB | G9: Union Bank | I9: Metric (FY25) | J9: Canara Bank | K9: SBI | L9: Bank of Baroda
B10: CMP (₹) | C10: 135 | D10: 1041 | E10: 284 | F10: 110 | G10: 177 | I10: CASA Ratio | J10: 0.335 | K10: 0.412 | L10: 0.388
B11: Mkt Cap (₹ Cr.) | C11: 122445 | D11: 960492 | E11: 146608 | F11: 126020 | G11: 134848 | I11: Credit-Deposit Ratio | J11: 0.763 | K11: 0.842 | L11: 0.784
B12: Total Advances (₹ Cr.) | C12: 944178 | D12: 3987695 | E12: 1076280 | F12: 956990 | G12: 936830 | I12: Cost-Income Ratio | J12: 0.452 | K12: 0.521 | L12: 0.412
B13: NII (₹ Cr.) | C13: 16543 | D13: 43005 | E13: 14218 | F13: 11175 | G13: 10842 | I13: Slippage Ratio | J13: 0.0163 | K13: 0.009 | L13: 0.018
B14: Net Profit (₹ Cr.) | C14: 18951 | D14: 67085 | E14: 19577 | F14: 10617 | G14: 13798 | I14: PCR % | J14: 0.873 | K14: 0.912 | L14: 0.945
B15: Gross NPA % | C15: 0.0423 | D15: 0.02 | E15: 0.0292 | F15: 0.04 | G15: 0.0476 | I15: Tier-1 CAR % | J15: 0.1458 | K15: 0.14 | L15: 0.131
B16: Net NPA % | C16: 0.0127 | D16: 0.0053 | E16: 0.0068 | F16: 0.004 | G16: 0.0102 | I16: ROCE % | J16: 0.0155 | K16: 0.018 | L16: 0.0138
B17: NIM % | C17: 0.02171 | D17: 0.0328 | E17: 0.031 | F17: 0.0315 | G17: 0.0305 | I17: Advances Growth % | J17: 0.1092 | K17: 0.145 | L17: 0.12
B18: CASA % | C18: 0.335 | D18: 0.412 | E18: 0.388 | F18: 0.43 | G18: 0.36 | I18: Deposits Growth % | J18: 0.063 | K18: 0.086 | L18: 0.071
B19: P/E (x) | C19: 6.46 | D19: 11.54 | E19: 7.47 | F19: 6.89 | G19: 6.98 | I19: Debt-Equity (x) | J19: 13.2 | K19: 13.8 | L19: 12.1
B20: P/B (x) | C20: 1.04 | D20: 1.61 | E20: 0.88 | F20: 0.85 | G20: 1.01 | I20: Mean | J20: =AVERAGE(J10:J19) -> 1.59728 | K20: =AVERAGE(K10:K19) -> 1.6885 | L20: =AVERAGE(L10:L19) -> 1.49828
B21: BVPS (₹) | C21: 129.77 | D21: 645.5 | E21: 321 | F21: 130 | G21: 175 | I21: Median | J21: =MEDIAN(J10:J19) -> 0.2404 | K21: =MEDIAN(K10:K19) -> 0.2785 | L21: =MEDIAN(L10:L19) -> 0.2595
B22: EPS (₹) | C22: 20.89 | D22: 90.24 | E22: 38.38 | F22: 16 | G22: 25.45
B23: Div Yield % | C23: 0.0175 | D23: 0.0168 | E23: 0.0306 | F23: 0.0274 | G23: 0.0282
B24: Mean | C24: =AVERAGE(C10:C23) -> 78743.614 | D24: =AVERAGE(D10:D23) -> 361433.38 | E24: =AVERAGE(E10:E23) -> 89809.658 | F24: =AVERAGE(F10:F23) -> 78933.305 | G24: =AVERAGE(G10:G23) -> 78335.994
B25: Median | C25: =MEDIAN(C10:C23) -> 13.675 | D25: =MEDIAN(D10:D23) -> 50.89 | E25: =MEDIAN(E10:E23) -> 22.925 | F25: =MEDIAN(F10:F23) -> 11.445 | G25: =MEDIAN(G10:G23) -> 16.215

Sheet Relative Valuation 
B1: RELATIVE VALUATION ANALYSIS
B3: Bank | C3: Mkt Cap | D3: CMP | E3: BVPS | F3: EPS | G3: ROE | H3: ROA | I3: NIM | J3: Gross NPA | K3: Net NPA | L3: CASA | M3: P/E | N3: P/B | O3: No. of Shares (Cr) | P3: Div Yield (%)
B4: Canara Bank | C4: =D4*O4 -> 122445 | D4: 135 | E4: =('Consolidated FS'!P4+'Consolidated FS'!P6)/O4 -> 129.77398 | F4: ='Consolidated FS'!G16/O4 -> 20.89441 | G4: ='Equity Schedule '!G9*100 -> 15.897233 | H4: ='Consolidated FS'!G16/'Consolidated FS'!P21*100 -> 1.0041318 | I4: ='Assumptions '!G7*100 -> 2.1710246 | J4: 4.23 | K4: 1.27 | L4: 33.5 | M4: =D4/F4 -> 6.4610582 | N4: =D4/E4 -> 1.0402702 | O4: ='Consolidated FS'!P4/2 -> 907 | P4: 1.75
B5: SBI | C5: 960492 | D5: 1041 | E5: 645.5 | F5: 90.24 | G5: 15.4 | H5: 1.1 | I5: 3.28 | J5: 2 | K5: 0.53 | L5: 41.2 | M5: 11.54 | N5: 1.61 | O5: 923 | P5: 1.68
B6: Bank of Baroda | C6: 146608 | D6: 284 | E6: 321 | F6: 38.38 | G6: 12.7 | H6: 1.05 | I6: 3.1 | J6: 2.92 | K6: 0.68 | L6: 38.8 | M6: 7.47 | N6: 0.88 | O6: 517 | P6: 3.06
B7: Punjab Natl Bank | C7: 126020 | D7: 110 | E7: 130 | F7: 16 | G7: 13 | H7: 0.9 | I7: 3.15 | J7: 4 | K7: 0.4 | L7: 43 | M7: 6.89 | N7: 0.85 | O7: 1149 | P7: 2.74
B8: Union Bank | C8: 134848 | D8: 177 | E8: 175 | F8: 25.45 | G8: 15.7 | H8: 0.95 | I8: 3.05 | J8: 4.76 | K8: 1.02 | L8: 36 | M8: 6.98 | N8: 1.01 | O8: 763 | P8: 2.82
B9: Indian Bank | C9: 66000 | D9: 592 | E9: 530 | F9: 74 | G9: 15.8 | H9: 1.12 | I9: 3.35 | J9: 3.73 | K9: 0.4 | L9: 40.5 | M9: 8 | N9: 1.12 | O9: 111.5 | P9: 2.5
B11: Mean | C11: =AVERAGE(C5:C9) -> 286793.6 | D11: =AVERAGE(D5:D9) -> 440.8 | E11: =AVERAGE(E5:E9) -> 360.3 | F11: =AVERAGE(F5:F9) -> 48.814 | G11: =AVERAGE(G5:G9) -> 14.52 | H11: =AVERAGE(H5:H9) -> 1.024 | I11: =AVERAGE(I5:I9) -> 3.186 | J11: =AVERAGE(J5:J9) -> 3.482 | ... P11: =AVERAGE(P5:P9) -> 2.56
B12: Median | C12: =MEDIAN(C5:C9) -> 134848 | D12: =MEDIAN(D5:D9) -> 284 | E12: =MEDIAN(E5:E9) -> 321 | F12: =MEDIAN(F5:F9) -> 38.38 | G12: =MEDIAN(G5:G9) -> 15.4 | H12: =MEDIAN(H5:H9) -> 1.05 | I12: =MEDIAN(I5:I9) -> 3.15 | J12: =MEDIAN(J5:J9) -> 3.73 | ... P12: =MEDIAN(P5:P9) -> 2.74
B13: Maximum | C13: =MAX(C5:C9) -> 960492 | D13: =MAX(D5:D9) -> 1041 | E13: =MAX(E5:E9) -> 645.5 | F13: =MAX(F5:F9) -> 90.24 | G13: =MAX(G5:G9) -> 15.8 | H13: =MAX(H5:H9) -> 1.12 | I13: =MAX(I5:I9) -> 3.35 | J13: =MAX(J5:J9) -> 4.76 | ... P13: =MAX(P5:P9) -> 3.06
B14: Minimum | C14: =MIN(C5:C9) -> 66000 | D14: =MIN(D5:D9) -> 110 | E14: =MIN(E5:E9) -> 130 | F14: =MIN(F5:F9) -> 16 | G14: =MIN(G5:G9) -> 12.7 | H14: =MIN(H5:H9) -> 0.9 | I14: =MIN(I5:I9) -> 3.05 | J14: =MIN(J5:J9) -> 2 | ... P14: =MIN(P5:P9) -> 1.68
B15: Std Deviation | C15: =STDEV(C5:C9) -> 377891.18 | D15: =STDEV(D5:D9) -> 382.98394 | E15: =STDEV(E5:E9) -> 223.07835 | F15: =STDEV(F5:F9) -> 31.945076 | G15: =STDEV(G5:G9) -> 1.5352524 | H15: =STDEV(H5:H9) -> 0.095551033 | I15: =STDEV(I5:I9) -> 0.1254193 | J15: =STDEV(J5:J9) -> 1.0577429 | ... P15: =STDEV(P5:P9) -> 0.53103672
B18: P/B MULTIPLE VALUATION -70%W
B19: Metric | C19: Value
B20: Canara BVPS (FY25) | C20: =E4 -> 129.77398
B21: Peer Mean P/B | C21: =AVERAGE(N5:N9) -> 1.094
B22: Peer Median P/B | C22: =MEDIAN(N5:N9) -> 1.01
B23: Peer Max P/B | C23: =MAX(N5:N9) -> 1.61
B24: Peer Min P/B | C24: =MIN(N5:N9) -> 0.85
B25: Peer Std Dev P/B | C25: =STDEV(N5:N9) -> 0.3079448
B26: Target Price - Mean P/B (₹) | C26: =E4*C21 -> 141.97273
B27: Target Price - Median P/B (₹) | C27: =E4*C22 -> 131.07172
B28: Target Price - Max P/B (₹) | C28: =E4*C23 -> 208.93611
B29: Target Price - Min P/B (₹) | C29: =E4*C24 -> 110.30788
B30: P/B Valuation (70% weight, ₹) | C30: =C27 -> 131.07172
B32: P/E MULTIPLE VALUATION - 30% W
B33: Canara EPS (FY25, ₹) | C33: =F4 -> 20.89441
B34: Peer Mean P/E (x) | C34: =AVERAGE(M5:M9) -> 8.176
B35: Peer Median P/E (x) | C35: =MEDIAN(M5:M9) -> 7.47
B36: Peer Max P/E (x) | C36: =MAX(M5:M9) -> 11.54
B37: Peer Min P/E (x) | C37: =MIN(M5:M9) -> 6.89
B38: Peer Std Dev P/E (x) | C38: =STDEV(M5:M9) -> 1.9319757
B39: Target Price - Mean P/E (₹) | C39: =F4*C34 -> 170.8327
B40: Target Price - Median P/E (₹) | C40: =F4*C35 -> 156.08124
B41: Target Price - Max P/E (₹) | C41: =F4*C36 -> 241.12149
B42: Target Price - Min P/E (₹) | C42: =F4*C37 -> 143.96249
B43: P/E Valuation (30% w) | C43: =C40 -> 156.08124
B45: WEIGHTED VALUATION
B46: Component | C46: Weight | D46: Multiple Used | E46: Canara Metric | F46: Notes
...
