Workbook

Sheet Company Overview
B1: COAL INDIA LTD
B16: About The Company:
B17: Coal India Limited (CIL) is the world's largest coal-producing company and a Maharatna Public Sector Undertaking under the Ministry of Coal, Government of India. The company is primarily engaged in the mining and production of coal and also operates coal washeries. Coal India supplies around 80% of India's total coal production and is a key supplier to the power and steel sectors. Other major consumers include cement, fertilizer, brick kiln, and various industrial sectors.
N19: Mining Areas / Major Operations
N20: > Eastern Coalfields Limited (ECL) – West Bengal & Jharkhand > Bharat Coking Coal Limited (BCCL) – Jharkhand > Central Coalfields Limited (CCL) – Jharkhand > Western Coalfields Limited (WCL) – Maharashtra & Madhya Pradesh > South Eastern Coalfields Limited (SECL) – Chhattisgarh & Madhya Pradesh > Northern Coalfields Limited (NCL) – Madhya Pradesh & Uttar Pradesh > Mahanadi Coalfields Limited (MCL) – Odisha
B25: Subsidiaries
B26: 1. Eastern Coalfields Limited (ECL), Sanctoria, West Bengal 2. Bharat Coking Coal Limited (BCCL), Dhanbad, Jharkhand 3. Central Coalfields Limited (CCL), Ranchi, Jharkhand 4. Western Coalfields Limited (WCL), Nagpur, Maharashtra 5. South Eastern Coalfields Limited (SECL), Bilaspur, Chhattisgarh 6. Northern Coalfields Limited (NCL), Singrauli, Madhya Pradesh 7. Mahanadi Coalfields Limited (MCL), Sambalpur, Odisha 8. Central Mine Planning & Design Institute Limited (CMPDI), Ranchi, Jharkhand 9. CIL Solar PV Limited, Kolkata, West Bengal 10. CIL Navikarniya Urja Limited, Kolkata, West Bengal 11. Coal India Africana Limitada, Mozambique (Wholly Owned Overseas Subsidiary)
N32: Units
N34: 1. Corporate Headquarters, Coal Bhawan, Premise No. 04 MAR, Plot No. AF-III, Action Area-1A, New Town, Rajarhat, Kolkata – 700156, West Bengal
N35: 2. Central Mine Planning & Design Institute (CMPDI), Ranchi, Jharkhand
N36: 3. CIL Solar PV Limited, Kolkata, West Bengal
N37: 4. CIL Navikarniya Urja Limited, Kolkata, West Bengal
N38: 5. Coal India Africana Limitada, Mozambique
N39: 6. Various First Mile Connectivity (FMC) Infrastructure Projects across India
N40: 7. Coal Washeries located across subsidiary mining areas

Sheet Promoters
B1: Statement showing shareholding pattern of the Promoter and Promoter Group
B2: Category of shareholder | C2: Entity Type | D2: Nos. of shareholders | E2: No. of fully paid up equity shares held | F2: Total nos. shares held | G2: Shareholding as a % of total no. of shares (calculated as per SCRR, 1957)As a % of (A+B+C2) | H2: Number of Voting Rights held in each class of securities | J2: Total No. Of shares on fully diluted basis (including warrants, ESOP, Convertible Securities etc.) | K2: Shareholding , as a % assuming full conversion of convertible securities ( as a percentage of diluted share capital)As a % of (A+B+C2) | L2: Number of equity shares held in dematerialized form
H3: Class eg: X | I3: Total
B5: A1) Indian | D5: - | E5: - | F5: - | G5: 0 | H5: - | I5: 0 | J5: - | K5: 0 | L5: -
B6: Central Government/ State Government(s) | D6: 1 | E6: 3890735938 | F6: 3890735938 | G6: 63.13 | H6: 3890735938 | I6: 63.13 | J6: 3890735938 | K6: 63.13 | L6: 3890735938
B7: PRESIDENT OF INDIA | C7: Promoter | D7: 1 | E7: 3890735938 | F7: 3890735938 | G7: 63.13 | H7: 3890735938 | I7: 63.13 | J7: 3890735938 | K7: 63.13 | L7: 3890735938
B8: Sub Total A1 | D8: 1 | E8: 3890735938 | F8: 3890735938 | G8: 63.13 | H8: 3890735938 | I8: 63.13 | J8: 3890735938 | K8: 63.13 | L8: 3890735938
B9: A2) Foreign | D9: - | E9: - | F9: - | G9: 0 | H9: - | I9: 0 | J9: - | K9: 0 | L9: -
B10: A=A1+A2 | D10: 1 | E10: 3890735938 | F10: 3890735938 | G10: 63.13 | H10: 3890735938 | I10: 63.13 | J10: 3890735938 | K10: 63.13 | L10: 3890735938

Sheet Public
B2: Statement showing shareholding pattern of the Public shareholder
B4: Category & Name of the Shareholders | C4: No. of shareholder | D4: No. of fully paid up equity shares held | E4: Total no. shares held | F4: Shareholding % calculated as per SCRR, 1957 As a % of (A+B+C2) | G4: No. of Voting Rights | H4: Total as a % of Total Voting right | I4: Total No. Of shares on fully diluted basis (including warrants, ESOP, Convertible Securities etc.) | J4: Shareholding , as a % assuming full conversion of convertible securities ( as a percentage of diluted share capital)As a % of (A+B+C2) | K4: No. of equity shares held in dematerialized form(Not Applicable) | L4: Sub-categorization of shares (XV)
L5: Shareholding (No. of shares) under
L6: SubCategory_I | M6: SubCategory_II | N6: SubCategory_III
B7: Institutions | C7: 0 | D7: 0 | E7: - | F7: 0 | G7: - | H7: 0 | I7: - | J7: 0 | K7: - | L7: - | M7: - | N7: -
B8: B2) Institutions (Domestic) | C8: 0 | D8: 0 | E8: - | F8: 0 | G8: - | H8: 0 | I8: - | J8: 0 | K8: - | L8: - | M8: - | N8: -
B9: Mutual Funds/ | C9: 42 | D9: 587322433 | E9: 587322433 | F9: 9.53 | G9: 587322433 | H9: 9.53 | I9: 587322433 | J9: 9.53 | K9: 587322433 | L9: - | M9: - | N9: -
B10: CPSE EXCHANGE TRADED SCHEME (CPSE ETF) | C10: 1 | D10: 96096558 | E10: 96096558 | F10: 1.56 | G10: 96096558 | H10: 1.56 | I10: 96096558 | J10: 1.56 | K10: 96096558 | L10: - | M10: - | N10: -
B11: PARAG PARIKH FLEXI CAP FUND | C11: 1 | D11: 180841782 | E11: 180841782 | F11: 2.93 | G11: 180841782 | H11: 2.93 | I11: 180841782 | J11: 2.93 | K11: 180841782 | L11: - | M11: - | N11: -
B12: SBI NIFTY 50 ETF | C12: 1 | D12: 96050614 | E12: 96050614 | F12: 1.56 | G12: 96050614 | H12: 1.56 | I12: 96050614 | J12: 1.56 | K12: 96050614 | L12: - | M12: - | N12: -
B13: Venture Capital Funds | C13: 0 | D13: 0 | E13: - | F13: 0 | G13: - | H13: 0 | I13: - | J13: 0 | K13: - | L13: - | M13: - | N13: -
B14: Alternate Investment Funds | C14: 30 | D14: 2194867 | E14: 2194867 | F14: 0.04 | G14: 2194867 | H14: 0.04 | I14: 2194867 | J14: 0.04 | K14: 2194867 | L14: - | M14: - | N14: -
B15: Banks | C15: 6 | D15: 1326404 | E15: 1326404 | F15: 0.02 | G15: 1326404 | H15: 0.02 | I15: 1326404 | J15: 0.02 | K15: 1326404 | L15: - | M15: - | N15: -
B16: Insurance Companies | C16: 40 | D16: 762779571 | E16: 762779571 | F16: 12.38 | G16: 762779571 | H16: 12.38 | I16: 762779571 | J16: 12.38 | K16: 762779571 | L16: - | M16: - | N16: -
B17: LIFE INSURANCE CORPORATION OF INDIA | C17: 1 | D17: 680772793 | E17: 680772793 | F17: 11.05 | G17: 680772793 | H17: 11.05 | I17: 680772793 | J17: 11.05 | K17: 680772793 | L17: - | M17: - | N17: -
B18: Provident Funds/ Pension Funds | C18: 3 | D18: 48625566 | E18: 48625566 | F18: 0.79 | G18: 48625566 | H18: 0.79 | I18: 48625566 | J18: 0.79 | K18: 48625566 | L18: - | M18: - | N18: -
B19: Asset reconstruction companies | C19: 0 | D19: 0 | E19: - | F19: 0 | G19: - | H19: 0 | I19: - | J19: 0 | K19: - | L19: - | M19: - | N19: -
B20: Sovereign Wealth Funds | C20: 0 | D20: 0 | E20: - | F20: 0 | G20: - | H20: 0 | I20: - | J20: 0 | K20: - | L20: - | M20: - | N20: -
B21: NBFCs registered with RBI | C21: 14 | D21: 70490 | E21: 70490 | F21: 0 | G21: 70490 | H21: 0 | I21: 70490 | J21: 0 | K21: 70490 | L21: - | M21: - | N21: -
B22: Other Financial Institutions | C22: 0 | D22: 0 | E22: - | F22: 0 | G22: - | H22: 0 | I22: - | J22: 0 | K22: - | L22: - | M22: - | N22: -
B23: Any Other(Institutions (Domestic)) | C23: 0 | D23: 0 | E23: - | F23: 0 | G23: - | H23: 0 | I23: - | J23: 0 | K23: - | L23: - | M23: - | N23: -
B24: Sub Total B1 | C24: 135 | D24: 1402319331 | E24: 1402319331 | F24: 22.75 | G24: 1402319331 | H24: 22.75 | I24: 1402319331 | J24: 22.75 | K24: 1402319331 | L24: - | M24: - | N24: -
B25: B19) Institutions (Foreign) | C25: 0 | D25: 0 | E25: - | F25: 0 | G25: - | H25: 0 | I25: - | J25: 0 | K25: - | L25: - | M25: - | N25: -
B26: Foreign Direct Investment | C26: 0 | D26: 0 | E26: - | F26: 0 | G26: - | H26: 0 | I26: - | J26: 0 | K26: - | L26: - | M26: - | N26: -
B27: Foreign Venture Capital Investors | C27: 0 | D27: 0 | E27: - | F27: 0 | G27: - | H27: 0 | I27: - | J27: 0 | K27: - | L27: - | M27: - | N27: -
B28: Sovereign Wealth Funds | C28: 0 | D28: 0 | E28: - | F28: 0 | G28: - | H28: 0 | I28: - | J28: 0 | K28: - | L28: - | M28: - | N28: -
B29: Foreign Portfolio Investors Category I | C29: 521 | D29: 482448388 | E29: 482448388 | F29: 7.83 | G29: 482448388 | H29: 7.83 | I29: 482448388 | J29: 7.83 | K29: 482448388 | L29: - | M29: - | N29: -
B30: Foreign Portfolio Investors Category II | C30: 54 | D30: 33833059 | E30: 33833059 | F30: 0.55 | G30: 33833059 | H30: 0.55 | I30: 33833059 | J30: 0.55 | K30: 33833059 | L30: - | M30: - | N30: -
B31: Overseas Depositories (holding DRs) (balancing figure) | C31: 0 | D31: 0 | E31: - | F31: 0 | G31: - | H31: 0 | I31: - | J31: 0 | K31: - | L31: - | M31: - | N31: -
B32: Any Other(Institutions (Foreign)) | C32: 0 | D32: 0 | E32: - | F32: 0 | G32: - | H32: 0 | I32: - | J32: 0 | K32: - | L32: - | M32: - | N32: -
B33: Sub Total B2 | C33: 575 | D33: 516281447 | E33: 516281447 | F33: 8.38 | G33: 516281447 | H33: 8.38 | I33: 516281447 | J33: 8.38 | K33: 516281447 | L33: - | M33: - | N33: -
B34: B28) Central Government/ State Government(s)/ President of India | C34: 0 | D34: 0 | E34: - | F34: 0 | G34: - | H34: 0 | I34: - | J34: 0 | K34: - | L34: - | M34: - | N34: -
B35: Central Government / President of India | C35: 0 | D35: 0 | E35: - | F35: 0 | G35: - | H35: 0 | I35: - | J35: 0 | K35: - | L35: - | M35: - | N35: -
B36: State Government / Governor | C36: 0 | D36: 0 | E36: - | F36: 0 | G36: - | H36: 0 | I36: - | J36: 0 | K36: - | L36: - | M36: - | N36: -
B37: Shareholding by Companies or Bodies Corporate where Central / State Government is a promoter | C37: 3 | D37: 6416456 | E37: 6416456 | F37: 0.1 | G37: 6416456 | H37: 0.1 | I37: 6416456 | J37: 0.1 | K37: 6416456 | L37: - | M37: - | N37: -
B38: Sub Total B3 | C38: 3 | D38: 6416456 | E38: 6416456 | F38: 0.1 | G38: 6416456 | H38: 0.1 | I38: 6416456 | J38: 0.1 | K38: 6416456 | L38: - | M38: - | N38: -
B39: B33) Non-Institutions | C39: 0 | D39: 0 | E39: - | F39: 0 | G39: - | H39: 0 | I39: - | J39: 0 | K39: - | L39: - | M39: - | N39: -
B40: Associate companies / Subsidiaries | C40: 0 | D40: 0 | E40: - | F40: 0 | G40: - | H40: 0 | I40: - | J40: 0 | K40: - | L40: - | M40: - | N40: -
B41: Directors and their relatives (excluding independent directors and nominee directors) | C41: 0 | D41: 0 | E41: - | F41: 0 | G41: - | H41: 0 | I41: - | J41: 0 | K41: - | L41: - | M41: - | N41: -
B42: Key Managerial Personnel | C42: 0 | D42: 0 | E42: - | F42: 0 | G42: - | H42: 0 | I42: - | J42: 0 | K42: - | L42: - | M42: - | N42: -
...

Sheet Balance Sheet 
B2: Coal India
B3: Consolidated Balance Sheet
C4: 44621 | D4: 44986 | E4: 45352 | F4: 45717 | G4: Mar 26
C6: 12 mths | D6: 12 mths | E6: 12 mths | F6: 12 mths | G6: 12 mths
B8: EQUITIES AND LIABILITIES
B9: SHAREHOLDER'S FUNDS
B10: Equity Share Capital | C10: 6162.73 | D10: 6162.73 | E10: 6162.73 | F10: 6162.73 | G10: 6162.73 | H10: Face Value | I10: 10
B11: Total Share Capital | C11: 6162.73 | D11: 6162.73 | E11: 6162.73 | F11: 6162.73 | G11: 6162.73 | H11: no of shares | I11: =C10/I10 -> 616.273
B12: Reserves and Surplus | C12: 36980.31 | D12: 51082.16 | E12: 76567.05 | F12: 92942.19 | G12: 112938.83
B13: Total Reserves and Surplus | C13: 36980.31 | D13: 51082.16 | E13: 76567.05 | F13: 92942.19 | G13: 112938.83
B14: Total Shareholders Funds | C14: 43143.04 | D14: 57244.89 | E14: 82729.78 | F14: 99104.92 | G14: 119101.56
B15: Minority Interest | C15: 673.79 | D15: 770.68 | E15: 852.12 | F15: 845.77 | G15: 1903.01
B16: NON-CURRENT LIABILITIES
B17: Long Term Borrowings | C17: 3301.78 | D17: 4106.25 | E17: 5617.2 | F17: 7385.75 | G17: 9232.36
B18: Deferred Tax Liabilities [Net] | C18: 811.02 | D18: 1330.68 | E18: 1822.16 | F18: 1831.9 | G18: 2434.19
B19: Other Long Term Liabilities | C19: 8967.03 | D19: 10191.56 | E19: 11067.45 | F19: 11756.86 | G19: 12382.87
B20: Long Term Provisions | C20: 65944 | D20: 68827.95 | E20: 74311.01 | F20: 74531.52 | G20: 72955.17
B21: Total Non-Current Liabilities | C21: 79023.83 | D21: 84456.44 | E21: 92817.82 | F21: 95506.03 | G21: 97004.59
B22: CURRENT LIABILITIES
B23: Short Term Borrowings | C23: 7.98 | D23: 8.48 | E23: 671.82 | F23: 1522.65 | G23: 4589.1
B24: Trade Payables | C24: 8591.78 | D24: 8549.18 | E24: 8385.65 | F24: 10205.63 | G24: 12554.39
B25: Other Current Liabilities | C25: 42708.23 | D25: 45213.6 | E25: 45534.49 | F25: 46791.02 | G25: 45699.35
B26: Short Term Provisions | C26: 6094.68 | D26: 14963.38 | E26: 6680.58 | F26: 6222.35 | G26: 4808.27
B27: Total Current Liabilities | C27: 57402.67 | D27: 68734.64 | E27: 61272.54 | F27: 64741.65 | G27: 67651.11
B28: Total Capital And Liabilities | C28: 180243.33 | D28: 211206.65 | E28: 237672.26 | F28: 260198.37 | G28: 285660.27
B29: ASSETS
B30: NON-CURRENT ASSETS
B31: Tangible Assets | C31: 42697.79 | D31: 44447.97 | E31: 67900.41 | F31: 76639.85 | G31: 89081.86
B32: Intangible Assets | C32: 105.62 | D32: 2588.11 | E32: 2718.21 | F32: 2579.89 | G32: 2764.23
B33: Capital Work-In-Progress | C33: 12713.73 | D33: 15262.62 | E33: 14738.66 | F33: 15888.64 | G33: 18818.58
B34: Intangible Assets Under Development | C34: 183.41 | D34: 2359.35 | E34: 4221.64 | F34: 6496.27 | G34: 0
B35: Other Assets | C35: 3873.55 | D35: 4924.85 | E35: 5049.58 | F35: 3645.3 | G35: 0
B36: Fixed Assets | C36: 59574.1 | D36: 69582.9 | E36: 94628.5 | F36: 105249.95 | G36: 110664.67
B37: Non-Current Investments | C37: 2426.97 | D37: 3085.4 | E37: 3859.31 | F37: 4416.07 | G37: 6038.41
B38: Deferred Tax Assets [Net] | C38: 4138.09 | D38: 4177 | E38: 3141.29 | F38: 2694.71 | G38: 2239.55
B39: Long Term Loans And Advances | C39: 353.39 | D39: 372.21 | E39: 358.71 | F39: 389.86 | G39: 888.92
B40: Other Non-Current Assets | C40: 20907.83 | D40: 25906.44 | E40: 31801.09 | F40: 51254.36 | G40: 40301.11
B41: Total Non-Current Assets | C41: 87400.38 | D41: 103123.95 | E41: 133788.9 | F41: 164004.95 | G41: 160132.66
B42: CURRENT ASSETS
B43: Current Investments | C43: 7279.41 | D43: 4054.01 | E43: 3251.1 | F43: 3175.26 | G43: 4187.47
...

Sheet P & L 
B2: Coal India
B3: Consolidated Profit & Loss account
C4: 44621 | D4: 44986 | E4: 45352 | F4: 45717 | G4: Mar 26
C6: 12 mths | D6: 12 mths | E6: 12 mths | F6: 12 mths | G6: 12 mths
B8: INCOME
B9: Revenue From Operations [Gross] | C9: 100623.37 | D9: 127627.47 | E9: 193907.1 | F9: 191356.71 | G9: 168400.29
B10: Less: Excise/Sevice Tax/Other Levies | C10: 0 | D10: 0 | E10: 63581.45 | F10: 64399.95 | G10: 0
B11: Revenue From Operations [Net] | C11: 100623.37 | D11: 127627.47 | E11: 130325.65 | F11: 126956.76 | G11: 168400.29
B12: Other Operating Revenues | C12: 9090.13 | D12: 10624.44 | E12: 11998.33 | F12: 16412.16 | G12: 0
B13: Total Operating Revenues | C13: 109713.5 | D13: 138251.91 | E13: 142323.98 | F13: 143368.92 | G13: 168400.29
B14: Other Income | C14: 3904.52 | D14: 6550.66 | E14: 7969.08 | F14: 9470.06 | G14: 11275.68
B15: Total Revenue | C15: 113618.02 | D15: 144802.57 | E15: 150293.06 | F15: 152838.98 | G15: 179675.97
B16: EXPENSES
B17: Cost Of Materials Consumed | C17: 12080.64 | D17: 16316.89 | E17: 11580.04 | F17: 11246.95 | G17: 11171.48
B18: Purchase Of Stock-In Trade | C18: 103.56 | D18: 469.74 | E18: 0 | F18: 0 | G18: 0
B19: Operating And Direct Expenses | C19: 22627.72 | D19: 23289.21 | E19: 27597.85 | F19: 31811.5 | G19: 0
B20: Changes In Inventories Of FG,WIP And Stock-In Trade | C20: 2308.49 | D20: -678.12 | E20: -1521.5 | F20: -2303.35 | G20: -2828.5
B21: Employee Benefit Expenses | C21: 40700.82 | D21: 49409.16 | E21: 48782.58 | F21: 46249.13 | G21: 46424.59
B22: Finance Costs | C22: 541.49 | D22: 684.31 | E22: 819.37 | F22: 883.65 | G22: 1216.26
B23: Provsions and Contingencies | C23: 172.77 | D23: 374.93 | E23: 1189.79 | F23: 0 | G23: 0
B24: Depreciation And Amortisation Expenses | C24: 4428.67 | D24: 4675.27 | E24: 6735.42 | F24: 9145.49 | G24: 10136.67
B25: Other Expenses | C25: 7028.99 | D25: 12252.23 | E25: 6723.73 | F25: 13407.2 | G25: 72390.73
B26: Less: Amounts Transfer To Capital Accounts | C26: 0 | D26: 0 | E26: 0 | F26: 4105.52 | G26: 0
B27: Total Expenses | C27: 89993.15 | D27: 106793.62 | E27: 101907.28 | F27: 106335.05 | G27: 138511.23
B28: Profit/Loss Before Exceptional, ExtraOrdinary Items And Tax | C28: 23624.87 | D28: 38008.95 | E28: 48385.78 | F28: 46503.93 | G28: 41164.74
B29: Profit/Loss Before Tax | C29: 23624.87 | D29: 38008.95 | E29: 48385.78 | F29: 46503.93 | G29: 41164.74
B30: Tax Expenses-Continued Operations
B31: Current Tax | C31: 6257.12 | D31: 9389.75 | E31: 11576.35 | F31: 11148.08 | G31: 10852.51
B32: Deferred Tax | C32: -19.26 | D32: 486.12 | E32: -132.87 | F32: 516.01 | G32: 0
B33: Total Tax Expenses | C33: 6237.86 | D33: 9875.87 | E33: 11443.48 | F33: 11664.09 | G33: 10852.51
B34: Profit/Loss After Tax And Before ExtraOrdinary Items | C34: 17387.01 | D34: 28133.08 | E34: 36942.3 | F34: 34839.84 | G34: 30312.23
B35: Profit/Loss From Continuing Operations | C35: 17387.01 | D35: 28133.08 | E35: 36942.3 | F35: 34839.84 | G35: 30312.23
B36: Profit/Loss For The Period | C36: 17387.01 | D36: 28133.08 | E36: 36942.3 | F36: 34839.84 | G36: 30312.23
B37: Minority Interest | C37: -20.32 | D37: 40.25 | E37: 33.16 | F37: 56.06 | G37: 23.71
B38: Share Of Profit/Loss Of Associates | C38: -8.59 | D38: -8.14 | E38: 426.83 | F38: 462.26 | G38: 758.35
B39: Consolidated Profit/Loss After MI And Associates | C39: 17358.1 | D39: 28165.19 | E39: 37402.29 | F39: 35358.16 | G39: 31094.29
B40: OTHER ADDITIONAL INFORMATION
B41: EARNINGS PER SHARE
B42: Basic EPS (Rs.) | C42: 28 | D42: 46 | E42: 61 | F42: 57 | G42: 50
B43: Diluted EPS (Rs.) | C43: 28 | D43: 46 | E43: 61 | F43: 57 | G43: 50
...

Sheet Cash Flow
B2: Coal India
B3: Cash Flow
C4: Mar '22 | D4: Mar '23 | E4: Mar '24 | F4: Mar '25 | G4: Mar '26
C6: 12 mths | D6: 12 mths | E6: 12 mths | F6: 12 mths | G6: 12 mths
B8: Net Profit Before Tax | C8: 11356.84 | D8: 15093.51 | E8: 16042.12 | F8: 17097.5 | G8: 19318.45
B9: Net Cash From Operating Activities | C9: 2157.35 | D9: 1211.01 | E9: 401.37 | F9: 1171.48 | G9: 3243.35
B10: Net Cash (used in)/from | C10: 8884.9 | D10: 12652.83 | E10: 14572.64 | F10: 15735.19 | G10: 12122.19
B11: Investing Activities
B12: Net Cash (used in)/from Financing Activities | C12: -10783.37 | D12: -14328.07 | E12: -15097.85 | F12: -16238.52 | G12: -15437.88
B13: Net (decrease)/increase In Cash and Cash Equivalents | C13: 258.88 | D13: -464.23 | E13: -123.84 | F13: 668.15 | G13: -72.34
B14: Opening Cash & Cash Equivalents | C14: 212.66 | D14: 631.32 | E14: 167.09 | F14: 43.25 | G14: 711.4
B15: Closing Cash & Cash Equivalents | C15: 471.54 | D15: 167.09 | E15: 43.25 | F15: 711.4 | G15: 639.06

Sheet Stock Analysis
R7: My Recommendation
R8: Investor Type | S8: View
R9: Already Holding | S9: HOLD
R10: Long-Term Dividend Investor | S10: BUY / ACCUMULATE
R11: Looking for High Growth | S11: Avoid
R12: Value Investor | S12: BUY ON DIPS
B23: Stock Analysis:
B24: Coal India appears fairly valued to slightly undervalued at current levels. The stock's biggest attraction remains its strong dividend yield, cash generation, and low valuation multiples rather than high earnings growth. Investors seeking stable income and value may continue to accumulate on corrections, while existing shareholders can comfortably hold the stock.

Sheet Ratio Analysis
B2: Ratio Analysis
B4: Years | C4: 2022 | D4: 2023 | E4: 2024 | F4: 2025 | G4: 2026 | H4: Trends
B5: Growth Rates
B6: Sales Growth | D6: ='Historical FS'!D6 -> 0.26011758 | E6: ='Historical FS'!E6 -> 0.029453987 | F6: ='Historical FS'!F6 -> 0.0073419813 | G6: ='Historical FS'!G6 -> 0.17459412
B7: EBITDA Growth | D7: =IFERROR('Historical FS'!D17/'Historical FS'!C17-1,0) -> 0.49117495 | E7: =IFERROR('Historical FS'!E17/'Historical FS'!D17-1,0) -> 0.30294039 | F7: =IFERROR('Historical FS'!F17/'Historical FS'!E17-1,0) -> -0.018937915 | G7: =IFERROR('Historical FS'!G17/'Historical FS'!F17-1,0) -> -0.12368567
B8: EBIT Growth | D8: =IFERROR('Historical FS'!D23/'Historical FS'!C23-1,0) -> 0.58636136 | E8: =IFERROR('Historical FS'!E23/'Historical FS'!D23-1,0) -> 0.28291022 | F8: =IFERROR('Historical FS'!F23/'Historical FS'!E23-1,0) -> -0.080476874 | G8: =IFERROR('Historical FS'!G23/'Historical FS'!F23-1,0) -> -0.17965837
B9: Net Profit Growth | D9: =IFERROR('Historical FS'!D37/'Historical FS'!C37-1,0) -> 0.61805164 | E9: =IFERROR('Historical FS'!E37/'Historical FS'!D37-1,0) -> 0.31312675 | F9: =IFERROR('Historical FS'!F37/'Historical FS'!E37-1,0) -> -0.056911995 | G9: =IFERROR('Historical FS'!G37/'Historical FS'!F37-1,0) -> -0.12995496
B10: Dividend Growth | D10: =IFERROR('Historical FS'!D45/'Historical FS'!C45-1,0) -> 0.32857385 | E10: =IFERROR('Historical FS'!E45/'Historical FS'!D45-1,0) -> 0.053762495 | F10: =IFERROR('Historical FS'!F45/'Historical FS'!E45-1,0) -> 0.075511037 | G10: =IFERROR('Historical FS'!G45/'Historical FS'!F45-1,0) -> -1
B12: Margins
B13: Gross Margin | C13: ='Historical FS'!C12 -> 0.66166051 | D13: ='Historical FS'!D12 -> 0.71502947 | E13: ='Historical FS'!E12 -> 0.73541781 | F13: ='Historical FS'!F12 -> 0.71573267 | G13: ='Historical FS'!G12 -> 0.95045745
B14: EBITDA Margin | C14: ='Historical FS'!C18 -> 0.22504532 | D14: ='Historical FS'!D18 -> 0.26631003 | E14: ='Historical FS'!E18 -> 0.33705838 | F14: ='Historical FS'!F18 -> 0.32826508 | G14: ='Historical FS'!G18 -> 0.24490451
B15: EBIT Margin | C15: ='Historical FS'!C24 -> 0.18467955 | D15: ='Historical FS'!D24 -> 0.23249299 | E15: ='Historical FS'!E24 -> 0.28973382 | F15: ='Historical FS'!F24 -> 0.26447517 | G15: ='Historical FS'!G24 -> 0.18471061
B16: EBT Margin | C16: ='Historical FS'!C32 -> 0.21533239 | D16: ='Historical FS'!D32 -> 0.27492532 | E16: ='Historical FS'!E32 -> 0.33996927 | F16: ='Historical FS'!F32 -> 0.32436549 | G16: ='Historical FS'!G32 -> 0.24444578
B17: Net Profit Margin | C17: ='Historical FS'!C38 -> 0.15847649 | D17: ='Historical FS'!D38 -> 0.20349144 | E17: ='Historical FS'!E38 -> 0.25956483 | F17: ='Historical FS'!F38 -> 0.24300832 | G17: ='Historical FS'!G38 -> 0.18000106
B19: Expense Ratios
B20: Sales Expenses | C20: ='Historical FS'!C15 -> 0.43661518 | D20: ='Historical FS'!D15 -> 0.44871944 | E20: ='Historical FS'!E15 -> 0.39835943 | F20: ='Historical FS'!F15 -> 0.38746759 | G20: ='Historical FS'!G15 -> 0.70555294
B21: Depreciation | C21: ='Historical FS'!C21 -> 0.040365771 | D21: ='Historical FS'!D21 -> 0.033817037 | E21: ='Historical FS'!E21 -> 0.047324562 | F21: ='Historical FS'!F21 -> 0.063789906 | G21: ='Historical FS'!G21 -> 0.060193899
B22: Operating Income | C22: ='Historical FS'!C24 -> 0.18467955 | D22: ='Historical FS'!D24 -> 0.23249299 | E22: ='Historical FS'!E24 -> 0.28973382 | F22: ='Historical FS'!F24 -> 0.26447517 | G22: ='Historical FS'!G24 -> 0.18471061
B24: Returns
B25: Return on Capital Employed | C25: =IFERROR('Historical FS'!C23/('Historical FS'!C68-'Balance Sheet '!C27),0) -> 0.16494408 | D25: =IFERROR('Historical FS'!D23/('Historical FS'!D68-'Balance Sheet '!D27),0) -> 0.22560642 | E25: =IFERROR('Historical FS'!E23/('Historical FS'!E68-'Balance Sheet '!E27),0) -> 0.23376494 | F25: =IFERROR('Historical FS'!F23/('Historical FS'!F68-'Balance Sheet '!F27),0) -> 0.19399446 | G25: =IFERROR('Historical FS'!G23/('Historical FS'!G68-'Balance Sheet '!G27),0) -> 0.14267896
B26: Retained Earnings | C26: ='Historical FS'!C48 -> 0.37972141 | D26: ='Historical FS'!D48 -> 0.49069245 | E26: ='Historical FS'!E48 -> 0.59128912 | F26: ='Historical FS'!F48 -> 0.53390027 | G26: ='Historical FS'!G48 -> 1
B27: Return on Equity | C27: =IFERROR('Historical FS'!C37/('Balance Sheet '!C14+'Balance Sheet '!C15),0) -> 0.39681123 | D27: =IFERROR('Historical FS'!D37/('Balance Sheet '!D14+'Balance Sheet '!D15),0) -> 0.48492293 | E27: =IFERROR('Historical FS'!E37/('Balance Sheet '!E14+'Balance Sheet '!E15),0) -> 0.44198923 | F27: =IFERROR('Historical FS'!F37/('Balance Sheet '!F14+'Balance Sheet '!F15),0) -> 0.34857028 | G27: =IFERROR('Historical FS'!G37/('Balance Sheet '!G14+'Balance Sheet '!G15),0) -> 0.25050484
B28: Self Sustained Growth Rate | C28: =IFERROR(C27*C26,0) -> 0.15067772 | D28: =IFERROR(D27*D26,0) -> 0.23794802 | E28: =IFERROR(E27*E26,0) -> 0.26134342 | F28: =IFERROR(F27*F26,0) -> 0.18610177 | G28: =IFERROR(G27*G26,0) -> 0.25050484
B29: Interest Coverage Ratio | C29: =IFERROR('Historical FS'!C23/'Historical FS'!C26,0) -> 37.418678 | D29: =IFERROR('Historical FS'!D23/'Historical FS'!D26,0) -> 46.970817 | E29: =IFERROR('Historical FS'!E23/'Historical FS'!E26,0) -> 50.326556 | F29: =IFERROR('Historical FS'!F23/'Historical FS'!F26,0) -> 42.910111 | G29: =IFERROR('Historical FS'!G23/'Historical FS'!G26,0) -> 25.574565
B31: Efficiency Ratios
B32: Debtor Turnover Ratio | C32: =IFERROR('Historical FS'!C5/'Historical FS'!C63,0) -> 9.6513537 | D32: =IFERROR('Historical FS'!D5/'Historical FS'!D63,0) -> 10.585515 | E32: =IFERROR('Historical FS'!E5/'Historical FS'!E63,0) -> 10.736773 | F32: =IFERROR('Historical FS'!F5/'Historical FS'!F63,0) -> 11.264305 | G32: =IFERROR('Historical FS'!G5/'Historical FS'!G63,0) -> 11.925868
B33: Creditor Turnover Ratio | C33: =IFERROR('Historical FS'!C8/'Balance Sheet '!C24,0) -> 4.3204563 | D33: =IFERROR('Historical FS'!D8/'Balance Sheet '!D24,0) -> 4.6083624 | E33: =IFERROR('Historical FS'!E8/'Balance Sheet '!E24,0) -> 4.490575 | F33: =IFERROR('Historical FS'!F8/'Balance Sheet '!F24,0) -> 3.9933938 | G33: =IFERROR('Historical FS'!G8/'Balance Sheet '!G24,0) -> 0.66454682
B34: Inventory Turnover | C34: =IFERROR('Historical FS'!C5/'Historical FS'!C64,0) -> 15.505718 | D34: =IFERROR('Historical FS'!D5/'Historical FS'!D64,0) -> 16.953689 | E34: =IFERROR('Historical FS'!E5/'Historical FS'!E64,0) -> 13.98455 | F34: =IFERROR('Historical FS'!F5/'Historical FS'!F64,0) -> 11.366127 | G34: =IFERROR('Historical FS'!G5/'Historical FS'!G64,0) -> 10.757446
B35: Fixed Asset Turnover | C35: =IFERROR('Historical FS'!C5/'Historical FS'!C57,0) -> 2.5631953 | D35: =IFERROR('Historical FS'!D5/'Historical FS'!D57,0) -> 2.9392736 | E35: =IFERROR('Historical FS'!E5/'Historical FS'!E57,0) -> 2.0153889 | F35: =IFERROR('Historical FS'!F5/'Historical FS'!F57,0) -> 1.8097626 | G35: =IFERROR('Historical FS'!G5/'Historical FS'!G57,0) -> 1.8335053
B36: Capital Turnover Ratio | C36: =IFERROR('Historical FS'!C5/'Historical FS'!C68,0) -> 0.60869659 | D36: =IFERROR('Historical FS'!D5/'Historical FS'!D68,0) -> 0.65458124 | E36: =IFERROR('Historical FS'!E5/'Historical FS'!E68,0) -> 0.59882453 | F36: =IFERROR('Historical FS'!F5/'Historical FS'!F68,0) -> 0.55099853 | G36: =IFERROR('Historical FS'!G5/'Historical FS'!G68,0) -> 0.58951247
B38: Working Capital Days
B39: Debtors Days | C39: =IFERROR('Historical FS'!C63/'Historical FS'!C5*365,0) -> 37.818529 | D39: =IFERROR('Historical FS'!D63/'Historical FS'!D5*365,0) -> 34.48108 | E39: =IFERROR('Historical FS'!E63/'Historical FS'!E5*365,0) -> 33.995317 | F39: =IFERROR('Historical FS'!F63/'Historical FS'!F5*365,0) -> 32.403242 | G39: =IFERROR('Historical FS'!G63/'Historical FS'!G5*365,0) -> 30.605739
B40: Payable Days | C40: =IFERROR('Balance Sheet '!C24/'Historical FS'!C8*365,0) -> 84.481817 | D40: =IFERROR('Balance Sheet '!D24/'Historical FS'!D8*365,0) -> 79.20384 | E40: =IFERROR('Balance Sheet '!E24/'Historical FS'!E8*365,0) -> 81.281351 | F40: =IFERROR('Balance Sheet '!F24/'Historical FS'!F8*365,0) -> 91.400952 | G40: =IFERROR('Balance Sheet '!G24/'Historical FS'!G8*365,0) -> 549.24647
B41: Inventory Days | C41: =IFERROR('Historical FS'!C64/'Historical FS'!C8*365,0) -> 69.57421 | D41: =IFERROR('Historical FS'!D64/'Historical FS'!D8*365,0) -> 75.548996 | E41: =IFERROR('Historical FS'!E64/'Historical FS'!E8*365,0) -> 98.646975 | F41: =IFERROR('Historical FS'!F64/'Historical FS'!F8*365,0) -> 112.96747 | G41: =IFERROR('Historical FS'!G64/'Historical FS'!G8*365,0) -> 684.86554
B42: Cash Conversion Cycle | C42: =C39+C41-C40 -> 22.910922 | D42: =D39+D41-D40 -> 30.826237 | E42: =E39+E41-E40 -> 51.36094 | F42: =F39+F41-F40 -> 53.969759 | G42: =G39+G41-G40 -> 166.2248
B44: Cash Flow Quality
B45: CFO / Sales | C45: =IFERROR('Historical FS'!C74/'Historical FS'!C5,0) -> 0.019663487 | D45: =IFERROR('Historical FS'!D74/'Historical FS'!D5,0) -> 0.008759445 | E45: =IFERROR('Historical FS'!E74/'Historical FS'!E5,0) -> 0.0028201151 | F45: =IFERROR('Historical FS'!F74/'Historical FS'!F5,0) -> 0.0081710876 | G45: =IFERROR('Historical FS'!G74/'Historical FS'!G5,0) -> 0.019259765
B46: CFO / Total Assets | C46: =IFERROR('Historical FS'!C74/'Historical FS'!C68,0) -> 0.011969098 | D46: =IFERROR('Historical FS'!D74/'Historical FS'!D68,0) -> 0.0057337683 | E46: =IFERROR('Historical FS'!E74/'Historical FS'!E68,0) -> 0.0016887541 | F46: =IFERROR('Historical FS'!F74/'Historical FS'!F68,0) -> 0.0045022573 | G46: =IFERROR('Historical FS'!G74/'Historical FS'!G68,0) -> 0.011353872
B47: CFO / Total Debt | C47: =IFERROR('Historical FS'!C74/'Historical FS'!C53,0) -> 0.65181463 | D47: =IFERROR('Historical FS'!D74/'Historical FS'!D53,0) -> 0.29431093 | E47: =IFERROR('Historical FS'!E74/'Historical FS'!E53,0) -> 0.063820754 | F47: =IFERROR('Historical FS'!F74/'Historical FS'!F53,0) -> 0.13150285 | G47: =IFERROR('Historical FS'!G74/'Historical FS'!G53,0) -> 0.23466045

Sheet Historical FS
B2: Historical Financial Statement
B3: Years | C3: 2022 | D3: 2023 | E3: 2024 | F3: 2025 | G3: 2026
B4: Income statement
B5: Sales | C5: ='P & L '!C13 -> 109713.5 | D5: ='P & L '!D13 -> 138251.91 | E5: ='P & L '!E13 -> 142323.98 | F5: ='P & L '!F13 -> 143368.92 | G5: ='P & L '!G13 -> 168400.29
B6: Sales Growth | D6: =D5/C5-1 -> 0.26011758 | E6: =E5/D5-1 -> 0.029453987 | F6: =F5/E5-1 -> 0.0073419813 | G6: =G5/F5-1 -> 0.17459412
B8: COGS | C8: ='P & L '!C17+'P & L '!C18+'P & L '!C19+'P & L '!C20 -> 37120.41 | D8: ='P & L '!D17+'P & L '!D18+'P & L '!D19+'P & L '!D20 -> 39397.72 | E8: ='P & L '!E17+'P & L '!E18+'P & L '!E19+'P & L '!E20 -> 37656.39 | F8: ='P & L '!F17+'P & L '!F18+'P & L '!F19+'P & L '!F20 -> 40755.1 | G8: ='P & L '!G17+'P & L '!G18+'P & L '!G19+'P & L '!G20 -> 8342.98
B9: COGS % Sales | C9: =C8/C5 -> 0.33833949 | D9: =D8/D5 -> 0.28497053 | E9: =E8/E5 -> 0.26458219 | F9: =F8/F5 -> 0.28426733 | G9: =G8/G5 -> 0.049542551
B11: Gross Profit | C11: =C5-C8 -> 72593.09 | D11: =D5-D8 -> 98854.19 | E11: =E5-E8 -> 104667.59 | F11: =F5-F8 -> 102613.82 | G11: =G5-G8 -> 160057.31
B12: Gross Margins | C12: =C11/C5 -> 0.66166051 | D12: =D11/D5 -> 0.71502947 | E12: =E11/E5 -> 0.73541781 | F12: =F11/F5 -> 0.71573267 | G12: =G11/G5 -> 0.95045745
B14: Selling & General Expense | C14: ='P & L '!C23+'P & L '!C21+'P & L '!C25 -> 47902.58 | D14: ='P & L '!D23+'P & L '!D21+'P & L '!D25 -> 62036.32 | E14: ='P & L '!E23+'P & L '!E21+'P & L '!E25 -> 56696.1 | F14: ='P & L '!F23+'P & L '!F21+('P & L '!F25-'P & L '!F26) -> 55550.81 | G14: ='P & L '!G23+'P & L '!G21+'P & L '!G25 -> 118815.32
B15: S&G Exp % Sales | C15: =C14/C5 -> 0.43661518 | D15: =D14/D5 -> 0.44871944 | E15: =E14/E5 -> 0.39835943 | F15: =F14/F5 -> 0.38746759 | G15: =G14/G5 -> 0.70555294
B17: EBITDA | C17: =C11-C14 -> 24690.51 | D17: =D11-D14 -> 36817.87 | E17: =E11-E14 -> 47971.49 | F17: =F11-F14 -> 47063.01 | G17: =G11-G14 -> 41241.99
B18: EBITDA Margins | C18: =C17/C5 -> 0.22504532 | D18: =D17/D5 -> 0.26631003 | E18: =E17/E5 -> 0.33705838 | F18: =F17/F5 -> 0.32826508 | G18: =G17/G5 -> 0.24490451
B20: Depreciation | C20: ='P & L '!C24 -> 4428.67 | D20: ='P & L '!D24 -> 4675.27 | E20: ='P & L '!E24 -> 6735.42 | F20: ='P & L '!F24 -> 9145.49 | G20: ='P & L '!G24 -> 10136.67
B21: Depreciation % of Sales | C21: =C20/C5 -> 0.040365771 | D21: =D20/D5 -> 0.033817037 | E21: =E20/E5 -> 0.047324562 | F21: =F20/F5 -> 0.063789906 | G21: =G20/G5 -> 0.060193899
B23: EBIT | C23: =IFERROR(C17-C20,0) -> 20261.84 | D23: =IFERROR(D17-D20,0) -> 32142.6 | E23: =IFERROR(E17-E20,0) -> 41236.07 | F23: =IFERROR(F17-F20,0) -> 37917.52 | G23: =IFERROR(G17-G20,0) -> 31105.32
B24: EBIT Margin | C24: =C23/C5 -> 0.18467955 | D24: =D23/D5 -> 0.23249299 | E24: =E23/E5 -> 0.28973382 | F24: =F23/F5 -> 0.26447517 | G24: =G23/G5 -> 0.18471061
B26: Interest | C26: ='P & L '!C22 -> 541.49 | D26: ='P & L '!D22 -> 684.31 | E26: ='P & L '!E22 -> 819.37 | F26: ='P & L '!F22 -> 883.65 | G26: ='P & L '!G22 -> 1216.26
B27: Interest % of Sales | C27: =C26/C5 -> 0.0049354911 | D27: =D26/D5 -> 0.0049497327 | E27: =E26/E5 -> 0.0057570762 | F27: =F26/F5 -> 0.0061634697 | G27: =G26/G5 -> 0.0072224341
B29: Other Income | C29: ='P & L '!C14 -> 3904.52 | D29: ='P & L '!D14 -> 6550.66 | E29: ='P & L '!E14 -> 7969.08 | F29: ='P & L '!F14 -> 9470.06 | G29: ='P & L '!G14 -> 11275.68
B31: Earnings Before Tax | C31: =IFERROR(C23-C26+C29,0) -> 23624.87 | D31: =IFERROR(D23-D26+D29,0) -> 38008.95 | E31: =IFERROR(E23-E26+E29,0) -> 48385.78 | F31: =IFERROR(F23-F26+F29,0) -> 46503.93 | G31: =IFERROR(G23-G26+G29,0) -> 41164.74
B32: EBT % Sales | C32: =C31/C5 -> 0.21533239 | D32: =D31/D5 -> 0.27492532 | E32: =E31/E5 -> 0.33996927 | F32: =F31/F5 -> 0.32436549 | G32: =G31/G5 -> 0.24444578
B34: Tax | C34: ='P & L '!C33 -> 6237.86 | D34: ='P & L '!D33 -> 9875.87 | E34: ='P & L '!E33 -> 11443.48 | F34: ='P & L '!F33 -> 11664.09 | G34: ='P & L '!G33 -> 10852.51
B35: Effective Tax Rate | C35: =C34/C31 -> 0.26403786 | D35: =D34/D31 -> 0.25983012 | E35: =E34/E31 -> 0.23650502 | F35: =F34/F31 -> 0.25081945 | G35: =G34/G31 -> 0.26363606
B37: Net Profit | C37: =IFERROR(C31-C34,0) -> 17387.01 | D37: =IFERROR(D31-D34,0) -> 28133.08 | E37: =IFERROR(E31-E34,0) -> 36942.3 | F37: =IFERROR(F31-F34,0) -> 34839.84 | G37: =IFERROR(G31-G34,0) -> 30312.23
B38: Net Margins | C38: =C37/C5 -> 0.15847649 | D38: =D37/D5 -> 0.20349144 | E38: =E37/E5 -> 0.25956483 | F38: =F37/F5 -> 0.24300832 | G38: =G37/G5 -> 0.18000106
B40: No. of Equity Shares (Cr) | C40: ='Balance Sheet '!C10/'Balance Sheet '!$I$10 -> 616.273 | D40: ='Balance Sheet '!D10/'Balance Sheet '!$I$10 -> 616.273 | E40: ='Balance Sheet '!E10/'Balance Sheet '!$I$10 -> 616.273 | F40: ='Balance Sheet '!F10/'Balance Sheet '!$I$10 -> 616.273 | G40: ='Balance Sheet '!G10/'Balance Sheet '!$I$10 -> 616.273
B42: Earnings Per Share | C42: =IFERROR(C37/C40,0) -> 28.213162 | D42: =IFERROR(D37/D40,0) -> 45.650353 | E42: =IFERROR(E37/E40,0) -> 59.9447 | F42: =IFERROR(F37/F40,0) -> 56.533127 | G42: =IFERROR(G37/G40,0) -> 49.186367
B43: EPS Growth % | D43: =IFERROR(D42/C42-1,0) -> 0.61805164 | E43: =IFERROR(E42/D42-1,0) -> 0.31312675 | F43: =IFERROR(F42/E42-1,0) -> -0.056911995 | G43: =IFERROR(G42/F42-1,0) -> -0.12995496
B45: Dividend per Share | C45: ='P & L '!C45/'Historical FS'!C40 -> 17.50002 | D45: ='P & L '!D45/'Historical FS'!D40 -> 23.250069 | E45: ='P & L '!E45/'Historical FS'!E40 -> 24.500051 | F45: ='P & L '!F45/'Historical FS'!F40 -> 26.350075 | G45: 0
B46: Dividend Payout Ratio | C46: =IFERROR(C45/C42,0) -> 0.62027859 | D46: =IFERROR(D45/D42,0) -> 0.50930755 | E46: =IFERROR(E45/E42,0) -> 0.40871088 | F46: =IFERROR(F45/F42,0) -> 0.46609973 | G46: =IFERROR(G45/G42,0) -> 0
B48: Retained Earnings | C48: =IFERROR(IF(C42>C45,1-C46,0),0) -> 0.37972141 | D48: =IFERROR(IF(D42>D45,1-D46,0),0) -> 0.49069245 | E48: =IFERROR(IF(E42>E45,1-E46,0),0) -> 0.59128912 | F48: =IFERROR(IF(F42>F45,1-F46,0),0) -> 0.53390027 | G48: =IFERROR(IF(G42>G45,1-G46,0),0) -> 1
B50: Balance Statement | C50: =C3 -> 2022 | D50: =D3 -> 2023 | E50: =E3 -> 2024 | F50: =F3 -> 2025 | G50: =G3 -> 2026
B51: Equity Share Capital | C51: ='Balance Sheet '!C11 -> 6162.73 | D51: ='Balance Sheet '!D11 -> 6162.73 | E51: ='Balance Sheet '!E11 -> 6162.73 | F51: ='Balance Sheet '!F11 -> 6162.73 | G51: ='Balance Sheet '!G11 -> 6162.73
B52: Reserves | C52: ='Balance Sheet '!C12 -> 36980.31 | D52: ='Balance Sheet '!D12 -> 51082.16 | E52: ='Balance Sheet '!E12 -> 76567.05 | F52: ='Balance Sheet '!F12 -> 92942.19 | G52: ='Balance Sheet '!G12 -> 112938.83
B53: Borrowings | C53: ='Balance Sheet '!C17+'Balance Sheet '!C23 -> 3309.76 | D53: ='Balance Sheet '!D17+'Balance Sheet '!D23 -> 4114.73 | E53: ='Balance Sheet '!E17+'Balance Sheet '!E23 -> 6289.02 | F53: ='Balance Sheet '!F17+'Balance Sheet '!F23 -> 8908.4 | G53: ='Balance Sheet '!G17+'Balance Sheet '!G23 -> 13821.46
B54: Other Liabilities | C54: ='Balance Sheet '!C18+'Balance Sheet '!C19+'Balance Sheet '!C20+'Balance Sheet '!C24+'Balance Sheet '!C25+'Balance Sheet '!C26 -> 133116.74 | D54: ='Balance Sheet '!D18+'Balance Sheet '!D19+'Balance Sheet '!D20+'Balance Sheet '!D24+'Balance Sheet '!D25+'Balance Sheet '!D26 -> 149076.35 | E54: ='Balance Sheet '!E18+'Balance Sheet '!E19+'Balance Sheet '!E20+'Balance Sheet '!E24+'Balance Sheet '!E25+'Balance Sheet '!E26 -> 147801.34 | F54: ='Balance Sheet '!F18+'Balance Sheet '!F19+'Balance Sheet '!F20+'Balance Sheet '!F24+'Balance Sheet '!F25+'Balance Sheet '!F26 -> 151339.28 | G54: ='Balance Sheet '!G18+'Balance Sheet '!G19+'Balance Sheet '!G20+'Balance Sheet '!G24+'Balance Sheet '!G25+'Balance Sheet '!G26 -> 150834.24
B55: Total Liabilities | C55: ='Balance Sheet '!C28 -> 180243.33 | D55: ='Balance Sheet '!D28 -> 211206.65 | E55: ='Balance Sheet '!E28 -> 237672.26 | F55: ='Balance Sheet '!F28 -> 260198.37 | G55: ='Balance Sheet '!G28 -> 285660.27
B57: Fixed Assets Net Block | C57: ='Balance Sheet '!C31+'Balance Sheet '!C32 -> 42803.41 | D57: ='Balance Sheet '!D31+'Balance Sheet '!D32 -> 47036.08 | E57: ='Balance Sheet '!E31+'Balance Sheet '!E32 -> 70618.62 | F57: ='Balance Sheet '!F31+'Balance Sheet '!F32 -> 79219.74 | G57: ='Balance Sheet '!G31+'Balance Sheet '!G32 -> 91846.09
B58: Capital Work in Progress | C58: ='Balance Sheet '!C33 -> 12713.73 | D58: ='Balance Sheet '!D33 -> 15262.62 | E58: ='Balance Sheet '!E33 -> 14738.66 | F58: ='Balance Sheet '!F33 -> 15888.64 | G58: ='Balance Sheet '!G33 -> 18818.58
...

Sheet Beta Calculation
B2: Date | C2: Nifty 50 Daily Returns | D2: COALINDIA.NS Daily Returns
B3: 44565 | C3: 1.02 | D3: -1.48
B4: 44566 | C4: 0.67 | D4: 0.46 | F4: Beta | G4: =G23 -> 0.88851666
B5: 44567 | C5: -1 | D5: 0.62
B6: 44568 | C6: 0.38 | D6: 1.49 | F6: SUMMARY OUTPUT
B7: 44571 | C7: 1.07 | D7: 2.39
B8: 44572 | C8: 0.29 | D8: -1.34 | F8: Regression Statistics
B9: 44573 | C9: 0.87 | D9: 0.5 | F9: Multiple R | G9: 0.43567516
B10: 44574 | C10: 0.25 | D10: 3.39 | F10: R Square | G10: 0.18981285
B11: 44575 | C11: -0.01 | D11: 0 | F11: Adjusted R Square | G11: 0.18906268
B12: 44578 | C12: 0.29 | D12: -0.64 | F12: Standard Error | G12: 1.613743
B13: 44579 | C13: -1.07 | D13: -1.77 | F13: Observations | G13: 1082
B14: 44580 | C14: -0.96 | D14: 1.93
B15: 44581 | C15: -1.01 | D15: 0.7 | F15: ANOVA
B16: 44582 | C16: -0.79 | D16: -3.82 | G16: df | H16: SS | I16: MS | J16: F | K16: Significance F
B17: 44585 | C17: -2.66 | D17: -1.54 | F17: Regression | G17: 1 | H17: 658.92006 | I17: 658.92006 | J17: 253.02534 | K17: 2.4008106e-51
B18: 44586 | C18: 0.75 | D18: 3.1 | F18: Residual | G18: 1080 | H18: 2812.4996 | I18: 2.6041663
B19: 44588 | C19: -0.97 | D19: -0.37 | F19: Total | G19: 1081 | H19: 3471.4197
B20: 44589 | C20: -0.05 | D20: 0.69
B21: 44592 | C21: 1.39 | D21: -1.14 | G21: Coefficients | H21: Standard Error | I21: t Stat | J21: P-value | K21: Lower 95% | L21: Upper 95% | M21: Lower 95.0% | N21: Upper 95.0%
B22: 44593 | C22: 1.37 | D22: 2.03 | F22: Intercept | G22: 0.12066618 | H22: 0.049092473 | I22: 2.4579364 | J22: 0.014129996 | K22: 0.024338743 | L22: 0.21699361 | M22: 0.024338743 | N22: 0.21699361
B23: 44594 | C23: 1.16 | D23: 0.49 | F23: X Variable 1 | G23: 0.88851666 | H23: 0.055857767 | I23: 15.90677 | J23: 2.4008106e-51 | K23: 0.77891462 | L23: 0.9981187 | M23: 0.77891462 | N23: 0.9981187
B24: 44595 | C24: -1.24 | D24: -1.56
B25: 44596 | C25: -0.25 | D25: -0.56
B26: 44599 | C26: -1.73 | D26: 0.34
B27: 44600 | C27: 0.31 | D27: -0.62
B28: 44601 | C28: 1.14 | D28: 5.41
B29: 44602 | C29: 0.81 | D29: -0.33
B30: 44603 | C30: -1.31 | D30: -0.92
B31: 44606 | C31: -3.06 | D31: -2.91
B32: 44607 | C32: 3.03 | D32: 1.24
B33: 44608 | C33: -0.17 | D33: 0.12
B34: 44609 | C34: -0.1 | D34: -0.49
B35: 44610 | C35: -0.16 | D35: 2.61
... B1084: 46168 | C1084: -0.49 | D1084: 0.03

Sheet WACC
B2: Cost of Capital-COAL INDIA
B4: Cost of capital
B5: As On Date:
B7: Cost of equity using CAPM:
B8: Risk-free rate | C8: 0.0668
B9: India default spread | C9: 0.0145
B10: Beta | C10: ='Beta Calculation'!G4 -> 0.88851666
B11: Market Return | C11: 0.12
B12: Equity risk premium | C12: =C11-C8 -> 0.0532
B13: Cost of equity | C13: =C8+(C10*C12) -> 0.11406909
B16: Cost of debt:
B17: Risk-free rate | C17: =C8 -> 0.0668
B18: Company credit rating
B19: Rating default spread | C19: 0.005
B20: Pre-tax cost of debt | C20: ='P & L '!G22/('Balance Sheet '!G17+'Balance Sheet '!G23) -> 0.087997939
B22: Marginal tax rate % | C22: 0.25
B23: Post-tax cost of debt | C23: =C20*(1-C22) -> 0.065998455
B26: Market value weights:
B27: Book value of Debt | C27: ='Balance Sheet '!G17+'Balance Sheet '!G23 -> 13821.46
B28: Share price (as on above date) | C28: 458
B29: No. of shares outstanding | C29: ='Historical FS'!G40 -> 616.273
B30: Market value of Equity | C30: =C28*C29 -> 282253.03
B33: D/E Ratio | C33: =IFERROR(C27/C30,0) -> 0.048968331
B34: weight of debt, wa | C34: =IFERROR(C27/(C27+C30),0) -> 0.046682373
B35: Weightof equity, we | C35: =IFERROR(C30/(C27+C30),0) -> 0.95331763
B37: Cost of Capital | C37: =IFERROR((C13*C35)+(C23*C34),0) -> 0.11182504

Sheet Assumptions
B2: Assumptions: COAL INDIA LTD
B4: Margins | C4: 2022 | D4: 2023 | E4: 2024 | F4: 2025 | G4: 2026 | I4: Median Of Revenue Growth
B5: EBITDA | C5: ='Historical FS'!C18 -> 0.22504532 | D5: ='Historical FS'!D18 -> 0.26631003 | E5: ='Historical FS'!E18 -> 0.33705838 | F5: ='Historical FS'!F18 -> 0.32826508 | G5: ='Historical FS'!G18 -> 0.24490451 | I5: =MEDIAN('Historical FS'!D6:G6) -> 0.10202405
B6: EBIT | C6: ='Historical FS'!C24 -> 0.18467955 | D6: ='Historical FS'!D24 -> 0.23249299 | E6: ='Historical FS'!E24 -> 0.28973382 | F6: ='Historical FS'!F24 -> 0.26447517 | G6: ='Historical FS'!G24 -> 0.18471061
B7: EBT | C7: ='Historical FS'!C32 -> 0.21533239 | D7: ='Historical FS'!D32 -> 0.27492532 | E7: ='Historical FS'!E32 -> 0.33996927 | F7: ='Historical FS'!F32 -> 0.32436549 | G7: ='Historical FS'!G32 -> 0.24444578
B8: Net Profit | C8: ='Historical FS'!C38 -> 0.15847649 | D8: ='Historical FS'!D38 -> 0.20349144 | E8: ='Historical FS'!E38 -> 0.25956483 | F8: ='Historical FS'!F38 -> 0.24300832 | G8: ='Historical FS'!G38 -> 0.18000106
B10: Historical Growth | C10: 2022 | D10: 2023 | E10: 2024 | F10: 2025 | G10: 2026
B11: Average Sales Growth | C11: =AVERAGE('Historical FS'!D6:G6) -> 0.11787692
B12: CAGR % | C12: =('Historical FS'!G5/'Historical FS'!C5)^(1/4)-1 -> 0.11306542 | D12: =('Historical FS'!G5/'Historical FS'!C5)^(1/4)-1 -> 0.11306542 | E12: (RRI Formula)
B14: Tax Rate | C14: 2022 | D14: 2023 | E14: 2024 | F14: 2025 | G14: 2026
B15: Effective Tax Rate | C15: ='Historical FS'!C35 -> 0.26403786 | D15: ='Historical FS'!D35 -> 0.25983012 | E15: ='Historical FS'!E35 -> 0.23650502 | F15: ='Historical FS'!F35 -> 0.25081945 | G15: ='Historical FS'!G35 -> 0.26363606 | I15: Average: | J15: =AVERAGE(C15:G15) -> 0.2549657
B16: Marginal Tax Rate | C16: 0.25
B18: Return On Capital Employed | C18: 2022 | D18: 2023 | E18: 2024 | F18: 2025 | G18: 2026
B19: EBIT*(1-T) | C19: ='Historical FS'!C23*(1-$C$16) -> 15196.38 | D19: ='Historical FS'!D23*(1-$C$16) -> 24106.95 | E19: ='Historical FS'!E23*(1-$C$16) -> 30927.053 | F19: ='Historical FS'!F23*(1-$C$16) -> 28438.14 | G19: ='Historical FS'!G23*(1-$C$16) -> 23328.99
B20: Book Equity | C20: ='Historical FS'!C51+'Historical FS'!C52 -> 43143.04 | D20: ='Historical FS'!D51+'Historical FS'!D52 -> 57244.89 | E20: ='Historical FS'!E51+'Historical FS'!E52 -> 82729.78 | F20: ='Historical FS'!F51+'Historical FS'!F52 -> 99104.92 | G20: ='Historical FS'!G51+'Historical FS'!G52 -> 119101.56
B21: Book Debt | C21: ='Historical FS'!C53 -> 3309.76 | D21: ='Historical FS'!D53 -> 4114.73 | E21: ='Historical FS'!E53 -> 6289.02 | F21: ='Historical FS'!F53 -> 8908.4 | G21: ='Historical FS'!G53 -> 13821.46
B22: Cash and Equivalents | C22: ='Historical FS'!C65 -> 29179.45 | D22: ='Historical FS'!D65 -> 39921.85 | E22: ='Historical FS'!E65 -> 30235.17 | F22: ='Historical FS'!F65 -> 34215.31 | G22: ='Historical FS'!G65 -> 52574.37
B23: Capital Employed | C23: =C20+C21-C22 -> 17273.35 | D23: =D20+D21-D22 -> 21437.77 | E23: =E20+E21-E22 -> 58783.63 | F23: =F20+F21-F22 -> 73798.01 | G23: =G20+G21-G22 -> 80348.65
B25: Pre/Post Tax Return on Capital Employed | C25: 2022 | D25: 2023 | E25: 2024 | F25: 2025 | G25: 2026
B26: Pre Tax ROCE | C26: =IFERROR('Historical FS'!C23/C23,0) -> 1.1730116 | D26: =IFERROR('Historical FS'!D23/D23,0) -> 1.4993444 | E26: =IFERROR('Historical FS'!E23/E23,0) -> 0.701489 | F26: =IFERROR('Historical FS'!F23/F23,0) -> 0.51380139 | G26: =IFERROR('Historical FS'!G23/G23,0) -> 0.38712934
B27: Post Tax ROCE | C27: =IFERROR(C19/C23,0) -> 0.8797587 | D27: =IFERROR(D19/D23,0) -> 1.1245083 | E27: =IFERROR(E19/E23,0) -> 0.52611675 | F27: =IFERROR(F19/F23,0) -> 0.38535104 | G27: =IFERROR(G19/G23,0) -> 0.29034701
B29: Growth in EBIT (Reinvestment-based) | C29: =FCFF!C22*G27 -> 0.13590449

Sheet Fixed Assets Schedule
B2: Fixed Asset Schedule
B3: Particulars | C3: 2022 | D3: 2023 | E3: 2024 | F3: 2025 | G3: 2026
B4: Opening Balance | D4: =C8 -> 42803.41 | E4: =D8 -> 47036.08 | F4: =E8 -> 70618.62 | G4: =F8 -> 79219.74
B5: Add: Gross Additions (Capex) | D5: =D8-C8+D7 -> 8907.94 | E5: =E8-D8+E7 -> 30317.96 | F5: =F8-E8+F7 -> 17746.61 | G5: =G8-F8+G7 -> 22763.02
B6: Fixed Assets Before Depreciation | D6: =D4+D5 -> 51711.35 | E6: =E4+E5 -> 77354.04 | F6: =F4+F5 -> 88365.23 | G6: =G4+G5 -> 101982.76
B7: Less: Depreciation | C7: ='Historical FS'!C20 -> 4428.67 | D7: ='Historical FS'!D20 -> 4675.27 | E7: ='Historical FS'!E20 -> 6735.42 | F7: ='Historical FS'!F20 -> 9145.49 | G7: ='Historical FS'!G20 -> 10136.67
B8: Closing Balance Net Block | C8: ='Balance Sheet '!C31+'Balance Sheet '!C32 -> 42803.41 | D8: ='Balance Sheet '!D31+'Balance Sheet '!D32 -> 47036.08 | E8: ='Balance Sheet '!E31+'Balance Sheet '!E32 -> 70618.62 | F8: ='Balance Sheet '!F31+'Balance Sheet '!F32 -> 79219.74 | G8: ='Balance Sheet '!G31+'Balance Sheet '!G32 -> 91846.09
B10: Net Capital Expenditure | D10: =D8-C8 -> 4232.67 | E10: =E8-D8 -> 23582.54 | F10: =F8-E8 -> 8601.12 | G10: =G8-F8 -> 12626.35
B11: Net Capex / Sales % | D11: =IFERROR(D10/'Historical FS'!D5,0) -> 0.030615635 | E11: =IFERROR(E10/'Historical FS'!E5,0) -> 0.16569618 | F11: =IFERROR(F10/'Historical FS'!F5,0) -> 0.059992919 | G11: =IFERROR(G10/'Historical FS'!G5,0) -> 0.074978196
B13: Median Net Capex / Sales % | C13: =MEDIAN(D11:G11) -> 0.067485558
B14: Average Net Capex / Sales % | C14: =AVERAGE(D11:G11) -> 0.082820733

Sheet Working Capital Changes
B2: Changes in Working Capital
B3: Particulars | C3: FY 2022 | D3: FY 2023 | E3: FY 2024 | F3: FY 2025 | G3: FY 2026
B4: Inventories | C4: ='Balance Sheet '!C44 -> 7075.68 | D4: ='Balance Sheet '!D44 -> 8154.68 | E4: ='Balance Sheet '!E44 -> 10177.23 | F4: ='Balance Sheet '!F44 -> 12613.7 | G4: ='Balance Sheet '!G44 -> 15654.3
B5: Receivables | C5: ='Balance Sheet '!C45 -> 11367.68 | D5: ='Balance Sheet '!D45 -> 13060.48 | E5: ='Balance Sheet '!E45 -> 13255.75 | F5: ='Balance Sheet '!F45 -> 12727.72 | G5: ='Balance Sheet '!G45 -> 14120.59
B6: Payables | C6: ='Balance Sheet '!C24 -> 8591.78 | D6: ='Balance Sheet '!D24 -> 8549.18 | E6: ='Balance Sheet '!E24 -> 8385.65 | F6: ='Balance Sheet '!F24 -> 10205.63 | G6: ='Balance Sheet '!G24 -> 12554.39
B7: Non-Cash Working Capital | C7: =C4+C5-C6 -> 9851.58 | D7: =D4+D5-D6 -> 12665.98 | E7: =E4+E5-E6 -> 15047.33 | F7: =F4+F5-F6 -> 15135.79 | G7: =G4+G5-G6 -> 17220.5
B9: Change in Working Capital | D9: =D7-C7 -> 2814.4 | E9: =E7-D7 -> 2381.35 | F9: =F7-E7 -> 88.46 | G9: =G7-F7 -> 2084.71
B10: Change in WC / % of Sales | D10: =IFERROR(D9/'Historical FS'!D5,0) -> 0.020357042 | E10: =IFERROR(E9/'Historical FS'!E5,0) -> 0.016731896 | F10: =IFERROR(F9/'Historical FS'!F5,0) -> 0.0006170096 | G10: =IFERROR(G9/'Historical FS'!G5,0) -> 0.012379492
B12: Median Change in WC / % of Sales | C12: =MEDIAN(D10:G10) -> 0.014555694
B13: Average Change in WC / % of Sales | C13: =AVERAGE(D10:G10) -> 0.01252136

Sheet FCFF
B2: FCFF Analysis - COAL INDIA LTD
B4: Particulars | C4: 2022 | D4: 2023 | E4: 2024 | F4: 2025 | G4: 2026
B5: EBIT (INR Cr.)
B6: EBIT | C6: ='Historical FS'!C23 -> 20261.84 | D6: ='Historical FS'!D23 -> 32142.6 | E6: ='Historical FS'!E23 -> 41236.07 | F6: ='Historical FS'!F23 -> 37917.52 | G6: ='Historical FS'!G23 -> 31105.32
B7: Less: Tax on EBIT (25%) | C7: =C6*Assumptions!$C$16 -> 5065.46 | D7: =D6*Assumptions!$C$16 -> 8035.65 | E7: =E6*Assumptions!$C$16 -> 10309.018 | F7: =F6*Assumptions!$C$16 -> 9479.38 | G7: =G6*Assumptions!$C$16 -> 7776.33
B8: EBIT × (1 - Tax Rate) | C8: =C6-C7 -> 15196.38 | D8: =D6-D7 -> 24106.95 | E8: =E6-E7 -> 30927.053 | F8: =F6-F7 -> 28438.14 | G8: =G6-G7 -> 23328.99
B10: Reinvestment
B11: Less: Net Capital Expenditure | D11: ='Fixed Assets Schedule'!D10 -> 4232.67 | E11: ='Fixed Assets Schedule'!E10 -> 23582.54 | F11: ='Fixed Assets Schedule'!F10 -> 8601.12 | G11: ='Fixed Assets Schedule'!G10 -> 12626.35
B12: Less: Change in Working Capital | D12: ='Working Capital Changes'!D9 -> 2814.4 | E12: ='Working Capital Changes'!E9 -> 2381.35 | F12: ='Working Capital Changes'!F9 -> 88.46 | G12: ='Working Capital Changes'!G9 -> 2084.71
B13: Total Reinvestment | D13: =IFERROR(D11+D12,0) -> 7047.07 | E13: =IFERROR(E11+E12,0) -> 25963.89 | F13: =IFERROR(F11+F12,0) -> 8689.58 | G13: =IFERROR(G11+G12,0) -> 14711.06
B15: Free Cash Flow to Firm (FCFF)
B16: FCFF (INR Cr.) | D16: =IFERROR(D8-D13,0) -> 17059.88 | E16: =IFERROR(E8-E13,0) -> 4963.1625 | F16: =IFERROR(F8-F13,0) -> 19748.56 | G16: =IFERROR(G8-G13,0) -> 8617.93
B18: Reinvestment Metrics
B19: Reinvestment Rate % | D19: =IFERROR(D13/D8,0) -> 0.29232524 | E19: =IFERROR(E13/E8,0) -> 0.83952035 | F19: =IFERROR(F13/F8,0) -> 0.30556077 | G19: =IFERROR(G13/G8,0) -> 0.63059138
B21: Summary Statistics
B22: Median Reinvestment Rate | C22: =MEDIAN(D19:G19) -> 0.46807608
B23: Average Reinvestment Rate | C23: =AVERAGE(D19:G19) -> 0.51699944

Sheet Forecasting
B2: Forecasting
B4: Sales Forecasting | G4: EBITDA Forecasting | L4: EPS Forecasting
B5: Year Weight | C5: Year | D5: Sales (INR Cr.) | E5: Sales Growth | G5: Year Weight | H5: Year | I5: EBITDA (INR Cr.) | J5: EBITDA Growth | L5: Year Weight | M5: Year | N5: EPS (INR) | O5: EPS Growth
B6: 1 | C6: 2022 | D6: {=TRANSPOSE('Historical FS'!C5:G5)} -> 109713.5 | G6: 1 | H6: 2022 | I6: {=TRANSPOSE('Historical FS'!C17:G17)} -> 24690.51 | L6: 1 | M6: 2022 | N6: {=TRANSPOSE('Historical FS'!C42:G42)} -> 28.213162
B7: 2 | C7: 2023 | D7: 138251.91 | E7: =(D7/D6)-1 -> 0.26011758 | G7: 2 | H7: 2023 | I7: 36817.87 | J7: =(I7/I6)-1 -> 0.49117495 | L7: 2 | M7: 2023 | N7: 45.650353 | O7: =IFERROR(N7/N6-1,0) -> 0.61805164
B8: 3 | C8: 2024 | D8: 142323.98 | E8: =(D8/D7)-1 -> 0.029453987 | G8: 3 | H8: 2024 | I8: 47971.49 | J8: =(I8/I7)-1 -> 0.30294039 | L8: 3 | M8: 2024 | N8: 59.9447 | O8: =IFERROR(N8/N7-1,0) -> 0.31312675
B9: 4 | C9: 2025 | D9: 143368.92 | E9: =(D9/D8)-1 -> 0.0073419813 | G9: 4 | H9: 2025 | I9: 47063.01 | J9: =(I9/I8)-1 -> -0.018937915 | L9: 4 | M9: 2025 | N9: 56.533127 | O9: =IFERROR(N9/N8-1,0) -> -0.056911995
B10: 5 | C10: 2026 | D10: 168400.29 | E10: =(D10/D9)-1 -> 0.17459412 | G10: 5 | H10: 2026 | I10: 41241.99 | J10: =(I10/I9)-1 -> -0.12368567 | L10: 5 | M10: 2026 | N10: 49.186367 | O10: =IFERROR(N10/N9-1,0) -> -0.12995496
B11: 6 | C11: 2027 | D11: =FORECAST(B11,$D$6:$D$10,$B$6:$B$10) -> 177158.9 | E11: =(D11/D10)-1 -> 0.052010641 | G11: 6 | H11: 2027 | I11: =FORECAST(G11,$I$6:$I$10,$G$6:$G$10) -> 52561.404 | J11: =(I11/I10)-1 -> 0.27446333 | L11: 6 | M11: 2027 | N11: =FORECAST(L11,$N$6:$N$10,$L$6:$L$10) -> 63.754297 | O11: =IFERROR(N11/N10-1,0) -> 0.29617821
B12: 7 | C12: 2028 | D12: =FORECAST(B12,$D$6:$D$10,$B$6:$B$10) -> 189407.96 | E12: =(D12/D11)-1 -> 0.069141653 | G12: 7 | H12: 2028 | I12: =FORECAST(G12,$I$6:$I$10,$G$6:$G$10) -> 56896.214 | J12: =(I12/I11)-1 -> 0.082471351 | L12: 7 | M12: 2028 | N12: =FORECAST(L12,$N$6:$N$10,$L$6:$L$10) -> 69.037216 | O12: =IFERROR(N12/N11-1,0) -> 0.082863723
B13: 8 | C13: 2029 | D13: =FORECAST(B13,$D$6:$D$10,$B$6:$B$10) -> 201657.02 | E13: =(D13/D12)-1 -> 0.064670245 | G13: 8 | H13: 2029 | I13: =FORECAST(G13,$I$6:$I$10,$G$6:$G$10) -> 61231.024 | J13: =(I13/I12)-1 -> 0.076188022 | L13: 8 | M13: 2029 | N13: =FORECAST(L13,$N$6:$N$10,$L$6:$L$10) -> 74.320134 | O13: =IFERROR(N13/N12-1,0) -> 0.076522762
B14: 9 | C14: 2030 | D14: =FORECAST(B14,$D$6:$D$10,$B$6:$B$10) -> 213906.07 | E14: =(D14/D13)-1 -> 0.060742043 | G14: 9 | H14: 2030 | I14: =FORECAST(G14,$I$6:$I$10,$G$6:$G$10) -> 65565.834 | J14: =(I14/I13)-1 -> 0.070794341 | L14: 9 | M14: 2030 | N14: =FORECAST(L14,$N$6:$N$10,$L$6:$L$10) -> 79.603053 | O14: =IFERROR(N14/N13-1,0) -> 0.071083274
B15: 10 | C15: 2031 | D15: =FORECAST(B15,$D$6:$D$10,$B$6:$B$10) -> 226155.13 | E15: =(D15/D14)-1 -> 0.057263727 | G15: 10 | H15: 2031 | I15: =FORECAST(G15,$I$6:$I$10,$G$6:$G$10) -> 69900.644 | J15: =(I15/I14)-1 -> 0.066113854 | L15: 10 | M15: 2031 | N15: =FORECAST(L15,$N$6:$N$10,$L$6:$L$10) -> 84.885971 | O15: =IFERROR(N15/N14-1,0) -> 0.066365777

Sheet Growth Scenarios
B2: Growth Scenarios
B5: Scenario 1: High Growth
B6: INR Cr. | C6: LTM | D6: Y1E | E6: Y2E | F6: Y3E | G6: Y4W | H6: Y5E | I6: Y6E | J6: Y7E | K6: Y8E | L6: Y9E | M6: Y10E | O6: Average Revenue Growth | P6: =Assumptions!I5 -> 0.10202405
B7: Sales | C7: ='Historical FS'!G5 -> 168400.29 | D7: =C7*(1+D8) -> 185581.17 | E7: =D7*(1+E8) -> 203788.59 | F7: =E7*(1+F8) -> 222984.76 | G7: =F7*(1+G8) -> 243116.42 | H7: =G7*(1+H8) -> 264114.13 | I7: =H7*(1+I8) -> 285891.69 | J7: =I7*(1+J8) -> 308346.01 | K7: =J7*(1+K8) -> 331357.12 | ... M7: =L7*(1+M8) -> 378488.52 | O7: Risk Free Rate | P7: =WACC!C17 -> 0.0668
B8: Sales Growth % | D8: =P6 -> 0.10202405 | E8: =D8-$P$9 -> 0.098110269 | F8: =E8-$P$9 -> 0.094196485 | G8: =F8-$P$9 -> 0.090282701 | H8: =G8-$P$9 -> 0.086368918 | I8: =H8-$P$9 -> 0.082455134 | J8: =I8-$P$9 -> 0.078541351 | K8: =J8-$P$9 -> 0.074627567 | L8: =K8-$P$9 -> 0.070713784 | M8: =L8-$P$9 -> 0.0668 | P8: =P6-P7 -> 0.035224052
O9: Growth Per Year | P9: =P8/9 -> 0.0039137836
B10: Scenario 2: Average Growth
B11: INR Cr. | C11: LTM | D11: Y1E | E11: Y2E | F11: Y3E | G11: Y4W | H11: Y5E | I11: Y6E | J11: Y7E | K11: Y8E | L11: Y9E | M11: Y10E | O11: Average Revenue Growth | P11: =Assumptions!C11 -> 0.11787692
B12: Sales | C12: =C7 -> 168400.29 | D12: =C12*(1+D13) -> 188250.8 | E12: =D12*(1+E13) -> 209372.86 | F12: =E12*(1+F13) -> 231676.61 | G12: =F12*(1+G13) -> 255041.49 | H12: =G12*(1+H13) -> 279315.34 | I12: =H12*(1+I13) -> 304314.3 | J12: =I12*(1+J13) -> 329823.64 | K12: =J12*(1+K13) -> 355599.5 | ... M12: =L12*(1+M13) -> 406847.28 | O12: Risk Free Rate | P12: =WACC!C8 -> 0.0668
B13: Sales Growth % | D13: =P11 -> 0.11787692 | E13: =D13-$P$14 -> 0.1122017 | F13: =E13-$P$14 -> 0.10652649 | G13: =F13-$P$14 -> 0.10085128 | H13: =G13-$P$14 -> 0.095176065 | I13: =H13-$P$14 -> 0.089500852 | J13: =I13-$P$14 -> 0.083825639 | K13: =J13-$P$14 -> 0.078150426 | L13: =K13-$P$14 -> 0.072475213 | M13: =L13-$P$14 -> 0.0668 | P13: =P11-P12 -> 0.051076916
O14: Growth Per Year | P14: =P13/9 -> 0.0056752129
B15: Scenario 3: EBIT Growth
B16: INR Cr. | C16: LTM | D16: Y1E | E16: Y2E | F16: Y3E | G16: Y4W | H16: Y5E | I16: Y6E | J16: Y7E | K16: Y8E | L16: Y9E | M16: Y10E | O16: Average Revenue Growth | P16: =Assumptions!C29 -> 0.13590449
B17: Sales | C17: =C12 -> 168400.29 | D17: =C17*(1+D18) -> 191286.65 | E17: =D17*(1+E18) -> 215814.61 | F17: =E17*(1+F18) -> 241830.61 | G17: =F17*(1+G18) -> 269125.95 | H17: =G17*(1+H18) -> 297435.68 | I17: =H17*(1+I18) -> 326439.56 | J17: =I17*(1+J18) -> 355765.2 | K17: =J17*(1+K18) -> 384993.64 | ... M17: =L17*(1+M18) -> 441300.28 | O17: Risk Free Rate | P17: =WACC!C8 -> 0.0668
B18: Sales Growth % | D18: =P16 -> 0.13590449 | E18: =D18-$P$19 -> 0.12822621 | F18: =E18-$P$19 -> 0.12054793 | G18: =F18-$P$19 -> 0.11286966 | H18: =G18-$P$19 -> 0.10519138 | I18: =H18-$P$19 -> 0.097513106 | J18: =I18-$P$19 -> 0.089834829 | K18: =J18-$P$19 -> 0.082156553 | L18: =K18-$P$19 -> 0.074478276 | M18: =L18-$P$19 -> 0.0668 | P18: =P16-P17 -> 0.069104487
O19: Growth Per Year | P19: =P18/9 -> 0.0076782764
B20: Live Scenario | C20: 2
B21: INR Cr. | C21: LTM | D21: Y1E | E21: Y2E | F21: Y3E | G21: Y4W | H21: Y5E | I21: Y6E | J21: Y7E | K21: Y8E | L21: Y9E | M21: Y10E
B22: Sales | C22: =C7 -> 168400.29 | D22: =C22*(1+D23) -> 188250.8 | E22: =D22*(1+E23) -> 209372.86 | F22: =E22*(1+F23) -> 231676.61 | G22: =F22*(1+G23) -> 255041.49 | H22: =G22*(1+H23) -> 279315.34 | I22: =H22*(1+I23) -> 304314.3 | J22: =I22*(1+J23) -> 329823.64 | K22: =J22*(1+K23) -> 355599.5 | ... M22: =L22*(1+M23) -> 406847.28
B23: Sales Growth % | D23: =CHOOSE($C$20,D8,D13,D18) -> 0.11787692 | E23: =CHOOSE($C$20,E8,E13,E18) -> 0.1122017 | F23: =CHOOSE($C$20,F8,F13,F18) -> 0.10652649 | G23: =CHOOSE($C$20,G8,G13,G18) -> 0.10085128 | H23: =CHOOSE($C$20,H8,H13,H18) -> 0.095176065 | I23: =CHOOSE($C$20,I8,I13,I18) -> 0.089500852 | J23: =CHOOSE($C$20,J8,J13,J18) -> 0.083825639 | K23: =CHOOSE($C$20,K8,K13,K18) -> 0.078150426 | ... M23: =CHOOSE($C$20,M8,M13,M18) -> 0.0668

Sheet DDM Valuation
B2: Dividend Discount Model (DDM) Valuation
B5: COST OF EQUITY
B6: Risk-Free Rate (Rf) | C6: =WACC!C8 -> 0.0668
B7: Beta (β) | C7: =WACC!C10 -> 0.88851666
B8: Market Return (Rm) | C8: =WACC!C11 -> 0.12
B9: Equity Risk Premium (ERP) | C9: =WACC!C12 -> 0.0532
B10: Cost of Equity (Ke) | C10: =WACC!C13 -> 0.11406909
B12: HISTORICAL DIVIDEND & EARNINGS
B13: Particulars | C13: 2022 | D13: 2023 | E13: 2024 | F13: 2025 | G13: 2026
B14: Earnings Per Share (EPS) | C14: ='Historical FS'!C42 -> 28.213162 | D14: ='Historical FS'!D42 -> 45.650353 | E14: ='Historical FS'!E42 -> 59.9447 | F14: ='Historical FS'!F42 -> 56.533127 | G14: ='Historical FS'!G42 -> 49.186367
B15: Dividend Per Share (DPS) | C15: ='Historical FS'!C45 -> 17.50002 | D15: ='Historical FS'!D45 -> 23.250069 | E15: ='Historical FS'!E45 -> 24.500051 | F15: ='Historical FS'!F45 -> 26.350075 | G15: ='Historical FS'!G45 -> 0
B16: Dividend Payout Ratio | C16: ='Historical FS'!C46 -> 0.62027859 | D16: ='Historical FS'!D46 -> 0.50930755 | E16: ='Historical FS'!E46 -> 0.40871088 | F16: ='Historical FS'!F46 -> 0.46609973 | G16: ='Historical FS'!G46 -> 0
B17: Retention Ratio (b) | C17: ='Historical FS'!C48 -> 0.37972141 | D17: ='Historical FS'!D48 -> 0.49069245 | E17: ='Historical FS'!E48 -> 0.59128912 | F17: ='Historical FS'!F48 -> 0.53390027 | G17: ='Historical FS'!G48 -> 1
B18: Return on Equity (ROE) | C18: ='Ratio Analysis'!C27 -> 0.39681123 | D18: ='Ratio Analysis'!D27 -> 0.48492293 | E18: ='Ratio Analysis'!E27 -> 0.44198923 | F18: ='Ratio Analysis'!F27 -> 0.34857028 | G18: ='Ratio Analysis'!G27 -> 0.25050484
B19: Sustainable Growth | C19: ='Ratio Analysis'!C28 -> 0.15067772 | D19: ='Ratio Analysis'!D28 -> 0.23794802 | E19: ='Ratio Analysis'!E28 -> 0.26134342 | F19: ='Ratio Analysis'!F28 -> 0.18610177 | G19: ='Ratio Analysis'!G28 -> 0.25050484
B21: DDM ASSUMPTIONS
B22: Stage 1 Assumptions ( High Growth Phase: Year 1–5 ) | F22: Stage 2 Assumptions (Terminal Phase)
B23: Base DPS 2025 Actual | E23: ='Historical FS'!F45 -> 26.350075 | F23: Terminal Growth Rate | I23: 0.04
B24: Stage 1 Growth Rate | E24: 0.08 | F24: Cost of Equity | I24: =C10 -> 0.11406909
B25: Dividend Payout | E25: ='Historical FS'!F46 -> 0.46609973
B26: Cost of Equity (Ke) | E26: =C10 -> 0.11406909
B28: TWO-STAGE DDM
B29: Particulars | C29: 2026 | D29: 2027 | E29: 2028 | F29: 2029 | G29: 2030 | H29: 2031 | I29: 2032 | J29: 2033 | K29: 2034 | L29: 2035 | M29: 2036 | N29: Terminal Value
C30: STAGE 1: High Growth Phase | H30: STAGE 2: Stable Growth Phase
B31: Period | C31: 1 | D31: 2 | E31: 3 | F31: 4 | G31: 5 | H31: 6 | I31: 7 | J31: 8 | K31: 9 | L31: 10 | M31: 10
B32: Growth Rate Applied | C32: =$E$24 -> 0.08 | D32: =$E$24 -> 0.08 | E32: =$E$24 -> 0.08 | F32: =$E$24 -> 0.08 | G32: =$E$24 -> 0.08 | H32: =$I$23 -> 0.04 | I32: =$I$23 -> 0.04 | J32: =$I$23 -> 0.04 | K32: =$I$23 -> 0.04 | L32: =$I$23 -> 0.04 | M32: =$I$23 -> 0.04 | N32: =$I$23 -> 0.04
