Workbook
Name UPDATE: 'Data Sheet'!$E$1

Sheet Company Overview
B1: DABUR INDIA LIMITED
B2: Sector : FMCG | Industry : Household & Personal Products
B3: Section | C3: Points for Equity Research
B4: Company Name | C4: Dabur India Ltd
B5: Industry | C5: FMCG / Consumer Defensive
B6: Founded | C6: 1884
B7: Business Type | C7: Ayurvedic & Natural Healthcare Company
B8: Presence | C8: 120+ Countries
B9: Core Segments | C9: Hair Care, Oral Care, Healthcare, Foods & Beverages, Home Care
B10: Key Brands | C10: Dabur Amla, Real, Dabur Red, Hajmola, Chyawanprash, Odonil
B11: Business Strength | C11: Strong Brand Value + Wide Distribution Network
B12: Competitive Advantage | C12: Ayurveda positioning, consumer trust, repeat purchases
B13: Revenue Drivers | C13: Rural expansion, premiumisation, wellness products, e-commerce
B14: Future Growth Focus | C14: Health & Wellness, Functional Beverages, Premium Products
B15: Management Strategy | C15: Double-digit CAGR target till FY28
B16: FY25 Revenue | C16: ₹12,563 Cr
B17: FY25 Operating Profit | C17: ₹2,317 Cr
B18: FY25 PAT | C18: ₹1,768 Cr
B19: International Business Growth | C19: 0.172
B20: ESG Highlights | C20: 61% renewable energy usage, 87% recyclable packaging
B21: Key Positives | C21: Stable cash flows, strong margins, defensive business model
B22: Risks | C22: Competition, inflation, changing consumer demand
B23: Valuation Methods | C23: DCF, Relative Valuation, FCFF
B24: Why Premium Valuation? | C24: Predictable earnings and strong brand loyalty
B25: Analyst View | C25: Stable long-term FMCG company with consistent growth potential
B27: Address | C27: Dabur Registered Office:8/3, Asaf Ali Road, New Delhi – 110002

Sheet Promoters
B2: Statement showing shareholding pattern of the Promoter and Promoter Group
B3: Category of shareholder | C3: Shareholding as a % of total no. of shares (calculated as per SCRR, 1957)As a % of (A+B+C2) | D3: Number of Voting Rights held in each class of securities
D4: Class eg: X | E4: Total
B6: A1) Indian | C6: 0 | D6: - | E6: 0
B7: Individuals/Hindu undivided Family | C7: 0.09 | D7: 1570625 | E7: 0.09
B8: ASHOK CHAND BURMAN & BROS (ANAND CHAND BURMAN) (HUF) | C8: 0 | D8: 30000 | E8: 0
B9: GYAN CHAND BURMAN & OTHERS (AMIT BURMAN) (HUF) | C9: 0 | D9: 30000 | E9: 0
B10: PRADIP BURMAN & ORS (PRADIP BURMAN) (HUF) | C10: 0 | D10: 30000 | E10: 0
B11: VIVEK CHAND BURMAN | C11: 0 | D11: 15000 | E11: 0
B12: GAURI TANDON | C12: 0.04 | D12: 677995 | E12: 0.04
B13: PRADIP BURMAN | C13: 0.03 | D13: 597630 | E13: 0.03
B14: SHIVANI BURMAN | C14: 0 | D14: 30000 | E14: 0
B15: ASHA BURMAN | C15: 0.01 | D15: 154000 | E15: 0.01
B16: EISHANA BURMAN | C16: 0 | D16: 6000 | E16: 0
B17: AMIT BURMAN | C17: 0 | D17: - | E17: 0
B18: ADITYA BURMAN | C18: 0 | D18: - | E18: 0
B19: ARIANA BURMAN | C19: 0 | D19: - | E19: 0
B20: DIVYA BURMAN | C20: 0 | D20: - | E20: 0
B21: ADHIRAJ BURMAN | C21: 0 | D21: - | E21: 0
B22: DIYA BURMAN | C22: 0 | D22: - | E22: 0
B23: SANDEEP TANDON | C23: 0 | D23: - | E23: 0
B24: ARMAAN TANDON | C24: 0 | D24: - | E24: 0
B25: POOJA BURMAN | C25: 0 | D25: - | E25: 0
B26: SUMATI RAVI RAHEJA | C26: 0 | D26: - | E26: 0
B27: RAMAN SOOD | C27: 0 | D27: - | E27: 0
B28: UMESH TALWAR | C28: 0 | D28: - | E28: 0
... B31: SIDHARTH BURMAN HUF | C31: 0 | D31: - | E31: 0
B32: Any Other (specify) | C32: 66.09 | D32: 1172228360 | E32: 66.09
B33: VIC ENTERPRISES PVT LTD | C33: 12.28 | D33: 217794000 | E33: 12.28
B34: RATNA COMMERCIAL ENTERPRISES PRIVATE LIMITED | C34: 8.99 | D34: 159405604 | E34: 8.99
B35: CHOWDRY ASSOCIATES | C35: 11.79 | D35: 209083800 | E35: 11.79
B36: SAHIWAL INVESTMENT AND TRADING COMPANY | C36: 0 | D36: 15000 | E36: 0
B37: BURMANS FINVEST PRIVATE LIMITED | C37: 2.99 | D37: 53012986 | E37: 2.99
B38: MILKY INVESTMENT AND TRADING COMPANY | C38: 5.98 | D38: 106147503 | E38: 5.98
B39: GYAN ENTERPRISES PVT LTD | C39: 10.9 | D39: 193379980 | E39: 10.9
B40: WINDY INVESTMENTS PRIVATE LIMITED | C40: 1 | D40: 17670995 | E40: 1
B41: M.B. FINMART PRIVATE LIMITED | C41: 1.49 | D41: 26506492 | E41: 1.49
B42: PURAN ASSOCIATES PRIVATE LIMITED | C42: 10.67 | D42: 189212000 | E42: 10.67
B43: BURMAN BROTHERS, PARTNERSHIP FIRM | C43: 0 | D43: - | E43: 0
B44: ASIA PACIFIC HEALTHCARE ADVISORS LLP | C44: 0 | D44: - | E44: 0
...

Sheet Public
B2: Statement showing shareholding pattern of the Public shareholder
B4: Category & Name of the Shareholders | C4: No. of shareholder | D4: No. of fully paid up equity shares held | E4: Total no. shares held | F4: Shareholding % calculated as per SCRR, 1957 As a % of (A+B+C2) | G4: No. of Voting Rights | H4: Total as a % of Total Voting right | I4: Total No. Of shares on fully diluted basis (including warrants, ESOP, Convertible Securities etc.) | J4: Shareholding , as a % assuming full conversion of convertible securities ( as a percentage of diluted share capital)As a % of (A+B+C2) | K4: No. of equity shares held in dematerialized form(Not Applicable)
B7: Institutions | C7: 0 | D7: 0 | E7: - | F7: 0 | G7: - | H7: 0 | I7: - | J7: 0 | K7: -
B8: B2) Institutions (Domestic) | C8: 0 | D8: 0 | E8: - | F8: 0 | G8: - | H8: 0 | I8: - | J8: 0 | K8: -
B9: Mutual Funds/ | C9: 35 | D9: 125909430 | E9: 125909430 | F9: 7.1 | G9: 125909430 | H9: 7.1 | I9: 125909430 | J9: 7.09 | K9: 125909430
B10: SBI LARGE & MIDCAP FUND | C10: 1 | D10: 30784597 | E10: 30784597 | F10: 1.74 | G10: 30784597 | H10: 1.74 | I10: 30784597 | J10: 1.73 | K10: 30784597
B11: HDFC TRUSTEE COMPANY LTD. A/C HDFC LARGE CAP FUND | C11: 1 | D11: 45904492 | E11: 45904492 | F11: 2.59 | G11: 45904492 | H11: 2.59 | I11: 45904492 | J11: 2.58 | K11: 45904492
B12: Venture Capital Funds | C12: 0 | D12: 0 | E12: - | F12: 0 | G12: - | H12: 0 | I12: - | J12: 0 | K12: -
B13: Alternate Investment Funds | C13: 4 | D13: 259605 | E13: 259605 | F13: 0.01 | G13: 259605 | H13: 0.01 | I13: 259605 | J13: 0.01 | K13: 259605
B14: Banks | C14: 3 | D14: 974315 | E14: 974315 | F14: 0.05 | G14: 974315 | H14: 0.05 | I14: 974315 | J14: 0.05 | K14: 974315
B15: Insurance Companies | C15: 28 | D15: 177720958 | E15: 177720958 | F15: 10.02 | G15: 177720958 | H15: 10.02 | I15: 177720958 | J15: 10 | K15: 177720958
B16: LIFE INSURANCE CORPORATION OF INDIA - ULIF00320091 | C16: 1 | D16: 151981918 | E16: 151981918 | F16: 8.57 | G16: 151981918 | H16: 8.57 | I16: 151981918 | J16: 8.55 | K16: 151981918
B17: Provident Funds/ Pension Funds | C17: 1 | D17: 22462399 | E17: 22462399 | F17: 1.27 | G17: 22462399 | H17: 1.27 | I17: 22462399 | J17: 1.26 | K17: 22462399
B18: NPS TRUST- A/C LIC PENSION FUND SCHEME E - TIER I | C18: 1 | D18: 22462399 | E18: 22462399 | F18: 1.27 | G18: 22462399 | H18: 1.27 | I18: 22462399 | J18: 1.26 | K18: 22462399
B19: Asset reconstruction companies | C19: 0 | D19: 0 | E19: - | F19: 0 | G19: - | H19: 0 | I19: - | J19: 0 | K19: -
B20: Sovereign Wealth Funds | C20: 2 | D20: 1812410 | E20: 1812410 | F20: 0.1 | G20: 1812410 | H20: 0.1 | I20: 1812410 | J20: 0.1 | K20: 1812410
B21: NBFCs registered with RBI | C21: 8 | D21: 128500 | E21: 128500 | F21: 0.01 | G21: 128500 | H21: 0.01 | I21: 128500 | J21: 0.01 | K21: 128500
B22: Other Financial Institutions | C22: 0 | D22: 0 | E22: - | F22: 0 | G22: - | H22: 0 | I22: - | J22: 0 | K22: -
B23: Any Other(Institutions (Domestic)) | C23: 0 | D23: 0 | E23: - | F23: 0 | G23: - | H23: 0 | I23: - | J23: 0 | K23: -
B24: Sub Total B1 | C24: 81 | D24: 329267617 | E24: 329267617 | F24: 18.56 | G24: 329267617 | H24: 18.56 | I24: 329267617 | J24: 18.53 | K24: 329267617
B25: B19) Institutions (Foreign) | C25: 0 | D25: 0 | E25: - | F25: 0 | G25: - | H25: 0 | I25: - | J25: 0 | K25: -
B26: Foreign Direct Investment | C26: 0 | D26: 0 | E26: - | F26: 0 | G26: - | H26: 0 | I26: - | J26: 0 | K26: -
B27: Foreign Venture Capital Investors | C27: 0 | D27: 0 | E27: - | F27: 0 | G27: - | H27: 0 | I27: - | J27: 0 | K27: -
B28: Sovereign Wealth Funds | C28: 0 | D28: 0 | E28: - | F28: 0 | G28: - | H28: 0 | I28: - | J28: 0 | K28: -
B29: Foreign Portfolio Investors Category I | C29: 623 | D29: 172140677 | E29: 172140677 | F29: 9.71 | G29: 172140677 | H29: 9.71 | I29: 172140677 | J29: 9.69 | K29: 172140677
B30: Foreign Portfolio Investors Category II | C30: 32 | D30: 4798098 | E30: 4798098 | F30: 0.27 | G30: 4798098 | H30: 0.27 | I30: 4798098 | J30: 0.27 | K30: 4798098
B31: Overseas Depositories (holding DRs) (balancing figure) | C31: 1 | D31: 6000 | E31: 6000 | F31: 0 | G31: 6000 | H31: 0 | I31: 6000 | J31: 0 | K31: -
B32: Any Other(Institutions (Foreign)) | C32: 1 | D32: 6000 | E32: 6000 | F32: 0 | G32: 6000 | H32: 0 | I32: 6000 | J32: 0 | K32: 6000
B33: FOREIGN BANK | C33: 1 | D33: 6000 | E33: 6000 | F33: 0 | G33: 6000 | H33: 0 | I33: 6000 | J33: 0 | K33: 6000
B34: Sub Total B2 | C34: 657 | D34: 176950775 | E34: 176950775 | F34: 9.98 | G34: 176950775 | H34: 9.98 | I34: 176950775 | J34: 9.96 | K34: 176944775
B35: B29) Central Government/ State Government(s)/ President of India | C35: 0 | D35: 0 | E35: - | F35: 0 | G35: - | H35: 0 | I35: - | J35: 0 | K35: -
B36: Central Government / President of India | C36: 0 | D36: 0 | E36: - | F36: 0 | G36: - | H36: 0 | I36: - | J36: 0 | K36: -
B37: State Government / Governor | C37: 0 | D37: 0 | E37: - | F37: 0 | G37: - | H37: 0 | I37: - | J37: 0 | K37: -
B38: Shareholding by Companies or Bodies Corporate where Central / State Government is a promoter | C38: 1 | D38: 238 | E38: 238 | F38: 0 | G38: 238 | H38: 0 | I38: 238 | J38: 0 | K38: 238
B39: Sub Total B3 | C39: 1 | D39: 238 | E39: 238 | F39: 0 | G39: 238 | H39: 0 | I39: 238 | J39: 0 | K39: 238
B40: B34) Non-Institutions | C40: 0 | D40: 0 | E40: - | F40: 0 | G40: - | H40: 0 | I40: - | J40: 0 | K40: -
B41: Associate companies / Subsidiaries | C41: 0 | D41: 0 | E41: - | F41: 0 | G41: - | H41: 0 | I41: - | J41: 0 | K41: -
B42: Directors and their relatives (excluding independent directors and nominee directors) | C42: 3 | D42: 4784865 | E42: 4784865 | F42: 0.27 | G42: 4784865 | H42: 0.27 | I42: 6819315 | J42: 0.38 | K42: 4784865
B43: Key Managerial Personnel | C43: 3 | D43: 375082 | E43: 375082 | F43: 0.02 | G43: 375082 | H43: 0.02 | I43: 445282 | J43: 0.03 | K43: 375082
B44: Relatives of promoters (other than 'immediate relatives' of promoters disclosed under 'Promoter and Promoter Group' category) | C44: 0 | D44: 0 | E44: - | F44: 0 | G44: - | H44: 0 | I44: - | J44: 0 | K44: -
...

Sheet Balance Sheet
A1: ='Profit & Loss'!A1 -> DABUR INDIA LTD
A3: Narration | B3: ='Data Sheet'!B53 -> 42825 | C3: ='Data Sheet'!C53 -> 43190 | D3: ='Data Sheet'!D53 -> 43555 | E3: ='Data Sheet'!E53 -> 43921 | F3: ='Data Sheet'!F53 -> 44286 | G3: ='Data Sheet'!G53 -> 44651 | H3: ='Data Sheet'!H53 -> 45016 | I3: ='Data Sheet'!I53 -> 45382 | ... K3: ='Data Sheet'!K53 -> 46112
A4: Equity Share Capital | B4: ='Data Sheet'!B54 -> 176.15 | C4: ='Data Sheet'!C54 -> 176.15 | D4: ='Data Sheet'!D54 -> 176.63 | E4: ='Data Sheet'!E54 -> 176.71 | F4: ='Data Sheet'!F54 -> 176.74 | G4: ='Data Sheet'!G54 -> 176.79 | H4: ='Data Sheet'!H54 -> 177.18 | I4: ='Data Sheet'!I54 -> 177.2 | ... K4: ='Data Sheet'!K54 -> 177.37
A5: Reserves | B5: ='Data Sheet'!B55 -> 4671.24 | C5: ='Data Sheet'!C55 -> 5530.37 | D5: ='Data Sheet'!D55 -> 5455.05 | E5: ='Data Sheet'!E55 -> 6429.04 | F5: ='Data Sheet'!F55 -> 7486.79 | G5: ='Data Sheet'!G55 -> 8204.51 | H5: ='Data Sheet'!H55 -> 8796.08 | I5: ='Data Sheet'!I55 -> 9689.1 | ... K5: ='Data Sheet'!K55 -> 11242.15
A6: Borrowings | B6: ='Data Sheet'!B56 -> 975 | C6: ='Data Sheet'!C56 -> 937.59 | D6: ='Data Sheet'!D56 -> 699.37 | E6: ='Data Sheet'!E56 -> 521.99 | F6: ='Data Sheet'!F56 -> 509.06 | G6: ='Data Sheet'!G56 -> 1030.1 | H6: ='Data Sheet'!H56 -> 1173.79 | I6: ='Data Sheet'!I56 -> 1365.09 | ... K6: ='Data Sheet'!K56 -> 1287.32 | L6: Long+Short | M6: =16+1047 -> 1063
A7: Other Liabilities | B7: ='Data Sheet'!B57 -> 1909.85 | C7: ='Data Sheet'!C57 -> 2057.52 | D7: ='Data Sheet'!D57 -> 2105.59 | E7: ='Data Sheet'!E57 -> 2208.84 | F7: ='Data Sheet'!F57 -> 2660.63 | G7: ='Data Sheet'!G57 -> 2872.46 | H7: ='Data Sheet'!H57 -> 3505.23 | I7: ='Data Sheet'!I57 -> 3884.97 | ... K7: ='Data Sheet'!K57 -> 4773.07
A8: Total | B8: ='Data Sheet'!B58 -> 7732.24 | C8: ='Data Sheet'!C58 -> 8701.63 | D8: ='Data Sheet'!D58 -> 8436.64 | E8: ='Data Sheet'!E58 -> 9336.58 | F8: ='Data Sheet'!F58 -> 10833.22 | G8: ='Data Sheet'!G58 -> 12283.86 | H8: ='Data Sheet'!H58 -> 13652.28 | I8: ='Data Sheet'!I58 -> 15116.36 | ... K8: ='Data Sheet'!K58 -> 17479.91
A10: Net Block | B10: ='Data Sheet'!B59 -> 1958.4 | C10: ='Data Sheet'!C59 -> 2028.11 | D10: ='Data Sheet'!D59 -> 1969.06 | E10: ='Data Sheet'!E59 -> 2252.68 | F10: ='Data Sheet'!F59 -> 2242.92 | G10: ='Data Sheet'!G59 -> 2307.9 | H10: ='Data Sheet'!H59 -> 3578.65 | I10: ='Data Sheet'!I59 -> 3815 | ... K10: ='Data Sheet'!K59 -> 3938.92 | M10: Other Liabilities - | N10: 2019 | O10: 1956 | P10: 1910 | Q10: 2058 | R10: 2106 | S10: 2209 | T10: 2661 | U10: 2872 | V10: 3505 | W10: 3885 | X10: 4479 | Y10: 4773
A11: Capital Work in Progress | B11: ='Data Sheet'!B60 -> 42.1 | C11: ='Data Sheet'!C60 -> 41.51 | D11: ='Data Sheet'!D60 -> 63.76 | E11: ='Data Sheet'!E60 -> 146.57 | F11: ='Data Sheet'!F60 -> 147.3 | G11: ='Data Sheet'!G60 -> 167.5 | H11: ='Data Sheet'!H60 -> 175.13 | I11: ='Data Sheet'!I60 -> 232.23 | ... K11: ='Data Sheet'!K60 -> 137.48 | M11: Non controlling int | N11: 18 | O11: 22 | P11: 25 | Q11: 27 | R11: 31 | S11: 36 | T11: 37 | U11: 41 | V11: 468 | W11: 437 | X11: 410 | Y11: 383
A12: Investments | B12: ='Data Sheet'!B61 -> 3240.16 | C12: ='Data Sheet'!C61 -> 3805.17 | D12: ='Data Sheet'!D61 -> 3358.76 | E12: ='Data Sheet'!E61 -> 2800.26 | F12: ='Data Sheet'!F61 -> 4159.63 | G12: ='Data Sheet'!G61 -> 6219.62 | H12: ='Data Sheet'!H61 -> 6265.26 | I12: ='Data Sheet'!I61 -> 6932.69 | ... K12: ='Data Sheet'!K61 -> 8947.26 | M12: Trade Payables | N12: 1096 | O12: 1330 | P12: 1310 | Q12: 1410 | R12: 1455 | S12: 1482 | T12: 1915 | U12: 2018 | V12: 2187 | W12: 2422 | X12: 2825 | Y12: 2954
A13: Other Assets | B13: ='Data Sheet'!B62 -> 2491.58 | C13: ='Data Sheet'!C62 -> 2826.84 | D13: ='Data Sheet'!D62 -> 3045.06 | E13: ='Data Sheet'!E62 -> 4137.07 | F13: ='Data Sheet'!F62 -> 4283.37 | G13: ='Data Sheet'!G62 -> 3588.84 | H13: ='Data Sheet'!H62 -> 3633.24 | I13: ='Data Sheet'!I62 -> 4136.44 | ... K13: ='Data Sheet'!K62 -> 4456.25 | M13: Advance from Customers | N13: 42 | O13: 35 | P13: 18 | Q13: 25 | R13: 28 | S13: 30 | T13: 43 | U13: 37 | V13: 9 | W13: 33 | X13: 28
A14: Total | B14: ='Data Sheet'!B63 -> 7732.24 | C14: ='Data Sheet'!C63 -> 8701.63 | D14: ='Data Sheet'!D63 -> 8436.64 | E14: ='Data Sheet'!E63 -> 9336.58 | F14: ='Data Sheet'!F63 -> 10833.22 | G14: ='Data Sheet'!G63 -> 12283.86 | H14: ='Data Sheet'!H63 -> 13652.28 | I14: ='Data Sheet'!I63 -> 15116.36 | ... K14: ='Data Sheet'!K63 -> 17479.91 | M14: Other liability items | N14: 863 | O14: 569 | P14: 557 | Q14: 596 | R14: 591 | S14: 660 | T14: 666 | U14: 777 | V14: 842 | W14: 994 | X14: 1216 | Y14: 1436
A16: Working Capital | B16: =B13-B7 -> 581.73 | C16: =C13-C7 -> 769.32 | D16: =D13-D7 -> 939.47 | E16: =E13-E7 -> 1928.23 | F16: =F13-F7 -> 1622.74 | G16: =G13-G7 -> 716.38 | H16: =H13-H7 -> 128.01 | I16: =I13-I7 -> 251.47 | ... K16: =K13-K7 -> -316.82
A17: Debtors | B17: ='Data Sheet'!B64 -> 650.42 | C17: ='Data Sheet'!C64 -> 706.08 | D17: ='Data Sheet'!D64 -> 833.56 | E17: ='Data Sheet'!E64 -> 813.89 | F17: ='Data Sheet'!F64 -> 561.58 | G17: ='Data Sheet'!G64 -> 646.15 | H17: ='Data Sheet'!H64 -> 848.75 | I17: ='Data Sheet'!I64 -> 898.72 | ... K17: ='Data Sheet'!K64 -> 715.41
A18: Inventory | B18: ='Data Sheet'!B65 -> 1106.71 | C18: ='Data Sheet'!C65 -> 1256.18 | D18: ='Data Sheet'!D65 -> 1300.53 | E18: ='Data Sheet'!E65 -> 1379.57 | F18: ='Data Sheet'!F65 -> 1734.28 | G18: ='Data Sheet'!G65 -> 1911.37 | H18: ='Data Sheet'!H65 -> 2024.2 | I18: ='Data Sheet'!I65 -> 1946.97 | ... K18: ='Data Sheet'!K65 -> 2321.63
A20: Debtor Days | B20: =IF('Profit & Loss'!B4>0,'Balance Sheet'!B17/('Profit & Loss'!B4/365),0) -> 31.181519 | C20: =IF('Profit & Loss'!C4>0,'Balance Sheet'!C17/('Profit & Loss'!C4/365),0) -> 33.375318 | D20: =IF('Profit & Loss'!D4>0,'Balance Sheet'!D17/('Profit & Loss'!D4/365),0) -> 35.731034 | E20: =IF('Profit & Loss'!E4>0,'Balance Sheet'!E17/('Profit & Loss'!E4/365),0) -> 34.206352 | F20: =IF('Profit & Loss'!F4>0,'Balance Sheet'!F17/('Profit & Loss'!F4/365),0) -> 21.437377 | G20: =IF('Profit & Loss'!G4>0,'Balance Sheet'!G17/('Profit & Loss'!G4/365),0) -> 21.659627 | H20: =IF('Profit & Loss'!H4>0,'Balance Sheet'!H17/('Profit & Loss'!H4/365),0) -> 26.868752 | I20: =IF('Profit & Loss'!I4>0,'Balance Sheet'!I17/('Profit & Loss'!I4/365),0) -> 26.445706 | ... K20: =IF('Profit & Loss'!K4>0,'Balance Sheet'!K17/('Profit & Loss'!K4/365),0) -> 19.793312
A21: Inventory Turnover | B21: =IF('Balance Sheet'!B18>0,'Profit & Loss'!B4/'Balance Sheet'!B18,0) -> 6.8794806 | C21: =IF('Balance Sheet'!C18>0,'Profit & Loss'!C4/'Balance Sheet'!C18,0) -> 6.1470888 | D21: =IF('Balance Sheet'!D18>0,'Profit & Loss'!D4/'Balance Sheet'!D18,0) -> 6.547323 | E21: =IF('Balance Sheet'!E18>0,'Profit & Loss'!E4/'Balance Sheet'!E18,0) -> 6.2951789 | F21: =IF('Balance Sheet'!F18>0,'Profit & Loss'!F4/'Balance Sheet'!F18,0) -> 5.5133254 | G21: =IF('Balance Sheet'!G18>0,'Profit & Loss'!G4/'Balance Sheet'!G18,0) -> 5.6967934 | H21: =IF('Balance Sheet'!H18>0,'Profit & Loss'!H4/'Balance Sheet'!H18,0) -> 5.6960231 | I21: =IF('Balance Sheet'!I18>0,'Profit & Loss'!I4/'Balance Sheet'!I18,0) -> 6.3709302 | ... K21: =IF('Balance Sheet'!K18>0,'Profit & Loss'!K4/'Balance Sheet'!K18,0) -> 5.6824602
A23: Return on Equity | B23: =IF(SUM('Balance Sheet'!B4:B5)>0,'Profit & Loss'!B12/SUM('Balance Sheet'!B4:B5),"") -> 0.26342836 | C23: =IF(SUM('Balance Sheet'!C4:C5)>0,'Profit & Loss'!C12/SUM('Balance Sheet'!C4:C5),"") -> 0.2373408 | D23: =IF(SUM('Balance Sheet'!D4:D5)>0,'Profit & Loss'!D12/SUM('Balance Sheet'!D4:D5),"") -> 0.25611008 | E23: =IF(SUM('Balance Sheet'!E4:E5)>0,'Profit & Loss'!E12/SUM('Balance Sheet'!E4:E5),"") -> 0.21874276 | F23: =IF(SUM('Balance Sheet'!F4:F5)>0,'Profit & Loss'!F12/SUM('Balance Sheet'!F4:F5),"") -> 0.22095562 | G23: =IF(SUM('Balance Sheet'!G4:G5)>0,'Profit & Loss'!G12/SUM('Balance Sheet'!G4:G5),"") -> 0.20751196 | H23: =IF(SUM('Balance Sheet'!H4:H5)>0,'Profit & Loss'!H12/SUM('Balance Sheet'!H4:H5),"") -> 0.19024858 | I23: =IF(SUM('Balance Sheet'!I4:I5)>0,'Profit & Loss'!I12/SUM('Balance Sheet'!I4:I5),"") -> 0.18676505 | ... K23: =IF(SUM('Balance Sheet'!K4:K5)>0,'Profit & Loss'!K12/SUM('Balance Sheet'!K4:K5),"") -> 0.16594655
A24: Return on Capital Emp | C24: =IF((B4+B5+B6+C4+C5+C6)>0,('Profit & Loss'!C10+'Profit & Loss'!C9)*2/(B4+B5+B6+C4+C5+C6),"") -> 0.28013316 | D24: =IF((C4+C5+C6+D4+D5+D6)>0,('Profit & Loss'!D10+'Profit & Loss'!D9)*2/(C4+C5+C6+D4+D5+D6),"") -> 0.27505634 | E24: =IF((D4+D5+D6+E4+E5+E6)>0,('Profit & Loss'!E10+'Profit & Loss'!E9)*2/(D4+D5+D6+E4+E5+E6),"") -> 0.26409209 | F24: =IF((E4+E5+E6+F4+F5+F6)>0,('Profit & Loss'!F10+'Profit & Loss'!F9)*2/(E4+E5+E6+F4+F5+F6),"") -> 0.27278235 | G24: =IF((F4+F5+F6+G4+G5+G6)>0,('Profit & Loss'!G10+'Profit & Loss'!G9)*2/(F4+F5+F6+G4+G5+G6),"") -> 0.26242963 | H24: =IF((G4+G5+G6+H4+H5+H6)>0,('Profit & Loss'!H10+'Profit & Loss'!H9)*2/(G4+G5+G6+H4+H5+H6),"") -> 0.23487751 | I24: =IF((H4+H5+H6+I4+I5+I6)>0,('Profit & Loss'!I10+'Profit & Loss'!I9)*2/(H4+H5+H6+I4+I5+I6),"") -> 0.23228262 | J24: =IF((I4+I5+I6+J4+J5+J6)>0,('Profit & Loss'!J10+'Profit & Loss'!J9)*2/(I4+I5+I6+J4+J5+J6),"") -> 0.21071644 | K24: =IF((J4+J5+J6+K4+K5+K6)>0,('Profit & Loss'!K10+'Profit & Loss'!K9)*2/(J4+J5+J6+K4+K5+K6),"") -> 0.20981605

Sheet Profit & Loss
A1: ='Data Sheet'!B1 -> DABUR INDIA LTD
A3: Narration | B3: ='Data Sheet'!B13 -> 42825 | C3: ='Data Sheet'!C13 -> 43190 | D3: ='Data Sheet'!D13 -> 43555 | E3: ='Data Sheet'!E13 -> 43921 | F3: ='Data Sheet'!F13 -> 44286 | G3: ='Data Sheet'!G13 -> 44651 | H3: ='Data Sheet'!H13 -> 45016 | I3: ='Data Sheet'!I13 -> 45382 | ... K3: ='Data Sheet'!K13 -> 46112 | L3: Trailing | M3: Best Case | N3: Worst Case
A4: Sales | B4: ='Data Sheet'!B14 -> 7613.59 | C4: ='Data Sheet'!C14 -> 7721.85 | D4: ='Data Sheet'!D14 -> 8514.99 | E4: ='Data Sheet'!E14 -> 8684.64 | F4: ='Data Sheet'!F14 -> 9561.65 | G4: ='Data Sheet'!G14 -> 10888.68 | H4: ='Data Sheet'!H14 -> 11529.89 | I4: ='Data Sheet'!I14 -> 12404.01 | ... K4: ='Data Sheet'!K14 -> 13192.57 | L4: =SUM(Quarters!H4:K4) -> 13192.57 | M4: =$K4+M23*K4 -> 13853.59 | N4: =$K4+N23*L4 -> 13798.466
A5: Expenses | B5: =SUM('Data Sheet'!B15,'Data Sheet'!B17:B21, -1*'Data Sheet'!B16) -> 6101.98 | C5: =SUM('Data Sheet'!C15,'Data Sheet'!C17:C21, -1*'Data Sheet'!C16) -> 6104.41 | D5: =SUM('Data Sheet'!D15,'Data Sheet'!D17:D21, -1*'Data Sheet'!D16) -> 6775.43 | E5: =SUM('Data Sheet'!E15,'Data Sheet'!E17:E21, -1*'Data Sheet'!E16) -> 6892.3 | F5: =SUM('Data Sheet'!F15,'Data Sheet'!F17:F21, -1*'Data Sheet'!F16) -> 7559.98 | G5: =SUM('Data Sheet'!G15,'Data Sheet'!G17:G21, -1*'Data Sheet'!G16) -> 8636.67 | H5: =SUM('Data Sheet'!H15,'Data Sheet'!H17:H21, -1*'Data Sheet'!H16) -> 9367.4 | I5: =SUM('Data Sheet'!I15,'Data Sheet'!I17:I21, -1*'Data Sheet'!I16) -> 10004.29 | ... K5: =SUM('Data Sheet'!K15,'Data Sheet'!K17:K21, -1*'Data Sheet'!K16) -> 10742.53 | L5: =SUM(Quarters!H5:K5) -> 10742.53 | M5: =M4-M6 -> 11251.99 | N5: =N4-N6 -> 11235.903
A6: Operating Profit | B6: =B4-B5 -> 1511.61 | C6: =C4-C5 -> 1617.44 | D6: =D4-D5 -> 1739.56 | E6: =E4-E5 -> 1792.34 | F6: =F4-F5 -> 2001.67 | G6: =G4-G5 -> 2252.01 | H6: =H4-H5 -> 2162.49 | I6: =I4-I5 -> 2399.72 | ... K6: =K4-K5 -> 2450.04 | L6: =SUM(Quarters!H6:K6) -> 2450.04 | M6: =M4*M24 -> 2601.6004 | N6: =N4*N24 -> 2562.5632
A7: Other Income | B7: ='Data Sheet'!B22 -> 295.93 | C7: ='Data Sheet'!C22 -> 290.88 | D7: ='Data Sheet'!D22 -> 221.79 | E7: ='Data Sheet'!E22 -> 205.29 | F7: ='Data Sheet'!F22 -> 325.29 | G7: ='Data Sheet'!G22 -> 308.16 | H7: ='Data Sheet'!H22 -> 445.39 | I7: ='Data Sheet'!I22 -> 482.41 | ... K7: ='Data Sheet'!K22 -> 584.72 | L7: =SUM(Quarters!H7:K7) -> 584.72 | M7: 0 | N7: 0
A8: Depreciation | B8: ='Data Sheet'!B23 -> 142.86 | C8: ='Data Sheet'!C23 -> 162.18 | D8: ='Data Sheet'!D23 -> 176.9 | E8: ='Data Sheet'!E23 -> 220.45 | F8: ='Data Sheet'!F23 -> 240.13 | G8: ='Data Sheet'!G23 -> 252.89 | H8: ='Data Sheet'!H23 -> 310.96 | I8: ='Data Sheet'!I23 -> 399.21 | ... K8: ='Data Sheet'!K23 -> 468.93 | L8: =SUM(Quarters!H8:K8) -> 468.93 | M8: =+$L8 -> 468.93 | N8: =+$L8 -> 468.93
A9: Interest | B9: ='Data Sheet'!B24 -> 54.03 | C9: ='Data Sheet'!C24 -> 53.05 | D9: ='Data Sheet'!D24 -> 59.58 | E9: ='Data Sheet'!E24 -> 49.54 | F9: ='Data Sheet'!F24 -> 30.81 | G9: ='Data Sheet'!G24 -> 38.6 | H9: ='Data Sheet'!H24 -> 78.24 | I9: ='Data Sheet'!I24 -> 124.18 | ... K9: ='Data Sheet'!K24 -> 145.4 | L9: =SUM(Quarters!H9:K9) -> 145.4 | M9: =+$L9 -> 145.4 | N9: =+$L9 -> 145.4
A10: Profit before tax | B10: ='Data Sheet'!B25 -> 1610.65 | C10: ='Data Sheet'!C25 -> 1693.09 | D10: ='Data Sheet'!D25 -> 1724.87 | E10: ='Data Sheet'!E25 -> 1727.64 | F10: ='Data Sheet'!F25 -> 2056.02 | G10: ='Data Sheet'!G25 -> 2268.68 | H10: ='Data Sheet'!H25 -> 2218.68 | I10: ='Data Sheet'!I25 -> 2358.74 | ... K10: ='Data Sheet'!K25 -> 2420.43 | L10: =SUM(Quarters!H10:K10) -> 2420.43 | M10: =M6+M7-SUM(M8:M9) -> 1987.2704 | N10: =N6+N7-SUM(N8:N9) -> 1948.2332
A11: Tax | B11: ='Data Sheet'!B26 -> 330.34 | C11: ='Data Sheet'!C26 -> 335.35 | D11: ='Data Sheet'!D26 -> 278.62 | E11: ='Data Sheet'!E26 -> 279.72 | F11: ='Data Sheet'!F26 -> 361.07 | G11: ='Data Sheet'!G26 -> 526.38 | H11: ='Data Sheet'!H26 -> 517.35 | I11: ='Data Sheet'!I26 -> 547.43 | ... K11: ='Data Sheet'!K26 -> 551.74 | L11: =SUM(Quarters!H11:K11) -> 551.74 | M11: =IF($L10>0,$L11/$L10,0) -> 0.22795123 | N11: =IF($L10>0,$L11/$L10,0) -> 0.22795123
A12: Net profit | B12: ='Data Sheet'!B27 -> 1276.94 | C12: ='Data Sheet'!C27 -> 1354.39 | D12: ='Data Sheet'!D27 -> 1442.33 | E12: ='Data Sheet'!E27 -> 1444.96 | F12: ='Data Sheet'!F27 -> 1693.3 | G12: ='Data Sheet'!G27 -> 1739.22 | H12: ='Data Sheet'!H27 -> 1707.15 | I12: ='Data Sheet'!I27 -> 1842.68 | ... K12: ='Data Sheet'!K27 -> 1895.03 | L12: =SUM(Quarters!H12:K12) -> 1895.03 | M12: =M10-M11*M10 -> 1534.2697 | N12: =N10-N11*N10 -> 1504.1311
A13: EPS | B13: =IF('Data Sheet'!B90>0,B12/'Data Sheet'!B90,0) -> 7.2491626 | C13: =IF('Data Sheet'!C90>0,C12/'Data Sheet'!C90,0) -> 7.6888447 | D13: =IF('Data Sheet'!D90>0,D12/'Data Sheet'!D90,0) -> 8.1658269 | E13: =IF('Data Sheet'!E90>0,E12/'Data Sheet'!E90,0) -> 8.1770132 | F13: =IF('Data Sheet'!F90>0,F12/'Data Sheet'!F90,0) -> 9.5807401 | G13: =IF('Data Sheet'!G90>0,G12/'Data Sheet'!G90,0) -> 9.8377736 | H13: =IF('Data Sheet'!H90>0,H12/'Data Sheet'!H90,0) -> 9.6351168 | I13: =IF('Data Sheet'!I90>0,I12/'Data Sheet'!I90,0) -> 10.398871 | ... K13: =IF('Data Sheet'!K90>0,K12/'Data Sheet'!K90,0) -> 10.68405 | L13: =IF('Data Sheet'!$B6>0,'Profit & Loss'!L12/'Data Sheet'!$B6,0) -> 10.68411 | M13: =IF('Data Sheet'!$B6>0,'Profit & Loss'!M12/'Data Sheet'!$B6,0) -> 8.6501564 | N13: =IF('Data Sheet'!$B6>0,'Profit & Loss'!N12/'Data Sheet'!$B6,0) -> 8.4802359
A14: Price to earning | B14: =IF(B15>0,B15/B13,"") -> 38.259591 | C14: =IF(C15>0,C15/C13,"") -> 42.711228 | D14: =IF(D15>0,D15/D13,"") -> 50.062291 | E14: =IF(E15>0,E15/E13,"") -> 55.038434 | F14: =IF(F15>0,F15/F13,"") -> 56.415266 | G14: =IF(G15>0,G15/G13,"") -> 54.504202 | H14: =IF(H15>0,H15/H13,"") -> 56.553544 | I14: =IF(I15>0,I15/I13,"") -> 50.308344 | ... K14: =IF(K15>0,K15/K13,"") -> 38.417079 | L14: =IF(L13>0,L15/L13,0) -> 41.561722 | M14: =M25 -> 45.26774 | N14: =N25 -> 41.561722
A15: Price | B15: ='Data Sheet'!B87 -> 277.35 | C15: ='Data Sheet'!C87 -> 328.4 | D15: ='Data Sheet'!D87 -> 408.8 | E15: ='Data Sheet'!E87 -> 450.05 | F15: ='Data Sheet'!F87 -> 540.5 | G15: ='Data Sheet'!G87 -> 536.2 | H15: ='Data Sheet'!H87 -> 544.9 | I15: ='Data Sheet'!I87 -> 523.15 | ... K15: ='Data Sheet'!K87 -> 410.45 | L15: ='Data Sheet'!B8 -> 444.05 | M15: =M13*M14 -> 391.57303 | N15: =N13*N14 -> 352.45321
A17: RATIOS:
A18: Dividend Payout | B18: =IF('Data Sheet'!B27>0, 'Data Sheet'!B28/'Data Sheet'!B27, 0) -> 0.31038263 | C18: =IF('Data Sheet'!C27>0, 'Data Sheet'!C28/'Data Sheet'!C27, 0) -> 0.81286779 | D18: =IF('Data Sheet'!D27>0, 'Data Sheet'!D28/'Data Sheet'!D27, 0) -> 0.33676759 | E18: =IF('Data Sheet'!E27>0, 'Data Sheet'!E28/'Data Sheet'!E27, 0) -> 0.36688213 | F18: =IF('Data Sheet'!F27>0, 'Data Sheet'!F28/'Data Sheet'!F27, 0) -> 0.49578929 | G18: =IF('Data Sheet'!G27>0, 'Data Sheet'!G28/'Data Sheet'!G27, 0) -> 0.52857603 | H18: =IF('Data Sheet'!H27>0, 'Data Sheet'!H28/'Data Sheet'!H27, 0) -> 0.53969481 | I18: =IF('Data Sheet'!I27>0, 'Data Sheet'!I28/'Data Sheet'!I27, 0) -> 0.52890355 | ... K18: =IF('Data Sheet'!K27>0, 'Data Sheet'!K28/'Data Sheet'!K27, 0) -> 0.77217775
A19: OPM | B19: =IF(B6>0,B6/B4,0) -> 0.19854103 | C19: =IF(C6>0,C6/C4,0) -> 0.20946276 | D19: =IF(D6>0,D6/D4,0) -> 0.20429384 | E19: =IF(E6>0,E6/E4,0) -> 0.20638046 | F19: =IF(F6>0,F6/F4,0) -> 0.20934358 | G19: =IF(G6>0,G6/G4,0) -> 0.20682121 | H19: =IF(H6>0,H6/H4,0) -> 0.18755513 | I19: =IF(I6>0,I6/I4,0) -> 0.19346324 | ... L19: =IF(L6>0,L6/L4,0) -> 0.18571363
G22: TRENDS: | H22: 10 YEARS | I22: 7 YEARS | J22: 5 YEARS | K22: 3 YEARS | L22: RECENT | M22: BEST | N22: WORST
G23: Sales Growth | H23: =IF(B4=0,"",POWER($K4/B4,1/9)-1) -> 0.06298383 | I23: =IF(D4=0,"",POWER($K4/D4,1/7)-1) -> 0.064543982 | J23: =IF(F4=0,"",POWER($K4/F4,1/5)-1) -> 0.066496201 | K23: =IF(H4=0,"",POWER($K4/H4, 1/3)-1) -> 0.045927097 | L23: =IF(ISERROR(MAX(IF(J4=0,"",(K4-J4)/J4),IF(K4=0,"",(L4-K4)/K4))),"",MAX(IF(J4=0,"",(K4-J4)/J4),IF(K4=0,"",(L4-K4)/K4))) -> 0.050105507 | M23: =MAX(K23:L23) -> 0.050105507 | N23: =MIN(H23:L23) -> 0.045927097
G24: OPM | H24: =IF(SUM(B4:$K$4)=0,"",SUMPRODUCT(B19:$K$19,B4:$K$4)/SUM(B4:$K$4)) -> 0.19715829 | I24: =IF(SUM(E4:$K$4)=0,"",SUMPRODUCT(E19:$K$19,E4:$K$4)/SUM(E4:$K$4)) -> 0.19504855 | J24: =IF(SUM(G4:$K$4)=0,"",SUMPRODUCT(G19:$K$19,G4:$K$4)/SUM(G4:$K$4)) -> 0.19116765 | K24: =IF(SUM(I4:$K$4)=0, "", SUMPRODUCT(I19:$K$19,I4:$K$4)/SUM(I4:$K$4)) -> 0.1877925 | L24: =L19 -> 0.18571363 | M24: =MAX(K24:L24) -> 0.1877925 | N24: =MIN(H24:L24) -> 0.18571363
G25: Price to Earning | H25: =IF(ISERROR(AVERAGEIF(B14:$L14,">0")),"",AVERAGEIF(B14:$L14,">0")) -> 48.601411 | I25: =IF(ISERROR(AVERAGEIF(E14:$L14,">0")),"",AVERAGEIF(E14:$L14,">0")) -> 50.447801 | J25: =IF(ISERROR(AVERAGEIF(G14:$L14,">0")),"",AVERAGEIF(G14:$L14,">0")) -> 48.688118 | K25: =IF(ISERROR(AVERAGEIF(I14:$L14,">0")),"",AVERAGEIF(I14:$L14,">0")) -> 45.26774 | L25: =L14 -> 41.561722 | M25: =MAX(K25:L25) -> 45.26774 | N25: =MIN(H25:L25) -> 41.561722

Sheet Quarters
A1: ='Profit & Loss'!A1 -> DABUR INDIA LTD
A3: Narration | B3: ='Data Sheet'!B38 -> 45291 | C3: ='Data Sheet'!C38 -> 45382 | D3: ='Data Sheet'!D38 -> 45473 | E3: ='Data Sheet'!E38 -> 45565 | F3: ='Data Sheet'!F38 -> 45657 | G3: ='Data Sheet'!G38 -> 45747 | H3: ='Data Sheet'!H38 -> 45838 | I3: ='Data Sheet'!I38 -> 45930 | ... K3: ='Data Sheet'!K38 -> 46112
A4: Sales | B4: ='Data Sheet'!B39 -> 3255.06 | C4: ='Data Sheet'!C39 -> 2814.64 | D4: ='Data Sheet'!D39 -> 3349.11 | E4: ='Data Sheet'!E39 -> 3028.59 | F4: ='Data Sheet'!F39 -> 3355.25 | G4: ='Data Sheet'!G39 -> 2830.14 | H4: ='Data Sheet'!H39 -> 3404.58 | I4: ='Data Sheet'!I39 -> 3191.32 | ... K4: ='Data Sheet'!K39 -> 3038.02
A5: Expenses | B5: ='Data Sheet'!B40 -> 2587.64 | C5: ='Data Sheet'!C40 -> 2348.23 | D5: ='Data Sheet'!D40 -> 2694.28 | E5: ='Data Sheet'!E40 -> 2476.04 | F5: ='Data Sheet'!F40 -> 2673.36 | G5: ='Data Sheet'!G40 -> 2403.27 | H5: ='Data Sheet'!H40 -> 2737.16 | I5: ='Data Sheet'!I40 -> 2603.35 | ... K5: ='Data Sheet'!K40 -> 2577.2
A6: Operating Profit | B6: ='Data Sheet'!B47 -> 667.42 | C6: ='Data Sheet'!C47 -> 466.41 | D6: ='Data Sheet'!D47 -> 654.83 | E6: ='Data Sheet'!E47 -> 552.55 | F6: ='Data Sheet'!F47 -> 681.89 | G6: ='Data Sheet'!G47 -> 426.87 | H6: ='Data Sheet'!H47 -> 667.42 | I6: ='Data Sheet'!I47 -> 587.97 | ... K6: ='Data Sheet'!K47 -> 460.82
A7: Other Income | B7: ='Data Sheet'!B41 -> 127.37 | C7: ='Data Sheet'!C41 -> 128.85 | D7: ='Data Sheet'!D41 -> 129.4 | E7: ='Data Sheet'!E41 -> 151.76 | F7: ='Data Sheet'!F41 -> 128.53 | G7: ='Data Sheet'!G41 -> 141.16 | H7: ='Data Sheet'!H41 -> 143.97 | I7: ='Data Sheet'!I41 -> 140.13 | ... K7: ='Data Sheet'!K41 -> 175.03
A8: Depreciation | B8: ='Data Sheet'!B42 -> 96.89 | C8: ='Data Sheet'!C42 -> 107.36 | D8: ='Data Sheet'!D42 -> 109.12 | E8: ='Data Sheet'!E42 -> 110.97 | F8: ='Data Sheet'!F42 -> 108.64 | G8: ='Data Sheet'!G42 -> 116.87 | H8: ='Data Sheet'!H42 -> 114.14 | I8: ='Data Sheet'!I42 -> 115.4 | ... K8: ='Data Sheet'!K42 -> 122.2
A9: Interest | B9: ='Data Sheet'!B43 -> 36.49 | C9: ='Data Sheet'!C43 -> 35.24 | D9: ='Data Sheet'!D43 -> 32.66 | E9: ='Data Sheet'!E43 -> 47.39 | F9: ='Data Sheet'!F43 -> 44.2 | G9: ='Data Sheet'!G43 -> 39.25 | H9: ='Data Sheet'!H43 -> 34.63 | I9: ='Data Sheet'!I43 -> 39.68 | ... K9: ='Data Sheet'!K43 -> 39.97
A10: Profit before tax | B10: ='Data Sheet'!B44 -> 661.41 | C10: ='Data Sheet'!C44 -> 452.66 | D10: ='Data Sheet'!D44 -> 642.45 | E10: ='Data Sheet'!E44 -> 545.95 | F10: ='Data Sheet'!F44 -> 657.58 | G10: ='Data Sheet'!G44 -> 411.91 | H10: ='Data Sheet'!H44 -> 662.62 | I10: ='Data Sheet'!I44 -> 573.02 | ... K10: ='Data Sheet'!K44 -> 473.68
A11: Tax | B11: ='Data Sheet'!B45 -> 154.97 | C11: ='Data Sheet'!C45 -> 111.44 | D11: ='Data Sheet'!D45 -> 148.1 | E11: ='Data Sheet'!E45 -> 128.43 | F11: ='Data Sheet'!F45 -> 141.76 | G11: ='Data Sheet'!G45 -> 99.18 | H11: ='Data Sheet'!H45 -> 154.33 | I11: ='Data Sheet'!I45 -> 128.23 | ... K11: ='Data Sheet'!K45 -> 111.68
A12: Net profit | B12: ='Data Sheet'!B46 -> 514.22 | C12: ='Data Sheet'!C46 -> 349.53 | D12: ='Data Sheet'!D46 -> 500.12 | E12: ='Data Sheet'!E46 -> 425 | F12: ='Data Sheet'!F46 -> 522.38 | G12: ='Data Sheet'!G46 -> 320.13 | H12: ='Data Sheet'!H46 -> 513.91 | I12: ='Data Sheet'!I46 -> 452.55 | ... K12: ='Data Sheet'!K46 -> 368.6
A14: OPM | B14: =IF(B4>0,B6/B4,"") -> 0.20504077 | C14: =IF(C4>0,C6/C4,"") -> 0.16570858 | D14: =IF(D4>0,D6/D4,"") -> 0.19552359 | E14: =IF(E4>0,E6/E4,"") -> 0.18244464 | F14: =IF(F4>0,F6/F4,"") -> 0.20323076 | G14: =IF(G4>0,G6/G4,"") -> 0.15082999 | H14: =IF(H4>0,H6/H4,"") -> 0.19603593 | I14: =IF(I4>0,I6/I4,"") -> 0.18424038 | ... K14: =IF(K4>0,K6/K4,"") -> 0.15168432

Sheet Cash Flow
A1: ='Balance Sheet'!A1 -> DABUR INDIA LTD
A3: Narration | B3: ='Data Sheet'!B78 -> 42825 | C3: ='Data Sheet'!C78 -> 43190 | D3: ='Data Sheet'!D78 -> 43555 | E3: ='Data Sheet'!E78 -> 43921 | F3: ='Data Sheet'!F78 -> 44286 | G3: ='Data Sheet'!G78 -> 44651 | H3: ='Data Sheet'!H78 -> 45016 | I3: ='Data Sheet'!I78 -> 45382 | ... K3: ='Data Sheet'!K78 -> 46112
A4: Cash from Operating Activity | B4: ='Data Sheet'!B79 -> 1226.94 | C4: ='Data Sheet'!C79 -> 1091.5 | D4: ='Data Sheet'!D79 -> 1499.13 | E4: ='Data Sheet'!E79 -> 1613.62 | F4: ='Data Sheet'!F79 -> 2114.67 | G4: ='Data Sheet'!G79 -> 1802.33 | H4: ='Data Sheet'!H79 -> 1488.43 | I4: ='Data Sheet'!I79 -> 2013.47 | ... K4: ='Data Sheet'!K79 -> 2578.62
A5: Cash from Investing Activity | B5: ='Data Sheet'!B80 -> -807.07 | C5: ='Data Sheet'!C80 -> -540.93 | D5: ='Data Sheet'!D80 -> 337.58 | E5: ='Data Sheet'!E80 -> -516.63 | F5: ='Data Sheet'!F80 -> -1404.22 | G5: ='Data Sheet'!G80 -> -1273.45 | H5: ='Data Sheet'!H80 -> -582.79 | I5: ='Data Sheet'!I80 -> -971.04 | ... K5: ='Data Sheet'!K80 -> -1285.22
A6: Cash from Financing Activity | B6: ='Data Sheet'!B81 -> -338.97 | C6: ='Data Sheet'!C81 -> -577.11 | D6: ='Data Sheet'!D81 -> -1888.2 | E6: ='Data Sheet'!E81 -> -1042.97 | F6: ='Data Sheet'!F81 -> -613.41 | G6: ='Data Sheet'!G81 -> -490.49 | H6: ='Data Sheet'!H81 -> -1035.24 | I6: ='Data Sheet'!I81 -> -1161.18 | ... K6: ='Data Sheet'!K81 -> -1235.73
A7: Net Cash Flow | B7: ='Data Sheet'!B82 -> 80.9 | C7: ='Data Sheet'!C82 -> -26.54 | D7: ='Data Sheet'!D82 -> -51.49 | E7: ='Data Sheet'!E82 -> 54.02 | F7: ='Data Sheet'!F82 -> 97.04 | G7: ='Data Sheet'!G82 -> 38.39 | H7: ='Data Sheet'!H82 -> -129.6 | I7: ='Data Sheet'!I82 -> -118.75 | ... K7: ='Data Sheet'!K82 -> 57.67

Sheet Stock Analysis
R3: Recommendation
R4: Investor Type
R5: Existing Shareholder | S5: HOLD
R6: Long-Term Investor | S6: ACCUMULATE
R7: Value Investor | S7: WAIT FOR DIPS
R8: Short-Term Trader | S8: NEUTRAL
A20: Stock Analysis:
A21: Despite the recent underperformance across the FMCG sector, Dabur India continues to demonstrate resilient fundamentals supported by strong brands, healthy cash generation, and a debt-free balance sheet. The correction seen across peers such as Godrej Consumer, Colgate-Palmolive, and Gillette suggests that sector-wide valuation compression rather than company-specific weakness has driven stock performance. While near-term growth remains moderate, improving rural demand and Dabur's strong market position provide a foundation for long-term value creation. Therefore, I maintain a HOLD recommendation, with accumulation advised on meaningful price corrections.

Sheet Ratio Analysis
B1: Ratio Analysis
B3: Years | C3: 2022 | D3: 2023 | E3: 2024 | F3: 2025 | G3: 2026
B4: Growth Rates
B5: Sales Growth | D5: =IFERROR(HistoricalFS!D5/HistoricalFS!C5-1,0) -> 0.058887762 | E5: =IFERROR(HistoricalFS!E5/HistoricalFS!D5-1,0) -> 0.075813386 | F5: =IFERROR(HistoricalFS!F5/HistoricalFS!E5-1,0) -> 0.012824885 | G5: =IFERROR(HistoricalFS!G5/HistoricalFS!F5-1,0) -> 0.050105507
B6: EBITDA Growth | D6: =IFERROR(HistoricalFS!D17/HistoricalFS!C17-1,0) -> -0.11365111 | E6: =IFERROR(HistoricalFS!E17/HistoricalFS!D17-1,0) -> 0.26084476 | F6: =IFERROR(HistoricalFS!F17/HistoricalFS!E17-1,0) -> -0.11830463 | G6: =IFERROR(HistoricalFS!G17/HistoricalFS!F17-1,0) -> 0.037845005
B7: EBIT Growth | D7: =IFERROR(HistoricalFS!D23/HistoricalFS!C23-1,0) -> -0.15745048 | E7: =IFERROR(HistoricalFS!E23/HistoricalFS!D23-1,0) -> 0.25657056 | F7: =IFERROR(HistoricalFS!F23/HistoricalFS!E23-1,0) -> -0.16291859 | G7: =IFERROR(HistoricalFS!G23/HistoricalFS!F23-1,0) -> 0.034163754
B8: Net Profit Growth | D8: =IFERROR(HistoricalFS!D37/HistoricalFS!C37-1,0) -> -0.11908764 | E8: =IFERROR(HistoricalFS!E37/HistoricalFS!D37-1,0) -> 0.25626583 | F8: =IFERROR(HistoricalFS!F37/HistoricalFS!E37-1,0) -> -0.14822361 | G8: =IFERROR(HistoricalFS!G37/HistoricalFS!F37-1,0) -> 0.047908647
B9: Dividend Growth | D9: =IFERROR(HistoricalFS!D45/HistoricalFS!C45-1,0) -> 2.1659673e-06 | E9: =IFERROR(HistoricalFS!E45/HistoricalFS!D45-1,0) -> 0.057687716 | F9: =IFERROR(HistoricalFS!F45/HistoricalFS!E45-1,0) -> 0.45454545 | G9: =IFERROR(HistoricalFS!G45/HistoricalFS!F45-1,0) -> 0.031248238
B11: Margins
B12: Gross Margin | C12: =IFERROR(HistoricalFS!C12,0) -> 0.45535731 | D12: =IFERROR(HistoricalFS!D12,0) -> 0.41167522 | E12: =IFERROR(HistoricalFS!E12,0) -> 0.46179743 | F12: =IFERROR(HistoricalFS!F12,0) -> 0.44411447 | G12: =IFERROR(HistoricalFS!G12,0) -> 0.47028289
B13: EBITDA Margin | C13: =IFERROR(HistoricalFS!C18,0) -> 0.20525077 | D13: =IFERROR(HistoricalFS!D18,0) -> 0.1718065 | E13: =IFERROR(HistoricalFS!E18,0) -> 0.20135585 | F13: =IFERROR(HistoricalFS!F18,0) -> 0.17528649 | G13: =IFERROR(HistoricalFS!G18,0) -> 0.17323994
B14: EBIT Margin | C14: =IFERROR(HistoricalFS!C24,0) -> 0.18202574 | D14: =IFERROR(HistoricalFS!D24,0) -> 0.14483659 | E14: =IFERROR(HistoricalFS!E24,0) -> 0.1691719 | F14: =IFERROR(HistoricalFS!F24,0) -> 0.13981751 | G14: =IFERROR(HistoricalFS!G24,0) -> 0.13769493
B15: EBT Margin | C15: =IFERROR(HistoricalFS!C32,0) -> 0.20678172 | D15: =IFERROR(HistoricalFS!D32,0) -> 0.17667992 | E15: =IFERROR(HistoricalFS!E32,0) -> 0.19805208 | F15: =IFERROR(HistoricalFS!F32,0) -> 0.17063398 | G15: =IFERROR(HistoricalFS!G32,0) -> 0.17099549
B16: Net Profit Margin | C16: =IFERROR(HistoricalFS!C38,0) -> 0.15843977 | D16: =IFERROR(HistoricalFS!D38,0) -> 0.13180958 | E16: =IFERROR(HistoricalFS!E38,0) -> 0.15391877 | F16: =IFERROR(HistoricalFS!F38,0) -> 0.12944427 | G16: =IFERROR(HistoricalFS!G38,0) -> 0.12917347
B18: Expense Ratios
B19: Sales Expenses | C19: =IFERROR(HistoricalFS!C15,0) -> 0.25010653 | D19: =IFERROR(HistoricalFS!D15,0) -> 0.23986872 | E19: =IFERROR(HistoricalFS!E15,0) -> 0.26044158 | F19: =IFERROR(HistoricalFS!F15,0) -> 0.26882797 | G19: =IFERROR(HistoricalFS!G15,0) -> 0.29704296
B20: Depreciation | C20: =IFERROR(HistoricalFS!C21,0) -> 0.023225037 | D20: =IFERROR(HistoricalFS!D21,0) -> 0.026969902 | E20: =IFERROR(HistoricalFS!E21,0) -> 0.032183947 | F20: =IFERROR(HistoricalFS!F21,0) -> 0.035468981 | G20: =IFERROR(HistoricalFS!G21,0) -> 0.035545008
B21: Operating Income | C21: =IFERROR(HistoricalFS!C24,0) -> 0.18202574 | D21: =IFERROR(HistoricalFS!D24,0) -> 0.14483659 | E21: =IFERROR(HistoricalFS!E24,0) -> 0.1691719 | F21: =IFERROR(HistoricalFS!F24,0) -> 0.13981751 | G21: =IFERROR(HistoricalFS!G24,0) -> 0.13769493
B23: Returns
B24: Return on Capital Employed | C24: =IFERROR(HistoricalFS!C23/SUM(HistoricalFS!C51+HistoricalFS!C53+HistoricalFS!C52),0) -> 0.21059779 | D24: =IFERROR(HistoricalFS!D23/SUM(HistoricalFS!D51+HistoricalFS!D53+HistoricalFS!D52),0) -> 0.16457493 | E24: =IFERROR(HistoricalFS!E23/SUM(HistoricalFS!E51+HistoricalFS!E53+HistoricalFS!E52),0) -> 0.1868344 | F24: =IFERROR(HistoricalFS!F23/SUM(HistoricalFS!F51+HistoricalFS!F53+HistoricalFS!F52),0) -> 0.14947928 | G24: =IFERROR(HistoricalFS!G23/SUM(HistoricalFS!G51+HistoricalFS!G53+HistoricalFS!G52),0) -> 0.14295844
B25: Retained Earnings | C25: =HistoricalFS!C48 -> 0.46712845 | D25: =HistoricalFS!D48 -> 0.39375555 | E25: =HistoricalFS!E48 -> 0.48952708 | F25: =HistoricalFS!F48 -> 0.12813764 | G25: =HistoricalFS!G48 -> 0.14132138
B26: Return on Equity | C26: =IFERROR(HistoricalFS!C37/(HistoricalFS!C51+HistoricalFS!C52),0) -> 0.20583919 | D26: =IFERROR(HistoricalFS!D37/(HistoricalFS!D51+HistoricalFS!D52),0) -> 0.16936431 | E26: =IFERROR(HistoricalFS!E37/(HistoricalFS!E51+HistoricalFS!E52),0) -> 0.1935082 | F26: =IFERROR(HistoricalFS!F37/(HistoricalFS!F51+HistoricalFS!F52),0) -> 0.15056631 | G26: =IFERROR(HistoricalFS!G37/(HistoricalFS!G51+HistoricalFS!G52),0) -> 0.14922956
B27: Self Sustained Growth Rate | C27: =IFERROR(C25*C26,0) -> 0.096153341 | D27: =IFERROR(D25*D26,0) -> 0.066688138 | E27: =IFERROR(E25*E26,0) -> 0.094727507 | F27: =IFERROR(F25*F26,0) -> 0.019293212 | G27: =IFERROR(G25*G26,0) -> 0.021089328
B28: Interest Coverage Ratio | C28: =IFERROR(HistoricalFS!C23/HistoricalFS!C26,0) -> 51.347668 | D28: =IFERROR(HistoricalFS!D23/HistoricalFS!D26,0) -> 21.343942 | E28: =IFERROR(HistoricalFS!E23/HistoricalFS!E26,0) -> 16.898132 | F28: =IFERROR(HistoricalFS!F23/HistoricalFS!F26,0) -> 10.743364 | G28: =IFERROR(HistoricalFS!G23/HistoricalFS!G26,0) -> 12.493466
B30: Efficiency Ratios
B31: Debtor Turnover Ratio | C31: =IFERROR(HistoricalFS!C5/HistoricalFS!C63,0) -> 16.851629 | D31: =IFERROR(HistoricalFS!D5/HistoricalFS!D63,0) -> 13.584554 | E31: =IFERROR(HistoricalFS!E5/HistoricalFS!E63,0) -> 13.801863 | F31: =IFERROR(HistoricalFS!F5/HistoricalFS!F63,0) -> 14.139662 | G31: =IFERROR(HistoricalFS!G5/HistoricalFS!G63,0) -> 18.440573
B32: Creditor Turnover Ratio | C32: =IFERROR(HistoricalFS!C5/HistoricalFS!C54,0) -> 3.790716 | D32: =IFERROR(HistoricalFS!D5/HistoricalFS!D54,0) -> 3.2893391 | E32: =IFERROR(HistoricalFS!E5/HistoricalFS!E54,0) -> 3.19282 | F32: =IFERROR(HistoricalFS!F5/HistoricalFS!F54,0) -> 2.8050814 | G32: =IFERROR(HistoricalFS!G5/HistoricalFS!G54,0) -> 2.763959
B33: Inventory Turnover | C33: =IFERROR(HistoricalFS!C5/HistoricalFS!C64,0) -> 5.6967934 | D33: =IFERROR(HistoricalFS!D5/HistoricalFS!D64,0) -> 5.6960231 | E33: =IFERROR(HistoricalFS!E5/HistoricalFS!E64,0) -> 6.3709302 | F33: =IFERROR(HistoricalFS!F5/HistoricalFS!F64,0) -> 5.4619518 | G33: =IFERROR(HistoricalFS!G5/HistoricalFS!G64,0) -> 5.6824602
B34: Fixed Asset Turnover | C34: =IFERROR(HistoricalFS!C5/HistoricalFS!C57,0) -> 4.7180034 | D34: =IFERROR(HistoricalFS!D5/HistoricalFS!D57,0) -> 3.2218546 | E34: =IFERROR(HistoricalFS!E5/HistoricalFS!E57,0) -> 3.2513788 | F34: =IFERROR(HistoricalFS!F5/HistoricalFS!F57,0) -> 3.1488888 | G34: =IFERROR(HistoricalFS!G5/HistoricalFS!G57,0) -> 3.3492861
B35: Capital Turnover Ratio | C35: =IFERROR(HistoricalFS!C5/SUM(HistoricalFS!C51+HistoricalFS!C52),0) -> 1.2991636 | D35: =IFERROR(HistoricalFS!D5/SUM(HistoricalFS!D51+HistoricalFS!D52),0) -> 1.2849165 | E35: =IFERROR(HistoricalFS!E5/SUM(HistoricalFS!E51+HistoricalFS!E52),0) -> 1.2572099 | F35: =IFERROR(HistoricalFS!F5/SUM(HistoricalFS!F51+HistoricalFS!F52),0) -> 1.1631748 | G35: =IFERROR(HistoricalFS!G5/SUM(HistoricalFS!G51+HistoricalFS!G52),0) -> 1.1552648
B37: Working Capital Days
B38: Debtors Days | C38: =IFERROR(365/C31,0) -> 21.659627 | D38: =IFERROR(365/D31,0) -> 26.868752 | E38: =IFERROR(365/E31,0) -> 26.445706 | F38: =IFERROR(365/F31,0) -> 25.813912 | G38: =IFERROR(365/G31,0) -> 19.793312
B39: Payable Days | C39: =IFERROR(365/C32,0) -> 96.287879 | D39: =IFERROR(365/D32,0) -> 110.96454 | E39: =IFERROR(365/E32,0) -> 114.319 | F39: =IFERROR(365/F32,0) -> 130.121 | G39: =IFERROR(365/G32,0) -> 132.05695
B40: Inventory Days | C40: =IFERROR(365/C33,0) -> 64.071132 | D40: =IFERROR(365/D33,0) -> 64.079796 | E40: =IFERROR(365/E33,0) -> 57.291477 | F40: =IFERROR(365/F33,0) -> 66.825928 | G40: =IFERROR(365/G33,0) -> 64.232742
B41: Cash Conversion Cycle | C41: =SUM(C38+C40-C39) -> -10.55712 | D41: =SUM(D38+D40-D39) -> -20.015993 | E41: =SUM(E38+E40-E39) -> -30.58182 | F41: =SUM(F38+F40-F39) -> -37.481161 | G41: =SUM(G38+G40-G39) -> -48.030895
B43: Cash Flow Quality
B44: CFO / Sales | C44: =IFERROR(HistoricalFS!C74/HistoricalFS!C5,0) -> 0.16552328 | D44: =IFERROR(HistoricalFS!D74/HistoricalFS!D5,0) -> 0.12909317 | E44: =IFERROR(HistoricalFS!E74/HistoricalFS!E5,0) -> 0.16232412 | F44: =IFERROR(HistoricalFS!F74/HistoricalFS!F5,0) -> 0.15814183 | G44: =IFERROR(HistoricalFS!G74/HistoricalFS!G5,0) -> 0.19546002
B45: CFO / Total Assets | C45: =IFERROR(HistoricalFS!C74/HistoricalFS!C68,0) -> 0.14672342 | D45: =IFERROR(HistoricalFS!D74/HistoricalFS!D68,0) -> 0.10902428 | E45: =IFERROR(HistoricalFS!E74/HistoricalFS!E68,0) -> 0.13319807 | F45: =IFERROR(HistoricalFS!F74/HistoricalFS!F68,0) -> 0.12241409 | G45: =IFERROR(HistoricalFS!G74/HistoricalFS!G68,0) -> 0.14751907
B46: CFO / Total Debt | C46: =IFERROR(HistoricalFS!C74/HistoricalFS!C53,0) -> 1.7496651 | D46: =IFERROR(HistoricalFS!D74/HistoricalFS!D53,0) -> 1.2680548 | E46: =IFERROR(HistoricalFS!E74/HistoricalFS!E53,0) -> 1.4749723 | F46: =IFERROR(HistoricalFS!F74/HistoricalFS!F53,0) -> 2.0905016 | G46: =IFERROR(HistoricalFS!G74/HistoricalFS!G53,0) -> 2.0030917

Sheet Data Sheet
A1: COMPANY NAME | B1: DABUR INDIA LTD
A2: LATEST VERSION | B2: 2.1 | E2: PLEASE DO NOT MAKE ANY CHANGES TO THIS SHEET
A3: CURRENT VERSION | B3: 2.1
A5: META
A6: Number of shares | B6: =IF(B9>0, B9/B8, 0) -> 177.36901
A7: Face Value | B7: 1
A8: Current Price | B8: 444.05
A9: Market Capitalization | B9: 78760.71
A12: PROFIT & LOSS
A13: Report Date | B13: 42825 | C13: 43190 | D13: 43555 | E13: 43921 | F13: 44286 | G13: 44651 | H13: 45016 | I13: 45382 | J13: 45747 | K13: 46112
A14: Sales | B14: 7613.59 | C14: 7721.85 | D14: 8514.99 | E14: 8684.64 | F14: 9561.65 | G14: 10888.68 | H14: 11529.89 | I14: 12404.01 | J14: 12563.09 | K14: 13192.57
A15: Raw Material Cost | B15: 2659.55 | C15: 2775.35 | D15: 3067.95 | E15: 3138.49 | F15: 3764.3 | G15: 4136.7 | H15: 4762.03 | I15: 4714.88 | J15: 4843.98 | K15: 6906.05
A16: Change in Inventory | B16: 23.02 | C16: 65.93 | D16: -12.64 | E16: 65.04 | F16: 207.2 | G16: 8.55 | H16: 90.79 | I16: -48.95 | J16: 57.1 | K16: 82.28
A17: Power and Fuel | B17: 87.48 | C17: 93.91 | D17: 105.26 | E17: 107.12 | F17: 104.01 | G17: 128.66 | H17: 150.59 | I17: 153.44 | J17: 155.95
A18: Other Mfr. Exp | B18: 1247.42 | C18: 1219 | D18: 1327.63 | E18: 1387.98 | F18: 1347.34 | G18: 1656.53 | H18: 1779.91 | I18: 1856.5 | J18: 1926.61
A19: Employee Cost | B19: 790.3 | C19: 793.36 | D19: 938.55 | E19: 949.16 | F19: 1034.9 | G19: 1081.39 | H19: 1138.43 | I19: 1241.06 | J19: 1292.36 | K19: 1375.64
A20: Selling and admin | B20: 1161.4 | C20: 1135.38 | D20: 1183.56 | E20: 1224.59 | F20: 1388.27 | G20: 1480.71 | H20: 1426.95 | I20: 1827.33 | J20: 1896.92 | K20: 888.06
A21: Other Expenses | B21: 178.85 | C21: 153.34 | D21: 139.84 | E21: 150 | F21: 128.36 | G21: 161.23 | H21: 200.28 | I21: 162.13 | J21: 188.03 | K21: 1655.06
A22: Other Income | B22: 295.93 | C22: 290.88 | D22: 221.79 | E22: 205.29 | F22: 325.29 | G22: 308.16 | H22: 445.39 | I22: 482.41 | J22: 550.65 | K22: 584.72
A23: Depreciation | B23: 142.86 | C23: 162.18 | D23: 176.9 | E23: 220.45 | F23: 240.13 | G23: 252.89 | H23: 310.96 | I23: 399.21 | J23: 445.6 | K23: 468.93
A24: Interest | B24: 54.03 | C24: 53.05 | D24: 59.58 | E24: 49.54 | F24: 30.81 | G24: 38.6 | H24: 78.24 | I24: 124.18 | J24: 163.5 | K24: 145.4
A25: Profit before tax | B25: 1610.65 | C25: 1693.09 | D25: 1724.87 | E25: 1727.64 | F25: 2056.02 | G25: 2268.68 | H25: 2218.68 | I25: 2358.74 | J25: 2257.89 | K25: 2420.43
A26: Tax | B26: 330.34 | C26: 335.35 | D26: 278.62 | E26: 279.72 | F26: 361.07 | G26: 526.38 | H26: 517.35 | I26: 547.43 | J26: 517.47 | K26: 551.74
A27: Net profit | B27: 1276.94 | C27: 1354.39 | D27: 1442.33 | E27: 1444.96 | F27: 1693.3 | G27: 1739.22 | H27: 1707.15 | I27: 1842.68 | J27: 1767.63 | K27: 1895.03
A28: Dividend Amount | B28: 396.34 | C28: 1100.94 | D28: 485.73 | E28: 530.13 | F28: 839.52 | G28: 919.31 | H28: 921.34 | I28: 974.6 | J28: 1417.84 | K28: 1463.3
A37: Quarters
A38: Report Date | B38: 45291 | C38: 45382 | D38: 45473 | E38: 45565 | F38: 45657 | G38: 45747 | H38: 45838 | I38: 45930 | J38: 46022 | K38: 46112
A39: Sales | B39: 3255.06 | C39: 2814.64 | D39: 3349.11 | E39: 3028.59 | F39: 3355.25 | G39: 2830.14 | H39: 3404.58 | I39: 3191.32 | J39: 3558.65 | K39: 3038.02
A40: Expenses | B40: 2587.64 | C40: 2348.23 | D40: 2694.28 | E40: 2476.04 | F40: 2673.36 | G40: 2403.27 | H40: 2737.16 | I40: 2603.35 | J40: 2824.82 | K40: 2577.2
A41: Other Income | B41: 127.37 | C41: 128.85 | D41: 129.4 | E41: 151.76 | F41: 128.53 | G41: 141.16 | H41: 143.97 | I41: 140.13 | J41: 125.59 | K41: 175.03
A42: Depreciation | B42: 96.89 | C42: 107.36 | D42: 109.12 | E42: 110.97 | F42: 108.64 | G42: 116.87 | H42: 114.14 | I42: 115.4 | J42: 117.19 | K42: 122.2
A43: Interest | B43: 36.49 | C43: 35.24 | D43: 32.66 | E43: 47.39 | F43: 44.2 | G43: 39.25 | H43: 34.63 | I43: 39.68 | J43: 31.12 | K43: 39.97
A44: Profit before tax | B44: 661.41 | C44: 452.66 | D44: 642.45 | E44: 545.95 | F44: 657.58 | G44: 411.91 | H44: 662.62 | I44: 573.02 | J44: 711.11 | K44: 473.68
A45: Tax | B45: 154.97 | C45: 111.44 | D45: 148.1 | E45: 128.43 | F45: 141.76 | G45: 99.18 | H45: 154.33 | I45: 128.23 | J45: 157.5 | K45: 111.68
A46: Net profit | B46: 514.22 | C46: 349.53 | D46: 500.12 | E46: 425 | F46: 522.38 | G46: 320.13 | H46: 513.91 | I46: 452.55 | J46: 559.97 | K46: 368.6 | M46: Year | N46: Interest Expense | O46: Opening Debt | P46: Closing Debt | Q46: Average Debt | R46: Cost of Debt
A47: Operating Profit | B47: 667.42 | C47: 466.41 | D47: 654.83 | E47: 552.55 | F47: 681.89 | G47: 426.87 | H47: 667.42 | I47: 587.97 | J47: 733.83 | K47: 460.82 | M47: 2022 | N47: 38.6 | O47: 0 | P47: 1030.1 | Q47: 1030.1 | R47: 0.0375
M48: 2023 | N48: 78.2 | O48: 1030.1 | P48: 1173.8 | Q48: 1101.95 | R48: 0.071
M49: 2024 | N49: 124.2 | O49: 1173.8 | P49: 1365.1 | Q49: 1269.45 | R49: 0.0978
M50: 2025 | N50: 163.5 | O50: 1365.1 | P50: 950.4 | Q50: 1157.75 | R50: 0.1412
M51: 2026 | N51: 145.4 | O51: 950.4 | P51: 1287.3 | Q51: 1118.85 | R51: 0.1299
...

Sheet Peer Comps
A1: RELATIVE VALUATION
A4: S.No. | B4: Company | C4: CMP | D4: Mkt Cap | E4: Revenue | F4: EBITDA | G4: PAT | H4: EPS | I4: P/E | J4: EV/EBITDA | K4: EV/Sales | L4: P/BV | M4: EBITDA Margin % | N4: Rev Growth | O4: ROE FY26 %
A5: 1 | B5: Godrej Consumer | C5: 1028 | D5: 105138 | E5: 14763 | F5: 3100 | G5: 2047 | H5: 20.12 | I5: 51.1 | J5: 34.8 | K5: 7.27 | L5: 10.2 | M5: 0.21 | N5: 0.082 | O5: 0.224
A6: 2 | B6: Colgate-Palmolive | C6: 2157 | D6: 58665 | E6: 5827 | F6: 1688 | G6: 1241 | H6: 45.65 | I6: 47.3 | J6: 34.9 | K6: 10.15 | L6: 25.6 | M6: 0.29 | N6: 0.091 | O6: 0.741
A7: 3 | B7: P&G Hygiene | C7: 9585 | D7: 31114 | E7: 4219 | F7: 935 | G7: 752 | H7: 231.85 | I7: 41.3 | J7: 33.5 | K7: 7.53 | L7: 9.1 | M7: 0.212 | N7: 0.087 | O7: 0.263
A8: 4 | B8: Gillette India | C8: 7784 | D8: 25366 | E8: 3106 | F8: 743 | G8: 583 | H8: 179 | I8: 43.5 | J8: 34.3 | K8: 8.32 | L8: 9.7 | M8: 0.239 | N8: 0.095 | O8: 0.304
A9: 5 | B9: Dabur India | C9: 451.05 | D9: 80002 | E9: 13193 | F9: 2285 | G9: 1704 | H9: 9.61 | I9: 46.9 | J9: 35.3 | K9: 6.09 | L9: 7.15 | M9: 0.173 | N9: 0.047 | O9: 0.166
B11: Mean | C11: =AVERAGE(C5:C9) -> 4201.01 | D11: =AVERAGE(D5:D9) -> 60057 | E11: =AVERAGE(E5:E9) -> 8221.6 | F11: =AVERAGE(F5:F9) -> 1750.2 | G11: =AVERAGE(G5:G9) -> 1265.4 | H11: =MEDIAN(H5:H9) -> 45.65 | I11: =AVERAGE(I5:I9) -> 46.02 | J11: =AVERAGE(J5:J9) -> 34.56 | K11: =AVERAGE(K5:K9) -> 7.872 | L11: =AVERAGE(L5:L9) -> 12.35 | M11: =AVERAGE(M5:M9) -> 0.2248 | N11: =AVERAGE(N5:N9) -> 0.0804 | O11: =AVERAGE(O5:O9) -> 0.3396
B12: Median | C12: =MEDIAN(C5:C9) -> 2157 | D12: =MEDIAN(D5:D9) -> 58665 | E12: =MEDIAN(E5:E9) -> 5827 | F12: =MEDIAN(F5:F9) -> 1688 | G12: =MEDIAN(G5:G9) -> 1241 | H12: =MEDIAN(H5:H9) -> 45.65 | I12: =MEDIAN(I5:I9) -> 46.9 | J12: =MEDIAN(J5:J9) -> 34.8 | ... O12: =MEDIAN(O5:O9) -> 0.263
B13: Min | C13: =MIN(C5:C9) -> 451.05 | D13: =MIN(D5:D9) -> 25366 | E13: =MIN(E5:E9) -> 3106 | F13: =MIN(F5:F9) -> 743 | G13: =MIN(G5:G9) -> 583 | H13: =MIN(H5:H9) -> 9.61 | I13: =MIN(I5:I9) -> 41.3 | J13: =MIN(J5:J9) -> 33.5 | ... O13: =MIN(O5:O9) -> 0.166
B14: Max | C14: =MAX(C5:C9) -> 9585 | D14: =MAX(D5:D9) -> 105138 | E14: =MAX(E5:E9) -> 14763 | F14: =MAX(F5:F9) -> 3100 | G14: =MAX(G5:G9) -> 2047 | H14: =MAX(H5:H9) -> 231.85 | I14: =MAX(I5:I9) -> 51.1 | J14: =MAX(J5:J9) -> 35.3 | ... O14: =MAX(O5:O9) -> 0.741
A17: IMPLIED PRICE FOR DABUR INDIA
C18: Multiple Used | D18: Dabur Metric | E18: Implied Price (₹) | F18: Current CMP (₹) | G18: Premium/ (Discount) | H18: Weight | I18: Wtd Price
B19: P/E Multiple | C19: =I12 -> 46.9 | D19: 9.608 | E19: =I12*9.608 -> 450.6152 | F19: 451.05 | G19: =E19/F19-1 -> -0.00096397295 | H19: 0.35 | I19: =E19*H19 -> 157.71532
B20: EV/EBITDA Multiple | C20: =J12 -> 34.8 | D20: 2285.48 | E20: =(J12*2285.48+562.07-1287.32)/177.37 -> 444.32234 | F20: 451.05 | G20: =E20/F20-1 -> -0.014915546 | H20: 0.35 | I20: =E20*H20 -> 155.51282
B21: EV/Sales Multiple | C21: =K12 -> 7.53 | D21: 13192.57 | E21: =(K12*13192.57+562.07-1287.32)/177.37 -> 555.98355 | F21: 451.05 | G21: =E21/F21-1 -> 0.23264283 | H21: 0.15 | I21: =E21*H21 -> 83.397532
B22: P/Book Value | C22: =L12 -> 9.7 | D22: 64.382477 | E22: =L12*64.3825 -> 624.51025 | F22: 451.05 | G22: =E22/F22-1 -> 0.38456989 | H22: 0.15 | I22: =E22*H22 -> 93.676537
A24: Weighted Target Price | E24: =SUM(I19+I20+I21+I22) -> 490.30221 | F24: 451.05 | G24: =E24/F24-1 -> 0.087024077

Sheet Fixed Asset Schedule
B2: Fixed Asset Schedule
B3: Particulars | C3: 2022 | D3: 2023 | E3: 2024 | F3: 2025 | G3: 2026
B4: Opening Balance | D4: =C8 -> 2307.9 | E4: =D8 -> 3578.65 | F4: =E8 -> 3815 | G4: =F8 -> 3989.69
B5: Add: Gross Additions (Capex) | D5: =D8-C8+D7 -> 1581.71 | E5: =E8-D8+E7 -> 635.56 | F5: =F8-E8+F7 -> 620.29 | G5: =G8-F8+G7 -> 418.16
B6: Fixed Assets Before Depreciation | C6: =HistoricalFS!C57 -> 2307.9 | D6: =D4+D5 -> 3889.61 | E6: =E4+E5 -> 4214.21 | F6: =F4+F5 -> 4435.29 | G6: =G4+G5 -> 4407.85
B7: Less: Depreciation | C7: =HistoricalFS!C20 -> 252.89 | D7: =HistoricalFS!D20 -> 310.96 | E7: =HistoricalFS!E20 -> 399.21 | F7: =HistoricalFS!F20 -> 445.6 | G7: =HistoricalFS!G20 -> 468.93
B8: Closing Balance Net Block | C8: =HistoricalFS!C57 -> 2307.9 | D8: =HistoricalFS!D57 -> 3578.65 | E8: =HistoricalFS!E57 -> 3815 | F8: =HistoricalFS!F57 -> 3989.69 | G8: =HistoricalFS!G57 -> 3938.92
B10: Net Capital Expenditure | D10: =D5-D7 -> 1270.75 | E10: =E5-E7 -> 236.35 | F10: =F5-F7 -> 174.69 | G10: =G5-G7 -> -50.77
B11: Net Capex / Sales % | D11: =D10/HistoricalFS!D5 -> 0.11021354 | E11: =E10/HistoricalFS!E5 -> 0.019054322 | F11: =F10/HistoricalFS!F5 -> 0.013905019 | G11: =G10/HistoricalFS!G5 -> -0.0038483783
B13: Median Net Capex / Sales % | C13: =MEDIAN(D11:G11) -> 0.01647967
B14: Average Net Capex / Sales % | C14: =AVERAGE(D11:G11) -> 0.034831126

Sheet Changes in Working Capital
B2: Changes in Working Capital
B3: Particulars | C3: FY 2022 | D3: FY 2023 | E3: FY 2024 | F3: FY 2025 | G3: FY 2026
B4: Inventories | C4: =HistoricalFS!C64 -> 1911.37 | D4: =HistoricalFS!D64 -> 2024.2 | E4: =HistoricalFS!E64 -> 1946.97 | F4: =HistoricalFS!F64 -> 2300.11 | G4: =HistoricalFS!G64 -> 2321.63
B5: Receivables | C5: =HistoricalFS!C63 -> 646.15 | D5: =HistoricalFS!D63 -> 848.75 | E5: =HistoricalFS!E63 -> 898.72 | F5: =HistoricalFS!F63 -> 888.5 | G5: =HistoricalFS!G63 -> 715.41
B6: Payables | C6: ='Balance Sheet'!U12 -> 2018 | D6: ='Balance Sheet'!V12 -> 2187 | E6: ='Balance Sheet'!W12 -> 2422 | F6: ='Balance Sheet'!X12 -> 2825 | G6: ='Balance Sheet'!Y12 -> 2954
B7: Non-Cash Working Capital | C7: =C4+C5-C6 -> 539.52 | D7: =D4+D5-D6 -> 685.95 | E7: =E4+E5-E6 -> 423.69 | F7: =F4+F5-F6 -> 363.61 | G7: =G4+G5-G6 -> 83.04
B9: Change in Working Capital | D9: =D7-C7 -> 146.43 | E9: =E7-D7 -> -262.26 | F9: =F7-E7 -> -60.08 | G9: =G7-F7 -> -280.57
B10: Change in WC / % of Sales | D10: =D9/HistoricalFS!D5 -> 0.012700034 | E10: =E9/HistoricalFS!E5 -> -0.021143163 | F10: =F9/HistoricalFS!F5 -> -0.004782263 | G10: =G9/HistoricalFS!G5 -> -0.021267274
B12: Median Change in WC / % of Sales | C12: =MEDIAN(D10:G10) -> -0.012962713
B13: Average Change in WC / % of Sales | C13: =AVERAGE(D10:G10) -> -0.0086231663

Sheet Beta Calculation
B1: Beta Calculation
B3: Date | C3: Nifty 50 | D3: DABUR.NS
B4: 44565 | C4: 1.02 | D4: -1.22
B5: 44566 | C5: 0.67 | D5: 1.47
B6: 44567 | C6: -1 | D6: 0.01 | F6: Beta | G6: =G26 -> 0.60376438
B7: 44568 | C7: 0.38 | D7: 0.85
B8: 44571 | C8: 1.07 | D8: 0.27
B9: 44572 | C9: 0.29 | D9: -0.26 | F9: SUMMARY OUTPUT
B10: 44573 | C10: 0.87 | D10: -0.86
B11: 44574 | C11: 0.25 | D11: -0.31 | F11: Regression Statistics
B12: 44575 | C12: -0.01 | D12: -0.84 | F12: Multiple R | G12: 0.3859228
B13: 44578 | C13: 0.29 | D13: -1.08 | F13: R Square | G13: 0.1489364
B14: 44579 | C14: -1.07 | D14: -1 | F14: Adjusted R Square | G14: 0.14814692
B15: 44580 | C15: -0.96 | D15: 0.82 | F15: Standard Error | G15: 1.2684881
B16: 44581 | C16: -1.01 | D16: -1.53 | F16: Observations | G16: 1080
B17: 44582 | C17: -0.79 | D17: -1.48
B18: 44585 | C18: -2.66 | D18: -0.99 | F18: ANOVA
B19: 44586 | C19: 0.75 | D19: -0.6 | G19: df | H19: SS | I19: MS | J19: F | K19: Significance F
B20: 44588 | C20: -0.97 | D20: -2.53 | F20: Regression | G20: 1 | H20: 303.5501 | I20: 303.5501 | J20: 188.65035 | K20: 1.1124659e-39
B21: 44589 | C21: -0.05 | D21: 0.93 | F21: Residual | G21: 1078 | H21: 1734.5688 | I21: 1.609062
B22: 44592 | C22: 1.39 | D22: 0.52 | F22: Total | G22: 1079 | H22: 2038.1189
B23: 44593 | C23: 1.37 | D23: 1.81
B24: 44594 | C24: 1.16 | D24: 2.01 | G24: Coefficients | H24: Standard Error | I24: t Stat | J24: P-value | K24: Lower 95% | L24: Upper 95% | M24: Lower 95.0% | N24: Upper 95.0%
B25: 44595 | C25: -1.24 | D25: -0.18 | F25: Intercept | G25: -0.030587584 | H25: 0.038623896 | I25: -0.7919342 | J25: 0.42857327 | K25: -0.10637412 | L25: 0.045198951 | M25: -0.10637412 | N25: 0.045198951
B26: 44596 | C26: -0.25 | D26: 2.26 | F26: X Variable 1 | G26: 0.60376438 | H26: 0.043958076 | I26: 13.735005 | J26: 1.1124659e-39 | K26: 0.51751129 | L26: 0.69001746 | M26: 0.51751129 | N26: 0.69001746
B27: 44599 | C27: -1.73 | D27: -0.4
B28: 44600 | C28: 0.31 | D28: -0.79
B29: 44601 | C29: 1.14 | D29: 1.47
B30: 44602 | C30: 0.81 | D30: -1.03
B31: 44603 | C31: -1.31 | D31: -0.66
B32: 44606 | C32: -3.06 | D32: -1.38
B33: 44607 | C33: 3.03 | D33: 1.69
B34: 44608 | C34: -0.17 | D34: -0.11
B35: 44609 | C35: -0.1 | D35: -1.33
B36: 44610 | C36: -0.16 | D36: -1.19
B37: 44613 | C37: -0.4 | D37: 1.06
B38: 44614 | C38: -0.67 | D38: -0.64
... B1083: 46164 | C1083: 0.27 | D1083: 0.94
H1087: 46037

Sheet Rm
B1: Total Market Return
B3: Year | C3: Annual
B4: 2000 | C4: -0.1465 | E4: Average return | F4: =AVERAGE(C4:C29) -> 0.15121154 | G4: Market Return
B5: 2001 | C5: -0.1618 | E5: Dividend yield | F5: 0.013 | G5: Dividend Yield
B6: 2002 | C6: 0.0325 | E6: Total market return | F6: =SUM(F4:F5) -> 0.16421154
B7: 2003 | C7: 0.719
B8: 2004 | C8: 0.1068
B9: 2005 | C9: 0.3634
B10: 2006 | C10: 0.3983
B11: 2007 | C11: 0.5477
B12: 2008 | C12: -0.5179
B13: 2009 | C13: 0.7576
B14: 2010 | C14: 0.1795
B15: 2011 | C15: -0.2462
B16: 2012 | C16: 0.277
B17: 2013 | C17: 0.0676
B18: 2014 | C18: 0.3139
... B29: 2025 | C29: 0.1051

Sheet WACC
B1: Weighted average cost of capital
B3: All Figures are in INR unless stated otherwise
B5: Peer Comp | N5: S.No. | O5: Name | P5: CMP Rs. | Q5: Mar Cap Rs.Cr. | R5: Debt Rs.Cr. | S5: Debt / Eq | T5: Beta
N6: 1 | O6: Godrej Consumer | P6: 1027.5 | Q6: 105138.38 | R6: 4415.81 | S6: 0.35 | T6: 0.62872046
H7: Debt/ | I7: Debt/ | J7: Levered/ | K7: Unlevered/ | N7: 2 | O7: Dabur India | P7: 451.05 | Q7: 80002.3 | R7: 1287.32 | S7: 0.11 | T7: =J10 -> 0.60376438
B8: Name of the company | D8: Country | E8: Total Equity | F8: Total Debt | G8: Tax Rate 1 | H8: Equity | I8: Capital | J8: beta 2 | K8: beta 3 | N8: 3 | O8: Colgate-Palmoliv | P8: 2156.9 | Q8: 58664.58 | R8: 47.41 | S8: 0.03 | T8: 0.014084006
N9: 4 | O9: P & G Hygiene | P9: 9585 | Q9: 31113.62 | R9: 2.06 | S9: 0 | T9: 0.851
B10: Dabur India | D10: India | E10: =Q7 -> 80002.3 | F10: =R7 -> 1287.32 | G10: 0.25 | H10: =S7 -> 0.11 | I10: =F10/(F10+E10) -> 0.015836216 | J10: ='Beta Calculation'!G6 -> 0.60376438 | K10: =J10/(1+(1-G10)*H10) -> 0.55775 | N10: 5 | O10: Gillette India | P10: 7783.5 | Q10: 25366.43 | R10: 0.05 | S10: 0 | T10: 0.42959689
B11: Godrej Consumer | D11: India | E11: =Q6 -> 105138.38 | F11: =R6 -> 4415.81 | G11: 0.25 | H11: =S6 -> 0.35 | I11: =F11/(F11+E11) -> 0.040307085 | J11: =T6 -> 0.62872046 | K11: =J11/(1+(1-G11)*H11) -> 0.4979964
