Workbook

Sheet About
A1: INDIAN OIL CORPORATION LIMITED
B6: COMPANY OVERVIEW
B7: ABOUT THE COMPANY | L7: Source
B8: Indian Oil Corporation Limited (NSE: IOC | BSE: 530965), commonly known as IndianOil, is India's largest oil refining and fuel marketing company and a Maharatna public sector enterprise functioning under the Ministry of Petroleum and Natural Gas. Formed in 1959 through the merger of Indian Refineries Limited and the original Indian Oil Company, the group today spans the entire hydrocarbon value chain - exploration and production, refining, pipeline transportation, marketing, petrochemicals and natural gas. IndianOil operates 11 refineries (including those of subsidiary Chennai Petroleum Corporation) with a combined capacity of over 80 million tonnes a year, moves crude and finished products through a cross-country pipeline network exceeding 20,000 km, and serves customers through more than 40,000 retail outlets - the largest fuel retail network in the country. Its portfolio includes well-known brands such as Indane LPG, SERVO lubricants and XtraPremium/XtraMile fuels. Majority owned by the Government of India (around 51.5%), the company is now steadily directing capital toward the energy transition - green hydrogen, biofuels, sustainable aviation fuel, EV charging infrastructure and renewable power - alongside its core refining and marketing businesses.
B9: REGISTERED OFFICE
B10: Address | C10: Indian Oil Bhavan, G-9, Ali Yavar Jung Marg, Bandra (East), Mumbai - 400051, Maharashtra, India
B12: S.No | C12: Name of Entity | D12: Type | F12: Country / Region of Operation | G12: Primary Business | H12: Remarks
B13: 1 | C13: Chennai Petroleum Corporation Limited (CPCL) | D13: Subsidiary | F13: India | G13: Refining & petrochemicals | H13: ~51.9% IOCL stake; principal refining subsidiary
B14: 2 | C14: Lanka IOC PLC | D14: Subsidiary | F14: Sri Lanka | G14: Refining, marketing & retail | H14: ~75.1% IOCL stake; international downstream arm
B15: 3 | C15: IOC Middle East FZE | D15: Subsidiary | F15: UAE | G15: Crude & product trading | H15: Wholly owned trading and marketing hub
B16: 4 | C16: IndianOil (Mauritius) Ltd. | D16: Subsidiary | F16: Mauritius | G16: Investment holding | H16: Wholly owned holding entity for overseas ventures
B17: 5 | C17: IOC Sweden AB | D17: Subsidiary | F17: Sweden | G17: Investment holding | H17: Wholly owned European holding company
B18: 6 | C18: IOCL Singapore Pte. Limited | D18: Subsidiary | F18: Singapore | G18: Trading & shipping | H18: Wholly owned trading and chartering hub
B19: 7 | C19: IOCL (USA) Inc. | D19: Subsidiary | F19: USA | G19: International trading | H19: Wholly owned North America trading arm
B20: 8 | C20: Indian Oil Tanking Limited | D20: Joint Venture | F20: India | G20: Petroleum storage & terminalling | H20: ~49.4% JV with Oiltanking GmbH, Germany
B21: 9 | C21: Indian Oil Petronas Private Limited | D21: Joint Venture | F21: India | G21: LPG bottling & auto LPG | H21: ~50% JV with Petronas, Malaysia
B22: 10 | C22: Indian Oil Skytanking Private Limited | D22: Joint Venture | F22: India | G22: Aviation fuel storage & handling | H22: ~50% JV serving major Indian airports
B23: 11 | C23: Lubrizol India Private Limited | D23: Joint Venture | F23: India | G23: Lubricant additives | H23: ~26% JV with The Lubrizol Corporation, USA
B24: 12 | C24: NPCIL - IndianOil Nuclear Energy Corporation Ltd. | D24: Joint Venture | F24: India | G24: Nuclear power generation | H24: ~26% JV with NPCIL; diversification into nuclear energy
... B26: 14 | C26: Indian Oil NTPC Green Energy Private Limited | D26: Joint Venture | F26: India | G26: Renewable energy | H26: ~50% JV with NTPC for solar & wind projects

Sheet Promoters
B1: Shareholding Pattern
B3: Indian Oil Corporation Ltd
B4: Scrip Code : 530965 | C4: Quarter Ending : Mar-26
B5: Statement showing shareholding pattern of the Promoter and Promoter Group
B6: Category of shareholder | C6: Entity Type | D6: Nos. of shareholders | E6: No. of fully paid up equity shares held | F6: Total nos. shares held | G6: Shareholding as a % of total no. of shares (calculated as per SCRR, 1957)As a % of (A+B+C2) | H6: Number of Voting Rights held in each class of securities | J6: Total No. Of shares on fully diluted basis (including warrants, ESOP, Convertible Securities etc.) | K6: Shareholding , as a % assuming full conversion of convertible securities ( as a percentage of diluted share capital)As a % of (A+B+C2) | L6: Number of equity shares held in dematerialized form
H7: Class eg: X | I7: Total
B9: A7) Indian | D9: - | E9: - | F9: - | G9: 0 | H9: - | I9: 0 | J9: - | K9: 0 | L9: -
B10: Central Government/ State Government(s) | D10: 1 | E10: 7272199767 | F10: 7272199767 | G10: 51.5 | H10: 7272199767 | I10: 51.5 | J10: 7272199767 | K10: 51.5 | L10: 7272199767
B11: President of India | C11: Promoter | D11: 1 | E11: 7272199767 | F11: 7272199767 | G11: 51.5 | H11: 7272199767 | I11: 51.5 | J11: 7272199767 | K11: 51.5 | L11: 7272199767
B12: Sub Total A1 | D12: 1 | E12: 7272199767 | F12: 7272199767 | G12: 51.5 | H12: 7272199767 | I12: 51.5 | J12: 7272199767 | K12: 51.5 | L12: 7272199767
B13: A8) Foreign | D13: - | E13: - | F13: - | G13: 0 | H13: - | I13: 0 | J13: - | K13: 0 | L13: -
B14: A=A1+A2 | D14: 1 | E14: 7272199767 | F14: 7272199767 | G14: 51.5 | H14: 7272199767 | I14: 51.5 | J14: 7272199767 | K14: 51.5 | L14: 7272199767

Sheet Public
B1: Shareholding Pattern Public Shareholder
B3: Indian Oil Corporation Ltd
B4: Scrip Code : 530965 | E4: Quarter Ending : Mar-26
B6: Statement showing shareholding pattern of the Public shareholder
B8: Category & Name of the Shareholders | C8: No. of shareholder | D8: No. of fully paid up equity shares held | E8: Total no. shares held | F8: Shareholding % calculated as per SCRR, 1957 As a % of (A+B+C2) | G8: No. of Voting Rights | H8: Total as a % of Total Voting right | I8: Total No. Of shares on fully diluted basis (including warrants, ESOP, Convertible Securities etc.) | J8: Shareholding , as a % assuming full conversion of convertible securities ( as a percentage of diluted share capital)As a % of (A+B+C2) | K8: No. of equity shares held in dematerialized form(Not Applicable) | L8: Sub-categorization of shares (XV)
L9: Shareholding (No. of shares) under
L10: SubCategory_I | M10: SubCategory_II | N10: SubCategory_III
B11: Institutions | C11: 0 | D11: 0 | E11: - | F11: 0 | G11: - | H11: 0 | I11: - | J11: 0 | K11: - | L11: - | M11: - | N11: -
B12: B2) Institutions (Domestic) | C12: 0 | D12: 0 | E12: - | F12: 0 | G12: - | H12: 0 | I12: - | J12: 0 | K12: - | L12: - | M12: - | N12: -
B13: Mutual Funds/ | C13: 34 | D13: 355639743 | E13: 355639743 | F13: 2.52 | G13: 355639743 | H13: 2.52 | I13: 355639743 | J13: 2.52 | K13: 355639683 | L13: - | M13: - | N13: -
B14: Venture Capital Funds | C14: 0 | D14: 0 | E14: - | F14: 0 | G14: - | H14: 0 | I14: - | J14: 0 | K14: - | L14: - | M14: - | N14: -
B15: Alternate Investment Funds | C15: 7 | D15: 564435 | E15: 564435 | F15: 0 | G15: 564435 | H15: 0 | I15: 564435 | J15: 0 | K15: 564435 | L15: - | M15: - | N15: -
B16: Banks | C16: 21 | D16: 81338 | E16: 81338 | F16: 0 | G16: 81338 | H16: 0 | I16: 81338 | J16: 0 | K16: 25171 | L16: - | M16: - | N16: -
B17: Insurance Companies | C17: 22 | D17: 929160203 | E17: 929160203 | F17: 6.58 | G17: 929160203 | H17: 6.58 | I17: 929160203 | J17: 6.58 | K17: 929159703 | L17: - | M17: - | N17: -
B18: LIFE INSURANCE CORPORATION OF INDIA | C18: 1 | D18: 853418670 | E18: 853418670 | F18: 6.04 | G18: 853418670 | H18: 6.04 | I18: 853418670 | J18: 6.04 | K18: 853418170 | L18: - | M18: - | N18: -
B19: Provident Funds/ Pension Funds | C19: 0 | D19: 0 | E19: - | F19: 0 | G19: - | H19: 0 | I19: - | J19: 0 | K19: - | L19: - | M19: - | N19: -
B20: Asset reconstruction companies | C20: 0 | D20: 0 | E20: - | F20: 0 | G20: - | H20: 0 | I20: - | J20: 0 | K20: - | L20: - | M20: - | N20: -
B21: Sovereign Wealth Funds | C21: 2 | D21: 14670520 | E21: 14670520 | F21: 0.1 | G21: 14670520 | H21: 0.1 | I21: 14670520 | J21: 0.1 | K21: 14670520 | L21: - | M21: - | N21: -
B22: NBFCs registered with RBI | C22: 14 | D22: 96399 | E22: 96399 | F22: 0 | G22: 96399 | H22: 0 | I22: 96399 | J22: 0 | K22: 96399 | L22: - | M22: - | N22: -
B23: Other Financial Institutions | C23: 0 | D23: 0 | E23: - | F23: 0 | G23: - | H23: 0 | I23: - | J23: 0 | K23: - | L23: - | M23: - | N23: -
B24: Sub Total B1 | C24: 100 | D24: 1300212638 | E24: 1300212638 | F24: 9.21 | G24: 1300212638 | H24: 9.21 | I24: 1300212638 | J24: 9.21 | K24: 1300155911 | L24: - | M24: - | N24: -
B25: B15) Institutions (Foreign) | C25: 0 | D25: 0 | E25: - | F25: 0 | G25: - | H25: 0 | I25: - | J25: 0 | K25: - | L25: - | M25: - | N25: -
B26: Foreign Direct Investment | C26: 0 | D26: 0 | E26: - | F26: 0 | G26: - | H26: 0 | I26: - | J26: 0 | K26: - | L26: - | M26: - | N26: -
B27: Foreign Venture Capital Investors | C27: 0 | D27: 0 | E27: - | F27: 0 | G27: - | H27: 0 | I27: - | J27: 0 | K27: - | L27: - | M27: - | N27: -
B28: Sovereign Wealth Funds | C28: 0 | D28: 0 | E28: - | F28: 0 | G28: - | H28: 0 | I28: - | J28: 0 | K28: - | L28: - | M28: - | N28: -
B29: Foreign Portfolio Investors Category I | C29: 751 | D29: 1332327749 | E29: 1332327749 | F29: 9.43 | G29: 1332327749 | H29: 9.43 | I29: 1332327749 | J29: 9.43 | K29: 1332327749 | L29: - | M29: - | N29: -
B30: Foreign Portfolio Investors Category II | C30: 49 | D30: 58141121 | E30: 58141121 | F30: 0.41 | G30: 58141121 | H30: 0.41 | I30: 58141121 | J30: 0.41 | K30: 58141121 | L30: - | M30: - | N30: -
B31: Overseas Depositories (holding DRs) (balancing figure) | C31: 0 | D31: 0 | E31: - | F31: 0 | G31: - | H31: 0 | I31: - | J31: 0 | K31: - | L31: - | M31: - | N31: -
B32: Sub Total B2 | C32: 800 | D32: 1390468870 | E32: 1390468870 | F32: 9.85 | G32: 1390468870 | H32: 9.85 | I32: 1390468870 | J32: 9.85 | K32: 1390468870 | L32: - | M32: - | N32: -
B33: B23) Central Government/ State Government(s)/ President of India | C33: 0 | D33: 0 | E33: - | F33: 0 | G33: - | H33: 0 | I33: - | J33: 0 | K33: - | L33: - | M33: - | N33: -
B34: State Government / Governor | C34: 1 | D34: 16200000 | E34: 16200000 | F34: 0.11 | G34: 16200000 | H34: 0.11 | I34: 16200000 | J34: 0.11 | K34: 16200000 | L34: - | M34: - | N34: -

Sheet Balance Sheet
B1: Indian Oil Corporation
B2: Consolidated Balance Sheet
C3: Mar 26 | D3: 45717 | E3: 45352 | F3: 44986 | G3: 44621
C5: 12 mths | D5: 12 mths | E5: 12 mths | F5: 12 mths | G5: 12 mths
B7: EQUITIES AND LIABILITIES
B8: SHAREHOLDER'S FUNDS
B9: Equity Share Capital | C9: 13771.56 | D9: 13771.56 | E9: 13771.56 | F9: 13771.56 | G9: 9181.04
B10: Total Share Capital | C10: 13771.56 | D10: 13771.56 | E10: 13771.56 | F10: 13771.56 | G10: 9181.04
B11: Reserves and Surplus | C11: 205745.99 | D11: 172715.76 | E11: 169644.71 | F11: 125948.68 | G11: 124354.14
B12: Total Reserves and Surplus | C12: 205745.99 | D12: 172715.76 | E12: 169644.71 | F12: 125948.68 | G12: 124354.14
B13: Total Shareholders Funds | C13: 219517.55 | D13: 186487.32 | E13: 183416.27 | F13: 139720.24 | G13: 133535.18
B14: Minority Interest | C14: 6029.56 | D14: 4537.34 | E14: 4746.71 | F14: 3494.1 | G14: 1591.47
B15: NON-CURRENT LIABILITIES
B16: Long Term Borrowings | C16: 63652.1 | D16: 51755.75 | E16: 46792.9 | F16: 63312.94 | G16: 55944.54
B17: Deferred Tax Liabilities [Net] | C17: 21615.85 | D17: 20664.96 | E17: 18960.7 | F17: 16800.42 | G17: 15354.37
B18: Other Long Term Liabilities | C18: 5492.46 | D18: 11400.64 | E18: 10626.67 | F18: 10379.62 | G18: 10458
B19: Long Term Provisions | C19: 1441.64 | D19: 1406.63 | E19: 1414.82 | F19: 1396.44 | G19: 1586.59
B20: Total Non-Current Liabilities | C20: 92202.05 | D20: 85227.98 | E20: 77795.09 | F20: 91889.42 | G20: 83343.5
B21: CURRENT LIABILITIES
B22: Short Term Borrowings | C22: 68170.29 | D22: 90804.15 | E22: 76660.67 | F22: 76801.88 | G22: 67605.56
B23: Trade Payables | C23: 57368.69 | D23: 60534.94 | E23: 59454.1 | F23: 54734.1 | G23: 49045.91
B24: Other Current Liabilities | C24: 75160.71 | D24: 69262.58 | E24: 69660.9 | F24: 64966.07 | G24: 65754.64
B25: Short Term Provisions | C25: 10506.11 | D25: 10012.74 | E25: 10628.26 | F25: 10156.28 | G25: 9748.59
B26: Total Current Liabilities | C26: 211205.8 | D26: 230614.41 | E26: 216403.93 | F26: 206658.33 | G26: 192154.7
B27: Total Capital And Liabilities | C27: 528954.96 | D27: 506867.05 | E27: 482362 | F27: 441762.09 | G27: 410624.85
B28: ASSETS
B29: NON-CURRENT ASSETS
B30: Tangible Assets | C30: 207625.53 | D30: 197162.03 | E30: 192159.52 | F30: 176532.05 | G30: 157194.98
B31: Intangible Assets | C31: 4095.37 | D31: 3979.1 | E31: 3837.23 | F31: 3514.48 | G31: 3318.33
B32: Capital Work-In-Progress | C32: 82896.79 | D32: 73740.41 | E32: 57316.86 | F32: 47550.08 | G32: 44049.82
B33: Intangible Assets Under Development | C33: 0 | D33: 4180.87 | E33: 3715.56 | F33: 3583.39 | G33: 3419.45
B34: Fixed Assets | C34: 294617.69 | D34: 279062.41 | E34: 257029.17 | F34: 231180 | G34: 207982.58
B35: Non-Current Investments | C35: 66160.99 | D35: 56849.59 | E35: 55162.04 | F35: 41753.92 | G35: 44338.76
B36: Deferred Tax Assets [Net] | C36: 1364.02 | D36: 0 | E36: 0 | F36: 0 | G36: 0
B37: Long Term Loans And Advances | C37: 3357.31 | D37: 3223.44 | E37: 2586.98 | F37: 2285.11 | G37: 2292.96
B38: Other Non-Current Assets | C38: 6643.14 | D38: 10087.42 | E38: 9134.5 | F38: 7676.53 | G38: 9148.82
B39: Total Non-Current Assets | C39: 372144.19 | D39: 349223.9 | E39: 323913.73 | F39: 282896.6 | G39: 263764.16
B40: CURRENT ASSETS
B41: Current Investments | C41: 7136.54 | D41: 10368.91 | E41: 10379.86 | F41: 10436.54 | G41: 8013.2
B42: Inventories | C42: 117132.72 | D42: 113878.49 | E42: 121375.83 | F42: 121107.58 | G42: 111736.51
...

Sheet Profit & Loss
B1: Indian Oil Corporation
B2: Consolidated Profit & Loss account
C3: Mar 26 | D3: 45717 | E3: 45352 | F3: 44986 | G3: 44621
C5: 12 mths | D5: 12 mths | E5: 12 mths | F5: 12 mths | G5: 12 mths
B7: INCOME
B8: Revenue From Operations [Gross] | C8: 901452.7 | D8: 854952.77 | E8: 876951.19 | F8: 947418.92 | G8: 732879.32
B9: Less: Excise/Sevice Tax/Other Levies | C9: 117037.27 | D9: 101256.92 | E9: 104883.6 | F9: 109654.03 | G9: 147395.1
B10: Revenue From Operations [Net] | C10: 784415.43 | D10: 753695.85 | E10: 772067.59 | F10: 837764.89 | G10: 585484.22
B11: Other Operating Revenues | C11: 0 | D11: 4409.96 | E11: 4284.26 | F11: 3991.02 | G11: 3851.52
B12: Total Operating Revenues | C12: 784415.43 | D12: 758105.81 | E12: 776351.85 | F12: 841755.91 | G12: 589335.74
B13: Other Income | C13: 4162.99 | D13: 3513.73 | E13: 3842.85 | F13: 4198.92 | G13: 3082.22
B14: Total Revenue | C14: 788578.42 | D14: 761619.54 | E14: 780194.7 | F14: 845954.83 | G14: 592417.96
B15: EXPENSES
B16: Cost Of Materials Consumed | C16: 433584.37 | D16: 449812.63 | E16: 446251.39 | F16: 503757.28 | G16: 330672.38
B17: Purchase Of Stock-In Trade | C17: 193977.16 | D17: 207762.62 | E17: 191316.43 | F17: 250207.42 | G17: 169991.5
B18: Changes In Inventories Of FG,WIP And Stock-In Trade | C18: 5562.28 | D18: -789.75 | E18: 1231.34 | F18: -6329.71 | G18: -13710.98
B19: Employee Benefit Expenses | C19: 11434.58 | D19: 10879.86 | E19: 11670.94 | F19: 9359.14 | G19: 11582.92
B20: Finance Costs | C20: 8307.88 | D20: 9261.93 | E20: 7825.65 | F20: 7541.36 | G20: 5423.26
B21: Provsions and Contingencies | C21: 1129.99 | D21: 173.27 | E21: 274.47 | F21: 683.33 | G21: -272.23
B22: Depreciation And Amortisation Expenses | C22: 18420.24 | D22: 16777.34 | E22: 15866.11 | F22: 13181.05 | G22: 12347.58
B23: Other Expenses | C23: 61665.4 | D23: 54276.64 | E23: 50016.51 | F23: 53379.46 | G23: 43330.47
B24: Total Expenses | C24: 734081.9 | D24: 748154.54 | E24: 724452.84 | F24: 831779.33 | G24: 559364.9
B25: Profit/Loss Before Exceptional, ExtraOrdinary Items And Tax | C25: 54496.52 | D25: 13465 | E25: 55741.86 | F25: 14175.5 | G25: 33053.06
B26: Exceptional Items | C26: 0 | D26: 1838.02 | E26: 0 | F26: 0 | G26: 0
B27: Profit/Loss Before Tax | C27: 54496.52 | D27: 15303.02 | E27: 55741.86 | F27: 14175.5 | G27: 33053.06
B28: Tax Expenses-Continued Operations
B29: Current Tax | C29: 13794.76 | D29: 1700.08 | E29: 12895.91 | F29: 1922.46 | G29: 7234.66
B30: Deferred Tax | C30: 0 | D30: 1574.54 | E30: 1230.73 | F30: 1410.97 | G30: 1327.36
B31: Total Tax Expenses | C31: 13794.76 | D31: 3274.62 | E31: 14126.64 | F31: 3333.43 | G31: 8562.02
B32: Profit/Loss After Tax And Before ExtraOrdinary Items | C32: 40701.76 | D32: 12028.4 | E32: 41615.22 | F32: 10842.07 | G32: 24491.04
B33: Profit/Loss From Continuing Operations | C33: 40701.76 | D33: 12028.4 | E33: 41615.22 | F33: 10842.07 | G33: 24491.04
B34: Profit/Loss For The Period | C34: 40701.76 | D34: 12028.4 | E34: 41615.22 | F34: 10842.07 | G34: 24491.04
B35: Minority Interest | C35: -1581.06 | D35: -190.99 | E35: -1431.46 | F35: -1912.14 | G35: -624.37
B36: Share Of Profit/Loss Of Associates | C36: 2975.56 | D36: 1760.43 | E36: 1545.93 | F36: 862.19 | G36: 1235.56
B37: Consolidated Profit/Loss After MI And Associates | C37: 42096.26 | D37: 13597.84 | E37: 41729.69 | F37: 9792.12 | G37: 25102.23
B38: OTHER ADDITIONAL INFORMATION
B39: EARNINGS PER SHARE
B40: Basic EPS (Rs.) | C40: 31 | D40: 10 | E40: 30 | F40: 7 | G40: 27
B41: Diluted EPS (Rs.) | C41: 31 | D41: 10 | E41: 30 | F41: 7 | G41: 27
B42: DIVIDEND AND DIVIDEND PERCENTAGE
...

Sheet Cash Flow
B1: Indian Oil Corporation
B2: Cash Flow
C3: Mar 26 | D3: 45717 | E3: 45717 | F3: 45352 | G3: 45352
C5: 12 mths | D5: 12 mths | E5: 12 mths | F5: 12 mths | G5: 12 mths
B7: Net Profit/Loss Before Extraordinary Items And Tax | C7: 48784.41 | D7: 15882.34 | E7: 15882.34 | F7: 52344.21 | G7: 52344.21
B8: Net CashFlow From Operating Activities | C8: 71398.57 | D8: 33170.46 | E8: 33170.46 | F8: 68096.6 | G8: 68096.6
B9: Net Cash Used In Investing Activities | C9: -17661.78 | D9: -29261.29 | E9: -29261.29 | F9: -29701.62 | G9: -29701.62
B10: Net Cash Used From Financing Activities | C10: -53718.55 | D10: -4110.28 | E10: -4110.28 | F10: -38294.02 | G10: -38294.02
B11: Net Inc/Dec In Cash And Cash Equivalents | C11: 18.24 | D11: -201.11 | E11: -201.11 | F11: 100.96 | G11: 100.96
B12: Cash And Cash Equivalents Begin of Year | C12: 263.17 | D12: 464.28 | E12: 464.28 | F12: 363.32 | G12: 363.32
B13: Cash And Cash Equivalents End Of Year | C13: 281.41 | D13: 263.17 | E13: 263.17 | F13: 464.28 | G13: 464.28
B17: Source : Dion Global Solutions Limited

Sheet Stock Analysis
B18: Recommendation - Indian Oil Corporation Ltd: | I18: Financial Year | J18: Revenue | K18: PAT | L18: Revenue Change | M18: PAT Change
B19: "HOLD" Indian Oil Corporation remains India's largest refining and fuel-marketing PSU, but earnings have swung sharply over the past two years on volatile crude prices and government-controlled LPG pricing. FY25 consolidated PAT (after minority interest and associates) fell around 67% YoY to ₹13,598 Cr on inventory losses and marketing under-recoveries, even as revenue held broadly flat at ₹7.58 lakh Cr. The trailing-twelve-month print (Mar'26) shows a sharp recovery to ₹42,096 Cr PAT, helped by softer crude, improved refining margins, and the Government's ₹30,000 Cr compensation for past LPG under-recoveries. The chart reflects this volatility well: the stock rallied sharply through 2024, gave back most of those gains into early 2025, then staged another strong run-up through early 2026 to a 52-week high of ₹188.96, before correcting about 24% to the current ₹143.89 - still roughly 11% above its 52-week low of ₹130.22. At this level, IOC trades at a TTM P/E of approximately 4.8-5.6x and a P/B of about 1.1x - inexpensive on an absolute basis, but broadly in line with how the market has historically priced cyclical, regulation-sensitive OMC earnings rather than signalling a clear valuation gap. | I19: TTM (Mar'26) | J19: ='Profit & Loss'!C12 -> 784415.43 | K19: ='Profit & Loss'!C37 -> 42096.26 | L19: =(J19-J20)/J20 -> 0.034704417 | M19: =(K19-K20)/K20 -> 2.0958049
I20: 2024-25 | J20: ='Profit & Loss'!D12 -> 758105.81 | K20: ='Profit & Loss'!D37 -> 13597.84 | L20: =(J20-J21)/J21 -> -0.023502282 | M20: =(K20-K21)/K21 -> -0.67414472
I21: 2023-24 | J21: ='Profit & Loss'!E12 -> 776351.85 | K21: ='Profit & Loss'!E37 -> 41729.69 | L21: =(J21-J22)/J22 -> -0.077699555 | M21: =(K21-K22)/K22 -> 3.2615583
I22: 2022-23 | J22: ='Profit & Loss'!F12 -> 841755.91 | K22: ='Profit & Loss'!F37 -> 9792.12 | L22: =(J22-J23)/J23 -> 0.42831302 | M22: =(K22-K23)/K23 -> -0.60991035
I23: 2021-22 | J23: ='Profit & Loss'!G12 -> 589335.74 | K23: ='Profit & Loss'!G37 -> 25102.23 | L23: =IFERROR(J23/J24,0) -> 0 | M23: =IFERROR(K23/K24,0) -> 0

Sheet Historical FS
B1: Indian Oil Corporation Limited
B2: Historical Financial Statement | C2: in Rs. Cr.
B3: Years | C3: 2022 | D3: 2023 | E3: 2024 | F3: 2025 | G3: 2026
B4: Income Statement
B5: Revenue from Operations (Net) | C5: 585484.22 | D5: 837764.89 | E5: 772067.59 | F5: 753695.85 | G5: 784415.43
B6: Revenue Growth % | D6: =(D5-C5)/C5 -> 0.43089235 | E6: =(E5-D5)/D5 -> -0.078419734 | F6: =(F5-E5)/E5 -> -0.023795507 | G6: =(G5-F5)/F5 -> 0.04075859
B8: Less: Excise/Service Tax/Other Levies | C8: 147395.1 | D8: 109654.03 | E8: 104883.6 | F8: 101256.92 | G8: 117037.27
B9: Revenue from Operations (Gross) | C9: 732879.32 | D9: 947418.92 | E9: 876951.19 | F9: 854952.77 | G9: 901452.7
B10: Other Operating Revenue | C10: 3851.52 | D10: 3991.02 | E10: 4284.26 | F10: 4409.96 | G10: 0
B11: Other Income | C11: 3082.22 | D11: 4198.92 | E11: 3842.85 | F11: 3513.73 | G11: 4162.99
B12: Total Revenue | C12: =C8+C11 -> 150477.32 | D12: =D8+D11 -> 113852.95 | E12: =E8+E11 -> 108726.45 | F12: =F8+F11 -> 104770.65 | G12: =G8+G11 -> 121200.26
B14: EXPENSES
B15: Cost of Materials Consumed | C15: 330672.38 | D15: 503757.28 | E15: 446251.39 | F15: 449812.63 | G15: 433584.37
B16: Purchase of Stock-in-Trade | C16: 169991.5 | D16: 250207.42 | E16: 191316.43 | F16: 207762.62 | G16: 193977.16
B17: Changes in Inventories of FG/WIP/SIT | C17: -13710.98 | D17: -6329.71 | E17: 1231.34 | F17: -789.75 | G17: 5562.28
B18: Employee Benefit Expenses | C18: 11582.92 | D18: 9359.14 | E18: 11670.94 | F18: 10879.86 | G18: 11434.58
B19: Finance Costs | C19: 5423.26 | D19: 7541.36 | E19: 7825.65 | F19: 9261.93 | G19: 8307.88
B20: Provisions & Contingencies | C20: -272.23 | D20: 683.33 | E20: 274.47 | F20: 173.27 | G20: 1129.99
B21: Depreciation & Amortisation Expenses | C21: 12347.58 | D21: 13181.05 | E21: 15866.11 | F21: 16777.34 | G21: 18420.24
B22: Other Expenses | C22: 43330.47 | D22: 53379.46 | E22: 50016.51 | F22: 54276.64 | G22: 61665.4
B23: Total Expenses | C23: =SUM(C15:C22) -> 559364.9 | D23: =SUM(D15:D22) -> 831779.33 | E23: =SUM(E15:E22) -> 724452.84 | F23: =SUM(F15:F22) -> 748154.54 | G23: =SUM(G15:G22) -> 734081.9
B25: EBITDA | C25: =C5+C8-C23+C18+C21 -> 197444.92 | D25: =D5+D8-D23+D18+D21 -> 138179.78 | E25: =E5+E8-E23+E18+E21 -> 180035.4 | F25: =F5+F8-F23+F18+F21 -> 134455.43 | G25: =G5+G8-G23+G18+G21 -> 197225.62
B26: EBITDA Margins | C26: =C25/C5 -> 0.33723355 | D26: =D25/D5 -> 0.16493861 | E26: =E25/E5 -> 0.23318606 | F26: =F25/F5 -> 0.17839481 | G26: =G25/G5 -> 0.25143006
B28: Depreciation & Amortisation | C28: 12347.58 | D28: 13181.05 | E28: 15866.11 | F28: 16777.34 | G28: 18420.24
B29: Depreciation % of Sales | C29: =C28/C5 -> 0.021089518 | D29: =D28/D5 -> 0.015733591 | E29: =E28/E5 -> 0.020550157 | F29: =F28/F5 -> 0.022260093 | G29: =G28/G5 -> 0.023482761
B31: EBIT | C31: =C25-C28 -> 185097.34 | D31: =D25-D28 -> 124998.73 | E31: =E25-E28 -> 164169.29 | F31: =F25-F28 -> 117678.09 | G31: =G25-G28 -> 178805.38
B32: EBIT Margin | C32: =C31/C5 -> 0.31614403 | D32: =D31/D5 -> 0.14920502 | E32: =E31/E5 -> 0.2126359 | F32: =F31/F5 -> 0.15613472 | G32: =G31/G5 -> 0.2279473
B34: Finance Costs | C34: 5423.26 | D34: 7541.36 | E34: 7825.65 | F34: 9261.93 | G34: 8307.88
B35: Finance Costs % of Sales | C35: =C34/C5 -> 0.0092628628 | D35: =D34/D5 -> 0.0090017618 | E35: =E34/E5 -> 0.010135965 | F35: =F34/F5 -> 0.012288684 | G35: =G34/G5 -> 0.010591174
B37: Profit Before Tax | C37: 33053.06 | D37: 14175.5 | E37: 55741.86 | F37: 15303.02 | G37: 54496.52
B38: PBT % Sales | C38: =C37/C5 -> 0.056454229 | D38: =D37/D5 -> 0.016920618 | E38: =E37/E5 -> 0.072198161 | F38: =F37/F5 -> 0.020303973 | G38: =G37/G5 -> 0.069474054
B40: Total Tax Expenses | C40: 8562.02 | D40: 3333.43 | E40: 14126.64 | F40: 3274.62 | G40: 13794.76
B41: Effective Tax Rate | C41: =C40/C37 -> 0.25903865 | D41: =D40/D37 -> 0.23515432 | E41: =E40/E37 -> 0.25342965 | F41: =F40/F37 -> 0.21398521 | G41: =G40/G37 -> 0.25313103
B43: Net Profit (after MI & Associates) | C43: 25102.23 | D43: 9792.12 | E43: 41729.69 | F43: 13597.84 | G43: 42096.26
B44: Net Profit Margins | C44: =C43/C5 -> 0.042874307 | D44: =D43/D5 -> 0.011688387 | E44: =E43/E5 -> 0.05404927 | F44: =F43/F5 -> 0.018041548 | G44: =G43/G5 -> 0.053665772
B46: Basic EPS (₹) | C46: 27 | D46: 7 | E46: 30 | F46: 10 | G46: 31
B47: EPS Growth % | D47: =(D46-C46)/C46 -> -0.74074074 | E47: =(E46-D46)/D46 -> 3.2857143 | F47: =(F46-E46)/E46 -> -0.66666667 | G47: =(G46-F46)/F46 -> 2.1
B50: Balance Sheet
B51: Years | C51: 2022 | D51: 2023 | E51: 2024 | F51: 2025 | G51: 2026
B52: EQUITY & LIABILITIES
...

Sheet Working Capital Changes
B1: Indian Oil Corporation Limited – Working Capital Analysis
B2: Change in Working Capital | C2: in Rs. Cr.
B3: Particulars | C3: 2022 | D3: 2023 | E3: 2024 | F3: 2025 | G3: 2026
B4: CURRENT ASSETS (Operating)
B5: Inventories | C5: 111736.51 | D5: 121107.58 | E5: 121375.83 | F5: 113878.49 | G5: 117132.72
B6: Trade Receivables | C6: 18700.42 | D6: 16271.21 | E6: 13831.45 | F6: 18550.96 | G6: 14634.83
B7: Short Term Loans & Advances | C7: 450.92 | D7: 379.73 | E7: 492.94 | F7: 628.76 | G7: 698.58
B8: Other Current Assets | C8: 6139.5 | D8: 8573.79 | E8: 9209.4 | F8: 10911.09 | G8: 12793.44
B9: Total Operating Current Assets (A) | C9: =C5+C6+C7+C8 -> 137027.35 | D9: =D5+D6+D7+D8 -> 146332.31 | E9: =E5+E6+E7+E8 -> 144909.62 | F9: =F5+F6+F7+F8 -> 143969.3 | G9: =G5+G6+G7+G8 -> 145259.57
B11: CURRENT LIABILITIES (Operating)
B12: Trade Payables | C12: 49045.91 | D12: 54734.1 | E12: 59454.1 | F12: 60534.94 | G12: 57368.69
B13: Other Current Liabilities | C13: 65754.64 | D13: 64966.07 | E13: 69660.9 | F13: 69262.58 | G13: 75160.71
B14: Short Term Provisions | C14: 9748.59 | D14: 10156.28 | E14: 10628.26 | F14: 10012.74 | G14: 10506.11
B15: Total Operating Current Liabilities (B) | C15: =C12+C13+C14 -> 124549.14 | D15: =D12+D13+D14 -> 129856.45 | E15: =E12+E13+E14 -> 139743.26 | F15: =F12+F13+F14 -> 139810.26 | G15: =G12+G13+G14 -> 143035.51
B17: Non-Cash Working Capital (A − B) | C17: =C9-C15 -> 12478.21 | D17: =D9-D15 -> 16475.86 | E17: =E9-E15 -> 5166.36 | F17: =F9-F15 -> 4159.04 | G17: =G9-G15 -> 2224.06
B19: Change in Working Capital (YoY) | D19: =D17-C17 -> 3997.65 | E19: =E17-D17 -> -11309.5 | F19: =F17-E17 -> -1007.32 | G19: =G17-F17 -> -1934.98
B20: Change in Working Capital / Sales % | D20: =D19/837764.89 -> 0.0047718042 | E20: =E19/772067.59 -> -0.014648329 | F20: =F19/753695.85 -> -0.0013365073 | G20: =G19/784415.43 -> -0.0024667796
B21: Median Change in WC / Sales % | D21: =MEDIAN(D20:G20) -> -0.0019016435
B22: Average Change in WC / Sales % | D22: =AVERAGE(D20:G20) -> -0.0034199529
B24: WORKING CAPITAL EFFICIENCY RATIOS
B25: Inventory Days | C25: =C5/585484.22*365 -> 69.658284 | D25: =D5/837764.89*365 -> 52.764525 | E25: =E5/772067.59*365 -> 57.381217 | F25: =F5/753695.85*365 -> 55.149101 | G25: =G5/784415.43*365 -> 54.503572
B26: Debtor Days (Receivable Days) | C26: =C6/585484.22*365 -> 11.658134 | D26: =D6/837764.89*365 -> 7.0890911 | E26: =E6/772067.59*365 -> 6.5389084 | F26: =F6/753695.85*365 -> 8.9838632 | G26: =G6/784415.43*365 -> 6.809801
B27: Creditor Days (Payable Days) | C27: =C12/585484.22*365 -> 30.575986 | D27: =D12/837764.89*365 -> 23.846722 | E27: =E12/772067.59*365 -> 28.107314 | F27: =F12/753695.85*365 -> 29.315875 | G27: =G12/784415.43*365 -> 26.694493
B28: Cash Conversion Cycle (days) | C28: =C25+C26-C27 -> 50.740432 | D28: =D25+D26-D27 -> 36.006894 | E28: =E25+E26-E27 -> 35.812811 | F28: =F25+F26-F27 -> 34.81709 | G28: =G25+G26-G27 -> 34.61888

Sheet Fixed Assets Schedule
B1: Indian Oil Corporation Limited – Fixed Assets Schedule
B2: Fixed Assets Schedule | C2: in Rs. Cr.
B3: Particulars | C3: 2022 | D3: 2023 | E3: 2024 | F3: 2025 | G3: 2026
B4: Beginning Balance (Net Fixed Assets) | D4: 207982.58 | E4: 231180 | F4: 257029.17 | G4: 279062.41
B5: Add: Gross Capital Expenditure (Purchases) | D5: 36378.47 | E5: 41715.28 | F5: 38810.58 | G5: 33975.52
B6: Gross Fixed Assets (Before Depreciation) | C6: 220330.16 | D6: =D4+D5 -> 244361.05 | E6: =E4+E5 -> 272895.28 | F6: =F4+F5 -> 295839.75 | G6: =G4+G5 -> 313037.93
B7: Less: Depreciation & Amortisation | C7: 12347.58 | D7: 13181.05 | E7: 15866.11 | F7: 16777.34 | G7: 18420.24
B8: Closing Balance (Net Fixed Assets) | C8: =C6-C7 -> 207982.58 | D8: =D6-D7 -> 231180 | E8: =E6-E7 -> 257029.17 | F8: =F6-F7 -> 279062.41 | G8: =G6-G7 -> 294617.69
B10: Net Capital Expenditure (Closing − Opening) | D10: =D8-D4 -> 23197.42 | E10: =E8-E4 -> 25849.17 | F10: =F8-F4 -> 22033.24 | G10: =G8-G4 -> 15555.28
B11: Net Capex / Sales % | D11: =D10/837764.89 -> 0.027689654 | E11: =E10/772067.59 -> 0.03348045 | F11: =F10/753695.85 -> 0.029233596 | G11: =G10/784415.43 -> 0.019830411
B12: Median Net Capex / Sales % | D12: =MEDIAN(D11:G11) -> 0.028461625
B13: Average Net Capex / Sales % | D13: =AVERAGE(D11:G11) -> 0.027558528
B15: Gross Capex / Sales % | D15: =D5/837764.89 -> 0.043423245 | E15: =E5/772067.59 -> 0.054030606 | F15: =F5/753695.85 -> 0.051493689 | G15: =G5/784415.43 -> 0.043313171
B16: Median Gross Capex / Sales % | D16: =MEDIAN(D15:G15) -> 0.047458467
B17: Average Gross Capex / Sales % | D17: =AVERAGE(D15:G15) -> 0.048065178
B19: Depreciation % of Sales | C19: =C7/585484.22 -> 0.021089518 | D19: =D7/837764.89 -> 0.015733591 | E19: =E7/772067.59 -> 0.020550157 | F19: =F7/753695.85 -> 0.022260093 | G19: =G7/784415.43 -> 0.023482761
B20: Median Depreciation / Sales % | C20: =MEDIAN(C19:G19) -> 0.021089518
B21: Average Depreciation / Sales % | C21: =AVERAGE(C19:G19) -> 0.020623224

Sheet FCFF
B1: Indian Oil Corporation Limited – FCFF Build
B2: Free Cash Flow to Firm (FCFF) | C2: in Rs. Cr.
B3: Particulars | C3: 2022 | D3: 2023 | E3: 2024 | F3: 2025 | G3: 2026
B4: EBIT | C4: ='Historical FS'!C31 -> 185097.34 | D4: ='Historical FS'!D31 -> 124998.73 | E4: ='Historical FS'!E31 -> 164169.29 | F4: ='Historical FS'!F31 -> 117678.09 | G4: ='Historical FS'!G31 -> 178805.38
B5: Effective Tax Rate | C5: ='Historical FS'!C41 -> 0.25903865 | D5: ='Historical FS'!D41 -> 0.23515432 | E5: ='Historical FS'!E41 -> 0.25342965 | F5: ='Historical FS'!F41 -> 0.21398521 | G5: ='Historical FS'!G41 -> 0.25313103
B6: Less: Tax on EBIT | C6: =C4*C5 -> 47947.365 | D6: =D4*D5 -> 29393.991 | E6: =E4*E5 -> 41605.365 | F6: =F4*F5 -> 25181.371 | G6: =G4*G5 -> 45261.189
B8: EBIT × (1 − t) [NOPAT] | C8: =C4-C6 -> 137149.98 | D8: =D4-D6 -> 95604.739 | E8: =E4-E6 -> 122563.92 | F8: =F4-F6 -> 92496.719 | G8: =G4-G6 -> 133544.19
B10: REINVESTMENT
B11: Less: Net Capital Expenditure | D11: ='Fixed Assets Schedule'!D10 -> 23197.42 | E11: ='Fixed Assets Schedule'!E10 -> 25849.17 | F11: ='Fixed Assets Schedule'!F10 -> 22033.24 | G11: ='Fixed Assets Schedule'!G10 -> 15555.28
B12: Less: Change in Working Capital | D12: ='Working Capital Changes'!D19 -> 3997.65 | E12: ='Working Capital Changes'!E19 -> -11309.5 | F12: ='Working Capital Changes'!F19 -> -1007.32 | G12: ='Working Capital Changes'!G19 -> -1934.98
B13: Total Reinvestment | D13: =D11+D12 -> 27195.07 | E13: =E11+E12 -> 14539.67 | F13: =F11+F12 -> 21025.92 | G13: =G11+G12 -> 13620.3
B15: Free Cash Flow to Firm | C15: =C8 -> 137149.98 | D15: =D8-D13 -> 68409.669 | E15: =E8-E13 -> 108024.25 | F15: =F8-F13 -> 71470.799 | G15: =G8-G13 -> 119923.89
B17: REINVESTMENT RATE & EFFICIENCY METRICS
B18: Reinvestment Rate (Reinvestment / NOPAT) | D18: =IF(D8<>0,D13/D8,0) -> 0.28445316 | E18: =IF(E8<>0,E13/E8,0) -> 0.11862928 | F18: =IF(F8<>0,F13/F8,0) -> 0.22731531 | G18: =IF(G8<>0,G13/G8,0) -> 0.10199096
B19: Median Reinvestment Rate | D19: =MEDIAN(D18:G18) -> 0.17297229
B20: Average Reinvestment Rate | D20: =AVERAGE(D18:G18) -> 0.18309718
B22: FCFF / Net Revenue % | C22: =C15/('Historical FS'!C5) -> 0.23425051 | D22: =D15/('Historical FS'!D5) -> 0.08165736 | E22: =E15/('Historical FS'!E5) -> 0.13991554 | F22: =F15/('Historical FS'!F5) -> 0.094827109 | G22: =G15/('Historical FS'!G5) -> 0.15288314
B23: NOPAT Margin (NOPAT / Net Revenue) | C23: =C8/('Historical FS'!C5) -> 0.23425051 | D23: =D8/('Historical FS'!D5) -> 0.11411882 | E23: =E8/('Historical FS'!E5) -> 0.15874766 | F23: =F8/('Historical FS'!F5) -> 0.1227242 | G23: =G8/('Historical FS'!G5) -> 0.17024677
B25: FCFF Growth (YoY) | E25: =IF(D15<>0,(E15-D15)/D15,0) -> 0.57907874 | F25: =IF(E15<>0,(F15-E15)/E15,0) -> -0.33838193 | G25: =IF(F15<>0,(G15-F15)/F15,0) -> 0.6779425

Sheet WACC
B1: WACC Calculation
B2: Cost Of Capital
B3: As On Date: | C3: June 2026
B5: Cost of Equity using CAPM:
B6: Risk-free rate | C6: 0.0685
B7: India Default Spread | C7: 0.0187
B8: Beta (Regression - IOC vs Nifty 50) | C8: =SLOPE(Beta!D2:D1101,Beta!C2:C1101) -> 1.0089971
B9: Equity Risk Premium (ERP) | C9: 0.075
B10: Cost of Equity (Ke) | C10: =C6+C8*C9 -> 0.14417478
B12: Cost of Debt:
B13: Finance Cost (₹ Cr.) | C13: ='Profit & Loss'!C20 -> 8307.88
B14: Long Term Borrowings (₹ Cr.) | C14: ='Balance Sheet'!C16 -> 63652.1
B15: Short Term Borrowings (₹ Cr.) | C15: ='Balance Sheet'!C22 -> 68170.29
B16: Total Debt (₹ Cr.) | C16: =C14+C15 -> 131822.39
B17: Pre-Tax Cost of Debt (Kd) | C17: =C13/C16 -> 0.063023285
B18: Marginal Tax Rate % | C18: 0.25
B19: Post-Tax Cost of Debt | C19: =C17*(1-C18) -> 0.047267463
B21: WACC Calculation:
B22: Equity Share Capital (₹ Cr.) | C22: ='Balance Sheet'!C9 -> 13771.56
B23: Face Value (₹) | C23: 10
B24: Shares Outstanding (Cr.) | C24: =C22/C23 -> 1377.156
B25: Share Price (₹, as on date) | C25: 147
B26: Market Value of Equity (₹ Cr.) | C26: =C24*C25 -> 202441.93
B28: Capital Structure Weights
B29: Total Capital (Equity + Debt) (₹ Cr.) | C29: =C26+C16 -> 334264.32
B30: Weight of Debt (Wd) | C30: =C16/C29 -> 0.39436572
B31: Weight of Equity (We) | C31: =C26/C29 -> 0.60563428
B33: WACC
B34: WACC | C34: =(C31*C10)+(C30*C19) -> 0.10595786

Sheet Assumption
B1: Indian Oil Corporation
B3: Particulars | C3: 2022 | D3: 2023 | E3: 2024 | F3: 2025 | G3: 2026 | I3: Metric | J3: Value
B4: A. Income Statement Build-up
B5: Revenue from Operations (Net) | C5: ='Profit & Loss'!G10 -> 585484.22 | D5: ='Profit & Loss'!F10 -> 837764.89 | E5: ='Profit & Loss'!E10 -> 772067.59 | F5: ='Profit & Loss'!D10 -> 753695.85 | G5: ='Profit & Loss'!C10 -> 784415.43
B6: Revenue Growth % | D6: =(Assumption!D5/Assumption!C5)-1 -> 0.43089235 | E6: =(Assumption!E5/Assumption!D5)-1 -> -0.078419734 | F6: =(Assumption!F5/Assumption!E5)-1 -> -0.023795507 | G6: =(Assumption!G5/Assumption!F5)-1 -> 0.04075859 | I6: Median Revenue Growth | J6: =MEDIAN(D6:G6) -> 0.0084815412
B7: Less: Cost of Materials Consumed | C7: ='Profit & Loss'!G16 -> 330672.38 | D7: ='Profit & Loss'!F16 -> 503757.28 | E7: ='Profit & Loss'!E16 -> 446251.39 | F7: ='Profit & Loss'!D16 -> 449812.63 | G7: ='Profit & Loss'!C16 -> 433584.37
B8: Less: Purchase of Stock-in-Trade | C8: ='Profit & Loss'!G17 -> 169991.5 | D8: ='Profit & Loss'!F17 -> 250207.42 | E8: ='Profit & Loss'!E17 -> 191316.43 | F8: ='Profit & Loss'!D17 -> 207762.62 | G8: ='Profit & Loss'!C17 -> 193977.16
B9: Less: Changes in Inventories | C9: ='Profit & Loss'!G18 -> -13710.98 | D9: ='Profit & Loss'!F18 -> -6329.71 | E9: ='Profit & Loss'!E18 -> 1231.34 | F9: ='Profit & Loss'!D18 -> -789.75 | G9: ='Profit & Loss'!C18 -> 5562.28
B10: Less: Employee Benefit Expenses | C10: ='Profit & Loss'!G19 -> 11582.92 | D10: ='Profit & Loss'!F19 -> 9359.14 | E10: ='Profit & Loss'!E19 -> 11670.94 | F10: ='Profit & Loss'!D19 -> 10879.86 | G10: ='Profit & Loss'!C19 -> 11434.58
B11: Less: Other Expenses | C11: ='Profit & Loss'!G23 -> 43330.47 | D11: ='Profit & Loss'!F23 -> 53379.46 | E11: ='Profit & Loss'!E23 -> 50016.51 | F11: ='Profit & Loss'!D23 -> 54276.64 | G11: ='Profit & Loss'!C23 -> 61665.4
B12: Total Operating Expenses | C12: =Assumption!C7+Assumption!C8+Assumption!C9+Assumption!C10+Assumption!C11 -> 541866.29 | D12: =Assumption!D7+Assumption!D8+Assumption!D9+Assumption!D10+Assumption!D11 -> 810373.59 | E12: =Assumption!E7+Assumption!E8+Assumption!E9+Assumption!E10+Assumption!E11 -> 700486.61 | F12: =Assumption!F7+Assumption!F8+Assumption!F9+Assumption!F10+Assumption!F11 -> 721942 | G12: =Assumption!G7+Assumption!G8+Assumption!G9+Assumption!G10+Assumption!G11 -> 706223.79
B13: EBITDA | C13: =Assumption!C5-Assumption!C12 -> 43617.93 | D13: =Assumption!D5-Assumption!D12 -> 27391.3 | E13: =Assumption!E5-Assumption!E12 -> 71580.98 | F13: =Assumption!F5-Assumption!F12 -> 31753.85 | G13: =Assumption!G5-Assumption!G12 -> 78191.64 | I13: Median EBITDA Margin | J13: =MEDIAN(C14:G14) -> 0.074498899
B14: EBITDA Margin % | C14: =Assumption!C13/Assumption!C5 -> 0.074498899 | D14: =Assumption!D13/Assumption!D5 -> 0.032695689 | E14: =Assumption!E13/Assumption!E5 -> 0.092713359 | F14: =Assumption!F13/Assumption!F5 -> 0.042130854 | G14: =Assumption!G13/Assumption!G5 -> 0.099681415
B15: Less: Depreciation & Amortisation | C15: ='Profit & Loss'!G22 -> 12347.58 | D15: ='Profit & Loss'!F22 -> 13181.05 | E15: ='Profit & Loss'!E22 -> 15866.11 | F15: ='Profit & Loss'!D22 -> 16777.34 | G15: ='Profit & Loss'!C22 -> 18420.24
B16: EBIT | C16: =Assumption!C13-Assumption!C15 -> 31270.35 | D16: =Assumption!D13-Assumption!D15 -> 14210.25 | E16: =Assumption!E13-Assumption!E15 -> 55714.87 | F16: =Assumption!F13-Assumption!F15 -> 14976.51 | G16: =Assumption!G13-Assumption!G15 -> 59771.4 | I16: Median EBIT Margin | J16: =MEDIAN(C17:G17) -> 0.053409381
B17: EBIT Margin % | C17: =Assumption!C16/Assumption!C5 -> 0.053409381 | D17: =Assumption!D16/Assumption!D5 -> 0.016962098 | E17: =Assumption!E16/Assumption!E5 -> 0.072163203 | F17: =Assumption!F16/Assumption!F5 -> 0.019870761 | G17: =Assumption!G16/Assumption!G5 -> 0.076198654
B18: Add: Other Income | C18: ='Profit & Loss'!G13 -> 3082.22 | D18: ='Profit & Loss'!F13 -> 4198.92 | E18: ='Profit & Loss'!E13 -> 3842.85 | F18: ='Profit & Loss'!D13 -> 3513.73 | G18: ='Profit & Loss'!C13 -> 4162.99
B19: Less: Finance Costs | C19: ='Profit & Loss'!G20 -> 5423.26 | D19: ='Profit & Loss'!F20 -> 7541.36 | E19: ='Profit & Loss'!E20 -> 7825.65 | F19: ='Profit & Loss'!D20 -> 9261.93 | G19: ='Profit & Loss'!C20 -> 8307.88
B20: PBT | C20: =Assumption!C16+Assumption!C18-Assumption!C19 -> 28929.31 | D20: =Assumption!D16+Assumption!D18-Assumption!D19 -> 10867.81 | E20: =Assumption!E16+Assumption!E18-Assumption!E19 -> 51732.07 | F20: =Assumption!F16+Assumption!F18-Assumption!F19 -> 9228.31 | G20: =Assumption!G16+Assumption!G18-Assumption!G19 -> 55626.51
B21: Less: Total Tax Expenses | C21: ='Profit & Loss'!G31 -> 8562.02 | D21: ='Profit & Loss'!F31 -> 3333.43 | E21: ='Profit & Loss'!E31 -> 14126.64 | F21: ='Profit & Loss'!D31 -> 3274.62 | G21: ='Profit & Loss'!C31 -> 13794.76
B22: Effective Tax Rate | C22: =Assumption!C21/Assumption!C20 -> 0.29596351 | D22: =Assumption!D21/Assumption!D20 -> 0.30672509 | E22: =Assumption!E21/Assumption!E20 -> 0.27307316 | F22: =Assumption!F21/Assumption!F20 -> 0.35484504 | G22: =Assumption!G21/Assumption!G20 -> 0.24798895
B23: Less: Minority Interest | C23: =-'Profit & Loss'!G35 -> 624.37 | D23: =-'Profit & Loss'!F35 -> 1912.14 | E23: =-'Profit & Loss'!E35 -> 1431.46 | F23: =-'Profit & Loss'!D35 -> 190.99 | G23: =-'Profit & Loss'!C35 -> 1581.06
B24: Net Profit - PAT | C24: =Assumption!C20-Assumption!C21-Assumption!C23 -> 19742.92 | D24: =Assumption!D20-Assumption!D21-Assumption!D23 -> 5622.24 | E24: =Assumption!E20-Assumption!E21-Assumption!E23 -> 36173.97 | F24: =Assumption!F20-Assumption!F21-Assumption!F23 -> 5762.7 | G24: =Assumption!G20-Assumption!G21-Assumption!G23 -> 40250.69 | I24: Median PAT Margin | J24: =MEDIAN(C25:G25) -> 0.03372067
B25: Net Profit Margin % | C25: =Assumption!C24/Assumption!C5 -> 0.03372067 | D25: =Assumption!D24/Assumption!D5 -> 0.0067109998 | E25: =Assumption!E24/Assumption!E5 -> 0.046853372 | F25: =Assumption!F24/Assumption!F5 -> 0.0076459224 | G25: =Assumption!G24/Assumption!G5 -> 0.051312976
B27: B. Historical Growth Analysis
B28: Average Revenue Growth (FY22-26) | C28: =AVERAGE(D6:G6) -> 0.092358924
B29: CAGR Revenue (FY22-26) | C29: =(G5/C5)^(1/4)-1 -> 0.075864886
B30: Median Revenue Growth (FY22-26) | C30: =MEDIAN(D6:G6) -> 0.0084815412
B32: C. Margin Analysis
B33: EBITDA Margin % | C33: =Assumption!C14 -> 0.074498899 | D33: =Assumption!D14 -> 0.032695689 | E33: =Assumption!E14 -> 0.092713359 | F33: =Assumption!F14 -> 0.042130854 | G33: =Assumption!G14 -> 0.099681415 | I33: Median EBITDA % | J33: =MEDIAN(C33:G33) -> 0.074498899
B34: EBIT Margin % | C34: =Assumption!C17 -> 0.053409381 | D34: =Assumption!D17 -> 0.016962098 | E34: =Assumption!E17 -> 0.072163203 | F34: =Assumption!F17 -> 0.019870761 | G34: =Assumption!G17 -> 0.076198654 | I34: Median EBIT % | J34: =MEDIAN(C34:G34) -> 0.053409381
B35: EBT Margin % | C35: =Assumption!C20/Assumption!C5 -> 0.049410913 | D35: =Assumption!D20/Assumption!D5 -> 0.012972387 | E35: =Assumption!E20/Assumption!E5 -> 0.067004587 | F35: =Assumption!F20/Assumption!F5 -> 0.012244077 | G35: =Assumption!G20/Assumption!G5 -> 0.070914605 | I35: Median EBT % | J35: =MEDIAN(C35:G35) -> 0.049410913
B36: Net Profit Margin % | C36: =Assumption!C25 -> 0.03372067 | D36: =Assumption!D25 -> 0.0067109998 | E36: =Assumption!E25 -> 0.046853372 | F36: =Assumption!F25 -> 0.0076459224 | G36: =Assumption!G25 -> 0.051312976 | I36: Median PAT % | J36: =MEDIAN(C36:G36) -> 0.03372067
B38: D. Tax Rate
B39: Effective Tax Rate | C39: =Assumption!C22 -> 0.29596351 | D39: =Assumption!D22 -> 0.30672509 | E39: =Assumption!E22 -> 0.27307316 | F39: =Assumption!F22 -> 0.35484504 | G39: =Assumption!G22 -> 0.24798895 | I39: Median Eff. Tax Rate | J39: =MEDIAN(C39:G39) -> 0.29596351
B40: Marginal Tax Rate (Standard) | C40: 0.25 | D40: 0.25 | E40: 0.25 | F40: 0.25 | G40: 0.25
B42: E. Return on Capital
B43: EBIT × (1 - Tax Rate) | C43: =Assumption!C16*(1-Assumption!C40) -> 23452.762 | D43: =Assumption!D16*(1-Assumption!D40) -> 10657.687 | E43: =Assumption!E16*(1-Assumption!E40) -> 41786.152 | F43: =Assumption!F16*(1-Assumption!F40) -> 11232.382 | G43: =Assumption!G16*(1-Assumption!G40) -> 44828.55
B44: Book Equity (Shareholders Funds) | C44: ='Balance Sheet'!G13 -> 133535.18 | D44: ='Balance Sheet'!F13 -> 139720.24 | E44: ='Balance Sheet'!E13 -> 183416.27 | F44: ='Balance Sheet'!D13 -> 186487.32 | G44: ='Balance Sheet'!C13 -> 219517.55
B45: Total Debt (LT + ST Borrowings) | C45: ='Balance Sheet'!G16+'Balance Sheet'!G22 -> 123550.1 | D45: ='Balance Sheet'!F16+'Balance Sheet'!F22 -> 140114.82 | E45: ='Balance Sheet'!E16+'Balance Sheet'!E22 -> 123453.57 | F45: ='Balance Sheet'!D16+'Balance Sheet'!D22 -> 142559.9 | G45: ='Balance Sheet'!C16+'Balance Sheet'!C22 -> 131822.39
...

Sheet Beta
B1: Date | C1: Nifty 50 Daily Returns | D1: IOC.NS Daily Returns
B2: 44565 | C2: 1.02 | D2: 0.97
B3: 44566 | C3: 0.67 | D3: 2.81
B4: 44567 | C4: -1 | D4: 0
B5: 44568 | C5: 0.38 | D5: 1.07 | F5: Beta | G5: =G26 -> 1.0080673
B6: 44571 | C6: 1.07 | D6: 1.01
B7: 44572 | C7: 0.29 | D7: -0.92
B8: 44573 | C8: 0.87 | D8: 0.46
B9: 44574 | C9: 0.25 | D9: 1.68 | F9: SUMMARY OUTPUT
B10: 44575 | C10: -0.01 | D10: 1.77
B11: 44578 | C11: 0.29 | D11: 0.36 | F11: Regression Statistics
B12: 44579 | C12: -1.07 | D12: 0.16 | F12: Multiple R | G12: 0.50335145
B13: 44580 | C13: -0.96 | D13: 0.93 | F13: R Square | G13: 0.25336269
B14: 44581 | C14: -1.01 | D14: 0.32 | F14: Adjusted R Square | G14: 0.25268331
B15: 44582 | C15: -0.79 | D15: -3.03 | F15: Standard Error | G15: 1.5184329
B16: 44585 | C16: -2.66 | D16: -1.11 | F16: Observations | G16: 1101
B17: 44586 | C17: 0.75 | D17: 0.91
B18: 44588 | C18: -0.97 | D18: 1.03 | F18: ANOVA
B19: 44589 | C19: -0.05 | D19: 1.14 | G19: df | H19: SS | I19: MS | J19: F | K19: Significance F
B20: 44592 | C20: 1.39 | D20: 0.89 | F20: Regression | G20: 1 | H20: 859.84832 | I20: 859.84832 | J20: 372.93286 | K20: 8.9555307e-72
B21: 44593 | C21: 1.37 | D21: -2.76 | F21: Residual | G21: 1099 | H21: 2533.8966 | I21: 2.3056384
B22: 44594 | C22: 1.16 | D22: 2.22 | F22: Total | G22: 1100 | H22: 3393.7449
B23: 44595 | C23: -1.24 | D23: 0.16
B24: 44596 | C24: -0.25 | D24: -0.4 | G24: Coefficients | H24: Standard Error | I24: t Stat | J24: P-value | K24: Lower 95% | L24: Upper 95% | M24: Lower 95.0% | N24: Upper 95.0%
B25: 44599 | C25: -1.73 | D25: -1.01 | F25: Intercept | G25: 0.067918738 | H25: 0.045791566 | I25: 1.483215 | J25: 0.138304 | K25: -0.021930033 | L25: 0.15776751 | M25: -0.021930033 | N25: 0.15776751
B26: 44600 | C26: 0.31 | D26: -1.26 | F26: X Variable 1 | G26: 1.0080673 | H26: 0.052200446 | I26: 19.31147 | J26: 8.9555307e-72 | K26: 0.90564353 | L26: 1.1104911 | M26: 0.90564353 | N26: 1.1104911
B27: 44601 | C27: 1.14 | D27: 3.15
B28: 44602 | C28: 0.81 | D28: -0.91
B29: 44603 | C29: -1.31 | D29: 1.75
B30: 44606 | C30: -3.06 | D30: -4.51
B31: 44607 | C31: 3.03 | D31: 1.89
B32: 44608 | C32: -0.17 | D32: 2.32
B33: 44609 | C33: -0.1 | D33: -0.08
B34: 44610 | C34: -0.16 | D34: -0.21
B35: 44613 | C35: -0.4 | D35: -1.61
B36: 44614 | C36: -0.67 | D36: -1.76
B37: 44615 | C37: -0.17 | D37: 0.04
B38: 44616 | C38: -4.78 | D38: -6.1
... B1102: 46196 | C1102: -0.95 | D1102: -0.09

Sheet Ratio Analysis
B1: RATIO ANALYSIS
B3: Ratio | C3: 2022 | D3: 2023 | E3: 2024 | F3: 2025 | G3: 2026 | H3: 5Y Avg
B4: 1. Income Statement Ratios
B5: Revenue from Operations (Net) (₹ Cr.) | C5: ='Profit & Loss'!G10 -> 585484.22 | D5: ='Profit & Loss'!F10 -> 837764.89 | E5: ='Profit & Loss'!E10 -> 772067.59 | F5: ='Profit & Loss'!D10 -> 753695.85 | G5: ='Profit & Loss'!C10 -> 784415.43 | H5: =AVERAGE(C5:G5) -> 746685.6
B6: Revenue Growth YoY (%) | D6: ='Profit & Loss'!F10/'Profit & Loss'!G10-1 -> 0.43089235 | E6: ='Profit & Loss'!E10/'Profit & Loss'!F10-1 -> -0.078419734 | F6: ='Profit & Loss'!D10/'Profit & Loss'!E10-1 -> -0.023795507 | G6: ='Profit & Loss'!C10/'Profit & Loss'!D10-1 -> 0.04075859 | H6: =AVERAGE(D6:G6) -> 0.092358924
B7: EBITDA (₹ Cr.) | C7: ='Profit & Loss'!G12-('Profit & Loss'!G16+'Profit & Loss'!G17+'Profit & Loss'!G18+'Profit & Loss'!G19+'Profit & Loss'!G23) -> 47469.45 | D7: ='Profit & Loss'!F12-('Profit & Loss'!F16+'Profit & Loss'!F17+'Profit & Loss'!F18+'Profit & Loss'!F19+'Profit & Loss'!F23) -> 31382.32 | E7: ='Profit & Loss'!E12-('Profit & Loss'!E16+'Profit & Loss'!E17+'Profit & Loss'!E18+'Profit & Loss'!E19+'Profit & Loss'!E23) -> 75865.24 | F7: ='Profit & Loss'!D12-('Profit & Loss'!D16+'Profit & Loss'!D17+'Profit & Loss'!D18+'Profit & Loss'!D19+'Profit & Loss'!D23) -> 36163.81 | G7: ='Profit & Loss'!C12-('Profit & Loss'!C16+'Profit & Loss'!C17+'Profit & Loss'!C18+'Profit & Loss'!C19+'Profit & Loss'!C23) -> 78191.64 | H7: =AVERAGE(C7:G7) -> 53814.492
B8: EBITDA Margin (%) | C8: =('Profit & Loss'!G12-('Profit & Loss'!G16+'Profit & Loss'!G17+'Profit & Loss'!G18+'Profit & Loss'!G19+'Profit & Loss'!G23))/'Profit & Loss'!G12 -> 0.08054738 | D8: =('Profit & Loss'!F12-('Profit & Loss'!F16+'Profit & Loss'!F17+'Profit & Loss'!F18+'Profit & Loss'!F19+'Profit & Loss'!F23))/'Profit & Loss'!F12 -> 0.037281972 | E8: =('Profit & Loss'!E12-('Profit & Loss'!E16+'Profit & Loss'!E17+'Profit & Loss'!E18+'Profit & Loss'!E19+'Profit & Loss'!E23))/'Profit & Loss'!E12 -> 0.097720177 | F8: =('Profit & Loss'!D12-('Profit & Loss'!D16+'Profit & Loss'!D17+'Profit & Loss'!D18+'Profit & Loss'!D19+'Profit & Loss'!D23))/'Profit & Loss'!D12 -> 0.047702853 | G8: =('Profit & Loss'!C12-('Profit & Loss'!C16+'Profit & Loss'!C17+'Profit & Loss'!C18+'Profit & Loss'!C19+'Profit & Loss'!C23))/'Profit & Loss'!C12 -> 0.099681415 | H8: =AVERAGE(C8:G8) -> 0.072586759
B9: EBITDA Growth YoY (%) | D9: =('Profit & Loss'!F12-('Profit & Loss'!F16+'Profit & Loss'!F17+'Profit & Loss'!F18+'Profit & Loss'!F19+'Profit & Loss'!F23))/('Profit & Loss'!G12-('Profit & Loss'!G16+'Profit & Loss'!G17+'Profit & Loss'!G18+'Profit & Loss'!G19+'Profit & Loss'!G23))-1 -> -0.33889438 | E9: =('Profit & Loss'!E12-('Profit & Loss'!E16+'Profit & Loss'!E17+'Profit & Loss'!E18+'Profit & Loss'!E19+'Profit & Loss'!E23))/('Profit & Loss'!F12-('Profit & Loss'!F16+'Profit & Loss'!F17+'Profit & Loss'!F18+'Profit & Loss'!F19+'Profit & Loss'!F23))-1 -> 1.4174516 | F9: =('Profit & Loss'!D12-('Profit & Loss'!D16+'Profit & Loss'!D17+'Profit & Loss'!D18+'Profit & Loss'!D19+'Profit & Loss'!D23))/('Profit & Loss'!E12-('Profit & Loss'!E16+'Profit & Loss'!E17+'Profit & Loss'!E18+'Profit & Loss'!E19+'Profit & Loss'!E23))-1 -> -0.52331516 | G9: =('Profit & Loss'!C12-('Profit & Loss'!C16+'Profit & Loss'!C17+'Profit & Loss'!C18+'Profit & Loss'!C19+'Profit & Loss'!C23))/('Profit & Loss'!D12-('Profit & Loss'!D16+'Profit & Loss'!D17+'Profit & Loss'!D18+'Profit & Loss'!D19+'Profit & Loss'!D23))-1 -> 1.1621516 | H9: =AVERAGE(D9:G9) -> 0.42934842
B10: EBIT (₹ Cr.) | C10: =('Profit & Loss'!G12-('Profit & Loss'!G16+'Profit & Loss'!G17+'Profit & Loss'!G18+'Profit & Loss'!G19+'Profit & Loss'!G23))-'Profit & Loss'!G22 -> 35121.87 | D10: =('Profit & Loss'!F12-('Profit & Loss'!F16+'Profit & Loss'!F17+'Profit & Loss'!F18+'Profit & Loss'!F19+'Profit & Loss'!F23))-'Profit & Loss'!F22 -> 18201.27 | E10: =('Profit & Loss'!E12-('Profit & Loss'!E16+'Profit & Loss'!E17+'Profit & Loss'!E18+'Profit & Loss'!E19+'Profit & Loss'!E23))-'Profit & Loss'!E22 -> 59999.13 | F10: =('Profit & Loss'!D12-('Profit & Loss'!D16+'Profit & Loss'!D17+'Profit & Loss'!D18+'Profit & Loss'!D19+'Profit & Loss'!D23))-'Profit & Loss'!D22 -> 19386.47 | G10: =('Profit & Loss'!C12-('Profit & Loss'!C16+'Profit & Loss'!C17+'Profit & Loss'!C18+'Profit & Loss'!C19+'Profit & Loss'!C23))-'Profit & Loss'!C22 -> 59771.4 | H10: =AVERAGE(C10:G10) -> 38496.028
B11: EBIT Margin (%) | C11: =(('Profit & Loss'!G12-('Profit & Loss'!G16+'Profit & Loss'!G17+'Profit & Loss'!G18+'Profit & Loss'!G19+'Profit & Loss'!G23))-'Profit & Loss'!G22)/'Profit & Loss'!G12 -> 0.05959569 | D11: =(('Profit & Loss'!F12-('Profit & Loss'!F16+'Profit & Loss'!F17+'Profit & Loss'!F18+'Profit & Loss'!F19+'Profit & Loss'!F23))-'Profit & Loss'!F22)/'Profit & Loss'!F12 -> 0.021622979 | E11: =(('Profit & Loss'!E12-('Profit & Loss'!E16+'Profit & Loss'!E17+'Profit & Loss'!E18+'Profit & Loss'!E19+'Profit & Loss'!E23))-'Profit & Loss'!E22)/'Profit & Loss'!E12 -> 0.077283425 | F11: =(('Profit & Loss'!D12-('Profit & Loss'!D16+'Profit & Loss'!D17+'Profit & Loss'!D18+'Profit & Loss'!D19+'Profit & Loss'!D23))-'Profit & Loss'!D22)/'Profit & Loss'!D12 -> 0.025572248 | G11: =(('Profit & Loss'!C12-('Profit & Loss'!C16+'Profit & Loss'!C17+'Profit & Loss'!C18+'Profit & Loss'!C19+'Profit & Loss'!C23))-'Profit & Loss'!C22)/'Profit & Loss'!C12 -> 0.076198654 | H11: =AVERAGE(C11:G11) -> 0.052054599
B12: Finance Costs (₹ Cr.) | C12: ='Profit & Loss'!G20 -> 5423.26 | D12: ='Profit & Loss'!F20 -> 7541.36 | E12: ='Profit & Loss'!E20 -> 7825.65 | F12: ='Profit & Loss'!D20 -> 9261.93 | G12: ='Profit & Loss'!C20 -> 8307.88 | H12: =AVERAGE(C12:G12) -> 7672.016
B13: Finance Costs % Revenue | C13: ='Profit & Loss'!G20/'Profit & Loss'!G12 -> 0.0092023267 | D13: ='Profit & Loss'!F20/'Profit & Loss'!F12 -> 0.0089590817 | E13: ='Profit & Loss'!E20/'Profit & Loss'!E12 -> 0.01008003 | F13: ='Profit & Loss'!D20/'Profit & Loss'!D12 -> 0.0122172 | G13: ='Profit & Loss'!C20/'Profit & Loss'!C12 -> 0.010591174 | H13: =AVERAGE(C13:G13) -> 0.010209962
B14: Depreciation & Amortisation (₹ Cr.) | C14: ='Profit & Loss'!G22 -> 12347.58 | D14: ='Profit & Loss'!F22 -> 13181.05 | E14: ='Profit & Loss'!E22 -> 15866.11 | F14: ='Profit & Loss'!D22 -> 16777.34 | G14: ='Profit & Loss'!C22 -> 18420.24 | H14: =AVERAGE(C14:G14) -> 15318.464
B15: Depreciation % of Revenue | C15: ='Profit & Loss'!G22/'Profit & Loss'!G12 -> 0.02095169 | D15: ='Profit & Loss'!F22/'Profit & Loss'!F12 -> 0.015658993 | E15: ='Profit & Loss'!E22/'Profit & Loss'!E12 -> 0.020436752 | F15: ='Profit & Loss'!D22/'Profit & Loss'!D12 -> 0.022130605 | G15: ='Profit & Loss'!C22/'Profit & Loss'!C12 -> 0.023482761 | H15: =AVERAGE(C15:G15) -> 0.02053216
B16: PBT (₹ Cr.) | C16: ='Profit & Loss'!G27 -> 33053.06 | D16: ='Profit & Loss'!F27 -> 14175.5 | E16: ='Profit & Loss'!E27 -> 55741.86 | F16: ='Profit & Loss'!D27 -> 15303.02 | G16: ='Profit & Loss'!C27 -> 54496.52 | H16: =AVERAGE(C16:G16) -> 34553.992
B17: PBT Margin (%) | C17: ='Profit & Loss'!G27/'Profit & Loss'!G12 -> 0.05608528 | D17: ='Profit & Loss'!F27/'Profit & Loss'!F12 -> 0.016840393 | E17: ='Profit & Loss'!E27/'Profit & Loss'!E12 -> 0.071799739 | F17: ='Profit & Loss'!D27/'Profit & Loss'!D12 -> 0.020185863 | G17: ='Profit & Loss'!C27/'Profit & Loss'!C12 -> 0.069474054 | H17: =AVERAGE(C17:G17) -> 0.046877066
B18: Net Profit (Consolidated PAT) (₹ Cr.) | C18: ='Profit & Loss'!G37 -> 25102.23 | D18: ='Profit & Loss'!F37 -> 9792.12 | E18: ='Profit & Loss'!E37 -> 41729.69 | F18: ='Profit & Loss'!D37 -> 13597.84 | G18: ='Profit & Loss'!C37 -> 42096.26 | H18: =AVERAGE(C18:G18) -> 26463.628
B19: Net Profit Margin (%) | C19: ='Profit & Loss'!G37/'Profit & Loss'!G12 -> 0.042594108 | D19: ='Profit & Loss'!F37/'Profit & Loss'!F12 -> 0.011632969 | E19: ='Profit & Loss'!E37/'Profit & Loss'!E12 -> 0.053751002 | F19: ='Profit & Loss'!D37/'Profit & Loss'!D12 -> 0.017936599 | G19: ='Profit & Loss'!C37/'Profit & Loss'!C12 -> 0.053665772 | H19: =AVERAGE(C19:G19) -> 0.03591609
B20: PAT Growth YoY (%) | D20: ='Profit & Loss'!F37/'Profit & Loss'!G37-1 -> -0.60991035 | E20: ='Profit & Loss'!E37/'Profit & Loss'!F37-1 -> 3.2615583 | F20: ='Profit & Loss'!D37/'Profit & Loss'!E37-1 -> -0.67414472 | G20: ='Profit & Loss'!C37/'Profit & Loss'!D37-1 -> 2.0958049 | H20: =AVERAGE(D20:G20) -> 1.018327
B21: Basic EPS (₹) | C21: ='Profit & Loss'!G40 -> 27 | D21: ='Profit & Loss'!F40 -> 7 | E21: ='Profit & Loss'!E40 -> 30 | F21: ='Profit & Loss'!D40 -> 10 | G21: ='Profit & Loss'!C40 -> 31 | H21: =AVERAGE(C21:G21) -> 21
B22: EPS Growth YoY (%) | D22: ='Profit & Loss'!F40/'Profit & Loss'!G40-1 -> -0.74074074 | E22: ='Profit & Loss'!E40/'Profit & Loss'!F40-1 -> 3.2857143 | F22: ='Profit & Loss'!D40/'Profit & Loss'!E40-1 -> -0.66666667 | G22: ='Profit & Loss'!C40/'Profit & Loss'!D40-1 -> 2.1 | H22: =AVERAGE(D22:G22) -> 0.99457672
B24: 2. Balance Sheet Ratios
B25: Total Shareholders Funds (₹ Cr.) | C25: ='Balance Sheet'!G13 -> 133535.18 | D25: ='Balance Sheet'!F13 -> 139720.24 | E25: ='Balance Sheet'!E13 -> 183416.27 | F25: ='Balance Sheet'!D13 -> 186487.32 | G25: ='Balance Sheet'!C13 -> 219517.55 | H25: =AVERAGE(C25:G25) -> 172535.31
B26: Total Equity incl. Minority Interest (₹ Cr.) | C26: ='Balance Sheet'!G13+'Balance Sheet'!G14 -> 135126.65 | D26: ='Balance Sheet'!F13+'Balance Sheet'!F14 -> 143214.34 | E26: ='Balance Sheet'!E13+'Balance Sheet'!E14 -> 188162.98 | F26: ='Balance Sheet'!D13+'Balance Sheet'!D14 -> 191024.66 | G26: ='Balance Sheet'!C13+'Balance Sheet'!C14 -> 225547.11 | H26: =AVERAGE(C26:G26) -> 176615.15
B27: Long Term Borrowings (₹ Cr.) | C27: ='Balance Sheet'!G16 -> 55944.54 | D27: ='Balance Sheet'!F16 -> 63312.94 | E27: ='Balance Sheet'!E16 -> 46792.9 | F27: ='Balance Sheet'!D16 -> 51755.75 | G27: ='Balance Sheet'!C16 -> 63652.1 | H27: =AVERAGE(C27:G27) -> 56291.646
B28: Short Term Borrowings (₹ Cr.) | C28: ='Balance Sheet'!G22 -> 67605.56 | D28: ='Balance Sheet'!F22 -> 76801.88 | E28: ='Balance Sheet'!E22 -> 76660.67 | F28: ='Balance Sheet'!D22 -> 90804.15 | G28: ='Balance Sheet'!C22 -> 68170.29 | H28: =AVERAGE(C28:G28) -> 76008.51
B29: Gross Debt (₹ Cr.) | C29: ='Balance Sheet'!G16+'Balance Sheet'!G22 -> 123550.1 | D29: ='Balance Sheet'!F16+'Balance Sheet'!F22 -> 140114.82 | E29: ='Balance Sheet'!E16+'Balance Sheet'!E22 -> 123453.57 | F29: ='Balance Sheet'!D16+'Balance Sheet'!D22 -> 142559.9 | G29: ='Balance Sheet'!C16+'Balance Sheet'!C22 -> 131822.39 | H29: =AVERAGE(C29:G29) -> 132300.16
B30: Cash & Cash Equivalents (₹ Cr.) | C30: ='Balance Sheet'!G44 -> 1820.14 | D30: ='Balance Sheet'!F44 -> 2096.64 | E30: ='Balance Sheet'!E44 -> 3158.79 | F30: ='Balance Sheet'!D44 -> 3304.94 | G30: ='Balance Sheet'!C44 -> 4414.66 | H30: =AVERAGE(C30:G30) -> 2959.034
B31: Net Debt (₹ Cr.) | C31: ='Balance Sheet'!G16+'Balance Sheet'!G22-'Balance Sheet'!G44 -> 121729.96 | D31: ='Balance Sheet'!F16+'Balance Sheet'!F22-'Balance Sheet'!F44 -> 138018.18 | E31: ='Balance Sheet'!E16+'Balance Sheet'!E22-'Balance Sheet'!E44 -> 120294.78 | F31: ='Balance Sheet'!D16+'Balance Sheet'!D22-'Balance Sheet'!D44 -> 139254.96 | G31: ='Balance Sheet'!C16+'Balance Sheet'!C22-'Balance Sheet'!C44 -> 127407.73 | H31: =AVERAGE(C31:G31) -> 129341.12
B32: Inventories (₹ Cr.) | C32: ='Balance Sheet'!G42 -> 111736.51 | D32: ='Balance Sheet'!F42 -> 121107.58 | E32: ='Balance Sheet'!E42 -> 121375.83 | F32: ='Balance Sheet'!D42 -> 113878.49 | G32: ='Balance Sheet'!C42 -> 117132.72 | H32: =AVERAGE(C32:G32) -> 117046.23
B33: Trade Receivables (₹ Cr.) | C33: ='Balance Sheet'!G43 -> 18700.42 | D33: ='Balance Sheet'!F43 -> 16271.21 | E33: ='Balance Sheet'!E43 -> 13831.45 | F33: ='Balance Sheet'!D43 -> 18550.96 | G33: ='Balance Sheet'!C43 -> 14634.83 | H33: =AVERAGE(C33:G33) -> 16397.774
B34: Trade Payables (₹ Cr.) | C34: ='Balance Sheet'!G23 -> 49045.91 | D34: ='Balance Sheet'!F23 -> 54734.1 | E34: ='Balance Sheet'!E23 -> 59454.1 | F34: ='Balance Sheet'!D23 -> 60534.94 | G34: ='Balance Sheet'!C23 -> 57368.69 | H34: =AVERAGE(C34:G34) -> 56227.548
B35: Total Assets (₹ Cr.) | C35: ='Balance Sheet'!G48 -> 410624.85 | D35: ='Balance Sheet'!F48 -> 441762.09 | E35: ='Balance Sheet'!E48 -> 482362 | F35: ='Balance Sheet'!D48 -> 506867.05 | G35: ='Balance Sheet'!C48 -> 528954.96 | H35: =AVERAGE(C35:G35) -> 474114.19
B36: Fixed Assets (Net Block) (₹ Cr.) | C36: ='Balance Sheet'!G34 -> 207982.58 | D36: ='Balance Sheet'!F34 -> 231180 | E36: ='Balance Sheet'!E34 -> 257029.17 | F36: ='Balance Sheet'!D34 -> 279062.41 | G36: ='Balance Sheet'!C34 -> 294617.69 | H36: =AVERAGE(C36:G36) -> 253974.37
B38: 3. Return Ratios
B39: RoE: PAT / Shareholders Funds (%) | C39: ='Profit & Loss'!G37/'Balance Sheet'!G13 -> 0.18798215 | D39: ='Profit & Loss'!F37/'Balance Sheet'!F13 -> 0.070083762 | E39: ='Profit & Loss'!E37/'Balance Sheet'!E13 -> 0.22751357 | F39: ='Profit & Loss'!D37/'Balance Sheet'!D13 -> 0.072915628 | G39: ='Profit & Loss'!C37/'Balance Sheet'!C13 -> 0.19176717 | H39: =AVERAGE(C39:G39) -> 0.15005246
B40: RoA: PAT / Total Assets (%) | C40: ='Profit & Loss'!G37/'Balance Sheet'!G48 -> 0.061131785 | D40: ='Profit & Loss'!F37/'Balance Sheet'!F48 -> 0.022166049 | E40: ='Profit & Loss'!E37/'Balance Sheet'!E48 -> 0.086511147 | F40: ='Profit & Loss'!D37/'Balance Sheet'!D48 -> 0.026827232 | G40: ='Profit & Loss'!C37/'Balance Sheet'!C48 -> 0.079583827 | H40: =AVERAGE(C40:G40) -> 0.055244008
B41: RoCE: EBIT / Capital Employed (%) | C41: =(('Profit & Loss'!G12-('Profit & Loss'!G16+'Profit & Loss'!G17+'Profit & Loss'!G18+'Profit & Loss'!G19+'Profit & Loss'!G23))-'Profit & Loss'!G22)/('Balance Sheet'!G48-'Balance Sheet'!G26) -> 0.16076279 | D41: =(('Profit & Loss'!F12-('Profit & Loss'!F16+'Profit & Loss'!F17+'Profit & Loss'!F18+'Profit & Loss'!F19+'Profit & Loss'!F23))-'Profit & Loss'!F22)/('Balance Sheet'!F48-'Balance Sheet'!F26) -> 0.07741803 | E41: =(('Profit & Loss'!E12-('Profit & Loss'!E16+'Profit & Loss'!E17+'Profit & Loss'!E18+'Profit & Loss'!E19+'Profit & Loss'!E23))-'Profit & Loss'!E22)/('Balance Sheet'!E48-'Balance Sheet'!E26) -> 0.2255962 | F41: =(('Profit & Loss'!D12-('Profit & Loss'!D16+'Profit & Loss'!D17+'Profit & Loss'!D18+'Profit & Loss'!D19+'Profit & Loss'!D23))-'Profit & Loss'!D22)/('Balance Sheet'!D48-'Balance Sheet'!D26) -> 0.070176596 | G41: =(('Profit & Loss'!C12-('Profit & Loss'!C16+'Profit & Loss'!C17+'Profit & Loss'!C18+'Profit & Loss'!C19+'Profit & Loss'!C23))-'Profit & Loss'!C22)/('Balance Sheet'!C48-'Balance Sheet'!C26) -> 0.18810876 | H41: =AVERAGE(C41:G41) -> 0.14441247
B43: 4. Leverage & Coverage Ratios
